Workbook

Sheet Resumo 100%
B3: Estimativa de Custo 100% | J3: Quantidade | R3: Preço R$ nacionalizado
J5: 100 | K5: 5.8
J6: 300 | K6: 2.1
J7: 300 | K7: 10
E8: USO: REVENDA | G8: CONSIDERAR ICMS 6% | J8: 300 | K8: 10
C9: PRODUTO: CABEÇOTES E BLOCOS | E9: PORTO SAÍDA: SHANGHAI | G9: =TODAY() -> 46148 | J9: 300 | K9: 10
C10: FRETE: FCL | E10: PORTO ENTRADA: PARANAGUÁ | G10: SIMULAÇÃO 100% | J10: 100 | K10: 11.5
J11: 100 | K11: 11.5
B12: REFERÊNCIA CÁLCULO BASE | C12: R$/USD: | D12: ='Rateio Custos Fixos'!B3 -> 5.1 | E12: NCM: | F12: ='LISTA DE COMPRAS'!D6 -> 84099959 | K12: 0
B13: VALORES ADUANEIROS | I13: ITEM | J13: 100 | K13: 10.8 | L13: QTY | O13: BRL UNIT PRICE
B14: DISCRIMINAÇÃO | D14: UNIDADE | E14: PREÇO USD | F14: PREÇO TOTAL USD | G14: R$ | I14: ='[1]Lista de Compra'!B4 -> 1 | J14: 100 | K14: 10.8 | L14: ='[1]Lista de Compra'!J4 -> 15 | M14: =K14*L14*'[1]Rateio Custos Fixos'!$B$26 -> 777.1464 | N14: =M14+(M14*$K$11) -> 9714.33 | O14: =N14/L14 -> 647.622
D15: ='LISTA DE COMPRAS'!J4 -> 425 | E15: - | F15: ='LISTA DE COMPRAS'!M4 -> 144359.55 | G15: =F15*$D$12 -> 736233.7 | J15: 100 | K15: 7.6
B16: TOTAL FOB | F16: =SUM(F15:F15) -> 144359.55 | G16: =SUM(G15:G15) -> 736233.7 | J16: 100 | K16: 14.4
B17: PRODUTO + FRETE | G17: =G16+G19 -> 755729 | I17: ='[1]Lista de Compra'!B6 -> 3 | J17: 100 | K17: 7.6 | L17: ='[1]Lista de Compra'!J6 -> 15 | M17: =K17*L17*'[1]Rateio Custos Fixos'!$B$26 -> 546.8808 | N17: =M17+(M17*$K$11) -> 6836.01 | O17: =N17/L17 -> 455.734
B18: Seguro | I18: ='[1]Lista de Compra'!B7 -> 4 | J18: 100 | K18: 14.4 | L18: ='[1]Lista de Compra'!J7 -> 15 | M18: =K18*L18*'[1]Rateio Custos Fixos'!$B$26 -> 1036.1952 | N18: =M18+(M18*$K$11) -> 12952.44 | O18: =N18/L18 -> 863.496
B19: Frete | F19: ='Rateio Custos Fixos'!G5 -> 3822.6078 | G19: =F19*D12 -> 19495.3 | I19: ='[1]Lista de Compra'!B8 -> 5 | J19: 100 | K19: 17.8 | L19: ='[1]Lista de Compra'!J8 -> 15 | M19: =K19*L19*'[1]Rateio Custos Fixos'!$B$26 -> 1280.8524 | N19: =M19+(M19*$K$11) -> 16010.655 | O19: =N19/L19 -> 1067.377
B20: TOTAL VALOR ADUANEIRO | G20: =G17 -> 755729 | I20: ='[1]Lista de Compra'!B9 -> 6 | J20: 100 | K20: 17.8 | L20: ='[1]Lista de Compra'!J9 -> 15 | M20: =K20*L20*'[1]Rateio Custos Fixos'!$B$26 -> 1280.8524 | N20: =M20+(M20*$K$11) -> 16010.655 | O20: =N20/L20 -> 1067.377
B21: IMPOSTOS | J21: 100 | K21: 4.4
B22: IMPOSTOS | C22: PERCENTUAL | G22: VALOR (R$) | J22: 100 | K22: 6.4
B23: IMPOSTO. IMPORTAÇÃO | C23: ='LISTA DE COMPRAS'!E5 -> 0.16 | G23: ='Est. Cust. Naci.'!R$4 -> 120916.64 | J23: 100 | K23: 4.6
B24: IPI | C24: ='LISTA DE COMPRAS'!F5 -> 0.0301 | G24: ='Est. Cust. Naci.'!S$4 -> 26387.034 | J24: 100 | K24: 5.1
B25: PIS | C25: ='LISTA DE COMPRAS'!G5 -> 0.0312 | G25: ='Est. Cust. Naci.'!T$4 -> 27351.344 | K25: 0
B26: COFINS | C26: ='LISTA DE COMPRAS'!H5 -> 0.1497 | G26: ='Est. Cust. Naci.'!U$4 -> 131233.85 | J26: 100 | K26: 9.3
B27: ICMS | C27: ='LISTA DE COMPRAS'!I5 -> 0.06 | G27: ='Est. Cust. Naci.'!V$4 -> 45343.74 | J27: 100 | K27: 9.3
B28: TOTAL VALOR IMPOSTOS | G28: =SUM(G23:G27) -> 351232.61 | J28: 100 | K28: 11
B29: DESPESAS ADUANEIRAS E LOGÍSTICAS | J29: 100 | K29: 11
B30: TAXA SISCOMEX | G30: ='Rateio Custos Fixos'!F$11 -> 214.5 | J30: 100 | K30: 9.8
B31: LIBERAÇÃO DE B/L | G31: ='Rateio Custos Fixos'!G$11 -> 540 | J31: 100 | K31: 10.2
B32: T.H.C|CAPATAZIA | G32: ='Rateio Custos Fixos'!H$11 -> 1547 | J32: 100 | K32: 10.2
B33: ISPS | G33: ='Rateio Custos Fixos'!I$11 -> 60 | J33: 100 | K33: 11
B34: DAMAGE PROTECTION | G34: ='Rateio Custos Fixos'!J$11 -> 300 | J34: 100 | K34: 13.6
B35: DESCONSOLIDAÇÃO | G35: ='Rateio Custos Fixos'!K$11 -> 400 | K35: 0
B36: DEVOLUÇÃO DE CONTAINER | G36: ='Rateio Custos Fixos'!L$11 -> 774.9 | K36: 0
B37: TRS | G37: ='Rateio Custos Fixos'!M$11 -> 140 | J37: 100 | K37: 5.4
B38: AFRMM | C38: 0.08 | G38: ='Rateio Custos Fixos'!N66 -> 1559.624 | J38: 100 | K38: 4.7
B39: ARMAZENAGEM TCP | G39: 0 | H39: 5 DIAS DE ARMAZENAGEM | J39: 100 | K39: 9.3
B40: SCANNER TCP | G40: ='Rateio Custos Fixos'!P11 -> 756.95 | K40: 0
B41: HANDLING - TCP | G41: ='Rateio Custos Fixos'!Q11 -> 225 | J41: 100 | K41: 4.4
B42: PESAGEM TCP | G42: ='Rateio Custos Fixos'!R11 -> 117.45 | J42: 100 | K42: 13.5
B43: TAXA DO PARCEIRO - PARANAGUÁ | G43: ='Rateio Custos Fixos'!S11 -> 286 | J43: 100 | K43: 15.2
...

Sheet LISTA DE COMPRAS
A1: LISTA DE COMPRA
A3: Item | B3: Estimativa de Custo 100% | C3: Produto | D3: NCM | E3: II | F3: IPI | G3: PIS | H3: COFINS | I3: ICMS | J3: Quantidade | K3: Preço Unitário | L3: Preço Unitário Sub 50% | M3: Preço total por produto | N3: Preço total por produto | O3: Preço total por produto Sub | P3: % Rateio Quantidade | Q3: % Rateio Preço | R3: Preço R$ nacionalizado
J4: =SUM(J5:J57) -> 425 | K4: =SUM(K5:K57) -> 17152.75 | M4: =SUM(M5:M57) -> 144359.55 | N4: =F59 -> 5.1 | P4: 1 | Q4: 1
A5: 1 | C5: Cylinder Head Cummins ISB 5.9/6.7 | D5: 84099959 | E5: 0.16 | F5: 0.0301 | G5: 0.0312 | H5: 0.1497 | I5: 0.06 | J5: 30 | K5: 328.57 | L5: =K5/2 -> 164.285 | M5: =K5*J5 -> 9857.1 | N5: =M5*$N$4 -> 50271.21 | O5: =L5*J5*$N$4 -> 25135.605 | P5: =(J5*$P$4)/$J$4 -> 0.070588235 | Q5: =(K5*$Q$4)/$K$4 -> 0.019155529 | R5: ='Est. Cust. Naci.'!AV6 -> 2541.1748
A6: 2 | C6: Cylinder Head Volvo FH13 | D6: 84099959 | E6: 0.16 | F6: 0.0301 | G6: 0.0312 | H6: 0.1497 | I6: 0.06 | J6: 30 | K6: 1275 | M6: =K6*J6 -> 38250 | N6: =M6*$N$4 -> 195075 | O6: =L6*J6*$N$4 -> 0 | P6: =(J6*$P$4)/$J$4 -> 0.070588235 | Q6: =(K6*$Q$4)/$K$4 -> 0.074332104 | R6: ='Est. Cust. Naci.'!AV7 -> 9860.9059
A7: 3 | C7: Cylinder Head Cummins 4BT | D7: 84099959 | E7: 0.16 | F7: 0.0301 | G7: 0.0312 | H7: 0.1497 | I7: 0.06 | J7: 20 | K7: 200 | M7: =K7*J7 -> 4000 | N7: =M7*$N$4 -> 20400 | O7: =L7*J7*$N$4 -> 0 | P7: =(J7*$P$4)/$J$4 -> 0.047058824 | Q7: =(K7*$Q$4)/$K$4 -> 0.011659938 | R7: ='Est. Cust. Naci.'!AV8 -> 1555.3356
A8: 4 | C8: Cylinder Head MB 457/460 Axor | D8: 84099959 | E8: 0.16 | F8: 0.0301 | G8: 0.0312 | H8: 0.1497 | I8: 0.06 | J8: 240 | K8: 132.43 | M8: =K8*J8 -> 31783.2 | N8: =M8*$N$4 -> 162094.32 | O8: =L8*J8*$N$4 -> 0 | P8: =(J8*$P$4)/$J$4 -> 0.56470588 | Q8: =(K8*$Q$4)/$K$4 -> 0.0077206279 | R8: ='Est. Cust. Naci.'!AV9 -> 1014.3389
A9: 5 | C9: CABECOTE CUMMINS SERIE C | D9: 84099959 | E9: 0.16 | F9: 0.0301 | G9: 0.0312 | H9: 0.1497 | I9: 0.06 | J9: 20 | K9: 229.43 | M9: =K9*J9 -> 4588.6 | N9: =M9*$N$4 -> 23401.86 | O9: =L9*J9*$N$4 -> 0 | P9: =(J9*$P$4)/$J$4 -> 0.047058824 | Q9: =(K9*$Q$4)/$K$4 -> 0.013375698 | R9: ='Est. Cust. Naci.'!AV10 -> 1784.2032
A10: 6 | C10: CABECOTE MAN 4CIL D08 | D10: 84099959 | E10: 0.16 | F10: 0.0301 | G10: 0.0312 | H10: 0.1497 | I10: 0.06 | J10: 3 | K10: 707.96 | M10: =K10*J10 -> 2123.88 | N10: =M10*$N$4 -> 10831.788 | O10: =L10*J10*$N$4 -> 0 | P10: =(J10*$P$4)/$J$4 -> 0.0070588235 | Q10: =(K10*$Q$4)/$K$4 -> 0.041273848 | R10: ='Est. Cust. Naci.'!AV11 -> 6018.69
A11: 7 | C11: CABECOTE MAN 6CIL D08 | D11: 84099959 | E11: 0.16 | F11: 0.0301 | G11: 0.0312 | H11: 0.1497 | I11: 0.06 | J11: 10 | K11: 583.41 | M11: =K11*J11 -> 5834.1 | N11: =M11*$N$4 -> 29753.91 | O11: =L11*J11*$N$4 -> 0 | P11: =(J11*$P$4)/$J$4 -> 0.023529412 | Q11: =(K11*$Q$4)/$K$4 -> 0.034012622 | R11: ='Est. Cust. Naci.'!AV12 -> 4611.6108
A12: 8 | C12: CABECOTE CUMMINS 6BT | D12: 84099959 | E12: 0.16 | F12: 0.0301 | G12: 0.0312 | H12: 0.1497 | I12: 0.06 | J12: 20 | K12: 152.08 | M12: =K12*J12 -> 3041.6 | N12: =M12*$N$4 -> 15512.16 | O12: =L12*J12*$N$4 -> 0 | P12: =(J12*$P$4)/$J$4 -> 0.047058824 | Q12: =(K12*$Q$4)/$K$4 -> 0.0088662168 | R12: ='Est. Cust. Naci.'!AV13 -> 1182.6772
A13: 9 | C13: CABECOTE MAN TGX 460 | D13: 84099959 | E13: 0.16 | F13: 0.0301 | G13: 0.0312 | H13: 0.1497 | I13: 0.06 | J13: 5 | K13: 1088.16 | M13: =K13*J13 -> 5440.8 | N13: =M13*$N$4 -> 27748.08 | O13: =L13*J13*$N$4 -> 0 | P13: =(J13*$P$4)/$J$4 -> 0.011764706 | Q13: =(K13*$Q$4)/$K$4 -> 0.06343939 | R13: ='Est. Cust. Naci.'!AV14 -> 8879.8027
A14: 10 | C14: CABECOTE CATERPILAR C 7 | D14: 84099959 | E14: 0.16 | F14: 0.0301 | G14: 0.0312 | H14: 0.1497 | I14: 0.06 | J14: 5 | K14: 938.7 | M14: =K14*J14 -> 4693.5 | N14: =M14*$N$4 -> 23936.85 | O14: =L14*J14*$N$4 -> 0 | P14: =(J14*$P$4)/$J$4 -> 0.011764706 | Q14: =(K14*$Q$4)/$K$4 -> 0.054725919 | R14: ='Est. Cust. Naci.'!AV15 -> 7660.1518
A15: 11 | C15: CABECOTE CATERPILAR C6.6 | D15: 84099959 | E15: 0.16 | F15: 0.0301 | G15: 0.0312 | H15: 0.1497 | I15: 0.06 | J15: 3 | K15: 812.84 | M15: =K15*J15 -> 2438.52 | N15: =M15*$N$4 -> 12436.452 | O15: =L15*J15*$N$4 -> 0 | P15: =(J15*$P$4)/$J$4 -> 0.0070588235 | Q15: =(K15*$Q$4)/$K$4 -> 0.04738832 | R15: ='Est. Cust. Naci.'!AV16 -> 6910.3225
A16: 12 | C16: BLOCO MB 352 A C/ ESGUICHO | D16: 84099112 | E16: 0.16 | F16: 0.0377 | G16: 0.0312 | H16: 0.1497 | I16: 0.06 | J16: 0 | K16: 634.54 | M16: =K16*J16 -> 0 | N16: =M16*$N$4 -> 0 | O16: =L16*J16*$N$4 -> 0 | P16: =(J16*$P$4)/$J$4 -> 0 | Q16: =(K16*$Q$4)/$K$4 -> 0.036993485 | R16: ='Est. Cust. Naci.'!AV17 -> #DIV/0!
A17: 13 | C17: BLOCO MB 366 A C/ ESGUICHO | D17: 84099112 | E17: 0.16 | F17: 0.0377 | G17: 0.0312 | H17: 0.1497 | I17: 0.06 | J17: 0 | K17: 634.54 | M17: =K17*J17 -> 0 | N17: =M17*$N$4 -> 0 | O17: =L17*J17*$N$4 -> 0 | P17: =(J17*$P$4)/$J$4 -> 0 | Q17: =(K17*$Q$4)/$K$4 -> 0.036993485 | R17: ='Est. Cust. Naci.'!AV18 -> #DIV/0!
... A28: 24 | C28: BLOCO MOTOR SCANIA DC 12 | D28: 84099112 | E28: 0.16 | F28: 0.0377 | G28: 0.0312 | H28: 0.1497 | I28: 0.06 | J28: 5 | K28: 1590 | M28: =K28*J28 -> 7950 | N28: =M28*$N$4 -> 40545 | O28: =L28*J28*$N$4 -> 0 | P28: =(J28*$P$4)/$J$4 -> 0.011764706 | Q28: =(K28*$Q$4)/$K$4 -> 0.092696506 | R28: ='Est. Cust. Naci.'!AV29 -> 12975.009
A29: 25 | Q29: =(K29*$Q$4)/$K$4 -> 0 | R29: ='Est. Cust. Naci.'!AV30 -> #DIV/0!
A30: 26 | Q30: =(K30*$Q$4)/$K$4 -> 0 | R30: ='Est. Cust. Naci.'!AV31 -> #DIV/0!
A31: 27 | Q31: =(K31*$Q$4)/$K$4 -> 0 | R31: ='Est. Cust. Naci.'!AV32 -> #DIV/0!
A32: 28 | Q32: =(K32*$Q$4)/$K$4 -> 0 | R32: ='Est. Cust. Naci.'!AV33 -> #DIV/0!
A33: 29 | Q33: =(K33*$Q$4)/$K$4 -> 0 | R33: ='Est. Cust. Naci.'!AV34 -> #DIV/0!
A34: 30 | Q34: =(K34*$Q$4)/$K$4 -> 0 | R34: ='Est. Cust. Naci.'!AV35 -> #DIV/0!
A35: 31 | Q35: =(K35*$Q$4)/$K$4 -> 0 | R35: ='Est. Cust. Naci.'!AV36 -> #DIV/0!
A36: 32 | Q36: =(K36*$Q$4)/$K$4 -> 0 | R36: ='Est. Cust. Naci.'!AV37 -> #DIV/0!
A37: 33 | Q37: =(K37*$Q$4)/$K$4 -> 0 | R37: ='Est. Cust. Naci.'!AV38 -> #DIV/0!
A38: 34 | Q38: =(K38*$Q$4)/$K$4 -> 0 | R38: ='Est. Cust. Naci.'!AV39 -> #DIV/0!
A39: 35 | Q39: =(K39*$Q$4)/$K$4 -> 0 | R39: ='Est. Cust. Naci.'!AV40 -> #DIV/0!
A40: 36 | Q40: =(K40*$Q$4)/$K$4 -> 0 | R40: ='Est. Cust. Naci.'!AV41 -> #DIV/0!
... A57: 53 | Q57: =(K57*$Q$4)/$K$4 -> 0 | R57: ='Est. Cust. Naci.'!AV58 -> #DIV/0!
E59: #VALUE! | F59: 5.1

Sheet Est. Cust. Naci.
C2: DETALHES DO PRODUTO | L2: VALOR ADUANEIRO | R2: IMPOSTOS | Y2: TAXAS PORTUÁRIAS
B3: Nº | C3: ITEM | D3: Código | E3: Bitola (mm) | F3: Embal. | G3: NCM | H3: QTD | I3: % Rateio Preço | J3: Preço unitário Fábrica (USD) | K3: Preço x QTD (Valor em USD) | L3: Preço x QTD (valor em BRL) | M3: Preço x QTD (valor em BRL) SUB | N3: THC (valor em BRL) | O3: Valor do frete (Valor em BRL) | P3: TOTAL VALOR ADUANEIRO | Q3: TOTAL VALOR ADUANEIRO + II | R3: IMPOSTO DE IMPORTAÇÃO | S3: IPI | T3: PIS | U3: COFINS | V3: ICMS | W3: TOTAL IMPOSTOS | X3: TOTAL IMPOSTOS (SUB) | Y3: TAXA SISCOMEX | Z3: LIBERAÇÃO DE B/L | AA3: T.H.C| CAPATAZIA | AB3: ISPS | AC3: DAMAGE PROTECTION | AD3: DESCONSOLIDAÇÃO | AE3: DEVOLUÇÃO DE CONTAINER | AF3: TRS | AG3: AFRMM | AH3: ARMAZENAGEM TCP | AI3: SCANNER TCP | AJ3: HANDLING - TCP | AK3: PESAGEM TCP | AL3: TAXA DO PARCEIRO - PARANAGUÁ | AM3: FRETE RODOVIÁRIO | AN3: DESEMBARAÇO ADUANEIRO | AO3: COMISSÃO SEAWISE | AP3: TOTAL TAXAS DESEMBARAÇO | AQ3: TOTAL | AR3: TOTAL (sub) | AS3: TOTAL (sub) | AT3: MÉTODO ANTIGO | AU3: MÉTODO ANTIGO (sub) | AV3: MÉTODO DANI | AW3: MÉTODO DANI (sub) | AX3: MÉTODO JULIANA | AY3: MÉTODO JULIANA (sub) | BA3: VALOR UNITÁRIO C/ COMISSÃO SEAWISE
A4: Nº | L4: =N62 -> 5.1 | M4: 4.8887 | N4: 0 | P4: =SUM(P6:P58) -> 755729.01 | Q4: =SUM(Q6:Q58) -> 876645.65 | R4: =SUM(R6:R58) -> 120916.64 | S4: =SUM(S6:S58) -> 26387.034 | T4: =SUM(T6:T58) -> 27351.344 | U4: =SUM(U6:U58) -> 131233.85 | V4: =SUM(V6:V58) -> 45343.74 | AG4: 0.08
A5: AAA | L5: =SUM(L6:L58) -> 736233.7 | O5: =SUM(O6:O58) -> 19495.3 | R5: ='LISTA DE COMPRAS'!E5 -> 0.16 | S5: ='LISTA DE COMPRAS'!F5 -> 0.0301 | T5: ='LISTA DE COMPRAS'!G5 -> 0.0312 | U5: ='LISTA DE COMPRAS'!H5 -> 0.1497 | V5: ='LISTA DE COMPRAS'!I5 -> 0.06 | W5: =SUM(W6:W58) -> 351232.61 | X5: =SUM(#REF!,X6) -> #REF! | Y5: =SUM(Y6:Y58) -> 214.5 | Z5: =SUM(Z6:Z58) -> 540 | AA5: =SUM(AA6:AA58) -> 1547 | AB5: =SUM(AB6:AB58) -> 60 | AC5: =SUM(AC6:AC58) -> 300 | AD5: =SUM(AD6:AD58) -> 400 | AE5: =SUM(AE6:AE58) -> 774.9 | AF5: =SUM(AF6:AF58) -> 140 | AG5: =SUM(AG6:AG58) -> 1559.624 | AH5: =SUM(AH6:AH6) -> 0 | AI5: =SUM(AI6:AI58) -> 756.95 | AJ5: =SUM(AJ6:AJ58) -> 225 | AK5: =SUM(AK6:AK58) -> 117.45 | AL5: =SUM(AL6:AL58) -> 286 | AM5: =SUM(AM6:AM58) -> 6000 | AN5: =SUM(AN6:AN58) -> 2400 | AO5: =SUM(AO6:AO58) -> 25768.18 | AP5: =SUM(AP6:AP58) -> 41089.604 | AQ5: =AP5+W5+P4 -> 1148051.2 | AR5: 21877.425 | AS5: =AP5+X5+Q4+#REF! -> #REF!
A6: AAA | B6: ='LISTA DE COMPRAS'!A5 -> 1 | C6: ='LISTA DE COMPRAS'!C5 -> Cylinder Head Cummins ISB 5.9/6.7 | G6: ='LISTA DE COMPRAS'!D5 -> 84099959 | H6: ='LISTA DE COMPRAS'!J5 -> 30 | I6: ='LISTA DE COMPRAS'!P5 -> 0.070588235 | J6: ='LISTA DE COMPRAS'!K5 -> 328.57 | K6: =H6*J6 -> 9857.1 | L6: =K6*$L$4 -> 50271.21 | M6: =L6*50% -> 25135.605 | N6: =$N$4*I6 -> 0 | O6: ='Rateio Custos Fixos'!E12 -> 373.44278 | P6: =SUM(L6,O6) -> 50644.653 | Q6: =P6+R6 -> 58747.797 | R6: =$P6*R$5 -> 8103.1444 | S6: =$Q6*S$5 -> 1768.3087 | T6: =$Q6*T$5 -> 1832.9313 | U6: =$Q6*U$5 -> 8794.5452 | V6: =$P6*V$5 -> 3038.6792 | W6: =SUM(R6:V6) -> 23537.609 | X6: =SUM(R11:V11) -> 5408.1491 | Y6: ='Rateio Custos Fixos'!F12 -> 4.108861 | Z6: ='Rateio Custos Fixos'!G12 -> 10.343986 | AA6: ='Rateio Custos Fixos'!H12 -> 29.633603 | AB6: ='Rateio Custos Fixos'!I12 -> 1.1493317 | AC6: ='Rateio Custos Fixos'!J12 -> 5.7466587 | AD6: ='Rateio Custos Fixos'!K12 -> 7.6622116 | AE6: ='Rateio Custos Fixos'!L12 -> 14.843619 | AF6: ='Rateio Custos Fixos'!M12 -> 2.6817741 | ... AO6: ='Rateio Custos Fixos'!V12 -> 1759.4924 | AP6: =SUM(Y6:AO6) -> 2052.9823 | AQ6: =AP6+W6+P6 -> 76235.244 | AR6: 2595.3166 | AS6: =AP6+X6+P6 -> 58105.784 | AT6: =(AQ6/H6) -> 2541.1748 | AU6: =AS6/H6 -> 1936.8595 | AV6: =AQ6/H6 -> 2541.1748 | AW6: =(AS6*#REF!)/'Est. Cust. Naci.'!H6 -> #REF! | AX6: =(J6*9) -> 2957.13 | AY6: =AX6/2 -> 1478.565 | BA6: =AQ6/H6 -> 2541.1748
B7: ='LISTA DE COMPRAS'!A6 -> 2 | C7: ='LISTA DE COMPRAS'!C6 -> Cylinder Head Volvo FH13 | G7: ='LISTA DE COMPRAS'!D6 -> 84099959 | H7: ='LISTA DE COMPRAS'!J6 -> 30 | I7: ='LISTA DE COMPRAS'!P6 -> 0.070588235 | J7: ='LISTA DE COMPRAS'!K6 -> 1275 | K7: =H7*J7 -> 38250 | L7: =K7*$L$4 -> 195075 | M7: =L7*50% -> 97537.5 | N7: =$N$4*I7 -> 0 | O7: ='Rateio Custos Fixos'!E13 -> 1449.1267 | P7: =SUM(L7,O7) -> 196524.13 | Q7: =P7+R7 -> 227967.99 | R7: =$P7*R$5 -> 31443.86 | S7: =$Q7*S$5 -> 6861.8364 | T7: =$Q7*T$5 -> 7112.6012 | U7: =$Q7*U$5 -> 34126.808 | V7: =$P7*V$5 -> 11791.448 | W7: =SUM(R7:V7) -> 91336.553 | X7: =SUM(R12:V12) -> 14136.603 | Y7: ='Rateio Custos Fixos'!F13 -> 15.944236 | Z7: ='Rateio Custos Fixos'!G13 -> 40.139336 | AA7: ='Rateio Custos Fixos'!H13 -> 114.99177 | AB7: ='Rateio Custos Fixos'!I13 -> 4.4599263 | AC7: ='Rateio Custos Fixos'!J13 -> 22.299631 | AD7: ='Rateio Custos Fixos'!K13 -> 29.732842 | AE7: ='Rateio Custos Fixos'!L13 -> 57.599948 | AF7: ='Rateio Custos Fixos'!M13 -> 10.406495 | ... AO7: ='Rateio Custos Fixos'!V13 -> 6827.625 | AP7: =SUM(Y7:AO7) -> 7966.4987 | AQ7: =AP7+W7+P7 -> 295827.18 | AR7: 2596.3166 | AS7: =AP7+X7+P7 -> 218627.23 | AT7: =(AQ7/H7) -> 9860.9059 | AU7: =AS7/H7 -> 7287.5743 | AV7: =AQ7/H7 -> 9860.9059 | AW7: =(AS7*#REF!)/'Est. Cust. Naci.'!H7 -> #REF! | AX7: =(J7*9) -> 11475
B8: ='LISTA DE COMPRAS'!A7 -> 3 | C8: ='LISTA DE COMPRAS'!C7 -> Cylinder Head Cummins 4BT | G8: ='LISTA DE COMPRAS'!D7 -> 84099959 | H8: ='LISTA DE COMPRAS'!J7 -> 20 | I8: ='LISTA DE COMPRAS'!P7 -> 0.047058824 | J8: ='LISTA DE COMPRAS'!K7 -> 200 | K8: =H8*J8 -> 4000 | L8: =K8*$L$4 -> 20400 | M8: =L8*50% -> 10200 | N8: =$N$4*I8 -> 0 | O8: ='Rateio Custos Fixos'!E14 -> 227.31399 | P8: =SUM(L8,O8) -> 20627.314 | Q8: =P8+R8 -> 23927.684 | R8: =$P8*R$5 -> 3300.3702 | S8: =$Q8*S$5 -> 720.2233 | T8: =$Q8*T$5 -> 746.54375 | U8: =$Q8*U$5 -> 3581.9743 | V8: =$P8*V$5 -> 1237.6388 | W8: =SUM(R8:V8) -> 9586.7504 | X8: =SUM(R13:V13) -> 7289.765 | Y8: ='Rateio Custos Fixos'!F14 -> 2.5010567 | Z8: ='Rateio Custos Fixos'!G14 -> 6.2963665 | AA8: ='Rateio Custos Fixos'!H14 -> 18.037924 | AB8: ='Rateio Custos Fixos'!I14 -> 0.69959627 | AC8: ='Rateio Custos Fixos'!J14 -> 3.4979814 | AD8: ='Rateio Custos Fixos'!K14 -> 4.6639752 | AE8: ='Rateio Custos Fixos'!L14 -> 9.0352859 | AF8: ='Rateio Custos Fixos'!M14 -> 1.6323913 | ... AO8: ='Rateio Custos Fixos'!V14 -> 714 | AP8: =SUM(Y8:AO8) -> 892.64685 | AQ8: =AP8+W8+P8 -> 31106.711 | AR8: 2597.3166 | AS8: =AP8+X8+P8 -> 28809.726 | AT8: =(AQ8/H8) -> 1555.3356 | AU8: =AS8/H8 -> 1440.4863 | AV8: =AQ8/H8 -> 1555.3356 | AW8: =(AS8*#REF!)/'Est. Cust. Naci.'!H8 -> #REF! | AX8: =(J8*9) -> 1800
B9: ='LISTA DE COMPRAS'!A8 -> 4 | C9: ='LISTA DE COMPRAS'!C8 -> Cylinder Head MB 457/460 Axor | G9: ='LISTA DE COMPRAS'!D8 -> 84099959 | H9: ='LISTA DE COMPRAS'!J8 -> 240 | I9: ='LISTA DE COMPRAS'!P8 -> 0.56470588 | J9: ='LISTA DE COMPRAS'!K8 -> 132.43 | K9: =H9*J9 -> 31783.2 | L9: =K9*$L$4 -> 162094.32 | M9: =L9*50% -> 81047.16 | N9: =$N$4*I9 -> 0 | O9: ='Rateio Custos Fixos'!E15 -> 150.51596 | P9: =SUM(L9,O9) -> 162244.84 | Q9: =P9+R9 -> 188204.01 | R9: =$P9*R$5 -> 25959.174 | S9: =$Q9*S$5 -> 5664.9407 | T9: =$Q9*T$5 -> 5871.9651 | U9: =$Q9*U$5 -> 28174.14 | V9: =$P9*V$5 -> 9734.6902 | W9: =SUM(R9:V9) -> 75404.91 | X9: =SUM(R14:V14) -> 13470.999 | Y9: ='Rateio Custos Fixos'!F15 -> 1.6560747 | Z9: ='Rateio Custos Fixos'!G15 -> 4.1691391 | AA9: ='Rateio Custos Fixos'!H15 -> 11.943811 | AB9: ='Rateio Custos Fixos'!I15 -> 0.46323767 | AC9: ='Rateio Custos Fixos'!J15 -> 2.3161884 | AD9: ='Rateio Custos Fixos'!K15 -> 3.0882512 | AE9: ='Rateio Custos Fixos'!L15 -> 5.9827146 | AF9: ='Rateio Custos Fixos'!M15 -> 1.0808879 | ... AO9: ='Rateio Custos Fixos'!V15 -> 5673.3012 | AP9: =SUM(Y9:AO9) -> 5791.5922 | AQ9: =AP9+W9+P9 -> 243441.34 | AR9: 2598.3166 | AS9: =AP9+X9+P9 -> 181507.43 | AT9: =(AQ9/H9) -> 1014.3389 | AU9: =AS9/H9 -> 756.28095 | AV9: =AQ9/H9 -> 1014.3389 | AW9: =(AS9*#REF!)/'Est. Cust. Naci.'!H9 -> #REF! | AX9: =(J9*9) -> 1191.87
B10: ='LISTA DE COMPRAS'!A9 -> 5 | C10: ='LISTA DE COMPRAS'!C9 -> CABECOTE CUMMINS SERIE C | G10: ='LISTA DE COMPRAS'!D9 -> 84099959 | H10: ='LISTA DE COMPRAS'!J9 -> 20 | I10: ='LISTA DE COMPRAS'!P9 -> 0.047058824 | J10: ='LISTA DE COMPRAS'!K9 -> 229.43 | K10: =H10*J10 -> 4588.6 | L10: =K10*$L$4 -> 23401.86 | M10: =L10*50% -> 11700.93 | N10: =$N$4*I10 -> 0 | O10: ='Rateio Custos Fixos'!E16 -> 260.76324 | P10: =SUM(L10,O10) -> 23662.623 | Q10: =P10+R10 -> 27448.643 | R10: =$P10*R$5 -> 3786.0197 | S10: =$Q10*S$5 -> 826.20415 | T10: =$Q10*T$5 -> 856.39766 | U10: =$Q10*U$5 -> 4109.0619 | V10: =$P10*V$5 -> 1419.7574 | W10: =SUM(R10:V10) -> 10997.441 | X10: =SUM(R15:V15) -> 11620.742 | Y10: ='Rateio Custos Fixos'!F16 -> 2.8690872 | Z10: ='Rateio Custos Fixos'!G16 -> 7.2228768 | AA10: ='Rateio Custos Fixos'!H16 -> 20.692204 | AB10: ='Rateio Custos Fixos'!I16 -> 0.80254187 | AC10: ='Rateio Custos Fixos'!J16 -> 4.0127093 | AD10: ='Rateio Custos Fixos'!K16 -> 5.3502791 | AE10: ='Rateio Custos Fixos'!L16 -> 10.364828 | AF10: ='Rateio Custos Fixos'!M16 -> 1.8725977 | ... AO10: ='Rateio Custos Fixos'!V16 -> 819.0651 | AP10: =SUM(Y10:AO10) -> 1023.9998 | AQ10: =AP10+W10+P10 -> 35684.064 | AR10: 2599.3166 | AS10: =AP10+X10+P10 -> 36307.365 | AT10: =(AQ10/H10) -> 1784.2032 | AU10: =AS10/H10 -> 1815.3683 | AV10: =AQ10/H10 -> 1784.2032 | AW10: =(AS10*#REF!)/'Est. Cust. Naci.'!H10 -> #REF! | AX10: =(J10*9) -> 2064.87
B11: ='LISTA DE COMPRAS'!A10 -> 6 | C11: ='LISTA DE COMPRAS'!C10 -> CABECOTE MAN 4CIL D08 | G11: ='LISTA DE COMPRAS'!D10 -> 84099959 | H11: ='LISTA DE COMPRAS'!J10 -> 3 | I11: ='LISTA DE COMPRAS'!P10 -> 0.0070588235 | J11: ='LISTA DE COMPRAS'!K10 -> 707.96 | K11: =H11*J11 -> 2123.88 | L11: =K11*$L$4 -> 10831.788 | M11: =L11*50% -> 5415.894 | N11: =$N$4*I11 -> 0 | O11: ='Rateio Custos Fixos'!E17 -> 804.64605 | P11: =SUM(L11,O11) -> 11636.434 | Q11: =P11+R11 -> 13498.264 | R11: =$P11*R$5 -> 1861.8294 | S11: =$Q11*S$5 -> 406.29773 | T11: =$Q11*T$5 -> 421.14582 | U11: =$Q11*U$5 -> 2020.69 | V11: =$P11*V$5 -> 698.18604 | W11: =SUM(R11:V11) -> 5408.1491 | X11: =SUM(R16:V16) -> 6209.3337 | Y11: ='Rateio Custos Fixos'!F17 -> 8.8532404 | Z11: ='Rateio Custos Fixos'!G17 -> 22.287878 | AA11: ='Rateio Custos Fixos'!H17 -> 63.850643 | AB11: ='Rateio Custos Fixos'!I17 -> 2.4764309 | AC11: ='Rateio Custos Fixos'!J17 -> 12.382154 | AD11: ='Rateio Custos Fixos'!K17 -> 16.509539 | AE11: ='Rateio Custos Fixos'!L17 -> 31.983105 | AF11: ='Rateio Custos Fixos'!M17 -> 5.7783388 | ... AO11: ='Rateio Custos Fixos'!V17 -> 379.11258 | AP11: =SUM(Y11:AO11) -> 1011.4867 | AQ11: =AP11+W11+P11 -> 18056.07 | AR11: 2600.3166 | AS11: =AP11+X11+P11 -> 18857.254 | AT11: =(AQ11/H11) -> 6018.69 | AU11: =AS11/H11 -> 6285.7515 | AV11: =AQ11/H11 -> 6018.69 | AW11: =(AS11*#REF!)/'Est. Cust. Naci.'!H11 -> #REF! | AX11: =(J11*9) -> 6371.64
B12: ='LISTA DE COMPRAS'!A11 -> 7 | C12: ='LISTA DE COMPRAS'!C11 -> CABECOTE MAN 6CIL D08 | G12: ='LISTA DE COMPRAS'!D11 -> 84099959 | H12: ='LISTA DE COMPRAS'!J11 -> 10 | I12: ='LISTA DE COMPRAS'!P11 -> 0.023529412 | J12: ='LISTA DE COMPRAS'!K11 -> 583.41 | K12: =H12*J12 -> 5834.1 | L12: =K12*$L$4 -> 29753.91 | M12: =L12*50% -> 14876.955 | N12: =$N$4*I12 -> 0 | O12: ='Rateio Custos Fixos'!E18 -> 663.08627 | P12: =SUM(L12,O12) -> 30416.996 | Q12: =P12+R12 -> 35283.716 | R12: =$P12*R$5 -> 4866.7194 | S12: =$Q12*S$5 -> 1062.0398 | T12: =$Q12*T$5 -> 1100.8519 | U12: =$Q12*U$5 -> 5281.9722 | V12: =$P12*V$5 -> 1825.0198 | W12: =SUM(R12:V12) -> 14136.603 | X12: =SUM(R17:V17) -> 335.18449 | Y12: ='Rateio Custos Fixos'!F18 -> 7.2957074 | Z12: ='Rateio Custos Fixos'!G18 -> 18.366816 | AA12: ='Rateio Custos Fixos'!H18 -> 52.617526 | AB12: ='Rateio Custos Fixos'!I18 -> 2.0407573 | AC12: ='Rateio Custos Fixos'!J18 -> 10.203787 | AD12: ='Rateio Custos Fixos'!K18 -> 13.605049 | AE12: ='Rateio Custos Fixos'!L18 -> 26.356381 | AF12: ='Rateio Custos Fixos'!M18 -> 4.7617671 | ... AO12: ='Rateio Custos Fixos'!V18 -> 1041.3868 | AP12: =SUM(Y12:AO12) -> 1562.5087 | AQ12: =AP12+W12+P12 -> 46116.108 | AR12: 2601.3166 | AS12: =AP12+X12+P12 -> 32314.689 | AT12: =(AQ12/H12) -> 4611.6108 | AU12: =AS12/H12 -> 3231.4689 | AV12: =AQ12/H12 -> 4611.6108 | AW12: =(AS12*#REF!)/'Est. Cust. Naci.'!H12 -> #REF! | AX12: =(J12*9) -> 5250.69
B13: ='LISTA DE COMPRAS'!A12 -> 8 | C13: ='LISTA DE COMPRAS'!C12 -> CABECOTE CUMMINS 6BT | G13: ='LISTA DE COMPRAS'!D12 -> 84099959 | H13: ='LISTA DE COMPRAS'!J12 -> 20 | I13: ='LISTA DE COMPRAS'!P12 -> 0.047058824 | J13: ='LISTA DE COMPRAS'!K12 -> 152.08 | K13: =H13*J13 -> 3041.6 | L13: =K13*$L$4 -> 15512.16 | M13: =L13*50% -> 7756.08 | N13: =$N$4*I13 -> 0 | O13: ='Rateio Custos Fixos'!E19 -> 172.84956 | P13: =SUM(L13,O13) -> 15685.01 | Q13: =P13+R13 -> 18194.611 | R13: =$P13*R$5 -> 2509.6015 | S13: =$Q13*S$5 -> 547.65779 | T13: =$Q13*T$5 -> 567.67187 | U13: =$Q13*U$5 -> 2723.7333 | V13: =$P13*V$5 -> 941.10057 | W13: =SUM(R13:V13) -> 7289.765 | X13: =SUM(R18:V18) -> 335.18449 | Y13: ='Rateio Custos Fixos'!F19 -> 1.9018035 | Z13: ='Rateio Custos Fixos'!G19 -> 4.7877571 | AA13: ='Rateio Custos Fixos'!H19 -> 13.716037 | AB13: ='Rateio Custos Fixos'!I19 -> 0.53197301 | AC13: ='Rateio Custos Fixos'!J19 -> 2.659865 | AD13: ='Rateio Custos Fixos'!K19 -> 3.5464867 | AE13: ='Rateio Custos Fixos'!L19 -> 6.8704314 | AF13: ='Rateio Custos Fixos'!M19 -> 1.2412704 | ... AO13: ='Rateio Custos Fixos'!V19 -> 542.9256 | AP13: =SUM(Y13:AO13) -> 678.76867 | AQ13: =AP13+W13+P13 -> 23653.543 | AR13: 2602.3166 | AS13: =AP13+X13+P13 -> 16698.963 | AT13: =(AQ13/H13) -> 1182.6772 | AU13: =AS13/H13 -> 834.94814 | AV13: =AQ13/H13 -> 1182.6772 | AW13: =(AS13*#REF!)/'Est. Cust. Naci.'!H13 -> #REF! | AX13: =(J13*9) -> 1368.72
B14: ='LISTA DE COMPRAS'!A13 -> 9 | C14: ='LISTA DE COMPRAS'!C13 -> CABECOTE MAN TGX 460 | G14: ='LISTA DE COMPRAS'!D13 -> 84099959 | H14: ='LISTA DE COMPRAS'!J13 -> 5 | I14: ='LISTA DE COMPRAS'!P13 -> 0.011764706 | J14: ='LISTA DE COMPRAS'!K13 -> 1088.16 | K14: =H14*J14 -> 5440.8 | L14: =K14*$L$4 -> 27748.08 | M14: =L14*50% -> 13874.04 | N14: =$N$4*I14 -> 0 | O14: ='Rateio Custos Fixos'!E20 -> 1236.7699 | P14: =SUM(L14,O14) -> 28984.85 | Q14: =P14+R14 -> 33622.426 | R14: =$P14*R$5 -> 4637.576 | S14: =$Q14*S$5 -> 1012.035 | T14: =$Q14*T$5 -> 1049.0197 | U14: =$Q14*U$5 -> 5033.2772 | V14: =$P14*V$5 -> 1739.091 | W14: =SUM(R14:V14) -> 13470.999 | X14: =SUM(R19:V19) -> 3732.9483 | Y14: ='Rateio Custos Fixos'!F20 -> 13.607749 | Z14: ='Rateio Custos Fixos'!G20 -> 34.257271 | AA14: ='Rateio Custos Fixos'!H20 -> 98.140737 | AB14: ='Rateio Custos Fixos'!I20 -> 3.8063634 | AC14: ='Rateio Custos Fixos'!J20 -> 19.031817 | AD14: ='Rateio Custos Fixos'!K20 -> 25.375756 | AE14: ='Rateio Custos Fixos'!L20 -> 49.159183 | AF14: ='Rateio Custos Fixos'!M20 -> 8.8815146 | ... AO14: ='Rateio Custos Fixos'!V20 -> 971.1828 | AP14: =SUM(Y14:AO14) -> 1943.1646 | AQ14: =AP14+W14+P14 -> 44399.013 | AR14: 2603.3166 | AS14: =AP14+X14+P14 -> 34660.963 | AT14: =(AQ14/H14) -> 8879.8027 | AU14: =AS14/H14 -> 6932.1926 | AV14: =AQ14/H14 -> 8879.8027 | AW14: =(AS14*#REF!)/'Est. Cust. Naci.'!H14 -> #REF! | AX14: =(J14*9) -> 9793.44
B15: ='LISTA DE COMPRAS'!A14 -> 10 | C15: ='LISTA DE COMPRAS'!C14 -> CABECOTE CATERPILAR C 7 | G15: ='LISTA DE COMPRAS'!D14 -> 84099959 | H15: ='LISTA DE COMPRAS'!J14 -> 5 | I15: ='LISTA DE COMPRAS'!P14 -> 0.011764706 | J15: ='LISTA DE COMPRAS'!K14 -> 938.7 | K15: =H15*J15 -> 4693.5 | L15: =K15*$L$4 -> 23936.85 | M15: =L15*50% -> 11968.425 | N15: =$N$4*I15 -> 0 | O15: ='Rateio Custos Fixos'!E21 -> 1066.8982 | P15: =SUM(L15,O15) -> 25003.748 | Q15: =P15+R15 -> 29004.348 | R15: =$P15*R$5 -> 4000.5997 | S15: =$Q15*S$5 -> 873.03087 | T15: =$Q15*T$5 -> 904.93565 | U15: =$Q15*U$5 -> 4341.9509 | V15: =$P15*V$5 -> 1500.2249 | W15: =SUM(R15:V15) -> 11620.742 | X15: =SUM(R20:V20) -> 4463.2216 | Y15: ='Rateio Custos Fixos'!F21 -> 11.73871 | Z15: ='Rateio Custos Fixos'!G21 -> 29.551996 | AA15: ='Rateio Custos Fixos'!H21 -> 84.660996 | AB15: ='Rateio Custos Fixos'!I21 -> 3.2835551 | AC15: ='Rateio Custos Fixos'!J21 -> 16.417776 | AD15: ='Rateio Custos Fixos'!K21 -> 21.890367 | AE15: ='Rateio Custos Fixos'!L21 -> 42.407114 | AF15: ='Rateio Custos Fixos'!M21 -> 7.6616286 | ... AO15: ='Rateio Custos Fixos'!V21 -> 837.78975 | AP15: =SUM(Y15:AO15) -> 1676.2688 | AQ15: =AP15+W15+P15 -> 38300.759 | AR15: 2604.3166 | AS15: =AP15+X15+P15 -> 31143.239 | AT15: =(AQ15/H15) -> 7660.1518 | AU15: =AS15/H15 -> 6228.6477 | AV15: =AQ15/H15 -> 7660.1518 | AW15: =(AS15*#REF!)/'Est. Cust. Naci.'!H15 -> #REF! | AX15: =(J15*9) -> 8448.3
B16: ='LISTA DE COMPRAS'!A15 -> 11 | C16: ='LISTA DE COMPRAS'!C15 -> CABECOTE CATERPILAR C6.6 | G16: ='LISTA DE COMPRAS'!D15 -> 84099959 | H16: ='LISTA DE COMPRAS'!J15 -> 3 | I16: ='LISTA DE COMPRAS'!P15 -> 0.0070588235 | J16: ='LISTA DE COMPRAS'!K15 -> 812.84 | K16: =H16*J16 -> 2438.52 | L16: =K16*$L$4 -> 12436.452 | M16: =L16*50% -> 6218.226 | N16: =$N$4*I16 -> 0 | O16: ='Rateio Custos Fixos'!E22 -> 923.84951 | P16: =SUM(L16,O16) -> 13360.302 | Q16: =P16+R16 -> 15497.95 | R16: =$P16*R$5 -> 2137.6482 | S16: =$Q16*S$5 -> 466.48829 | T16: =$Q16*T$5 -> 483.53603 | U16: =$Q16*U$5 -> 2320.0431 | V16: =$P16*V$5 -> 801.61809 | W16: =SUM(R16:V16) -> 6209.3337 | X16: =SUM(R21:V21) -> 6509.778 | Y16: ='Rateio Custos Fixos'!F22 -> 10.164795 | Z16: ='Rateio Custos Fixos'!G22 -> 25.589693 | AA16: ='Rateio Custos Fixos'!H22 -> 73.309731 | AB16: ='Rateio Custos Fixos'!I22 -> 2.8432992 | AC16: ='Rateio Custos Fixos'!J22 -> 14.216496 | AD16: ='Rateio Custos Fixos'!K22 -> 18.955328 | AE16: ='Rateio Custos Fixos'!L22 -> 36.721209 | AF16: ='Rateio Custos Fixos'!M22 -> 6.6343648 | ... AO16: ='Rateio Custos Fixos'!V22 -> 435.27582 | AP16: =SUM(Y16:AO16) -> 1161.3324 | AQ16: =AP16+W16+P16 -> 20730.968 | AR16: 2605.3166 | AS16: =AP16+X16+P16 -> 21031.412 | AT16: =(AQ16/H16) -> 6910.3225 | AU16: =AS16/H16 -> 7010.4706 | AV16: =AQ16/H16 -> 6910.3225 | AW16: =(AS16*#REF!)/'Est. Cust. Naci.'!H16 -> #REF! | AX16: =(J16*9) -> 7315.56
B17: ='LISTA DE COMPRAS'!A16 -> 12 | C17: ='LISTA DE COMPRAS'!C16 -> BLOCO MB 352 A C/ ESGUICHO | G17: ='LISTA DE COMPRAS'!D16 -> 84099112 | H17: ='LISTA DE COMPRAS'!J16 -> 0 | I17: ='LISTA DE COMPRAS'!P16 -> 0 | J17: ='LISTA DE COMPRAS'!K16 -> 634.54 | K17: =H17*J17 -> 0 | L17: =K17*$L$4 -> 0 | M17: =L17*50% -> 0 | N17: =$N$4*I17 -> 0 | O17: ='Rateio Custos Fixos'!E23 -> 721.19909 | P17: =SUM(L17,O17) -> 721.19909 | Q17: =P17+R17 -> 836.59094 | R17: =$P17*R$5 -> 115.39185 | S17: =$Q17*S$5 -> 25.181387 | T17: =$Q17*T$5 -> 26.101637 | U17: =$Q17*U$5 -> 125.23766 | V17: =$P17*V$5 -> 43.271945 | W17: =SUM(R17:V17) -> 335.18449 | X17: =SUM(R22:V22) -> 5842.8056 | Y17: ='Rateio Custos Fixos'!F23 -> 7.9351025 | Z17: ='Rateio Custos Fixos'!G23 -> 19.976482 | AA17: ='Rateio Custos Fixos'!H23 -> 57.228921 | AB17: ='Rateio Custos Fixos'!I23 -> 2.2196091 | AC17: ='Rateio Custos Fixos'!J23 -> 11.098046 | AD17: ='Rateio Custos Fixos'!K23 -> 14.797394 | AE17: ='Rateio Custos Fixos'!L23 -> 28.666252 | AF17: ='Rateio Custos Fixos'!M23 -> 5.1790879 | ... AO17: ='Rateio Custos Fixos'!V23 -> 0 | AP17: =SUM(Y17:AO17) -> 566.79287 | AQ17: =AP17+W17+P17 -> 1623.1764 | AR17: 2606.3166 | AS17: =AP17+X17+P17 -> 7130.7975 | AT17: =(AQ17/H17) -> #DIV/0! | AU17: =AS17/H17 -> #DIV/0! | AV17: =AQ17/H17 -> #DIV/0! | AW17: =(AS17*#REF!)/'Est. Cust. Naci.'!H17 -> #REF! | AX17: =(J17*9) -> 5710.86
B18: ='LISTA DE COMPRAS'!A17 -> 13 | C18: ='LISTA DE COMPRAS'!C17 -> BLOCO MB 366 A C/ ESGUICHO | G18: ='LISTA DE COMPRAS'!D17 -> 84099112 | H18: ='LISTA DE COMPRAS'!J17 -> 0 | I18: ='LISTA DE COMPRAS'!P17 -> 0 | J18: ='LISTA DE COMPRAS'!K17 -> 634.54 | K18: =H18*J18 -> 0 | L18: =K18*$L$4 -> 0 | M18: =L18*50% -> 0 | N18: =$N$4*I18 -> 0 | O18: ='Rateio Custos Fixos'!E24 -> 721.19909 | P18: =SUM(L18,O18) -> 721.19909 | Q18: =P18+R18 -> 836.59094 | R18: =$P18*R$5 -> 115.39185 | S18: =$Q18*S$5 -> 25.181387 | T18: =$Q18*T$5 -> 26.101637 | U18: =$Q18*U$5 -> 125.23766 | V18: =$P18*V$5 -> 43.271945 | W18: =SUM(R18:V18) -> 335.18449 | X18: =SUM(R23:V23) -> 4907.4087 | Y18: ='Rateio Custos Fixos'!F24 -> 7.9351025 | Z18: ='Rateio Custos Fixos'!G24 -> 19.976482 | AA18: ='Rateio Custos Fixos'!H24 -> 57.228921 | AB18: ='Rateio Custos Fixos'!I24 -> 2.2196091 | AC18: ='Rateio Custos Fixos'!J24 -> 11.098046 | AD18: ='Rateio Custos Fixos'!K24 -> 14.797394 | AE18: ='Rateio Custos Fixos'!L24 -> 28.666252 | AF18: ='Rateio Custos Fixos'!M24 -> 5.1790879 | ... AO18: ='Rateio Custos Fixos'!V24 -> 0 | AP18: =SUM(Y18:AO18) -> 566.79287 | AQ18: =AP18+W18+P18 -> 1623.1764 | AR18: 2607.3166 | AS18: =AP18+X18+P18 -> 6195.4006 | AT18: =(AQ18/H18) -> #DIV/0! | AU18: =AS18/H18 -> #DIV/0! | AV18: =AQ18/H18 -> #DIV/0! | AW18: =(AS18*#REF!)/'Est. Cust. Naci.'!H18 -> #REF! | AX18: =(J18*9) -> 5710.86
... B29: ='LISTA DE COMPRAS'!A28 -> 24 | C29: ='LISTA DE COMPRAS'!C28 -> BLOCO MOTOR SCANIA DC 12 | G29: ='LISTA DE COMPRAS'!D28 -> 84099112 | H29: ='LISTA DE COMPRAS'!J28 -> 5 | I29: ='LISTA DE COMPRAS'!P28 -> 0.011764706 | J29: ='LISTA DE COMPRAS'!K28 -> 1590 | K29: =H29*J29 -> 7950 | L29: =K29*$L$4 -> 40545 | M29: =L29*50% -> 20272.5 | N29: =$N$4*I29 -> 0 | O29: ='Rateio Custos Fixos'!E35 -> 1807.1462 | P29: =SUM(L29,O29) -> 42352.146 | Q29: =P29+R29 -> 49128.49 | R29: =$P29*R$5 -> 6776.3434 | S29: =$Q29*S$5 -> 1478.7675 | T29: =$Q29*T$5 -> 1532.8089 | U29: =$Q29*U$5 -> 7354.5349 | V29: =$P29*V$5 -> 2541.1288 | W29: =SUM(R29:V29) -> 19683.583 | X29: =SUM(R34:V34) -> 0 | Y29: ='Rateio Custos Fixos'!F35 -> 19.883401 | Z29: ='Rateio Custos Fixos'!G35 -> 50.056113 | AA29: ='Rateio Custos Fixos'!H35 -> 143.4015 | AB29: ='Rateio Custos Fixos'!I35 -> 5.5617904 | AC29: ='Rateio Custos Fixos'!J35 -> 27.808952 | AD29: ='Rateio Custos Fixos'!K35 -> 37.078603 | AE29: ='Rateio Custos Fixos'!L35 -> 71.830523 | AF29: ='Rateio Custos Fixos'!M35 -> 12.977511 | ... AO29: ='Rateio Custos Fixos'!V35 -> 1419.075 | AP29: =SUM(Y29:AO29) -> 2839.3175 | AQ29: =AP29+W29+P29 -> 64875.047 | AR29: 2618.3166 | AS29: =AP29+X29+P29 -> 45191.464 | AT29: =(AQ29/H29) -> 12975.009 | AU29: =AS29/H29 -> 9038.2927 | AV29: =AQ29/H29 -> 12975.009 | AW29: =(AS29*#REF!)/'Est. Cust. Naci.'!H29 -> #REF! | AX29: =(J29*9) -> 14310
B30: ='LISTA DE COMPRAS'!A29 -> 25 | C30: ='LISTA DE COMPRAS'!C29 -> 0 | G30: ='LISTA DE COMPRAS'!D30 -> 0 | H30: ='LISTA DE COMPRAS'!J29 -> 0 | I30: ='LISTA DE COMPRAS'!P29 -> 0 | J30: ='LISTA DE COMPRAS'!K29 -> 0 | K30: =H30*J30 -> 0 | L30: =K30*$L$4 -> 0 | M30: =L30*50% -> 0 | N30: =$N$4*I30 -> 0 | O30: ='Rateio Custos Fixos'!E36 -> 0 | P30: =SUM(L30,O30) -> 0 | Q30: =P30+R30 -> 0 | R30: =$P30*R$5 -> 0 | S30: =$Q30*S$5 -> 0 | T30: =$Q30*T$5 -> 0 | U30: =$Q30*U$5 -> 0 | V30: =$P30*V$5 -> 0 | W30: =SUM(R30:V30) -> 0 | X30: =SUM(R35:V35) -> 0 | Y30: ='Rateio Custos Fixos'!F36 -> 0 | Z30: ='Rateio Custos Fixos'!G36 -> 0 | AA30: ='Rateio Custos Fixos'!H36 -> 0 | AB30: ='Rateio Custos Fixos'!I36 -> 0 | AC30: ='Rateio Custos Fixos'!J36 -> 0 | AD30: ='Rateio Custos Fixos'!K36 -> 0 | AE30: ='Rateio Custos Fixos'!L36 -> 0 | AF30: ='Rateio Custos Fixos'!M36 -> 0 | ... AN30: ='Rateio Custos Fixos'!U36 -> 0 | AP30: =SUM(Y30:AO30) -> 0 | AQ30: =AP30+W30+P30 -> 0 | AR30: 2619.3166 | AS30: =AP30+X30+P30 -> 0 | AT30: =(AQ30/H30) -> #DIV/0! | AU30: =AS30/H30 -> #DIV/0! | AV30: =AQ30/H30 -> #DIV/0! | AW30: =(AS30*#REF!)/'Est. Cust. Naci.'!H30 -> #REF! | AX30: =(J30*9) -> 0
B31: ='LISTA DE COMPRAS'!A30 -> 26 | C31: ='LISTA DE COMPRAS'!C30 -> 0 | G31: ='LISTA DE COMPRAS'!D31 -> 0 | H31: ='LISTA DE COMPRAS'!J30 -> 0 | I31: ='LISTA DE COMPRAS'!P30 -> 0 | J31: ='LISTA DE COMPRAS'!K30 -> 0 | K31: =H31*J31 -> 0 | L31: =K31*$L$4 -> 0 | M31: =L31*50% -> 0 | N31: =$N$4*I31 -> 0 | O31: ='Rateio Custos Fixos'!E37 -> 0 | P31: =SUM(L31,O31) -> 0 | Q31: =P31+R31 -> 0 | R31: =$P31*R$5 -> 0 | S31: =$Q31*S$5 -> 0 | T31: =$Q31*T$5 -> 0 | U31: =$Q31*U$5 -> 0 | V31: =$P31*V$5 -> 0 | W31: =SUM(R31:V31) -> 0 | X31: =SUM(R36:V36) -> 0 | Y31: ='Rateio Custos Fixos'!F37 -> 0 | Z31: ='Rateio Custos Fixos'!G37 -> 0 | AA31: ='Rateio Custos Fixos'!H37 -> 0 | AB31: ='Rateio Custos Fixos'!I37 -> 0 | AC31: ='Rateio Custos Fixos'!J37 -> 0 | AD31: ='Rateio Custos Fixos'!K37 -> 0 | AE31: ='Rateio Custos Fixos'!L37 -> 0 | AF31: ='Rateio Custos Fixos'!M37 -> 0 | ... AN31: ='Rateio Custos Fixos'!U37 -> 0 | AP31: =SUM(Y31:AO31) -> 0 | AQ31: =AP31+W31+P31 -> 0 | AR31: 2620.3166 | AS31: =AP31+X31+P31 -> 0 | AT31: =(AQ31/H31) -> #DIV/0! | AU31: =AS31/H31 -> #DIV/0! | AV31: =AQ31/H31 -> #DIV/0! | AW31: =(AS31*#REF!)/'Est. Cust. Naci.'!H31 -> #REF! | AX31: =(J31*9) -> 0
B32: ='LISTA DE COMPRAS'!A31 -> 27 | C32: ='LISTA DE COMPRAS'!C31 -> 0 | G32: ='LISTA DE COMPRAS'!D32 -> 0 | H32: ='LISTA DE COMPRAS'!J31 -> 0 | I32: ='LISTA DE COMPRAS'!P31 -> 0 | J32: ='LISTA DE COMPRAS'!K31 -> 0 | K32: =H32*J32 -> 0 | L32: =K32*$L$4 -> 0 | M32: =L32*50% -> 0 | N32: =$N$4*I32 -> 0 | O32: ='Rateio Custos Fixos'!E38 -> 0 | P32: =SUM(L32,O32) -> 0 | Q32: =P32+R32 -> 0 | R32: =$P32*R$5 -> 0 | S32: =$Q32*S$5 -> 0 | T32: =$Q32*T$5 -> 0 | U32: =$Q32*U$5 -> 0 | V32: =$P32*V$5 -> 0 | W32: =SUM(R32:V32) -> 0 | X32: =SUM(R37:V37) -> 0 | Y32: ='Rateio Custos Fixos'!F38 -> 0 | Z32: ='Rateio Custos Fixos'!G38 -> 0 | AA32: ='Rateio Custos Fixos'!H38 -> 0 | AB32: ='Rateio Custos Fixos'!I38 -> 0 | AC32: ='Rateio Custos Fixos'!J38 -> 0 | AD32: ='Rateio Custos Fixos'!K38 -> 0 | AE32: ='Rateio Custos Fixos'!L38 -> 0 | AF32: ='Rateio Custos Fixos'!M38 -> 0 | ... AN32: ='Rateio Custos Fixos'!U38 -> 0 | AP32: =SUM(Y32:AO32) -> 0 | AQ32: =AP32+W32+P32 -> 0 | AR32: 2621.3166 | AS32: =AP32+X32+P32 -> 0 | AT32: =(AQ32/H32) -> #DIV/0! | AU32: =AS32/H32 -> #DIV/0! | AV32: =AQ32/H32 -> #DIV/0! | AW32: =(AS32*#REF!)/'Est. Cust. Naci.'!H32 -> #REF! | AX32: =(J32*9) -> 0
B33: ='LISTA DE COMPRAS'!A32 -> 28 | C33: ='LISTA DE COMPRAS'!C32 -> 0 | G33: ='LISTA DE COMPRAS'!D33 -> 0 | H33: ='LISTA DE COMPRAS'!J32 -> 0 | I33: ='LISTA DE COMPRAS'!P32 -> 0 | J33: ='LISTA DE COMPRAS'!K32 -> 0 | K33: =H33*J33 -> 0 | L33: =K33*$L$4 -> 0 | M33: =L33*50% -> 0 | N33: =$N$4*I33 -> 0 | O33: ='Rateio Custos Fixos'!E39 -> 0 | P33: =SUM(L33,O33) -> 0 | Q33: =P33+R33 -> 0 | R33: =$P33*R$5 -> 0 | S33: =$Q33*S$5 -> 0 | T33: =$Q33*T$5 -> 0 | U33: =$Q33*U$5 -> 0 | V33: =$P33*V$5 -> 0 | W33: =SUM(R33:V33) -> 0 | X33: =SUM(R38:V38) -> 0 | Y33: ='Rateio Custos Fixos'!F39 -> 0 | Z33: ='Rateio Custos Fixos'!G39 -> 0 | AA33: ='Rateio Custos Fixos'!H39 -> 0 | AB33: ='Rateio Custos Fixos'!I39 -> 0 | AC33: ='Rateio Custos Fixos'!J39 -> 0 | AD33: ='Rateio Custos Fixos'!K39 -> 0 | AE33: ='Rateio Custos Fixos'!L39 -> 0 | AF33: ='Rateio Custos Fixos'!M39 -> 0 | ... AN33: ='Rateio Custos Fixos'!U39 -> 0 | AP33: =SUM(Y33:AO33) -> 0 | AQ33: =AP33+W33+P33 -> 0 | AR33: 2622.3166 | AS33: =AP33+X33+P33 -> 0 | AT33: =(AQ33/H33) -> #DIV/0! | AU33: =AS33/H33 -> #DIV/0! | AV33: =AQ33/H33 -> #DIV/0! | AW33: =(AS33*#REF!)/'Est. Cust. Naci.'!H33 -> #REF! | AX33: =(J33*9) -> 0
B34: ='LISTA DE COMPRAS'!A33 -> 29 | C34: ='LISTA DE COMPRAS'!C33 -> 0 | G34: ='LISTA DE COMPRAS'!D34 -> 0 | H34: ='LISTA DE COMPRAS'!J33 -> 0 | I34: ='LISTA DE COMPRAS'!P33 -> 0 | J34: ='LISTA DE COMPRAS'!K33 -> 0 | K34: =H34*J34 -> 0 | L34: =K34*$L$4 -> 0 | M34: =L34*50% -> 0 | N34: =$N$4*I34 -> 0 | O34: ='Rateio Custos Fixos'!E40 -> 0 | P34: =SUM(L34,O34) -> 0 | Q34: =P34+R34 -> 0 | R34: =$P34*R$5 -> 0 | S34: =$Q34*S$5 -> 0 | T34: =$Q34*T$5 -> 0 | U34: =$Q34*U$5 -> 0 | V34: =$P34*V$5 -> 0 | W34: =SUM(R34:V34) -> 0 | X34: =SUM(R39:V39) -> 0 | Y34: ='Rateio Custos Fixos'!F40 -> 0 | Z34: ='Rateio Custos Fixos'!G40 -> 0 | AA34: ='Rateio Custos Fixos'!H40 -> 0 | AB34: ='Rateio Custos Fixos'!I40 -> 0 | AC34: ='Rateio Custos Fixos'!J40 -> 0 | AD34: ='Rateio Custos Fixos'!K40 -> 0 | AE34: ='Rateio Custos Fixos'!L40 -> 0 | AF34: ='Rateio Custos Fixos'!M40 -> 0 | ... AN34: ='Rateio Custos Fixos'!U40 -> 0 | AP34: =SUM(Y34:AO34) -> 0 | AQ34: =AP34+W34+P34 -> 0 | AR34: 2623.3166 | AS34: =AP34+X34+P34 -> 0 | AT34: =(AQ34/H34) -> #DIV/0! | AU34: =AS34/H34 -> #DIV/0! | AV34: =AQ34/H34 -> #DIV/0! | AW34: =(AS34*#REF!)/'Est. Cust. Naci.'!H34 -> #REF! | AX34: =(J34*9) -> 0
B35: ='LISTA DE COMPRAS'!A34 -> 30 | C35: ='LISTA DE COMPRAS'!C34 -> 0 | G35: ='LISTA DE COMPRAS'!D35 -> 0 | H35: ='LISTA DE COMPRAS'!J34 -> 0 | I35: ='LISTA DE COMPRAS'!P34 -> 0 | J35: ='LISTA DE COMPRAS'!K34 -> 0 | K35: =H35*J35 -> 0 | L35: =K35*$L$4 -> 0 | M35: =L35*50% -> 0 | N35: =$N$4*I35 -> 0 | O35: ='Rateio Custos Fixos'!E41 -> 0 | P35: =SUM(L35,O35) -> 0 | Q35: =P35+R35 -> 0 | R35: =$P35*R$5 -> 0 | S35: =$Q35*S$5 -> 0 | T35: =$Q35*T$5 -> 0 | U35: =$Q35*U$5 -> 0 | V35: =$P35*V$5 -> 0 | W35: =SUM(R35:V35) -> 0 | X35: =SUM(R40:V40) -> 0 | Y35: ='Rateio Custos Fixos'!F41 -> 0 | Z35: ='Rateio Custos Fixos'!G41 -> 0 | AA35: ='Rateio Custos Fixos'!H41 -> 0 | AB35: ='Rateio Custos Fixos'!I41 -> 0 | AC35: ='Rateio Custos Fixos'!J41 -> 0 | AD35: ='Rateio Custos Fixos'!K41 -> 0 | AE35: ='Rateio Custos Fixos'!L41 -> 0 | AF35: ='Rateio Custos Fixos'!M41 -> 0 | ... AN35: ='Rateio Custos Fixos'!U41 -> 0 | AP35: =SUM(Y35:AO35) -> 0 | AQ35: =AP35+W35+P35 -> 0 | AR35: 2624.3166 | AS35: =AP35+X35+P35 -> 0 | AT35: =(AQ35/H35) -> #DIV/0! | AU35: =AS35/H35 -> #DIV/0! | AV35: =AQ35/H35 -> #DIV/0! | AW35: =(AS35*#REF!)/'Est. Cust. Naci.'!H35 -> #REF! | AX35: =(J35*9) -> 0
B36: ='LISTA DE COMPRAS'!A35 -> 31 | C36: ='LISTA DE COMPRAS'!C35 -> 0 | G36: ='LISTA DE COMPRAS'!D36 -> 0 | H36: ='LISTA DE COMPRAS'!J35 -> 0 | I36: ='LISTA DE COMPRAS'!P35 -> 0 | J36: ='LISTA DE COMPRAS'!K35 -> 0 | K36: =H36*J36 -> 0 | L36: =K36*$L$4 -> 0 | M36: =L36*50% -> 0 | N36: =$N$4*I36 -> 0 | O36: ='Rateio Custos Fixos'!E42 -> 0 | P36: =SUM(L36,O36) -> 0 | Q36: =P36+R36 -> 0 | R36: =$P36*R$5 -> 0 | S36: =$Q36*S$5 -> 0 | T36: =$Q36*T$5 -> 0 | U36: =$Q36*U$5 -> 0 | V36: =$P36*V$5 -> 0 | W36: =SUM(R36:V36) -> 0 | X36: =SUM(R41:V41) -> 0 | Y36: ='Rateio Custos Fixos'!F42 -> 0 | Z36: ='Rateio Custos Fixos'!G42 -> 0 | AA36: ='Rateio Custos Fixos'!H42 -> 0 | AB36: ='Rateio Custos Fixos'!I42 -> 0 | AC36: ='Rateio Custos Fixos'!J42 -> 0 | AD36: ='Rateio Custos Fixos'!K42 -> 0 | AE36: ='Rateio Custos Fixos'!L42 -> 0 | AF36: ='Rateio Custos Fixos'!M42 -> 0 | ... AN36: ='Rateio Custos Fixos'!U42 -> 0 | AP36: =SUM(Y36:AO36) -> 0 | AQ36: =AP36+W36+P36 -> 0 | AR36: 2625.3166 | AS36: =AP36+X36+P36 -> 0 | AT36: =(AQ36/H36) -> #DIV/0! | AU36: =AS36/H36 -> #DIV/0! | AV36: =AQ36/H36 -> #DIV/0! | AW36: =(AS36*#REF!)/'Est. Cust. Naci.'!H36 -> #REF! | AX36: =(J36*9) -> 0
B37: ='LISTA DE COMPRAS'!A36 -> 32 | C37: ='LISTA DE COMPRAS'!C36 -> 0 | G37: ='LISTA DE COMPRAS'!D37 -> 0 | H37: ='LISTA DE COMPRAS'!J36 -> 0 | I37: ='LISTA DE COMPRAS'!P36 -> 0 | J37: ='LISTA DE COMPRAS'!K36 -> 0 | K37: =H37*J37 -> 0 | L37: =K37*$L$4 -> 0 | M37: =L37*50% -> 0 | N37: =$N$4*I37 -> 0 | O37: ='Rateio Custos Fixos'!E43 -> 0 | P37: =SUM(L37,O37) -> 0 | Q37: =P37+R37 -> 0 | R37: =$P37*R$5 -> 0 | S37: =$Q37*S$5 -> 0 | T37: =$Q37*T$5 -> 0 | U37: =$Q37*U$5 -> 0 | V37: =$P37*V$5 -> 0 | W37: =SUM(R37:V37) -> 0 | X37: =SUM(R42:V42) -> 0 | Y37: ='Rateio Custos Fixos'!F43 -> 0 | Z37: ='Rateio Custos Fixos'!G43 -> 0 | AA37: ='Rateio Custos Fixos'!H43 -> 0 | AB37: ='Rateio Custos Fixos'!I43 -> 0 | AC37: ='Rateio Custos Fixos'!J43 -> 0 | AD37: ='Rateio Custos Fixos'!K43 -> 0 | AE37: ='Rateio Custos Fixos'!L43 -> 0 | AF37: ='Rateio Custos Fixos'!M43 -> 0 | ... AN37: ='Rateio Custos Fixos'!U43 -> 0 | AP37: =SUM(Y37:AO37) -> 0 | AQ37: =AP37+W37+P37 -> 0 | AR37: 2626.3166 | AS37: =AP37+X37+P37 -> 0 | AT37: =(AQ37/H37) -> #DIV/0! | AU37: =AS37/H37 -> #DIV/0! | AV37: =AQ37/H37 -> #DIV/0! | AW37: =(AS37*#REF!)/'Est. Cust. Naci.'!H37 -> #REF! | AX37: =(J37*9) -> 0
B38: ='LISTA DE COMPRAS'!A37 -> 33 | C38: ='LISTA DE COMPRAS'!C37 -> 0 | G38: ='LISTA DE COMPRAS'!D38 -> 0 | H38: ='LISTA DE COMPRAS'!J37 -> 0 | I38: ='LISTA DE COMPRAS'!P37 -> 0 | J38: ='LISTA DE COMPRAS'!K37 -> 0 | K38: =H38*J38 -> 0 | L38: =K38*$L$4 -> 0 | M38: =L38*50% -> 0 | N38: =$N$4*I38 -> 0 | O38: ='Rateio Custos Fixos'!E44 -> 0 | P38: =SUM(L38,O38) -> 0 | Q38: =P38+R38 -> 0 | R38: =$P38*R$5 -> 0 | S38: =$Q38*S$5 -> 0 | T38: =$Q38*T$5 -> 0 | U38: =$Q38*U$5 -> 0 | V38: =$P38*V$5 -> 0 | W38: =SUM(R38:V38) -> 0 | X38: =SUM(R43:V43) -> 0 | Y38: ='Rateio Custos Fixos'!F44 -> 0 | Z38: ='Rateio Custos Fixos'!G44 -> 0 | AA38: ='Rateio Custos Fixos'!H44 -> 0 | AB38: ='Rateio Custos Fixos'!I44 -> 0 | AC38: ='Rateio Custos Fixos'!J44 -> 0 | AD38: ='Rateio Custos Fixos'!K44 -> 0 | AE38: ='Rateio Custos Fixos'!L44 -> 0 | AF38: ='Rateio Custos Fixos'!M44 -> 0 | ... AN38: ='Rateio Custos Fixos'!U44 -> 0 | AP38: =SUM(Y38:AO38) -> 0 | AQ38: =AP38+W38+P38 -> 0 | AR38: 2627.3166 | AS38: =AP38+X38+P38 -> 0 | AT38: =(AQ38/H38) -> #DIV/0! | AU38: =AS38/H38 -> #DIV/0! | AV38: =AQ38/H38 -> #DIV/0! | AW38: =(AS38*#REF!)/'Est. Cust. Naci.'!H38 -> #REF! | AX38: =(J38*9) -> 0
B39: ='LISTA DE COMPRAS'!A38 -> 34 | C39: ='LISTA DE COMPRAS'!C38 -> 0 | G39: ='LISTA DE COMPRAS'!D39 -> 0 | H39: ='LISTA DE COMPRAS'!J38 -> 0 | I39: ='LISTA DE COMPRAS'!P38 -> 0 | J39: ='LISTA DE COMPRAS'!K38 -> 0 | K39: =H39*J39 -> 0 | L39: =K39*$L$4 -> 0 | M39: =L39*50% -> 0 | N39: =$N$4*I39 -> 0 | O39: ='Rateio Custos Fixos'!E45 -> 0 | P39: =SUM(L39,O39) -> 0 | Q39: =P39+R39 -> 0 | R39: =$P39*R$5 -> 0 | S39: =$Q39*S$5 -> 0 | T39: =$Q39*T$5 -> 0 | U39: =$Q39*U$5 -> 0 | V39: =$P39*V$5 -> 0 | W39: =SUM(R39:V39) -> 0 | X39: =SUM(R44:V44) -> 0 | Y39: ='Rateio Custos Fixos'!F45 -> 0 | Z39: ='Rateio Custos Fixos'!G45 -> 0 | AA39: ='Rateio Custos Fixos'!H45 -> 0 | AB39: ='Rateio Custos Fixos'!I45 -> 0 | AC39: ='Rateio Custos Fixos'!J45 -> 0 | AD39: ='Rateio Custos Fixos'!K45 -> 0 | AE39: ='Rateio Custos Fixos'!L45 -> 0 | AF39: ='Rateio Custos Fixos'!M45 -> 0 | ... AN39: ='Rateio Custos Fixos'!U45 -> 0 | AP39: =SUM(Y39:AO39) -> 0 | AQ39: =AP39+W39+P39 -> 0 | AR39: 2628.3166 | AS39: =AP39+X39+P39 -> 0 | AT39: =(AQ39/H39) -> #DIV/0! | AU39: =AS39/H39 -> #DIV/0! | AV39: =AQ39/H39 -> #DIV/0! | AW39: =(AS39*#REF!)/'Est. Cust. Naci.'!H39 -> #REF! | AX39: =(J39*9) -> 0
B40: ='LISTA DE COMPRAS'!A39 -> 35 | C40: ='LISTA DE COMPRAS'!C39 -> 0 | G40: ='LISTA DE COMPRAS'!D40 -> 0 | H40: ='LISTA DE COMPRAS'!J39 -> 0 | I40: ='LISTA DE COMPRAS'!P39 -> 0 | J40: ='LISTA DE COMPRAS'!K39 -> 0 | K40: =H40*J40 -> 0 | L40: =K40*$L$4 -> 0 | M40: =L40*50% -> 0 | N40: =$N$4*I40 -> 0 | O40: ='Rateio Custos Fixos'!E46 -> 0 | P40: =SUM(L40,O40) -> 0 | Q40: =P40+R40 -> 0 | R40: =$P40*R$5 -> 0 | S40: =$Q40*S$5 -> 0 | T40: =$Q40*T$5 -> 0 | U40: =$Q40*U$5 -> 0 | V40: =$P40*V$5 -> 0 | W40: =SUM(R40:V40) -> 0 | X40: =SUM(R45:V45) -> 0 | Y40: ='Rateio Custos Fixos'!F46 -> 0 | Z40: ='Rateio Custos Fixos'!G46 -> 0 | AA40: ='Rateio Custos Fixos'!H46 -> 0 | AB40: ='Rateio Custos Fixos'!I46 -> 0 | AC40: ='Rateio Custos Fixos'!J46 -> 0 | AD40: ='Rateio Custos Fixos'!K46 -> 0 | AE40: ='Rateio Custos Fixos'!L46 -> 0 | AF40: ='Rateio Custos Fixos'!M46 -> 0 | ... AN40: ='Rateio Custos Fixos'!U46 -> 0 | AP40: =SUM(Y40:AO40) -> 0 | AQ40: =AP40+W40+P40 -> 0 | AR40: 2629.3166 | AS40: =AP40+X40+P40 -> 0 | AT40: =(AQ40/H40) -> #DIV/0! | AU40: =AS40/H40 -> #DIV/0! | AV40: =AQ40/H40 -> #DIV/0! | AW40: =(AS40*#REF!)/'Est. Cust. Naci.'!H40 -> #REF! | AX40: =(J40*9) -> 0
B41: ='LISTA DE COMPRAS'!A40 -> 36 | C41: ='LISTA DE COMPRAS'!C40 -> 0 | G41: ='LISTA DE COMPRAS'!D41 -> 0 | H41: ='LISTA DE COMPRAS'!J40 -> 0 | I41: ='LISTA DE COMPRAS'!P40 -> 0 | J41: ='LISTA DE COMPRAS'!K40 -> 0 | K41: =H41*J41 -> 0 | L41: =K41*$L$4 -> 0 | M41: =L41*50% -> 0 | N41: =$N$4*I41 -> 0 | O41: ='Rateio Custos Fixos'!E47 -> 0 | P41: =SUM(L41,O41) -> 0 | Q41: =P41+R41 -> 0 | R41: =$P41*R$5 -> 0 | S41: =$Q41*S$5 -> 0 | T41: =$Q41*T$5 -> 0 | U41: =$Q41*U$5 -> 0 | V41: =$P41*V$5 -> 0 | W41: =SUM(R41:V41) -> 0 | X41: =SUM(R46:V46) -> 0 | Y41: ='Rateio Custos Fixos'!F47 -> 0 | Z41: ='Rateio Custos Fixos'!G47 -> 0 | AA41: ='Rateio Custos Fixos'!H47 -> 0 | AB41: ='Rateio Custos Fixos'!I47 -> 0 | AC41: ='Rateio Custos Fixos'!J47 -> 0 | AD41: ='Rateio Custos Fixos'!K47 -> 0 | AE41: ='Rateio Custos Fixos'!L47 -> 0 | AF41: ='Rateio Custos Fixos'!M47 -> 0 | ... AN41: ='Rateio Custos Fixos'!U47 -> 0 | AP41: =SUM(Y41:AO41) -> 0 | AQ41: =AP41+W41+P41 -> 0 | AR41: 2630.3166 | AS41: =AP41+X41+P41 -> 0 | AT41: =(AQ41/H41) -> #DIV/0! | AU41: =AS41/H41 -> #DIV/0! | AV41: =AQ41/H41 -> #DIV/0! | AW41: =(AS41*#REF!)/'Est. Cust. Naci.'!H41 -> #REF! | AX41: =(J41*9) -> 0
... B53: ='LISTA DE COMPRAS'!A52 -> 48 | C53: ='LISTA DE COMPRAS'!C52 -> 0 | G53: ='LISTA DE COMPRAS'!D53 -> 0 | H53: ='LISTA DE COMPRAS'!J52 -> 0 | I53: ='LISTA DE COMPRAS'!P52 -> 0 | J53: ='LISTA DE COMPRAS'!K52 -> 0 | K53: =H53*J53 -> 0 | L53: =K53*$L$4 -> 0 | M53: =L53*50% -> 0 | N53: =$N$4*I53 -> 0 | O53: ='Rateio Custos Fixos'!E59 -> 0 | P53: =SUM(L53,O53) -> 0 | Q53: =P53+R53 -> 0 | R53: =$P53*R$5 -> 0 | S53: =$Q53*S$5 -> 0 | T53: =$Q53*T$5 -> 0 | U53: =$Q53*U$5 -> 0 | V53: =$P53*V$5 -> 0 | W53: =SUM(R53:V53) -> 0 | X53: =SUM(R58:V58) -> 0 | Y53: ='Rateio Custos Fixos'!F59 -> 0 | Z53: ='Rateio Custos Fixos'!G59 -> 0 | AA53: ='Rateio Custos Fixos'!H59 -> 0 | AB53: ='Rateio Custos Fixos'!I59 -> 0 | AC53: ='Rateio Custos Fixos'!J59 -> 0 | AD53: ='Rateio Custos Fixos'!K59 -> 0 | AE53: ='Rateio Custos Fixos'!L59 -> 0 | AF53: ='Rateio Custos Fixos'!M59 -> 0 | ... AN53: ='Rateio Custos Fixos'!U59 -> 0 | AP53: =SUM(Y53:AO53) -> 0 | AQ53: =AP53+W53+P53 -> 0 | AR53: 2642.3166 | AS53: =AP53+X53+P53 -> 0 | AT53: =(AQ53/H53) -> #DIV/0! | AU53: =AS53/H53 -> #DIV/0! | AV53: =AQ53/H53 -> #DIV/0! | AW53: =(AS53*#REF!)/'Est. Cust. Naci.'!H53 -> #REF! | AX53: =(J53*9) -> 0
B54: ='LISTA DE COMPRAS'!A53 -> 49 | C54: ='LISTA DE COMPRAS'!C53 -> 0 | G54: ='LISTA DE COMPRAS'!D54 -> 0 | H54: ='LISTA DE COMPRAS'!J53 -> 0 | I54: ='LISTA DE COMPRAS'!P53 -> 0 | J54: ='LISTA DE COMPRAS'!K53 -> 0 | K54: =H54*J54 -> 0 | L54: =K54*$L$4 -> 0 | M54: =L54*50% -> 0 | N54: =$N$4*I54 -> 0 | O54: ='Rateio Custos Fixos'!E60 -> 0 | P54: =SUM(L54,O54) -> 0 | Q54: =P54+R54 -> 0 | R54: =$P54*R$5 -> 0 | S54: =$Q54*S$5 -> 0 | T54: =$Q54*T$5 -> 0 | U54: =$Q54*U$5 -> 0 | V54: =$P54*V$5 -> 0 | W54: =SUM(R54:V54) -> 0 | X54: =SUM(#REF!) -> #REF! | Y54: ='Rateio Custos Fixos'!F60 -> 0 | Z54: ='Rateio Custos Fixos'!G60 -> 0 | AA54: ='Rateio Custos Fixos'!H60 -> 0 | AB54: ='Rateio Custos Fixos'!I60 -> 0 | AC54: ='Rateio Custos Fixos'!J60 -> 0 | AD54: ='Rateio Custos Fixos'!K60 -> 0 | AE54: ='Rateio Custos Fixos'!L60 -> 0 | AF54: ='Rateio Custos Fixos'!M60 -> 0 | ... AN54: ='Rateio Custos Fixos'!U60 -> 0 | AP54: =SUM(Y54:AO54) -> 0 | AQ54: =AP54+W54+P54 -> 0 | AR54: 2643.3166 | AS54: =AP54+X54+P54 -> #REF! | AT54: =(AQ54/H54) -> #DIV/0! | AU54: =AS54/H54 -> #REF! | AV54: =AQ54/H54 -> #DIV/0! | AW54: =(AS54*#REF!)/'Est. Cust. Naci.'!H54 -> #REF! | AX54: =(J54*9) -> 0
B55: ='LISTA DE COMPRAS'!A54 -> 50 | C55: ='LISTA DE COMPRAS'!C54 -> 0 | G55: ='LISTA DE COMPRAS'!D55 -> 0 | H55: ='LISTA DE COMPRAS'!J54 -> 0 | I55: ='LISTA DE COMPRAS'!P54 -> 0 | J55: ='LISTA DE COMPRAS'!K54 -> 0 | K55: =H55*J55 -> 0 | L55: =K55*$L$4 -> 0 | M55: =L55*50% -> 0 | N55: =$N$4*I55 -> 0 | O55: ='Rateio Custos Fixos'!E61 -> 0 | P55: =SUM(L55,O55) -> 0 | Q55: =P55+R55 -> 0 | R55: =$P55*R$5 -> 0 | S55: =$Q55*S$5 -> 0 | T55: =$Q55*T$5 -> 0 | U55: =$Q55*U$5 -> 0 | V55: =$P55*V$5 -> 0 | W55: =SUM(R55:V55) -> 0 | X55: =SUM(#REF!) -> #REF! | Y55: ='Rateio Custos Fixos'!F61 -> 0 | Z55: ='Rateio Custos Fixos'!G61 -> 0 | AA55: ='Rateio Custos Fixos'!H61 -> 0 | AB55: ='Rateio Custos Fixos'!I61 -> 0 | AC55: ='Rateio Custos Fixos'!J61 -> 0 | AD55: ='Rateio Custos Fixos'!K61 -> 0 | AE55: ='Rateio Custos Fixos'!L61 -> 0 | AF55: ='Rateio Custos Fixos'!M61 -> 0 | ... AN55: ='Rateio Custos Fixos'!U61 -> 0 | AP55: =SUM(Y55:AO55) -> 0 | AQ55: =AP55+W55+P55 -> 0 | AR55: 2644.3166 | AS55: =AP55+X55+P55 -> #REF! | AT55: =(AQ55/H55) -> #DIV/0! | AU55: =AS55/H55 -> #REF! | AV55: =AQ55/H55 -> #DIV/0! | AW55: =(AS55*#REF!)/'Est. Cust. Naci.'!H55 -> #REF! | AX55: =(J55*9) -> 0
B56: ='LISTA DE COMPRAS'!A55 -> 51 | C56: ='LISTA DE COMPRAS'!C55 -> 0 | G56: ='LISTA DE COMPRAS'!D56 -> 0 | H56: ='LISTA DE COMPRAS'!J55 -> 0 | I56: ='LISTA DE COMPRAS'!P55 -> 0 | J56: ='LISTA DE COMPRAS'!K55 -> 0 | K56: =H56*J56 -> 0 | L56: =K56*$L$4 -> 0 | M56: =L56*50% -> 0 | N56: =$N$4*I56 -> 0 | O56: ='Rateio Custos Fixos'!E62 -> 0 | P56: =SUM(L56,O56) -> 0 | Q56: =P56+R56 -> 0 | R56: =$P56*R$5 -> 0 | S56: =$Q56*S$5 -> 0 | T56: =$Q56*T$5 -> 0 | U56: =$Q56*U$5 -> 0 | V56: =$P56*V$5 -> 0 | W56: =SUM(R56:V56) -> 0 | X56: =SUM(R59:V59) -> 0 | Y56: ='Rateio Custos Fixos'!F62 -> 0 | Z56: ='Rateio Custos Fixos'!G62 -> 0 | AA56: ='Rateio Custos Fixos'!H62 -> 0 | AB56: ='Rateio Custos Fixos'!I62 -> 0 | AC56: ='Rateio Custos Fixos'!J62 -> 0 | AD56: ='Rateio Custos Fixos'!K62 -> 0 | AE56: ='Rateio Custos Fixos'!L62 -> 0 | AF56: ='Rateio Custos Fixos'!M62 -> 0 | ... AN56: ='Rateio Custos Fixos'!U62 -> 0 | AP56: =SUM(Y56:AO56) -> 0 | AQ56: =AP56+W56+P56 -> 0 | AR56: 2645.3166 | AS56: =AP56+X56+P56 -> 0 | AT56: =(AQ56/H56) -> #DIV/0! | AU56: =AS56/H56 -> #DIV/0! | AV56: =AQ56/H56 -> #DIV/0! | AW56: =(AS56*#REF!)/'Est. Cust. Naci.'!H56 -> #REF! | AX56: =(J56*9) -> 0
B57: ='LISTA DE COMPRAS'!A56 -> 52 | C57: ='LISTA DE COMPRAS'!C56 -> 0 | G57: ='LISTA DE COMPRAS'!D57 -> 0 | H57: ='LISTA DE COMPRAS'!J56 -> 0 | I57: ='LISTA DE COMPRAS'!P56 -> 0 | J57: ='LISTA DE COMPRAS'!K56 -> 0 | K57: =H57*J57 -> 0 | L57: =K57*$L$4 -> 0 | M57: =L57*50% -> 0 | N57: =$N$4*I57 -> 0 | O57: ='Rateio Custos Fixos'!E63 -> 0 | P57: =SUM(L57,O57) -> 0 | Q57: =P57+R57 -> 0 | R57: =$P57*R$5 -> 0 | S57: =$Q57*S$5 -> 0 | T57: =$Q57*T$5 -> 0 | U57: =$Q57*U$5 -> 0 | V57: =$P57*V$5 -> 0 | W57: =SUM(R57:V57) -> 0 | X57: =SUM(R60:V60) -> 0 | Y57: ='Rateio Custos Fixos'!F63 -> 0 | Z57: ='Rateio Custos Fixos'!G63 -> 0 | AA57: ='Rateio Custos Fixos'!H63 -> 0 | AB57: ='Rateio Custos Fixos'!I63 -> 0 | AC57: ='Rateio Custos Fixos'!J63 -> 0 | AD57: ='Rateio Custos Fixos'!K63 -> 0 | AE57: ='Rateio Custos Fixos'!L63 -> 0 | AF57: ='Rateio Custos Fixos'!M63 -> 0 | ... AN57: ='Rateio Custos Fixos'!U63 -> 0 | AP57: =SUM(Y57:AO57) -> 0 | AQ57: =AP57+W57+P57 -> 0 | AR57: 2646.3166 | AS57: =AP57+X57+P57 -> 0 | AT57: =(AQ57/H57) -> #DIV/0! | AU57: =AS57/H57 -> #DIV/0! | AV57: =AQ57/H57 -> #DIV/0! | AW57: =(AS57*#REF!)/'Est. Cust. Naci.'!H57 -> #REF! | AX57: =(J57*9) -> 0
B58: ='LISTA DE COMPRAS'!A57 -> 53 | C58: ='LISTA DE COMPRAS'!C57 -> 0 | G58: ='LISTA DE COMPRAS'!#REF! -> #REF! | H58: ='LISTA DE COMPRAS'!J57 -> 0 | I58: ='LISTA DE COMPRAS'!P57 -> 0 | J58: ='LISTA DE COMPRAS'!K57 -> 0 | K58: =H58*J58 -> 0 | L58: =K58*$L$4 -> 0 | M58: =L58*50% -> 0 | N58: =$N$4*I58 -> 0 | O58: ='Rateio Custos Fixos'!E64 -> 0 | P58: =SUM(L58,O58) -> 0 | Q58: =P58+R58 -> 0 | R58: =$P58*R$5 -> 0 | S58: =$Q58*S$5 -> 0 | T58: =$Q58*T$5 -> 0 | U58: =$Q58*U$5 -> 0 | V58: =$P58*V$5 -> 0 | W58: =SUM(R58:V58) -> 0 | X58: =SUM(R61:V61) -> 0 | Y58: ='Rateio Custos Fixos'!F64 -> 0 | Z58: ='Rateio Custos Fixos'!G64 -> 0 | AA58: ='Rateio Custos Fixos'!H64 -> 0 | AB58: ='Rateio Custos Fixos'!I64 -> 0 | AC58: ='Rateio Custos Fixos'!J64 -> 0 | AD58: ='Rateio Custos Fixos'!K64 -> 0 | AE58: ='Rateio Custos Fixos'!L64 -> 0 | AF58: ='Rateio Custos Fixos'!M64 -> 0 | ... AN58: ='Rateio Custos Fixos'!U64 -> 0 | AP58: =SUM(Y58:AO58) -> 0 | AQ58: =AP58+W58+P58 -> 0 | AR58: 2647.3166 | AS58: =AP58+X58+P58 -> 0 | AT58: =(AQ58/H58) -> #DIV/0! | AU58: =AS58/H58 -> #DIV/0! | AV58: =AQ58/H58 -> #DIV/0! | AW58: =(AS58*#REF!)/'Est. Cust. Naci.'!H58 -> #REF! | AX58: =(J58*9) -> 0
B59: ='LISTA DE COMPRAS'!A58 -> 0
L62: #VALUE! | N62: 5.1

Sheet Rateio Custos Fixos
A1: CÂMBIO | F1: FRETE | G1: R$
F2: 3363 | G2: =F2*B3 -> 17151.3
A3: #VALUE! | B3: 5.1 | F3: 2344 | G3: =F3 -> 2344
A4: #VALUE! | B4: {=_FV(A4,"Preço")} -> 5.973 | F4: TOTAL | G4: =SUM(G2:G3) -> 19495.3
G5: =G4/B3 -> 3822.6078
U8: ='Rateio Custos Fixos'!#REF! -> #REF!
A10: Produto | B10: Quantidade | C10: ='[2]Lista de Compra'!Q2 -> % Rateio Preço | E10: FRETE | F10: TAXA SISCOMEX | G10: LIBERAÇÃO DE B/L | H10: T.H.C| CAPATAZIA | I10: ISPS | J10: DAMAGE PROTECTION | K10: DESCONSOLIDAÇÃO | L10: DEVOLUÇÃO DE CONTAINER | M10: TRS | N10: AFRMM | O10: ARMAZENAGEM TCP | P10: SCANNER TCP | Q10: HANDLING - TCP | R10: PESAGEM TCP | S10: TAXA DO PARCEIRO - PARANAGUÁ | T10: FRETE RODOVIÁRIO | U10: DESEMBARAÇO ADUANEIRO | V10: COMISSÃO SEAWISE
B11: =SUM(B12:B64) -> 425 | C11: =SUM(C12:C64) -> 1 | E11: =G4 -> 19495.3 | F11: 214.5 | G11: 540 | H11: =1547 -> 1547 | I11: 60 | J11: 300 | K11: 400 | L11: =774.9 -> 774.9 | M11: 140 | N11: 0.08 | O11: 0 | P11: =756.95 -> 756.95 | Q11: 225 | R11: =117.45 -> 117.45 | S11: 286 | T11: 6000 | U11: 2400 | V11: 0.035 | W11: =SUM(E11:V11) -> 33257.215
A12: ='LISTA DE COMPRAS'!A5 -> 1 | B12: ='LISTA DE COMPRAS'!J5 -> 30 | C12: ='LISTA DE COMPRAS'!Q5 -> 0.019155529 | E12: =E$11*$C12 -> 373.44278 | F12: =F$11*$C12 -> 4.108861 | G12: =G$11*$C12 -> 10.343986 | H12: =H$11*$C12 -> 29.633603 | I12: =I$11*$C12 -> 1.1493317 | J12: =J$11*$C12 -> 5.7466587 | K12: =K$11*$C12 -> 7.6622116 | L12: =L$11*$C12 -> 14.843619 | M12: =M$11*$C12 -> 2.6817741 | N12: =$N$11*E12 -> 29.875423 | O12: =O$11*$C12 -> 0 | P12: =P$11*$C12 -> 14.499778 | Q12: =Q$11*$C12 -> 4.309994 | R12: =R$11*$C12 -> 2.2498169 | S12: =S$11*$C12 -> 5.4784813 | T12: =T$11*$C12 -> 114.93317 | U12: =U$11*$C12 -> 45.97327 | V12: =V$11*'Est. Cust. Naci.'!L6 -> 1759.4924
A13: ='LISTA DE COMPRAS'!A6 -> 2 | B13: ='LISTA DE COMPRAS'!J6 -> 30 | C13: ='LISTA DE COMPRAS'!Q6 -> 0.074332104 | E13: =E$11*$C13 -> 1449.1267 | F13: =F$11*$C13 -> 15.944236 | G13: =G$11*$C13 -> 40.139336 | H13: =H$11*$C13 -> 114.99177 | I13: =I$11*$C13 -> 4.4599263 | J13: =J$11*$C13 -> 22.299631 | K13: =K$11*$C13 -> 29.732842 | L13: =L$11*$C13 -> 57.599948 | M13: =M$11*$C13 -> 10.406495 | N13: =$N$11*E13 -> 115.93013 | O13: =O$11*$C13 -> 0 | P13: =P$11*$C13 -> 56.265686 | Q13: =Q$11*$C13 -> 16.724723 | R13: =R$11*$C13 -> 8.7303056 | S13: =S$11*$C13 -> 21.258982 | T13: =T$11*$C13 -> 445.99263 | U13: =U$11*$C13 -> 178.39705 | V13: =V$11*'Est. Cust. Naci.'!L7 -> 6827.625 | W13: =SUM(F13:U13) -> 1138.8737
A14: ='LISTA DE COMPRAS'!A7 -> 3 | B14: ='LISTA DE COMPRAS'!J7 -> 20 | C14: ='LISTA DE COMPRAS'!Q7 -> 0.011659938 | E14: =E$11*$C14 -> 227.31399 | F14: =F$11*$C14 -> 2.5010567 | G14: =G$11*$C14 -> 6.2963665 | H14: =H$11*$C14 -> 18.037924 | I14: =I$11*$C14 -> 0.69959627 | J14: =J$11*$C14 -> 3.4979814 | K14: =K$11*$C14 -> 4.6639752 | L14: =L$11*$C14 -> 9.0352859 | M14: =M$11*$C14 -> 1.6323913 | N14: =$N$11*E14 -> 18.185119 | O14: =O$11*$C14 -> 0 | P14: =P$11*$C14 -> 8.82599 | Q14: =Q$11*$C14 -> 2.623486 | R14: =R$11*$C14 -> 1.3694597 | S14: =S$11*$C14 -> 3.3347422 | T14: =T$11*$C14 -> 69.959627 | U14: =U$11*$C14 -> 27.983851 | V14: =V$11*'Est. Cust. Naci.'!L8 -> 714 | W14: =SUM(F14:U14) -> 178.64685
A15: ='LISTA DE COMPRAS'!A8 -> 4 | B15: ='LISTA DE COMPRAS'!J8 -> 240 | C15: ='LISTA DE COMPRAS'!Q8 -> 0.0077206279 | E15: =E$11*$C15 -> 150.51596 | F15: =F$11*$C15 -> 1.6560747 | G15: =G$11*$C15 -> 4.1691391 | H15: =H$11*$C15 -> 11.943811 | I15: =I$11*$C15 -> 0.46323767 | J15: =J$11*$C15 -> 2.3161884 | K15: =K$11*$C15 -> 3.0882512 | L15: =L$11*$C15 -> 5.9827146 | M15: =M$11*$C15 -> 1.0808879 | N15: =$N$11*E15 -> 12.041277 | O15: =O$11*$C15 -> 0 | P15: =P$11*$C15 -> 5.8441293 | Q15: =Q$11*$C15 -> 1.7371413 | R15: =R$11*$C15 -> 0.90678775 | S15: =S$11*$C15 -> 2.2080996 | T15: =T$11*$C15 -> 46.323767 | U15: =U$11*$C15 -> 18.529507 | V15: =V$11*'Est. Cust. Naci.'!L9 -> 5673.3012 | W15: =SUM(F15:U15) -> 118.29101
A16: ='LISTA DE COMPRAS'!A9 -> 5 | B16: ='LISTA DE COMPRAS'!J9 -> 20 | C16: ='LISTA DE COMPRAS'!Q9 -> 0.013375698 | E16: =E$11*$C16 -> 260.76324 | F16: =F$11*$C16 -> 2.8690872 | G16: =G$11*$C16 -> 7.2228768 | H16: =H$11*$C16 -> 20.692204 | I16: =I$11*$C16 -> 0.80254187 | J16: =J$11*$C16 -> 4.0127093 | K16: =K$11*$C16 -> 5.3502791 | L16: =L$11*$C16 -> 10.364828 | M16: =M$11*$C16 -> 1.8725977 | N16: =$N$11*E16 -> 20.861059 | O16: =O$11*$C16 -> 0 | P16: =P$11*$C16 -> 10.124734 | Q16: =Q$11*$C16 -> 3.009532 | R16: =R$11*$C16 -> 1.5709757 | S16: =S$11*$C16 -> 3.8254496 | T16: =T$11*$C16 -> 80.254187 | U16: =U$11*$C16 -> 32.101675 | V16: =V$11*'Est. Cust. Naci.'!L10 -> 819.0651
A17: ='LISTA DE COMPRAS'!A10 -> 6 | B17: ='LISTA DE COMPRAS'!J10 -> 3 | C17: ='LISTA DE COMPRAS'!Q10 -> 0.041273848 | E17: =E$11*$C17 -> 804.64605 | F17: =F$11*$C17 -> 8.8532404 | G17: =G$11*$C17 -> 22.287878 | H17: =H$11*$C17 -> 63.850643 | I17: =I$11*$C17 -> 2.4764309 | J17: =J$11*$C17 -> 12.382154 | K17: =K$11*$C17 -> 16.509539 | L17: =L$11*$C17 -> 31.983105 | M17: =M$11*$C17 -> 5.7783388 | N17: =$N$11*E17 -> 64.371684 | O17: =O$11*$C17 -> 0 | P17: =P$11*$C17 -> 31.242239 | Q17: =Q$11*$C17 -> 9.2866158 | R17: =R$11*$C17 -> 4.8476135 | S17: =S$11*$C17 -> 11.804321 | T17: =T$11*$C17 -> 247.64309 | U17: =U$11*$C17 -> 99.057236 | V17: =V$11*'Est. Cust. Naci.'!L11 -> 379.11258
A18: ='LISTA DE COMPRAS'!A11 -> 7 | B18: ='LISTA DE COMPRAS'!J11 -> 10 | C18: ='LISTA DE COMPRAS'!Q11 -> 0.034012622 | E18: =E$11*$C18 -> 663.08627 | F18: =F$11*$C18 -> 7.2957074 | G18: =G$11*$C18 -> 18.366816 | H18: =H$11*$C18 -> 52.617526 | I18: =I$11*$C18 -> 2.0407573 | J18: =J$11*$C18 -> 10.203787 | K18: =K$11*$C18 -> 13.605049 | L18: =L$11*$C18 -> 26.356381 | M18: =M$11*$C18 -> 4.7617671 | N18: =$N$11*E18 -> 53.046901 | O18: =O$11*$C18 -> 0 | P18: =P$11*$C18 -> 25.745854 | Q18: =Q$11*$C18 -> 7.6528399 | R18: =R$11*$C18 -> 3.9947824 | S18: =S$11*$C18 -> 9.7276099 | T18: =T$11*$C18 -> 204.07573 | U18: =U$11*$C18 -> 81.630293 | V18: =V$11*'Est. Cust. Naci.'!L12 -> 1041.3868
