Workbook

Sheet Resumo 100%
B3: Estimativa de Custo 100%
C5: CLIENTE: ALUPLOM | S5: ='Est. Cust. Naci.'!#REF! -> #REF!
C8: REGIME TRIBUTÁRIO: PRESUMIDO | E8: USO: INDUSTRIALIZAÇÃO | G8: CONSIDERAR ICMS 6% | J8: Valor das despesas | K8: 52965.362
C9: PRODUTO: CHAPA DE AÇO INOX | E9: PORTO SAÍDA: SHANGHAI | G9: =TODAY() -> 46105 | J9: Custo total | K9: 90312.509
C10: FRETE: FCL | E10: PORTO ENTRADA: PARANGUÁ | G10: SIMULAÇÃO 100%
K11: 1.4181903
B12: REFERÊNCIA CÁLCULO BASE | C12: R$/USD: | D12: ='Rateio Custos Fixos'!B3 -> 5.26 | E12: NCM: | F12: ='LISTA DE COMPRAS'!D5 -> 72192300
B13: VALORES ADUANEIROS | I13: ITEM | J13: DESCRIÇÃO | K13: USD UNIT PRICE | L13: QTY | O13: BRL UNIT PRICE
B14: DISCRIMINAÇÃO | C14: PESO BRUTO | E14: PREÇO USD | F14: PREÇO TOTAL USD | G14: R$ | I14: ='[1]Lista de Compra'!B4 -> 1 | J14: ='[1]Lista de Compra'!C4 -> Nº 9 | K14: ='[1]Lista de Compra'!K4 -> 107.71 | L14: ='[1]Lista de Compra'!J4 -> 15 | M14: =K14*L14*'[1]Rateio Custos Fixos'!$B$26 -> 7750.5962 | N14: =M14+(M14*$K$11) -> 18742.416 | O14: =N14/L14 -> 1249.4944
B15: ='LISTA DE COMPRAS'!C5 -> Chapa de aço Inox | C15: ='LISTA DE COMPRAS'!J5 -> 27 | E15: ='LISTA DE COMPRAS'!K5 -> 1500 | F15: =E15*C15 -> 40500 | G15: =F15*$D$12 -> 213030
B16: TOTAL FOB | F16: =SUM(F15:F15) -> 40500 | G16: =SUM(G15:G15) -> 213030
B17: PRODUTO + FRETE | G17: =G16+G19 -> 234240 | I17: ='[1]Lista de Compra'!B6 -> 3 | J17: ='[1]Lista de Compra'!C6 -> Nº 9 | K17: ='[1]Lista de Compra'!K6 -> 64.63 | L17: ='[1]Lista de Compra'!J6 -> 15 | M17: =K17*L17*'[1]Rateio Custos Fixos'!$B$26 -> 4650.6455 | N17: =M17+(M17*$K$11) -> 11246.146 | O17: =N17/L17 -> 749.74305
B18: Seguro | I18: ='[1]Lista de Compra'!B7 -> 4 | J18: ='[1]Lista de Compra'!C7 -> Nº 9 | K18: ='[1]Lista de Compra'!K7 -> 107.71 | L18: ='[1]Lista de Compra'!J7 -> 15 | M18: =K18*L18*'[1]Rateio Custos Fixos'!$B$26 -> 7750.5962 | N18: =M18+(M18*$K$11) -> 18742.416 | O18: =N18/L18 -> 1249.4944
B19: Frete | F19: ='Rateio Custos Fixos'!G5 -> 4032.3194 | G19: =F19*D12 -> 21210 | I19: ='[1]Lista de Compra'!B8 -> 5 | J19: ='[1]Lista de Compra'!C8 -> Nº 9 | K19: ='[1]Lista de Compra'!K8 -> 86.17 | L19: ='[1]Lista de Compra'!J8 -> 15 | M19: =K19*L19*'[1]Rateio Custos Fixos'!$B$26 -> 6200.6209 | N19: =M19+(M19*$K$11) -> 14994.281 | O19: =N19/L19 -> 999.61874
B20: TOTAL VALOR ADUANEIRO | G20: =G17 -> 234240 | I20: ='[1]Lista de Compra'!B9 -> 6 | J20: ='[1]Lista de Compra'!C9 -> Nº 9 | K20: ='[1]Lista de Compra'!K9 -> 64.63 | L20: ='[1]Lista de Compra'!J9 -> 15 | M20: =K20*L20*'[1]Rateio Custos Fixos'!$B$26 -> 4650.6455 | N20: =M20+(M20*$K$11) -> 11246.146 | O20: =N20/L20 -> 749.74305
B21: IMPOSTOS
B22: IMPOSTOS | C22: PERCENTUAL | G22: VALOR (R$)
B23: IMPOSTO. IMPORTAÇÃO | C23: ='Est. Cust. Naci.'!R4 -> 0.126 | G23: ='Est. Cust. Naci.'!R$7 -> 29514.24
B24: IPI | C24: ='Est. Cust. Naci.'!S4 -> 0.0365 | G24: ='Est. Cust. Naci.'!S$7 -> 9627.0298
B25: PIS | C25: ='Est. Cust. Naci.'!T4 -> 0.021 | G25: ='Est. Cust. Naci.'!T$7 -> 4919.04
B26: COFINS | C26: ='Est. Cust. Naci.'!U4 -> 0.0965 | G26: ='Est. Cust. Naci.'!U$7 -> 22604.16
B27: ICMS | C27: 0.06 | G27: ='Est. Cust. Naci.'!V$7 -> 14054.4
B28: TOTAL VALOR IMPOSTOS | G28: =SUM(G23:G27) -> 80718.87
B29: DESPESAS ADUANEIRAS E LOGÍSTICAS
B30: TAXA SISCOMEX | G30: ='Rateio Custos Fixos'!F11 -> 214.5
B31: LIBERAÇÃO DE B/L | G31: ='Rateio Custos Fixos'!G11 -> 490
B32: T.H.C|CAPATAZIA | G32: ='Rateio Custos Fixos'!H11 -> 1547
B33: ISPS | G33: ='Rateio Custos Fixos'!I11 -> 48
B34: DAMAGE PROTECTION | G34: ='Rateio Custos Fixos'!J11 -> 122
B35: DESCONSOLIDAÇÃO | G35: ='Rateio Custos Fixos'!K11 -> 1072.94
B36: DEVOLUÇÃO DE CONTAINER | G36: ='Rateio Custos Fixos'!L11 -> 774.9
B37: TRS | G37: ='Rateio Custos Fixos'!M11 -> 29.8
B38: AFRMM | C38: 0.08 | G38: =C38*G19 -> 1696.8
B39: ARMAZENAGEM | G39: ='[1]Est. Cust. Naci. 100%'!AB21 -> 0 | H39: 5 DIAS DE ARMAZENAGEM
B40: SCANNER | G40: ='Rateio Custos Fixos'!P11 -> 756.95
B41: HANDLING | G41: ='Rateio Custos Fixos'!Q11 -> 320.33
B42: PESAGEM | G42: ='Rateio Custos Fixos'!R11 -> 117.45
B43: TAXA DO PARCEIRO | G43: ='Rateio Custos Fixos'!S11 -> 286
B44: FRETE RODOVIÁRIO | G44: ='Rateio Custos Fixos'!T11 -> 6000
B45: DESEMBARAÇO ADUANEIRO | G45: ='Rateio Custos Fixos'!U11 -> 2300
...

Sheet LISTA DE COMPRAS
A1: LISTA DE COMPRA
A3: Item | B3: Estimativa de Custo 100% | C3: Produto | D3: NCM | E3: II | F3: IPI | G3: PIS | H3: COFINS | I3: ICMS | J3: Quantidade (kg) | K3: Preço Unitário | L3: Preço Unitário Sub 50% | M3: Preço total por produto | N3: Preço total por produto | O3: Preço total por produto Sub | P3: % Rateio Quantidade | Q3: % Rateio Preço | R3: Preço R$ Quilo nacionalizado | S3: Preço R$ Rolo nancionalizado
J4: =SUM(J5:J5) -> 27 | K4: =SUM(K5:K5) -> 1500 | M4: =SUM(M5:M5) -> 40500 | N4: 5.38 | P4: 1 | Q4: 1
A5: 1 | C5: Chapa de aço Inox | D5: 72192300 | E5: 0.126 | F5: 0.0365 | G5: 0.021 | H5: 0.0965 | I5: 0.06 | J5: 27 | K5: 1500 | L5: =K5/2 -> 750 | M5: =K5*J5 -> 40500 | N5: =M5*$N$4 -> 217890 | O5: =L5*J5*$N$4 -> 108945 | P5: =(J5*$P$4)/$J$4 -> 1 | Q5: =(K5*$Q$4)/$K$4 -> 1 | R5: ='Est. Cust. Naci.'!AU6 -> 12249.464 | S5: ='Resumo 100%'!G49 -> 12249.464
E16: #VALUE! | F16: 5.26

Sheet Est. Cust. Naci.
C2: DETALHES DO PRODUTO | L2: VALOR ADUANEIRO | R2: IMPOSTOS | Y2: TAXAS PORTUÁRIAS
B3: Nº | C3: ITEM | D3: Código | E3: Bitola (mm) | F3: Embal. | G3: NCM | H3: QTD | I3: % Rateio Preço | J3: Preço unitário Fábrica (USD) | K3: Preço x QTD (Valor em USD) | L3: Preço x QTD (valor em BRL) | M3: Preço x QTD (valor em BRL) SUB | N3: THC (valor em BRL) | O3: Valor do frete (Valor em BRL) | P3: TOTAL VALOR ADUANEIRO | Q3: VALOR COM IMPOSTO DE IMPORTAÇÃO | R3: IMPOSTO DE IMPORTAÇÃO | S3: IPI | T3: PIS | U3: COFINS | V3: ICMS | W3: TOTAL IMPOSTOS | X3: TOTAL IMPOSTOS (SUB) | Y3: TAXA SISCOMEX | Z3: LIBERAÇÃO DE B/L | AA3: T.H.C| CAPATAZIA | AB3: ISPS | AC3: DAMAGE PROTECTION | AD3: DESCONSOLIDAÇÃO | AE3: DEVOLUÇÃO DE CONTAINER | AF3: TRS | AG3: AFRMM | AH3: ARMAZENAGEM TCP | AI3: SCANNER TCP | AJ3: HANDLING - TCP | AK3: PESAGEM TCP | AL3: TAXA DO PARCEIRO - PARANAGUÁ | AM3: FRETE RODOVIÁRIO | AN3: DESEMBARAÇO ADUANEIRO | AO3: TOTAL TAXAS DESEMBARAÇO | AP3: TOTAL | AQ3: TOTAL (sub) | AR3: TOTAL (sub) | AS3: MÉTODO ANTIGO | AT3: MÉTODO ANTIGO (sub) | AU3: MÉTODO DANI | AV3: MÉTODO DANI (sub) | AW3: MÉTODO JULIANA | AX3: MÉTODO JULIANA (sub) | AZ3: VALOR UNITÁRIO C/ COMISSÃO SEAWISE
A4: Nº | L4: =N13 -> 5.26 | M4: 4.8887 | N4: 0 | P4: =SUM(P6:P6) -> 234240 | R4: ='LISTA DE COMPRAS'!E5 -> 0.126 | S4: ='LISTA DE COMPRAS'!F5 -> 0.0365 | T4: ='LISTA DE COMPRAS'!G5 -> 0.021 | U4: ='LISTA DE COMPRAS'!H5 -> 0.0965 | V4: ='LISTA DE COMPRAS'!I5 -> 0.06 | AG4: 0.08
A5: AAA | R5: =R4 -> 0.126 | S5: =S4 -> 0.0365 | T5: =T4 -> 0.021 | U5: =U4 -> 0.0965 | V5: =V4 -> 0.06 | W5: =W6 -> 80718.87 | X5: =SUM(#REF!,X6) -> #REF! | AO5: =SUM(AO6:AO6) -> 15776.67 | AP5: =AO5+W5+P4 -> 330735.54 | AQ5: 21877.425 | AR5: =AO5+X5+Q4+#REF! -> #REF!
A6: AAA | B6: ='LISTA DE COMPRAS'!A5 -> 1 | C6: ='LISTA DE COMPRAS'!C5 -> Chapa de aço Inox | G6: ='LISTA DE COMPRAS'!D5 -> 72192300 | H6: ='LISTA DE COMPRAS'!J5 -> 27 | I6: ='LISTA DE COMPRAS'!Q5 -> 1 | J6: ='LISTA DE COMPRAS'!K5 -> 1500 | K6: =H6*J6 -> 40500 | L6: =K6*$L$4 -> 213030 | M6: =L6*50% -> 106515 | N6: =$N$4*I6 -> 0 | O6: ='Rateio Custos Fixos'!E13 -> 21210 | P6: =SUM(L6,O6) -> 234240 | Q6: =SUM(P6+R6) -> 263754.24 | R6: =$P6*R$5 -> 29514.24 | S6: =$Q6*S$4 -> 9627.0298 | T6: =$P6*T$5 -> 4919.04 | U6: =$P6*U$5 -> 22604.16 | V6: =$P6*V$5 -> 14054.4 | W6: =SUM(R6:V6) -> 80718.87 | X6: =SUM(R12:V12) -> 89676.442 | Y6: ='Rateio Custos Fixos'!F13 -> 214.5 | Z6: ='Rateio Custos Fixos'!G13 -> 490 | AA6: ='Rateio Custos Fixos'!H13 -> 1547 | AB6: ='Rateio Custos Fixos'!I13 -> 48 | AC6: ='Rateio Custos Fixos'!J13 -> 122 | AD6: ='Rateio Custos Fixos'!K13 -> 1072.94 | AE6: ='Rateio Custos Fixos'!L13 -> 774.9 | AF6: ='Rateio Custos Fixos'!M13 -> 29.8 | ... AN6: ='Rateio Custos Fixos'!U13 -> 2300 | AO6: =SUM(Y6:AN6) -> 15776.67 | AP6: =AO6+W6+P6 -> 330735.54 | AQ6: 2595.3166 | AR6: =AO6+X6+P6 -> 339693.11 | AS6: =(AP6/H6) -> 12249.464 | AT6: =AR6/H6 -> 12581.226 | AU6: =(L6+(L6*$AP$17))/H6 -> 12249.464 | AV6: =(AR6*#REF!)/'Est. Cust. Naci.'!H6 -> #REF! | AW6: =(J6*9) -> 13500 | AX6: =AW6/2 -> 6750 | AZ6: =AP6/H6 -> 12249.464
R7: =SUM(R6:R6) -> 29514.24 | S7: =SUM(S6:S6) -> 9627.0298 | T7: =SUM(T6:T6) -> 4919.04 | U7: =SUM(U6:U6) -> 22604.16 | V7: =SUM(V6:V6) -> 14054.4
R11: =#REF!*R$5 -> #REF! | S11: =#REF!*S$5 -> #REF! | T11: =#REF!*T$5 -> #REF! | U11: =#REF!*U$5 -> #REF! | V11: =#REF!*V$5 -> #REF!
R12: =$Q6*R$5 -> 33233.034 | S12: =$Q6*S$5 -> 9627.0298 | T12: =$Q6*T$5 -> 5538.839 | U12: =$Q6*U$5 -> 25452.284 | V12: =$Q6*V$5 -> 15825.254
L13: #VALUE! | N13: 5.26
O14: =P4+W5+AO5 -> 330735.54 | AO14: fob | AP14: =SUM(L6:L6) -> 213030
AO15: despesas | AP15: =AP16-AP14 -> 117705.54
AO16: total | AP16: =AP5 -> 330735.54
P17: =P4='Resumo 100%'!G20 -> TRUE | AO17: despesas/fob | AP17: =AP15/AP14 -> 0.55253035
P18: =W5='Resumo 100%'!G28 -> TRUE
P19: =AO5=#REF! -> #REF!
S35: 13890.636 | T35: 4030.765 | U35: 2604.4943 | V35: 11968.271 | W35: 7441.4123 | Y35: =SUM(S35:X35) -> 39935.579
P38: 13890.636 | R38: II | S38: =P38=S35 -> TRUE
P39: 2604.4943 | R39: PIS | S39: =T35=P41 -> FALSE
P40: 11968.271 | R40: COFINS | S40: =V35=P40 -> TRUE
P41: 4092.7768 | R41: IPI | S41: =P41=T35 -> FALSE
P42: 7441.4123 | R42: ICMS | S42: =W35=P42 -> TRUE
P43: =SUM(P38:P42) -> 39997.591

Sheet Rateio Custos Fixos
A1: CÂMBIO | F1: FRETE | G1: R$
F2: 3500 | G2: =F2*B3 -> 18410
A3: #VALUE! | B3: 5.26 | F3: 2800 | G3: =F3 -> 2800
A4: #VALUE! | B4: {=_FV(A4,"Preço")} -> 6.3477 | F4: TOTAL | G4: =SUM(G2:G3) -> 21210
G5: =G4/B3 -> 4032.3194
U8: ='Rateio Custos Fixos'!#REF! -> #REF!
A10: Produto | B10: Quantidade | C10: ='[2]Lista de Compra'!Q2 -> % Rateio Preço | E10: FRETE | F10: TAXA SISCOMEX | G10: LIBERAÇÃO DE B/L | H10: T.H.C| CAPATAZIA | I10: ISPS | J10: DAMAGE PROTECTION | K10: DESCONSOLIDAÇÃO | L10: DEVOLUÇÃO DE CONTAINER | M10: TRS | N10: AFRMM | O10: ARMAZENAGEM TCP | P10: SCANNER TCP | Q10: HANDLING - TCP | R10: PESAGEM TCP | S10: TAXA DO PARCEIRO - PARANAGUÁ | T10: FRETE RODOVIÁRIO | U10: DESEMBARAÇO ADUANEIRO
B11: =SUM(B12:B13) -> #REF! | C11: =SUM(C12:C13) -> #REF! | E11: =G4 -> 21210 | F11: 214.5 | G11: 490 | H11: 1547 | I11: 48 | J11: 122 | K11: 1072.94 | L11: 774.9 | M11: 29.8 | N11: 0.08 | O11: 0 | P11: 756.95 | Q11: 320.33 | R11: 117.45 | S11: 286 | T11: 6000 | U11: 2300
A12: ='LISTA DE COMPRAS'!#REF! -> #REF! | B12: ='LISTA DE COMPRAS'!#REF! -> #REF! | C12: ='LISTA DE COMPRAS'!#REF! -> #REF! | E12: =E$11*$C12 -> #REF! | F12: =F$11*$C12 -> #REF! | G12: =G$11*$C12 -> #REF! | H12: =H$11*$C12 -> #REF! | I12: =I$11*$C12 -> #REF! | J12: =J$11*$C12 -> #REF! | K12: =K$11*$C12 -> #REF! | L12: =L$11*$C12 -> #REF! | M12: =M$11*$C12 -> #REF! | N12: =$N$11*E12 -> #REF! | O12: =O$11*$C12 -> #REF! | P12: =P$11*$C12 -> #REF! | Q12: =Q$11*$C12 -> #REF! | R12: =R$11*$C12 -> #REF! | S12: =S$11*$C12 -> #REF! | T12: =T$11*$C12 -> #REF! | U12: =U$11*$C12 -> #REF! | V12: =SUM(F12:U12) -> #REF!
A13: ='LISTA DE COMPRAS'!A5 -> 1 | B13: ='LISTA DE COMPRAS'!J5 -> 27 | C13: ='LISTA DE COMPRAS'!Q5 -> 1 | E13: =E$11*$C13 -> 21210 | F13: =F$11*$C13 -> 214.5 | G13: =G$11*$C13 -> 490 | H13: =H$11*$C13 -> 1547 | I13: =I$11*$C13 -> 48 | J13: =J$11*$C13 -> 122 | K13: =K$11*$C13 -> 1072.94 | L13: =L$11*$C13 -> 774.9 | M13: =M$11*$C13 -> 29.8 | N13: =$N$11*E13 -> 1696.8 | O13: =O$11*$C13 -> 0 | P13: =P$11*$C13 -> 756.95 | Q13: =Q$11*$C13 -> 320.33 | R13: =R$11*$C13 -> 117.45 | S13: =S$11*$C13 -> 286 | T13: =T$11*$C13 -> 6000 | U13: =U$11*$C13 -> 2300 | V13: =SUM(F13:U13) -> 15776.67
A14: ='LISTA DE COMPRAS'!#REF! -> #REF! | B14: ='LISTA DE COMPRAS'!#REF! -> #REF! | C14: ='LISTA DE COMPRAS'!#REF! -> #REF! | E14: =E$11*$C14 -> #REF! | F14: =F$11*$C14 -> #REF! | G14: =G$11*$C14 -> #REF! | H14: =H$11*$C14 -> #REF! | I14: =I$11*$C14 -> #REF! | J14: =J$11*$C14 -> #REF! | K14: =K$11*$C14 -> #REF! | L14: =L$11*$C14 -> #REF! | M14: =M$11*$C14 -> #REF! | N14: =$N$11*E14 -> #REF! | O14: =O$11*$C14 -> #REF! | P14: =P$11*$C14 -> #REF! | Q14: =Q$11*$C14 -> #REF! | R14: =R$11*$C14 -> #REF! | S14: =S$11*$C14 -> #REF! | T14: =T$11*$C14 -> #REF! | U14: =U$11*$C14 -> #REF!
E15: =SUM(E12:E14) -> #REF! | F15: =SUM(F12:F14) -> #REF! | G15: =SUM(G12:G14) -> #REF! | H15: =SUM(H12:H14) -> #REF! | I15: =SUM(I12:I14) -> #REF! | J15: =SUM(J12:J14) -> #REF! | K15: =SUM(K12:K14) -> #REF! | L15: =SUM(L12:L14) -> #REF! | ... U15: =SUM(U12:U14) -> #REF! | V15: =SUM(V12:V13) -> #REF!
E16: =E11=E15 -> #REF! | F16: =F11=F15 -> #REF! | G16: =G11=G15 -> #REF! | H16: =H11=H15 -> #REF! | I16: =I11=I15 -> #REF! | J16: =J11=J15 -> #REF! | K16: =K11=K15 -> #REF! | L16: =L11=L15 -> #REF! | M16: =M11=M15 -> #REF! | N16: =#REF!=N15 -> #REF! | O16: =O11=O15 -> #REF! | P16: =P11=P15 -> #REF! | Q16: =Q11=Q15 -> #REF! | R16: =R11=R15 -> #REF! | S16: =S11=S15 -> #REF! | T16: =T11=T15 -> #REF! | U16: =U11=U15 -> #REF!
N17: =E11*8% -> 1696.8
N18: =N15=N17 -> #REF!
