Workbook

Sheet Resumo 100%
B3: Estimativa de Custo 100% | J3: Quantidade | R3: Preço R$ nacionalizado
J5: 100 | K5: 5.8
J6: 300 | K6: 2.1
J7: 300 | K7: 10
C8: REGIME TRIBUTÁRIO: SIMPLES NACIONAL | E8: USO: REVENDA | G8: CONSIDERAR ICMS 18% | J8: 300 | K8: 10
C9: PRODUTO: AMORTECEDORES | E9: PORTO SAÍDA: SHANGHAI | G9: =TODAY() -> 46129 | J9: 300 | K9: 10
C10: FRETE: 1x40 | E10: PORTO ENTRADA: PARANAGUÁ | G10: SIMULAÇÃO 100% | J10: 100 | K10: 11.5
J11: 100 | K11: 11.5
B12: REFERÊNCIA CÁLCULO BASE | C12: R$/USD: | D12: ='Rateio Custos Fixos'!B3 -> 5.16 | E12: NCM: | F12: ='LISTA DE COMPRAS'!D6 -> 8708-8000 | K12: 0
B13: VALORES ADUANEIROS | I13: ITEM | J13: 100 | K13: 10.8 | L13: QTY | O13: BRL UNIT PRICE
B14: DISCRIMINAÇÃO | D14: UNIDADE | E14: PREÇO USD | F14: PREÇO TOTAL USD | G14: R$ | I14: ='[1]Lista de Compra'!B4 -> 1 | J14: 100 | K14: 10.8 | L14: ='[1]Lista de Compra'!J4 -> 15 | M14: =K14*L14*'[1]Rateio Custos Fixos'!$B$26 -> 777.1464 | N14: =M14+(M14*$K$11) -> 9714.33 | O14: =N14/L14 -> 647.622
D15: ='LISTA DE COMPRAS'!J4 -> 5700 | E15: - | F15: ='LISTA DE COMPRAS'!M4 -> 57040 | G15: =F15*$D$12 -> 294326.4 | J15: 100 | K15: 7.6
B16: TOTAL FOB | F16: =SUM(F15:F15) -> 57040 | G16: =SUM(G15:G15) -> 294326.4 | J16: 100 | K16: 14.4
B17: PRODUTO + FRETE | G17: =G16+G19 -> 312306.4 | I17: ='[1]Lista de Compra'!B6 -> 3 | J17: 100 | K17: 7.6 | L17: ='[1]Lista de Compra'!J6 -> 15 | M17: =K17*L17*'[1]Rateio Custos Fixos'!$B$26 -> 546.8808 | N17: =M17+(M17*$K$11) -> 6836.01 | O17: =N17/L17 -> 455.734
B18: Seguro | I18: ='[1]Lista de Compra'!B7 -> 4 | J18: 100 | K18: 14.4 | L18: ='[1]Lista de Compra'!J7 -> 15 | M18: =K18*L18*'[1]Rateio Custos Fixos'!$B$26 -> 1036.1952 | N18: =M18+(M18*$K$11) -> 12952.44 | O18: =N18/L18 -> 863.496
B19: Frete | F19: ='Rateio Custos Fixos'!G5 -> 3484.4961 | G19: =F19*D12 -> 17980 | I19: ='[1]Lista de Compra'!B8 -> 5 | J19: 100 | K19: 17.8 | L19: ='[1]Lista de Compra'!J8 -> 15 | M19: =K19*L19*'[1]Rateio Custos Fixos'!$B$26 -> 1280.8524 | N19: =M19+(M19*$K$11) -> 16010.655 | O19: =N19/L19 -> 1067.377
B20: TOTAL VALOR ADUANEIRO | G20: =G17 -> 312306.4 | I20: ='[1]Lista de Compra'!B9 -> 6 | J20: 100 | K20: 17.8 | L20: ='[1]Lista de Compra'!J9 -> 15 | M20: =K20*L20*'[1]Rateio Custos Fixos'!$B$26 -> 1280.8524 | N20: =M20+(M20*$K$11) -> 16010.655 | O20: =N20/L20 -> 1067.377
B21: IMPOSTOS | J21: 100 | K21: 4.4
B22: IMPOSTOS | C22: PERCENTUAL | G22: VALOR (R$) | J22: 100 | K22: 6.4
B23: IMPOSTO. IMPORTAÇÃO | C23: ='LISTA DE COMPRAS'!E5 -> 0.18 | G23: ='Est. Cust. Naci.'!R$4 -> 56215.152 | J23: 100 | K23: 4.6
B24: IPI | C24: ='LISTA DE COMPRAS'!F5 -> 0.0306 | G24: ='Est. Cust. Naci.'!S$4 -> 11276.759 | J24: 100 | K24: 5.1
B25: PIS | C25: ='LISTA DE COMPRAS'!G5 -> 0.0312 | G25: ='Est. Cust. Naci.'!T$4 -> 11497.872 | K25: 0
B26: COFINS | C26: ='LISTA DE COMPRAS'!H5 -> 0.1437 | G26: ='Est. Cust. Naci.'!U$4 -> 52956.547 | J26: 100 | K26: 9.3
B27: ICMS | C27: ='LISTA DE COMPRAS'!I5 -> 0.18 | G27: ='Est. Cust. Naci.'!V$4 -> 56215.152 | J27: 100 | K27: 9.3
B28: TOTAL VALOR IMPOSTOS | G28: =SUM(G23:G27) -> 188161.48 | J28: 100 | K28: 11
B29: DESPESAS ADUANEIRAS E LOGÍSTICAS | J29: 100 | K29: 11
B30: TAXA SISCOMEX | G30: ='Rateio Custos Fixos'!F$11 -> 214.5 | J30: 100 | K30: 9.8
B31: LIBERAÇÃO DE B/L | G31: ='Rateio Custos Fixos'!G$11 -> 490 | J31: 100 | K31: 10.2
B32: T.H.C|CAPATAZIA | G32: ='Rateio Custos Fixos'!H$11 -> 1547 | J32: 100 | K32: 10.2
B33: ISPS | G33: ='Rateio Custos Fixos'!I$11 -> 48 | J33: 100 | K33: 11
B34: DAMAGE PROTECTION | G34: ='Rateio Custos Fixos'!J$11 -> 122 | J34: 100 | K34: 13.6
B35: DESCONSOLIDAÇÃO | G35: ='Rateio Custos Fixos'!K$11 -> 1072.94 | K35: 0
B36: DEVOLUÇÃO DE CONTAINER | G36: ='Rateio Custos Fixos'!L$11 -> 774.9 | K36: 0
B37: TRS | G37: ='Rateio Custos Fixos'!M$11 -> 29.8 | J37: 100 | K37: 5.4
B38: AFRMM | C38: 0.08 | G38: ='Rateio Custos Fixos'!N66 -> 1438.4 | J38: 100 | K38: 4.7
B39: ARMAZENAGEM TCP | G39: 0 | H39: 5 DIAS DE ARMAZENAGEM | J39: 100 | K39: 9.3
B40: SCANNER TCP | G40: ='Rateio Custos Fixos'!P11 -> 756.95 | K40: 0
B41: HANDLING - TCP | G41: ='Rateio Custos Fixos'!Q11 -> 320.33 | J41: 100 | K41: 4.4
B42: PESAGEM TCP | G42: ='Rateio Custos Fixos'!R11 -> 117.45 | J42: 100 | K42: 13.5
B43: TAXA DO PARCEIRO - PARANAGUÁ | G43: ='Rateio Custos Fixos'!S11 -> 286 | J43: 100 | K43: 15.2
...

Sheet LISTA DE COMPRAS
A1: LISTA DE COMPRA
A3: Item | B3: Estimativa de Custo 100% | C3: Produto | D3: NCM | E3: II | F3: IPI | G3: PIS | H3: COFINS | I3: ICMS | J3: Quantidade | K3: Preço Unitário | L3: Preço Unitário Sub 50% | M3: Preço total por produto | N3: Preço total por produto | O3: Preço total por produto Sub | P3: % Rateio Quantidade | Q3: % Rateio Preço | R3: Preço R$ nacionalizado
J4: =SUM(J5:J57) -> 5700 | K4: =SUM(K5:K57) -> 480 | M4: =SUM(M5:M57) -> 57040 | N4: =F59 -> 5.16 | P4: 1 | Q4: 1
A5: 1 | C5: 2231832 | D5: 8708-8000 | E5: 0.18 | F5: 0.0306 | G5: 0.0312 | H5: 0.1437 | I5: 0.18 | J5: 100 | K5: 5.8 | L5: =K5/2 -> 2.9 | M5: =K5*J5 -> 580 | N5: =M5*$N$4 -> 2992.8 | O5: =L5*J5*$N$4 -> 1496.4 | P5: =(J5*$P$4)/$J$4 -> 0.01754386 | Q5: =(K5*$Q$4)/$K$4 -> 0.012083333 | R5: ='Est. Cust. Naci.'!AU6 -> 53.328071
A6: 2 | C6: 1384624 | D6: 8708-8000 | E6: 0.18 | F6: 0.0306 | G6: 0.0312 | H6: 0.1437 | I6: 0.18 | J6: 300 | K6: 2.1 | M6: =K6*J6 -> 630 | N6: =M6*$N$4 -> 3250.8 | O6: =L6*J6*$N$4 -> 0 | P6: =(J6*$P$4)/$J$4 -> 0.052631579 | Q6: =(K6*$Q$4)/$K$4 -> 0.004375 | R6: ='Est. Cust. Naci.'!AU7 -> 18.012534
A7: 3 | C7: 1515117 | D7: 8708-8000 | E7: 0.18 | F7: 0.0306 | G7: 0.0312 | H7: 0.1437 | I7: 0.18 | J7: 300 | K7: 10 | M7: =K7*J7 -> 3000 | N7: =M7*$N$4 -> 15480 | O7: =L7*J7*$N$4 -> 0 | P7: =(J7*$P$4)/$J$4 -> 0.052631579 | Q7: =(K7*$Q$4)/$K$4 -> 0.020833333 | R7: ='Est. Cust. Naci.'!AU8 -> 85.773973
A8: 4 | C8: 1515118 | D8: 8708-8000 | E8: 0.18 | F8: 0.0306 | G8: 0.0312 | H8: 0.1437 | I8: 0.18 | J8: 300 | K8: 10 | M8: =K8*J8 -> 3000 | N8: =M8*$N$4 -> 15480 | O8: =L8*J8*$N$4 -> 0 | P8: =(J8*$P$4)/$J$4 -> 0.052631579 | Q8: =(K8*$Q$4)/$K$4 -> 0.020833333 | R8: ='Est. Cust. Naci.'!AU9 -> 85.773973
A9: 5 | C9: 1777207 | D9: 8708-8000 | E9: 0.18 | F9: 0.0306 | G9: 0.0312 | H9: 0.1437 | I9: 0.18 | J9: 300 | K9: 10 | M9: =K9*J9 -> 3000 | N9: =M9*$N$4 -> 15480 | O9: =L9*J9*$N$4 -> 0 | P9: =(J9*$P$4)/$J$4 -> 0.052631579 | Q9: =(K9*$Q$4)/$K$4 -> 0.020833333 | R9: ='Est. Cust. Naci.'!AU10 -> 85.773973
A10: 6 | C10: 1349840.1 | D10: 8708-8000 | E10: 0.18 | F10: 0.0306 | G10: 0.0312 | H10: 0.1437 | I10: 0.18 | J10: 100 | K10: 11.5 | M10: =K10*J10 -> 1150 | N10: =M10*$N$4 -> 5934 | O10: =L10*J10*$N$4 -> 0 | P10: =(J10*$P$4)/$J$4 -> 0.01754386 | Q10: =(K10*$Q$4)/$K$4 -> 0.023958333 | R10: ='Est. Cust. Naci.'!AU11 -> 105.73669
A11: 7 | C11: 1349840.2 | D11: 8708-8000 | E11: 0.18 | F11: 0.0306 | G11: 0.0312 | H11: 0.1437 | I11: 0.18 | J11: 100 | K11: 11.5 | M11: =K11*J11 -> 1150 | N11: =M11*$N$4 -> 5934 | O11: =L11*J11*$N$4 -> 0 | P11: =(J11*$P$4)/$J$4 -> 0.01754386 | Q11: =(K11*$Q$4)/$K$4 -> 0.023958333 | R11: ='Est. Cust. Naci.'!AU12 -> 105.73669
A12: 8 | C12: RP-13412 | D12: 8708-8000 | E12: 0.18 | F12: 0.0306 | G12: 0.0312 | H12: 0.1437 | I12: 0.18 | K12: 0 | M12: =K12*J12 -> 0 | N12: =M12*$N$4 -> 0 | O12: =L12*J12*$N$4 -> 0 | P12: =(J12*$P$4)/$J$4 -> 0 | Q12: =(K12*$Q$4)/$K$4 -> 0 | R12: ='Est. Cust. Naci.'!AU13 -> #DIV/0!
A13: 9 | C13: 1476415.1 | D13: 8708-8000 | E13: 0.18 | F13: 0.0306 | G13: 0.0312 | H13: 0.1437 | I13: 0.18 | J13: 100 | K13: 10.8 | M13: =K13*J13 -> 1080 | N13: =M13*$N$4 -> 5572.8 | O13: =L13*J13*$N$4 -> 0 | P13: =(J13*$P$4)/$J$4 -> 0.01754386 | Q13: =(K13*$Q$4)/$K$4 -> 0.0225 | R13: ='Est. Cust. Naci.'!AU14 -> 99.300547
A14: 10 | C14: 1476415.2 | D14: 8708-8000 | E14: 0.18 | F14: 0.0306 | G14: 0.0312 | H14: 0.1437 | I14: 0.18 | J14: 100 | K14: 10.8 | M14: =K14*J14 -> 1080 | N14: =M14*$N$4 -> 5572.8 | O14: =L14*J14*$N$4 -> 0 | P14: =(J14*$P$4)/$J$4 -> 0.01754386 | Q14: =(K14*$Q$4)/$K$4 -> 0.0225 | R14: ='Est. Cust. Naci.'!AU15 -> 99.300547
A15: 11 | C15: 2023668 | D15: 8708-8000 | E15: 0.18 | F15: 0.0306 | G15: 0.0312 | H15: 0.1437 | I15: 0.18 | J15: 100 | K15: 7.6 | M15: =K15*J15 -> 760 | N15: =M15*$N$4 -> 3921.6 | O15: =L15*J15*$N$4 -> 0 | P15: =(J15*$P$4)/$J$4 -> 0.01754386 | Q15: =(K15*$Q$4)/$K$4 -> 0.015833333 | R15: ='Est. Cust. Naci.'!AU16 -> 69.878163
A16: 12 | C16: 1761377; 2074003 | D16: 8708-8000 | E16: 0.18 | F16: 0.0306 | G16: 0.0312 | H16: 0.1437 | I16: 0.18 | J16: 100 | K16: 14.4 | M16: =K16*J16 -> 1440 | N16: =M16*$N$4 -> 7430.4 | O16: =L16*J16*$N$4 -> 0 | P16: =(J16*$P$4)/$J$4 -> 0.01754386 | Q16: =(K16*$Q$4)/$K$4 -> 0.03 | R16: ='Est. Cust. Naci.'!AU17 -> 132.40073
A17: 13 | C17: 1761373 | D17: 8708-8000 | E17: 0.18 | F17: 0.0306 | G17: 0.0312 | H17: 0.1437 | I17: 0.18 | J17: 100 | K17: 7.6 | M17: =K17*J17 -> 760 | N17: =M17*$N$4 -> 3921.6 | O17: =L17*J17*$N$4 -> 0 | P17: =(J17*$P$4)/$J$4 -> 0.01754386 | Q17: =(K17*$Q$4)/$K$4 -> 0.015833333 | R17: ='Est. Cust. Naci.'!AU18 -> 69.878163
A18: 14 | C18: 1462266 | D18: 8708-8000 | E18: 0.18 | F18: 0.0306 | G18: 0.0312 | H18: 0.1437 | I18: 0.18 | J18: 100 | K18: 14.4 | M18: =K18*J18 -> 1440 | N18: =M18*$N$4 -> 7430.4 | O18: =L18*J18*$N$4 -> 0 | P18: =(J18*$P$4)/$J$4 -> 0.01754386 | Q18: =(K18*$Q$4)/$K$4 -> 0.03 | R18: ='Est. Cust. Naci.'!AU19 -> 132.40073
A19: 15 | C19: 1952540 | D19: 8708-8000 | E19: 0.18 | F19: 0.0306 | G19: 0.0312 | H19: 0.1437 | I19: 0.18 | J19: 100 | K19: 17.8 | M19: =K19*J19 -> 1780 | N19: =M19*$N$4 -> 9184.8 | O19: =L19*J19*$N$4 -> 0 | P19: =(J19*$P$4)/$J$4 -> 0.01754386 | Q19: =(K19*$Q$4)/$K$4 -> 0.037083333 | R19: ='Est. Cust. Naci.'!AU20 -> 163.66201
A20: 16 | C20: 1952434 | D20: 8708-8000 | E20: 0.18 | F20: 0.0306 | G20: 0.0312 | H20: 0.1437 | I20: 0.18 | J20: 100 | K20: 17.8 | M20: =K20*J20 -> 1780 | N20: =M20*$N$4 -> 9184.8 | O20: =L20*J20*$N$4 -> 0 | P20: =(J20*$P$4)/$J$4 -> 0.01754386 | Q20: =(K20*$Q$4)/$K$4 -> 0.037083333 | R20: ='Est. Cust. Naci.'!AU21 -> 163.66201
A21: 17 | C21: 3198849 | D21: 8708-8000 | E21: 0.18 | F21: 0.0306 | G21: 0.0312 | H21: 0.1437 | I21: 0.18 | J21: 100 | K21: 4.4 | M21: =K21*J21 -> 440 | N21: =M21*$N$4 -> 2270.4 | O21: =L21*J21*$N$4 -> 0 | P21: =(J21*$P$4)/$J$4 -> 0.01754386 | Q21: =(K21*$Q$4)/$K$4 -> 0.0091666667 | R21: ='Est. Cust. Naci.'!AU22 -> 40.455778
A22: 18 | C22: 8078547 | D22: 8708-8000 | E22: 0.18 | F22: 0.0306 | G22: 0.0312 | H22: 0.1437 | I22: 0.18 | J22: 100 | K22: 6.4 | M22: =K22*J22 -> 640 | N22: =M22*$N$4 -> 3302.4 | O22: =L22*J22*$N$4 -> 0 | P22: =(J22*$P$4)/$J$4 -> 0.01754386 | Q22: =(K22*$Q$4)/$K$4 -> 0.013333333 | R22: ='Est. Cust. Naci.'!AU23 -> 58.844768
A23: 19 | C23: 21552066 | D23: 8708-8000 | E23: 0.18 | F23: 0.0306 | G23: 0.0312 | H23: 0.1437 | I23: 0.18 | J23: 100 | K23: 4.6 | M23: =K23*J23 -> 460 | N23: =M23*$N$4 -> 2373.6 | O23: =L23*J23*$N$4 -> 0 | P23: =(J23*$P$4)/$J$4 -> 0.01754386 | Q23: =(K23*$Q$4)/$K$4 -> 0.0095833333 | R23: ='Est. Cust. Naci.'!AU24 -> 42.294677
A24: 20 | C24: 8129279 | D24: 8708-8000 | E24: 0.18 | F24: 0.0306 | G24: 0.0312 | H24: 0.1437 | I24: 0.18 | J24: 100 | K24: 5.1 | M24: =K24*J24 -> 510 | N24: =M24*$N$4 -> 2631.6 | O24: =L24*J24*$N$4 -> 0 | P24: =(J24*$P$4)/$J$4 -> 0.01754386 | Q24: =(K24*$Q$4)/$K$4 -> 0.010625 | R24: ='Est. Cust. Naci.'!AU25 -> 46.891925
A25: 21 | C25: DC46SK407-KA | D25: 8708-8000 | E25: 0.18 | F25: 0.0306 | G25: 0.0312 | H25: 0.1437 | I25: 0.18 | K25: 0 | M25: =K25*J25 -> 0 | N25: =M25*$N$4 -> 0 | O25: =L25*J25*$N$4 -> 0 | P25: =(J25*$P$4)/$J$4 -> 0 | Q25: =(K25*$Q$4)/$K$4 -> 0 | R25: ='Est. Cust. Naci.'!AU26 -> #DIV/0!
A26: 22 | C26: BC455C368-CB | D26: 8708-8000 | E26: 0.18 | F26: 0.0306 | G26: 0.0312 | H26: 0.1437 | I26: 0.18 | J26: 100 | K26: 9.3 | M26: =K26*J26 -> 930 | N26: =M26*$N$4 -> 4798.8 | O26: =L26*J26*$N$4 -> 0 | P26: =(J26*$P$4)/$J$4 -> 0.01754386 | Q26: =(K26*$Q$4)/$K$4 -> 0.019375 | R26: ='Est. Cust. Naci.'!AU27 -> 85.508804
A27: 23 | C27: BC455C398-CA | D27: 8708-8000 | E27: 0.18 | F27: 0.0306 | G27: 0.0312 | H27: 0.1437 | I27: 0.18 | J27: 100 | K27: 9.3 | M27: =K27*J27 -> 930 | N27: =M27*$N$4 -> 4798.8 | O27: =L27*J27*$N$4 -> 0 | P27: =(J27*$P$4)/$J$4 -> 0.01754386 | Q27: =(K27*$Q$4)/$K$4 -> 0.019375 | R27: ='Est. Cust. Naci.'!AU28 -> 85.508804
A28: 24 | C28: BC455C368-BB | D28: 8708-8000 | E28: 0.18 | F28: 0.0306 | G28: 0.0312 | H28: 0.1437 | I28: 0.18 | J28: 100 | K28: 11 | M28: =K28*J28 -> 1100 | N28: =M28*$N$4 -> 5676 | O28: =L28*J28*$N$4 -> 0 | P28: =(J28*$P$4)/$J$4 -> 0.01754386 | Q28: =(K28*$Q$4)/$K$4 -> 0.022916667 | R28: ='Est. Cust. Naci.'!AU29 -> 101.13945
A29: 25 | C29: BC455C398-BA | D29: 8708-8000 | E29: 0.18 | F29: 0.0306 | G29: 0.0312 | H29: 0.1437 | I29: 0.18 | J29: 100 | K29: 11 | M29: =K29*J29 -> 1100 | N29: =M29*$N$4 -> 5676 | O29: =L29*J29*$N$4 -> 0 | P29: =(J29*$P$4)/$J$4 -> 0.01754386 | Q29: =(K29*$Q$4)/$K$4 -> 0.022916667 | R29: ='Est. Cust. Naci.'!AU30 -> 101.13945
A30: 26 | C30: DC465K407-DA | D30: 8708-8000 | E30: 0.18 | F30: 0.0306 | G30: 0.0312 | H30: 0.1437 | I30: 0.18 | J30: 100 | K30: 9.8 | M30: =K30*J30 -> 980 | N30: =M30*$N$4 -> 5056.8 | O30: =L30*J30*$N$4 -> 0 | P30: =(J30*$P$4)/$J$4 -> 0.01754386 | Q30: =(K30*$Q$4)/$K$4 -> 0.020416667 | R30: ='Est. Cust. Naci.'!AU31 -> 90.106052
A31: 27 | C31: DC465K407-EA | D31: 8708-8000 | E31: 0.18 | F31: 0.0306 | G31: 0.0312 | H31: 0.1437 | I31: 0.18 | J31: 100 | K31: 10.2 | M31: =K31*J31 -> 1020 | N31: =M31*$N$4 -> 5263.2 | O31: =L31*J31*$N$4 -> 0 | P31: =(J31*$P$4)/$J$4 -> 0.01754386 | Q31: =(K31*$Q$4)/$K$4 -> 0.02125 | R31: ='Est. Cust. Naci.'!AU32 -> 93.78385
A32: 28 | C32: 2T2899515 | D32: 8708-8000 | E32: 0.18 | F32: 0.0306 | G32: 0.0312 | H32: 0.1437 | I32: 0.18 | J32: 100 | K32: 10.2 | M32: =K32*J32 -> 1020 | N32: =M32*$N$4 -> 5263.2 | O32: =L32*J32*$N$4 -> 0 | P32: =(J32*$P$4)/$J$4 -> 0.01754386 | Q32: =(K32*$Q$4)/$K$4 -> 0.02125 | R32: ='Est. Cust. Naci.'!AU33 -> 93.78385
A33: 29 | C33: 2R2899515 | D33: 8708-8000 | E33: 0.18 | F33: 0.0306 | G33: 0.0312 | H33: 0.1437 | I33: 0.18 | J33: 100 | K33: 11 | M33: =K33*J33 -> 1100 | N33: =M33*$N$4 -> 5676 | O33: =L33*J33*$N$4 -> 0 | P33: =(J33*$P$4)/$J$4 -> 0.01754386 | Q33: =(K33*$Q$4)/$K$4 -> 0.022916667 | R33: ='Est. Cust. Naci.'!AU34 -> 101.13945
A34: 30 | C34: 2V2899515 | D34: 8708-8000 | E34: 0.18 | F34: 0.0306 | G34: 0.0312 | H34: 0.1437 | I34: 0.18 | J34: 100 | K34: 13.6 | M34: =K34*J34 -> 1360 | N34: =M34*$N$4 -> 7017.6 | O34: =L34*J34*$N$4 -> 0 | P34: =(J34*$P$4)/$J$4 -> 0.01754386 | Q34: =(K34*$Q$4)/$K$4 -> 0.028333333 | R34: ='Est. Cust. Naci.'!AU35 -> 125.04513
A35: 31 | C35: 938170519 | D35: 8708-8000 | E35: 0.18 | F35: 0.0306 | G35: 0.0312 | H35: 0.1437 | I35: 0.18 | K35: 0 | M35: =K35*J35 -> 0 | N35: =M35*$N$4 -> 0 | O35: =L35*J35*$N$4 -> 0 | P35: =(J35*$P$4)/$J$4 -> 0 | Q35: =(K35*$Q$4)/$K$4 -> 0 | R35: ='Est. Cust. Naci.'!AU36 -> #DIV/0!
A36: 32 | C36: 938170119 | D36: 8708-8000 | E36: 0.18 | F36: 0.0306 | G36: 0.0312 | H36: 0.1437 | I36: 0.18 | K36: 0 | M36: =K36*J36 -> 0 | N36: =M36*$N$4 -> 0 | O36: =L36*J36*$N$4 -> 0 | P36: =(J36*$P$4)/$J$4 -> 0 | Q36: =(K36*$Q$4)/$K$4 -> 0 | R36: ='Est. Cust. Naci.'!AU37 -> #DIV/0!
A37: 33 | C37: 9583172103 | D37: 8708-8000 | E37: 0.18 | F37: 0.0306 | G37: 0.0312 | H37: 0.1437 | I37: 0.18 | J37: 100 | K37: 5.4 | M37: =K37*J37 -> 540 | N37: =M37*$N$4 -> 2786.4 | O37: =L37*J37*$N$4 -> 0 | P37: =(J37*$P$4)/$J$4 -> 0.01754386 | Q37: =(K37*$Q$4)/$K$4 -> 0.01125 | R37: ='Est. Cust. Naci.'!AU38 -> 49.650273
A38: 34 | C38: 9583170003 | D38: 8708-8000 | E38: 0.18 | F38: 0.0306 | G38: 0.0312 | H38: 0.1437 | I38: 0.18 | J38: 100 | K38: 4.7 | M38: =K38*J38 -> 470 | N38: =M38*$N$4 -> 2425.2 | O38: =L38*J38*$N$4 -> 0 | P38: =(J38*$P$4)/$J$4 -> 0.01754386 | Q38: =(K38*$Q$4)/$K$4 -> 0.0097916667 | R38: ='Est. Cust. Naci.'!AU39 -> 43.214127
A39: 35 | C39: 9583172703 | D39: 8708-8000 | E39: 0.18 | F39: 0.0306 | G39: 0.0312 | H39: 0.1437 | I39: 0.18 | J39: 100 | K39: 9.3 | M39: =K39*J39 -> 930 | N39: =M39*$N$4 -> 4798.8 | O39: =L39*J39*$N$4 -> 0 | P39: =(J39*$P$4)/$J$4 -> 0.01754386 | Q39: =(K39*$Q$4)/$K$4 -> 0.019375 | R39: ='Est. Cust. Naci.'!AU40 -> 85.508804
A40: 36 | C40: 583171103 | D40: 8708-8000 | E40: 0.18 | F40: 0.0306 | G40: 0.0312 | H40: 0.1437 | I40: 0.18 | K40: 0 | M40: =K40*J40 -> 0 | N40: =M40*$N$4 -> 0 | O40: =L40*J40*$N$4 -> 0 | P40: =(J40*$P$4)/$J$4 -> 0 | Q40: =(K40*$Q$4)/$K$4 -> 0 | R40: ='Est. Cust. Naci.'!AU41 -> #DIV/0!
A41: 37 | C41: 9583170703 | D41: 8708-8000 | E41: 0.18 | F41: 0.0306 | G41: 0.0312 | H41: 0.1437 | I41: 0.18 | J41: 100 | K41: 4.4 | M41: =K41*J41 -> 440 | N41: =M41*$N$4 -> 2270.4 | O41: =L41*J41*$N$4 -> 0 | P41: =(J41*$P$4)/$J$4 -> 0.01754386 | Q41: =(K41*$Q$4)/$K$4 -> 0.0091666667 | R41: ='Est. Cust. Naci.'!AU42 -> 40.455778
...

Sheet Est. Cust. Naci.
C2: DETALHES DO PRODUTO | L2: VALOR ADUANEIRO | R2: IMPOSTOS | Y2: TAXAS PORTUÁRIAS
B3: Nº | C3: ITEM | D3: Código | E3: Bitola (mm) | F3: Embal. | G3: NCM | H3: QTD | I3: % Rateio Preço | J3: Preço unitário Fábrica (USD) | K3: Preço x QTD (Valor em USD) | L3: Preço x QTD (valor em BRL) | M3: Preço x QTD (valor em BRL) SUB | N3: THC (valor em BRL) | O3: Valor do frete (Valor em BRL) | P3: TOTAL VALOR ADUANEIRO | Q3: TOTAL VALOR ADUANEIRO + II | R3: IMPOSTO DE IMPORTAÇÃO | S3: IPI | T3: PIS | U3: COFINS | V3: ICMS | W3: TOTAL IMPOSTOS | X3: TOTAL IMPOSTOS (SUB) | Y3: TAXA SISCOMEX | Z3: LIBERAÇÃO DE B/L | AA3: T.H.C| CAPATAZIA | AB3: ISPS | AC3: DAMAGE PROTECTION | AD3: DESCONSOLIDAÇÃO | AE3: DEVOLUÇÃO DE CONTAINER | AF3: TRS | AG3: AFRMM | AH3: ARMAZENAGEM TCP | AI3: SCANNER TCP | AJ3: HANDLING - TCP | AK3: PESAGEM TCP | AL3: TAXA DO PARCEIRO - PARANAGUÁ | AM3: FRETE RODOVIÁRIO | AN3: DESEMBARAÇO ADUANEIRO | AO3: TOTAL TAXAS DESEMBARAÇO | AP3: TOTAL | AQ3: TOTAL (sub) | AR3: TOTAL (sub) | AS3: MÉTODO ANTIGO | AT3: MÉTODO ANTIGO (sub) | AU3: MÉTODO DANI | AV3: MÉTODO DANI (sub) | AW3: MÉTODO JULIANA | AX3: MÉTODO JULIANA (sub) | AZ3: VALOR UNITÁRIO C/ COMISSÃO SEAWISE
A4: Nº | L4: =N62 -> 5.16 | M4: 4.8887 | N4: 0 | P4: =SUM(P6:P58) -> 312306.4 | Q4: =SUM(Q6:Q58) -> 368521.55 | R4: =SUM(R6:R58) -> 56215.152 | S4: =SUM(S6:S58) -> 11276.759 | T4: =SUM(T6:T58) -> 11497.872 | U4: =SUM(U6:U58) -> 52956.547 | V4: =SUM(V6:V58) -> 56215.152 | AG4: 0.08
A5: AAA | L5: =SUM(L6:L58) -> 294326.4 | O5: =SUM(O6:O58) -> 17980 | R5: ='LISTA DE COMPRAS'!E5 -> 0.18 | S5: ='LISTA DE COMPRAS'!F5 -> 0.0306 | T5: ='LISTA DE COMPRAS'!G5 -> 0.0312 | U5: ='LISTA DE COMPRAS'!H5 -> 0.1437 | V5: ='LISTA DE COMPRAS'!I5 -> 0.18 | W5: =SUM(W6:W58) -> 188161.48 | X5: =SUM(#REF!,X6) -> #REF! | Y5: =SUM(Y6:Y58) -> 214.5 | Z5: =SUM(Z6:Z58) -> 490 | AA5: =SUM(AA6:AA58) -> 1547 | AB5: =SUM(AB6:AB58) -> 48 | AC5: =SUM(AC6:AC58) -> 122 | AD5: =SUM(AD6:AD58) -> 1072.94 | AE5: =SUM(AE6:AE58) -> 774.9 | AF5: =SUM(AF6:AF58) -> 29.8 | AG5: =SUM(AG6:AG58) -> 1438.4 | AH5: =SUM(AH6:AH6) -> 0 | AI5: =SUM(AI6:AI58) -> 756.95 | AJ5: =SUM(AJ6:AJ58) -> 320.33 | AK5: =SUM(AK6:AK58) -> 117.45 | AL5: =SUM(AL6:AL58) -> 286 | AM5: =SUM(AM6:AM58) -> 6000 | AN5: =SUM(AN6:AN58) -> 2400 | AO5: =SUM(AO6:AO58) -> 15618.27 | AP5: =AO5+W5+P4 -> 516086.15 | AQ5: 21877.425 | AR5: =AO5+X5+Q4+#REF! -> #REF!
A6: AAA | B6: ='LISTA DE COMPRAS'!A5 -> 1 | C6: ='LISTA DE COMPRAS'!C5 -> 2231832 | G6: ='LISTA DE COMPRAS'!D6 -> 8708-8000 | H6: ='LISTA DE COMPRAS'!J5 -> 100 | I6: ='LISTA DE COMPRAS'!P5 -> 0.01754386 | J6: ='LISTA DE COMPRAS'!K5 -> 5.8 | K6: =H6*J6 -> 580 | L6: =K6*$L$4 -> 2992.8 | M6: =L6*50% -> 1496.4 | N6: =$N$4*I6 -> 0 | O6: ='Rateio Custos Fixos'!E12 -> 217.25833 | P6: =SUM(L6,O6) -> 3210.0583 | Q6: =P6+R6 -> 3787.8688 | R6: =$P6*R$5 -> 577.8105 | S6: =$Q6*S$5 -> 115.90879 | T6: =$Q6*T$5 -> 118.18151 | U6: =$Q6*U$5 -> 544.31675 | V6: =$P6*V$5 -> 577.8105 | W6: =SUM(R6:V6) -> 1934.028 | X6: =SUM(R11:V11) -> 3834.7108 | Y6: ='Rateio Custos Fixos'!F12 -> 2.591875 | Z6: ='Rateio Custos Fixos'!G12 -> 5.9208333 | AA6: ='Rateio Custos Fixos'!H12 -> 18.692917 | AB6: ='Rateio Custos Fixos'!I12 -> 0.58 | AC6: ='Rateio Custos Fixos'!J12 -> 1.4741667 | AD6: ='Rateio Custos Fixos'!K12 -> 12.964692 | AE6: ='Rateio Custos Fixos'!L12 -> 9.363375 | AF6: ='Rateio Custos Fixos'!M12 -> 0.36008333 | ... AN6: ='Rateio Custos Fixos'!U12 -> 29 | AO6: =SUM(Y6:AN6) -> 188.72076 | AP6: =AO6+W6+P6 -> 5332.8071 | AQ6: 2595.3166 | AR6: =AO6+X6+P6 -> 7233.4899 | AS6: =(AP6/H6) -> 53.328071 | AT6: =AR6/H6 -> 72.334899 | AU6: =AP6/H6 -> 53.328071 | AV6: =(AR6*#REF!)/'Est. Cust. Naci.'!H6 -> #REF! | AW6: =(J6*9) -> 52.2 | AX6: =AW6/2 -> 26.1 | AZ6: =AP6/H6 -> 53.328071
B7: ='LISTA DE COMPRAS'!A6 -> 2 | C7: ='LISTA DE COMPRAS'!C6 -> 1384624 | G7: ='LISTA DE COMPRAS'!D7 -> 8708-8000 | H7: ='LISTA DE COMPRAS'!J6 -> 300 | I7: ='LISTA DE COMPRAS'!P6 -> 0.052631579 | J7: ='LISTA DE COMPRAS'!K6 -> 2.1 | K7: =H7*J7 -> 630 | L7: =K7*$L$4 -> 3250.8 | M7: =L7*50% -> 1625.4 | N7: =$N$4*I7 -> 0 | O7: ='Rateio Custos Fixos'!E13 -> 78.6625 | P7: =SUM(L7,O7) -> 3329.4625 | Q7: =P7+R7 -> 3928.7658 | R7: =$P7*R$5 -> 599.30325 | S7: =$Q7*S$5 -> 120.22023 | T7: =$Q7*T$5 -> 122.57749 | U7: =$Q7*U$5 -> 564.56364 | V7: =$P7*V$5 -> 599.30325 | W7: =SUM(R7:V7) -> 2005.9679 | X7: =SUM(R12:V12) -> 3834.7108 | Y7: ='Rateio Custos Fixos'!F13 -> 0.9384375 | Z7: ='Rateio Custos Fixos'!G13 -> 2.14375 | AA7: ='Rateio Custos Fixos'!H13 -> 6.768125 | AB7: ='Rateio Custos Fixos'!I13 -> 0.21 | AC7: ='Rateio Custos Fixos'!J13 -> 0.53375 | AD7: ='Rateio Custos Fixos'!K13 -> 4.6941125 | AE7: ='Rateio Custos Fixos'!L13 -> 3.3901875 | AF7: ='Rateio Custos Fixos'!M13 -> 0.130375 | ... AN7: ='Rateio Custos Fixos'!U13 -> 10.5 | AO7: =SUM(Y7:AN7) -> 68.329931 | AP7: =AO7+W7+P7 -> 5403.7603 | AQ7: 2596.3166 | AR7: =AO7+X7+P7 -> 7232.5032 | AS7: =(AP7/H7) -> 18.012534 | AT7: =AR7/H7 -> 24.108344 | AU7: =AP7/H7 -> 18.012534 | AV7: =(AR7*#REF!)/'Est. Cust. Naci.'!H7 -> #REF! | AW7: =(J7*9) -> 18.9
B8: ='LISTA DE COMPRAS'!A7 -> 3 | C8: ='LISTA DE COMPRAS'!C7 -> 1515117 | G8: ='LISTA DE COMPRAS'!D8 -> 8708-8000 | H8: ='LISTA DE COMPRAS'!J7 -> 300 | I8: ='LISTA DE COMPRAS'!P7 -> 0.052631579 | J8: ='LISTA DE COMPRAS'!K7 -> 10 | K8: =H8*J8 -> 3000 | L8: =K8*$L$4 -> 15480 | M8: =L8*50% -> 7740 | N8: =$N$4*I8 -> 0 | O8: ='Rateio Custos Fixos'!E14 -> 374.58333 | P8: =SUM(L8,O8) -> 15854.583 | Q8: =P8+R8 -> 18708.408 | R8: =$P8*R$5 -> 2853.825 | S8: =$Q8*S$5 -> 572.4773 | T8: =$Q8*T$5 -> 583.70234 | U8: =$Q8*U$5 -> 2688.3983 | V8: =$P8*V$5 -> 2853.825 | W8: =SUM(R8:V8) -> 9552.2279 | X8: =SUM(R13:V13) -> 0 | Y8: ='Rateio Custos Fixos'!F14 -> 4.46875 | Z8: ='Rateio Custos Fixos'!G14 -> 10.208333 | AA8: ='Rateio Custos Fixos'!H14 -> 32.229167 | AB8: ='Rateio Custos Fixos'!I14 -> 1 | AC8: ='Rateio Custos Fixos'!J14 -> 2.5416667 | AD8: ='Rateio Custos Fixos'!K14 -> 22.352917 | AE8: ='Rateio Custos Fixos'!L14 -> 16.14375 | AF8: ='Rateio Custos Fixos'!M14 -> 0.62083333 | ... AN8: ='Rateio Custos Fixos'!U14 -> 50 | AO8: =SUM(Y8:AN8) -> 325.38063 | AP8: =AO8+W8+P8 -> 25732.192 | AQ8: 2597.3166 | AR8: =AO8+X8+P8 -> 16179.964 | AS8: =(AP8/H8) -> 85.773973 | AT8: =AR8/H8 -> 53.933213 | AU8: =AP8/H8 -> 85.773973 | AV8: =(AR8*#REF!)/'Est. Cust. Naci.'!H8 -> #REF! | AW8: =(J8*9) -> 90
B9: ='LISTA DE COMPRAS'!A8 -> 4 | C9: ='LISTA DE COMPRAS'!C8 -> 1515118 | G9: ='LISTA DE COMPRAS'!D9 -> 8708-8000 | H9: ='LISTA DE COMPRAS'!J8 -> 300 | I9: ='LISTA DE COMPRAS'!P8 -> 0.052631579 | J9: ='LISTA DE COMPRAS'!K8 -> 10 | K9: =H9*J9 -> 3000 | L9: =K9*$L$4 -> 15480 | M9: =L9*50% -> 7740 | N9: =$N$4*I9 -> 0 | O9: ='Rateio Custos Fixos'!E15 -> 374.58333 | P9: =SUM(L9,O9) -> 15854.583 | Q9: =P9+R9 -> 18708.408 | R9: =$P9*R$5 -> 2853.825 | S9: =$Q9*S$5 -> 572.4773 | T9: =$Q9*T$5 -> 583.70234 | U9: =$Q9*U$5 -> 2688.3983 | V9: =$P9*V$5 -> 2853.825 | W9: =SUM(R9:V9) -> 9552.2279 | X9: =SUM(R14:V14) -> 3601.2936 | Y9: ='Rateio Custos Fixos'!F15 -> 4.46875 | Z9: ='Rateio Custos Fixos'!G15 -> 10.208333 | AA9: ='Rateio Custos Fixos'!H15 -> 32.229167 | AB9: ='Rateio Custos Fixos'!I15 -> 1 | AC9: ='Rateio Custos Fixos'!J15 -> 2.5416667 | AD9: ='Rateio Custos Fixos'!K15 -> 22.352917 | AE9: ='Rateio Custos Fixos'!L15 -> 16.14375 | AF9: ='Rateio Custos Fixos'!M15 -> 0.62083333 | ... AN9: ='Rateio Custos Fixos'!U15 -> 50 | AO9: =SUM(Y9:AN9) -> 325.38063 | AP9: =AO9+W9+P9 -> 25732.192 | AQ9: 2598.3166 | AR9: =AO9+X9+P9 -> 19781.258 | AS9: =(AP9/H9) -> 85.773973 | AT9: =AR9/H9 -> 65.937525 | AU9: =AP9/H9 -> 85.773973 | AV9: =(AR9*#REF!)/'Est. Cust. Naci.'!H9 -> #REF! | AW9: =(J9*9) -> 90
B10: ='LISTA DE COMPRAS'!A9 -> 5 | C10: ='LISTA DE COMPRAS'!C9 -> 1777207 | G10: ='LISTA DE COMPRAS'!D10 -> 8708-8000 | H10: ='LISTA DE COMPRAS'!J9 -> 300 | I10: ='LISTA DE COMPRAS'!P9 -> 0.052631579 | J10: ='LISTA DE COMPRAS'!K9 -> 10 | K10: =H10*J10 -> 3000 | L10: =K10*$L$4 -> 15480 | M10: =L10*50% -> 7740 | N10: =$N$4*I10 -> 0 | O10: ='Rateio Custos Fixos'!E16 -> 374.58333 | P10: =SUM(L10,O10) -> 15854.583 | Q10: =P10+R10 -> 18708.408 | R10: =$P10*R$5 -> 2853.825 | S10: =$Q10*S$5 -> 572.4773 | T10: =$Q10*T$5 -> 583.70234 | U10: =$Q10*U$5 -> 2688.3983 | V10: =$P10*V$5 -> 2853.825 | W10: =SUM(R10:V10) -> 9552.2279 | X10: =SUM(R15:V15) -> 3601.2936 | Y10: ='Rateio Custos Fixos'!F16 -> 4.46875 | Z10: ='Rateio Custos Fixos'!G16 -> 10.208333 | AA10: ='Rateio Custos Fixos'!H16 -> 32.229167 | AB10: ='Rateio Custos Fixos'!I16 -> 1 | AC10: ='Rateio Custos Fixos'!J16 -> 2.5416667 | AD10: ='Rateio Custos Fixos'!K16 -> 22.352917 | AE10: ='Rateio Custos Fixos'!L16 -> 16.14375 | AF10: ='Rateio Custos Fixos'!M16 -> 0.62083333 | ... AN10: ='Rateio Custos Fixos'!U16 -> 50 | AO10: =SUM(Y10:AN10) -> 325.38063 | AP10: =AO10+W10+P10 -> 25732.192 | AQ10: 2599.3166 | AR10: =AO10+X10+P10 -> 19781.258 | AS10: =(AP10/H10) -> 85.773973 | AT10: =AR10/H10 -> 65.937525 | AU10: =AP10/H10 -> 85.773973 | AV10: =(AR10*#REF!)/'Est. Cust. Naci.'!H10 -> #REF! | AW10: =(J10*9) -> 90
B11: ='LISTA DE COMPRAS'!A10 -> 6 | C11: ='LISTA DE COMPRAS'!C10 -> 1349840.1 | G11: ='LISTA DE COMPRAS'!D11 -> 8708-8000 | H11: ='LISTA DE COMPRAS'!J10 -> 100 | I11: ='LISTA DE COMPRAS'!P10 -> 0.01754386 | J11: ='LISTA DE COMPRAS'!K10 -> 11.5 | K11: =H11*J11 -> 1150 | L11: =K11*$L$4 -> 5934 | M11: =L11*50% -> 2967 | N11: =$N$4*I11 -> 0 | O11: ='Rateio Custos Fixos'!E17 -> 430.77083 | P11: =SUM(L11,O11) -> 6364.7708 | Q11: =P11+R11 -> 7510.4296 | R11: =$P11*R$5 -> 1145.6588 | S11: =$Q11*S$5 -> 229.81915 | T11: =$Q11*T$5 -> 234.3254 | U11: =$Q11*U$5 -> 1079.2487 | V11: =$P11*V$5 -> 1145.6588 | W11: =SUM(R11:V11) -> 3834.7108 | X11: =SUM(R16:V16) -> 2534.2436 | Y11: ='Rateio Custos Fixos'!F17 -> 5.1390625 | Z11: ='Rateio Custos Fixos'!G17 -> 11.739583 | AA11: ='Rateio Custos Fixos'!H17 -> 37.063542 | AB11: ='Rateio Custos Fixos'!I17 -> 1.15 | AC11: ='Rateio Custos Fixos'!J17 -> 2.9229167 | AD11: ='Rateio Custos Fixos'!K17 -> 25.705854 | AE11: ='Rateio Custos Fixos'!L17 -> 18.565313 | AF11: ='Rateio Custos Fixos'!M17 -> 0.71395833 | ... AN11: ='Rateio Custos Fixos'!U17 -> 57.5 | AO11: =SUM(Y11:AN11) -> 374.18772 | AP11: =AO11+W11+P11 -> 10573.669 | AQ11: 2600.3166 | AR11: =AO11+X11+P11 -> 9273.2022 | AS11: =(AP11/H11) -> 105.73669 | AT11: =AR11/H11 -> 92.732022 | AU11: =AP11/H11 -> 105.73669 | AV11: =(AR11*#REF!)/'Est. Cust. Naci.'!H11 -> #REF! | AW11: =(J11*9) -> 103.5
B12: ='LISTA DE COMPRAS'!A11 -> 7 | C12: ='LISTA DE COMPRAS'!C11 -> 1349840.2 | G12: ='LISTA DE COMPRAS'!D12 -> 8708-8000 | H12: ='LISTA DE COMPRAS'!J11 -> 100 | I12: ='LISTA DE COMPRAS'!P11 -> 0.01754386 | J12: ='LISTA DE COMPRAS'!K11 -> 11.5 | K12: =H12*J12 -> 1150 | L12: =K12*$L$4 -> 5934 | M12: =L12*50% -> 2967 | N12: =$N$4*I12 -> 0 | O12: ='Rateio Custos Fixos'!E18 -> 430.77083 | P12: =SUM(L12,O12) -> 6364.7708 | Q12: =P12+R12 -> 7510.4296 | R12: =$P12*R$5 -> 1145.6588 | S12: =$Q12*S$5 -> 229.81915 | T12: =$Q12*T$5 -> 234.3254 | U12: =$Q12*U$5 -> 1079.2487 | V12: =$P12*V$5 -> 1145.6588 | W12: =SUM(R12:V12) -> 3834.7108 | X12: =SUM(R17:V17) -> 4801.7248 | Y12: ='Rateio Custos Fixos'!F18 -> 5.1390625 | Z12: ='Rateio Custos Fixos'!G18 -> 11.739583 | AA12: ='Rateio Custos Fixos'!H18 -> 37.063542 | AB12: ='Rateio Custos Fixos'!I18 -> 1.15 | AC12: ='Rateio Custos Fixos'!J18 -> 2.9229167 | AD12: ='Rateio Custos Fixos'!K18 -> 25.705854 | AE12: ='Rateio Custos Fixos'!L18 -> 18.565313 | AF12: ='Rateio Custos Fixos'!M18 -> 0.71395833 | ... AN12: ='Rateio Custos Fixos'!U18 -> 57.5 | AO12: =SUM(Y12:AN12) -> 374.18772 | AP12: =AO12+W12+P12 -> 10573.669 | AQ12: 2601.3166 | AR12: =AO12+X12+P12 -> 11540.683 | AS12: =(AP12/H12) -> 105.73669 | AT12: =AR12/H12 -> 115.40683 | AU12: =AP12/H12 -> 105.73669 | AV12: =(AR12*#REF!)/'Est. Cust. Naci.'!H12 -> #REF! | AW12: =(J12*9) -> 103.5
B13: ='LISTA DE COMPRAS'!A12 -> 8 | C13: ='LISTA DE COMPRAS'!C12 -> RP-13412 | G13: ='LISTA DE COMPRAS'!D13 -> 8708-8000 | H13: ='LISTA DE COMPRAS'!J12 -> 0 | I13: ='LISTA DE COMPRAS'!P12 -> 0 | J13: ='LISTA DE COMPRAS'!K12 -> 0 | K13: =H13*J13 -> 0 | L13: =K13*$L$4 -> 0 | M13: =L13*50% -> 0 | N13: =$N$4*I13 -> 0 | O13: ='Rateio Custos Fixos'!E19 -> 0 | P13: =SUM(L13,O13) -> 0 | Q13: =P13+R13 -> 0 | R13: =$P13*R$5 -> 0 | S13: =$Q13*S$5 -> 0 | T13: =$Q13*T$5 -> 0 | U13: =$Q13*U$5 -> 0 | V13: =$P13*V$5 -> 0 | W13: =SUM(R13:V13) -> 0 | X13: =SUM(R18:V18) -> 2534.2436 | Y13: ='Rateio Custos Fixos'!F19 -> 0 | Z13: ='Rateio Custos Fixos'!G19 -> 0 | AA13: ='Rateio Custos Fixos'!H19 -> 0 | AB13: ='Rateio Custos Fixos'!I19 -> 0 | AC13: ='Rateio Custos Fixos'!J19 -> 0 | AD13: ='Rateio Custos Fixos'!K19 -> 0 | AE13: ='Rateio Custos Fixos'!L19 -> 0 | AF13: ='Rateio Custos Fixos'!M19 -> 0 | ... AN13: ='Rateio Custos Fixos'!U19 -> 0 | AO13: =SUM(Y13:AN13) -> 0 | AP13: =AO13+W13+P13 -> 0 | AQ13: 2602.3166 | AR13: =AO13+X13+P13 -> 2534.2436 | AS13: =(AP13/H13) -> #DIV/0! | AT13: =AR13/H13 -> #DIV/0! | AU13: =AP13/H13 -> #DIV/0! | AV13: =(AR13*#REF!)/'Est. Cust. Naci.'!H13 -> #REF! | AW13: =(J13*9) -> 0
B14: ='LISTA DE COMPRAS'!A13 -> 9 | C14: ='LISTA DE COMPRAS'!C13 -> 1476415.1 | G14: ='LISTA DE COMPRAS'!D14 -> 8708-8000 | H14: ='LISTA DE COMPRAS'!J13 -> 100 | I14: ='LISTA DE COMPRAS'!P13 -> 0.01754386 | J14: ='LISTA DE COMPRAS'!K13 -> 10.8 | K14: =H14*J14 -> 1080 | L14: =K14*$L$4 -> 5572.8 | M14: =L14*50% -> 2786.4 | N14: =$N$4*I14 -> 0 | O14: ='Rateio Custos Fixos'!E20 -> 404.55 | P14: =SUM(L14,O14) -> 5977.35 | Q14: =P14+R14 -> 7053.273 | R14: =$P14*R$5 -> 1075.923 | S14: =$Q14*S$5 -> 215.83015 | T14: =$Q14*T$5 -> 220.06212 | U14: =$Q14*U$5 -> 1013.5553 | V14: =$P14*V$5 -> 1075.923 | W14: =SUM(R14:V14) -> 3601.2936 | X14: =SUM(R19:V19) -> 4801.7248 | Y14: ='Rateio Custos Fixos'!F20 -> 4.82625 | Z14: ='Rateio Custos Fixos'!G20 -> 11.025 | AA14: ='Rateio Custos Fixos'!H20 -> 34.8075 | AB14: ='Rateio Custos Fixos'!I20 -> 1.08 | AC14: ='Rateio Custos Fixos'!J20 -> 2.745 | AD14: ='Rateio Custos Fixos'!K20 -> 24.14115 | AE14: ='Rateio Custos Fixos'!L20 -> 17.43525 | AF14: ='Rateio Custos Fixos'!M20 -> 0.6705 | ... AN14: ='Rateio Custos Fixos'!U20 -> 54 | AO14: =SUM(Y14:AN14) -> 351.41107 | AP14: =AO14+W14+P14 -> 9930.0547 | AQ14: 2603.3166 | AR14: =AO14+X14+P14 -> 11130.486 | AS14: =(AP14/H14) -> 99.300547 | AT14: =AR14/H14 -> 111.30486 | AU14: =AP14/H14 -> 99.300547 | AV14: =(AR14*#REF!)/'Est. Cust. Naci.'!H14 -> #REF! | AW14: =(J14*9) -> 97.2
B15: ='LISTA DE COMPRAS'!A14 -> 10 | C15: ='LISTA DE COMPRAS'!C14 -> 1476415.2 | G15: ='LISTA DE COMPRAS'!D15 -> 8708-8000 | H15: ='LISTA DE COMPRAS'!J14 -> 100 | I15: ='LISTA DE COMPRAS'!P14 -> 0.01754386 | J15: ='LISTA DE COMPRAS'!K14 -> 10.8 | K15: =H15*J15 -> 1080 | L15: =K15*$L$4 -> 5572.8 | M15: =L15*50% -> 2786.4 | N15: =$N$4*I15 -> 0 | O15: ='Rateio Custos Fixos'!E21 -> 404.55 | P15: =SUM(L15,O15) -> 5977.35 | Q15: =P15+R15 -> 7053.273 | R15: =$P15*R$5 -> 1075.923 | S15: =$Q15*S$5 -> 215.83015 | T15: =$Q15*T$5 -> 220.06212 | U15: =$Q15*U$5 -> 1013.5553 | V15: =$P15*V$5 -> 1075.923 | W15: =SUM(R15:V15) -> 3601.2936 | X15: =SUM(R20:V20) -> 5935.4654 | Y15: ='Rateio Custos Fixos'!F21 -> 4.82625 | Z15: ='Rateio Custos Fixos'!G21 -> 11.025 | AA15: ='Rateio Custos Fixos'!H21 -> 34.8075 | AB15: ='Rateio Custos Fixos'!I21 -> 1.08 | AC15: ='Rateio Custos Fixos'!J21 -> 2.745 | AD15: ='Rateio Custos Fixos'!K21 -> 24.14115 | AE15: ='Rateio Custos Fixos'!L21 -> 17.43525 | AF15: ='Rateio Custos Fixos'!M21 -> 0.6705 | ... AN15: ='Rateio Custos Fixos'!U21 -> 54 | AO15: =SUM(Y15:AN15) -> 351.41107 | AP15: =AO15+W15+P15 -> 9930.0547 | AQ15: 2604.3166 | AR15: =AO15+X15+P15 -> 12264.226 | AS15: =(AP15/H15) -> 99.300547 | AT15: =AR15/H15 -> 122.64226 | AU15: =AP15/H15 -> 99.300547 | AV15: =(AR15*#REF!)/'Est. Cust. Naci.'!H15 -> #REF! | AW15: =(J15*9) -> 97.2
B16: ='LISTA DE COMPRAS'!A15 -> 11 | C16: ='LISTA DE COMPRAS'!C15 -> 2023668 | G16: ='LISTA DE COMPRAS'!D16 -> 8708-8000 | H16: ='LISTA DE COMPRAS'!J15 -> 100 | I16: ='LISTA DE COMPRAS'!P15 -> 0.01754386 | J16: ='LISTA DE COMPRAS'!K15 -> 7.6 | K16: =H16*J16 -> 760 | L16: =K16*$L$4 -> 3921.6 | M16: =L16*50% -> 1960.8 | N16: =$N$4*I16 -> 0 | O16: ='Rateio Custos Fixos'!E22 -> 284.68333 | P16: =SUM(L16,O16) -> 4206.2833 | Q16: =P16+R16 -> 4963.4143 | R16: =$P16*R$5 -> 757.131 | S16: =$Q16*S$5 -> 151.88048 | T16: =$Q16*T$5 -> 154.85853 | U16: =$Q16*U$5 -> 713.24264 | V16: =$P16*V$5 -> 757.131 | W16: =SUM(R16:V16) -> 2534.2436 | X16: =SUM(R21:V21) -> 5935.4654 | Y16: ='Rateio Custos Fixos'!F22 -> 3.39625 | Z16: ='Rateio Custos Fixos'!G22 -> 7.7583333 | AA16: ='Rateio Custos Fixos'!H22 -> 24.494167 | AB16: ='Rateio Custos Fixos'!I22 -> 0.76 | AC16: ='Rateio Custos Fixos'!J22 -> 1.9316667 | AD16: ='Rateio Custos Fixos'!K22 -> 16.988217 | AE16: ='Rateio Custos Fixos'!L22 -> 12.26925 | AF16: ='Rateio Custos Fixos'!M22 -> 0.47183333 | ... AN16: ='Rateio Custos Fixos'!U22 -> 38 | AO16: =SUM(Y16:AN16) -> 247.28928 | AP16: =AO16+W16+P16 -> 6987.8163 | AQ16: 2605.3166 | AR16: =AO16+X16+P16 -> 10389.038 | AS16: =(AP16/H16) -> 69.878163 | AT16: =AR16/H16 -> 103.89038 | AU16: =AP16/H16 -> 69.878163 | AV16: =(AR16*#REF!)/'Est. Cust. Naci.'!H16 -> #REF! | AW16: =(J16*9) -> 68.4
B17: ='LISTA DE COMPRAS'!A16 -> 12 | C17: ='LISTA DE COMPRAS'!C16 -> 1761377; 2074003 | G17: ='LISTA DE COMPRAS'!D17 -> 8708-8000 | H17: ='LISTA DE COMPRAS'!J16 -> 100 | I17: ='LISTA DE COMPRAS'!P16 -> 0.01754386 | J17: ='LISTA DE COMPRAS'!K16 -> 14.4 | K17: =H17*J17 -> 1440 | L17: =K17*$L$4 -> 7430.4 | M17: =L17*50% -> 3715.2 | N17: =$N$4*I17 -> 0 | O17: ='Rateio Custos Fixos'!E23 -> 539.4 | P17: =SUM(L17,O17) -> 7969.8 | Q17: =P17+R17 -> 9404.364 | R17: =$P17*R$5 -> 1434.564 | S17: =$Q17*S$5 -> 287.77354 | T17: =$Q17*T$5 -> 293.41616 | U17: =$Q17*U$5 -> 1351.4071 | V17: =$P17*V$5 -> 1434.564 | W17: =SUM(R17:V17) -> 4801.7248 | X17: =SUM(R22:V22) -> 1467.1937 | Y17: ='Rateio Custos Fixos'!F23 -> 6.435 | Z17: ='Rateio Custos Fixos'!G23 -> 14.7 | AA17: ='Rateio Custos Fixos'!H23 -> 46.41 | AB17: ='Rateio Custos Fixos'!I23 -> 1.44 | AC17: ='Rateio Custos Fixos'!J23 -> 3.66 | AD17: ='Rateio Custos Fixos'!K23 -> 32.1882 | AE17: ='Rateio Custos Fixos'!L23 -> 23.247 | AF17: ='Rateio Custos Fixos'!M23 -> 0.894 | ... AN17: ='Rateio Custos Fixos'!U23 -> 72 | AO17: =SUM(Y17:AN17) -> 468.5481 | AP17: =AO17+W17+P17 -> 13240.073 | AQ17: 2606.3166 | AR17: =AO17+X17+P17 -> 9905.5418 | AS17: =(AP17/H17) -> 132.40073 | AT17: =AR17/H17 -> 99.055418 | AU17: =AP17/H17 -> 132.40073 | AV17: =(AR17*#REF!)/'Est. Cust. Naci.'!H17 -> #REF! | AW17: =(J17*9) -> 129.6
B18: ='LISTA DE COMPRAS'!A17 -> 13 | C18: ='LISTA DE COMPRAS'!C17 -> 1761373 | G18: ='LISTA DE COMPRAS'!D18 -> 8708-8000 | H18: ='LISTA DE COMPRAS'!J17 -> 100 | I18: ='LISTA DE COMPRAS'!P17 -> 0.01754386 | J18: ='LISTA DE COMPRAS'!K17 -> 7.6 | K18: =H18*J18 -> 760 | L18: =K18*$L$4 -> 3921.6 | M18: =L18*50% -> 1960.8 | N18: =$N$4*I18 -> 0 | O18: ='Rateio Custos Fixos'!E24 -> 284.68333 | P18: =SUM(L18,O18) -> 4206.2833 | Q18: =P18+R18 -> 4963.4143 | R18: =$P18*R$5 -> 757.131 | S18: =$Q18*S$5 -> 151.88048 | T18: =$Q18*T$5 -> 154.85853 | U18: =$Q18*U$5 -> 713.24264 | V18: =$P18*V$5 -> 757.131 | W18: =SUM(R18:V18) -> 2534.2436 | X18: =SUM(R23:V23) -> 2134.0999 | Y18: ='Rateio Custos Fixos'!F24 -> 3.39625 | Z18: ='Rateio Custos Fixos'!G24 -> 7.7583333 | AA18: ='Rateio Custos Fixos'!H24 -> 24.494167 | AB18: ='Rateio Custos Fixos'!I24 -> 0.76 | AC18: ='Rateio Custos Fixos'!J24 -> 1.9316667 | AD18: ='Rateio Custos Fixos'!K24 -> 16.988217 | AE18: ='Rateio Custos Fixos'!L24 -> 12.26925 | AF18: ='Rateio Custos Fixos'!M24 -> 0.47183333 | ... AN18: ='Rateio Custos Fixos'!U24 -> 38 | AO18: =SUM(Y18:AN18) -> 247.28928 | AP18: =AO18+W18+P18 -> 6987.8163 | AQ18: 2607.3166 | AR18: =AO18+X18+P18 -> 6587.6725 | AS18: =(AP18/H18) -> 69.878163 | AT18: =AR18/H18 -> 65.876725 | AU18: =AP18/H18 -> 69.878163 | AV18: =(AR18*#REF!)/'Est. Cust. Naci.'!H18 -> #REF! | AW18: =(J18*9) -> 68.4
... B53: ='LISTA DE COMPRAS'!A52 -> 48 | C53: ='LISTA DE COMPRAS'!C52 -> 500348789 | G53: ='LISTA DE COMPRAS'!D53 -> 8708-8000 | H53: ='LISTA DE COMPRAS'!J52 -> 100 | I53: ='LISTA DE COMPRAS'!P52 -> 0.01754386 | J53: ='LISTA DE COMPRAS'!K52 -> 4.4 | K53: =H53*J53 -> 440 | L53: =K53*$L$4 -> 2270.4 | M53: =L53*50% -> 1135.2 | N53: =$N$4*I53 -> 0 | O53: ='Rateio Custos Fixos'!E59 -> 164.81667 | P53: =SUM(L53,O53) -> 2435.2167 | Q53: =P53+R53 -> 2873.5557 | R53: =$P53*R$5 -> 438.339 | S53: =$Q53*S$5 -> 87.930803 | T53: =$Q53*T$5 -> 89.654937 | U53: =$Q53*U$5 -> 412.92995 | V53: =$P53*V$5 -> 438.339 | W53: =SUM(R53:V53) -> 1467.1937 | X53: =SUM(R58:V58) -> 5935.4654 | Y53: ='Rateio Custos Fixos'!F59 -> 1.96625 | Z53: ='Rateio Custos Fixos'!G59 -> 4.4916667 | AA53: ='Rateio Custos Fixos'!H59 -> 14.180833 | AB53: ='Rateio Custos Fixos'!I59 -> 0.44 | AC53: ='Rateio Custos Fixos'!J59 -> 1.1183333 | AD53: ='Rateio Custos Fixos'!K59 -> 9.8352833 | AE53: ='Rateio Custos Fixos'!L59 -> 7.10325 | AF53: ='Rateio Custos Fixos'!M59 -> 0.27316667 | ... AN53: ='Rateio Custos Fixos'!U59 -> 22 | AO53: =SUM(Y53:AN53) -> 143.16747 | AP53: =AO53+W53+P53 -> 4045.5778 | AQ53: 2642.3166 | AR53: =AO53+X53+P53 -> 8513.8495 | AS53: =(AP53/H53) -> 40.455778 | AT53: =AR53/H53 -> 85.138495 | AU53: =AP53/H53 -> 40.455778 | AV53: =(AR53*#REF!)/'Est. Cust. Naci.'!H53 -> #REF! | AW53: =(J53*9) -> 39.6
B54: ='LISTA DE COMPRAS'!A53 -> 49 | C54: ='LISTA DE COMPRAS'!C53 -> 410228762 | G54: ='LISTA DE COMPRAS'!D54 -> 8708-8000 | H54: ='LISTA DE COMPRAS'!J53 -> 0 | I54: ='LISTA DE COMPRAS'!P53 -> 0 | J54: ='LISTA DE COMPRAS'!K53 -> 0 | K54: =H54*J54 -> 0 | L54: =K54*$L$4 -> 0 | M54: =L54*50% -> 0 | N54: =$N$4*I54 -> 0 | O54: ='Rateio Custos Fixos'!E60 -> 0 | P54: =SUM(L54,O54) -> 0 | Q54: =P54+R54 -> 0 | R54: =$P54*R$5 -> 0 | S54: =$Q54*S$5 -> 0 | T54: =$Q54*T$5 -> 0 | U54: =$Q54*U$5 -> 0 | V54: =$P54*V$5 -> 0 | W54: =SUM(R54:V54) -> 0 | X54: =SUM(#REF!) -> #REF! | Y54: ='Rateio Custos Fixos'!F60 -> 0 | Z54: ='Rateio Custos Fixos'!G60 -> 0 | AA54: ='Rateio Custos Fixos'!H60 -> 0 | AB54: ='Rateio Custos Fixos'!I60 -> 0 | AC54: ='Rateio Custos Fixos'!J60 -> 0 | AD54: ='Rateio Custos Fixos'!K60 -> 0 | AE54: ='Rateio Custos Fixos'!L60 -> 0 | AF54: ='Rateio Custos Fixos'!M60 -> 0 | ... AN54: ='Rateio Custos Fixos'!U60 -> 0 | AO54: =SUM(Y54:AN54) -> 0 | AP54: =AO54+W54+P54 -> 0 | AQ54: 2643.3166 | AR54: =AO54+X54+P54 -> #REF! | AS54: =(AP54/H54) -> #DIV/0! | AT54: =AR54/H54 -> #REF! | AU54: =AP54/H54 -> #DIV/0! | AV54: =(AR54*#REF!)/'Est. Cust. Naci.'!H54 -> #REF! | AW54: =(J54*9) -> 0
B55: ='LISTA DE COMPRAS'!A54 -> 50 | C55: ='LISTA DE COMPRAS'!C54 -> 41005911 | G55: ='LISTA DE COMPRAS'!D55 -> 8708-8000 | H55: ='LISTA DE COMPRAS'!J54 -> 100 | I55: ='LISTA DE COMPRAS'!P54 -> 0.01754386 | J55: ='LISTA DE COMPRAS'!K54 -> 6.2 | K55: =H55*J55 -> 620 | L55: =K55*$L$4 -> 3199.2 | M55: =L55*50% -> 1599.6 | N55: =$N$4*I55 -> 0 | O55: ='Rateio Custos Fixos'!E61 -> 232.24167 | P55: =SUM(L55,O55) -> 3431.4417 | Q55: =P55+R55 -> 4049.1012 | R55: =$P55*R$5 -> 617.6595 | S55: =$Q55*S$5 -> 123.9025 | T55: =$Q55*T$5 -> 126.33196 | U55: =$Q55*U$5 -> 581.85584 | V55: =$P55*V$5 -> 617.6595 | W55: =SUM(R55:V55) -> 2067.4093 | X55: =SUM(#REF!) -> #REF! | Y55: ='Rateio Custos Fixos'!F61 -> 2.770625 | Z55: ='Rateio Custos Fixos'!G61 -> 6.3291667 | AA55: ='Rateio Custos Fixos'!H61 -> 19.982083 | AB55: ='Rateio Custos Fixos'!I61 -> 0.62 | AC55: ='Rateio Custos Fixos'!J61 -> 1.5758333 | AD55: ='Rateio Custos Fixos'!K61 -> 13.858808 | AE55: ='Rateio Custos Fixos'!L61 -> 10.009125 | AF55: ='Rateio Custos Fixos'!M61 -> 0.38491667 | ... AN55: ='Rateio Custos Fixos'!U61 -> 31 | AO55: =SUM(Y55:AN55) -> 201.73599 | AP55: =AO55+W55+P55 -> 5700.5869 | AQ55: 2644.3166 | AR55: =AO55+X55+P55 -> #REF! | AS55: =(AP55/H55) -> 57.005869 | AT55: =AR55/H55 -> #REF! | AU55: =AP55/H55 -> 57.005869 | AV55: =(AR55*#REF!)/'Est. Cust. Naci.'!H55 -> #REF! | AW55: =(J55*9) -> 55.8
B56: ='LISTA DE COMPRAS'!A55 -> 51 | C56: ='LISTA DE COMPRAS'!C55 -> 97383885 | G56: ='LISTA DE COMPRAS'!D56 -> 8708-8000 | H56: ='LISTA DE COMPRAS'!J55 -> 100 | I56: ='LISTA DE COMPRAS'!P55 -> 0.01754386 | J56: ='LISTA DE COMPRAS'!K55 -> 17.8 | K56: =H56*J56 -> 1780 | L56: =K56*$L$4 -> 9184.8 | M56: =L56*50% -> 4592.4 | N56: =$N$4*I56 -> 0 | O56: ='Rateio Custos Fixos'!E62 -> 666.75833 | P56: =SUM(L56,O56) -> 9851.5583 | Q56: =P56+R56 -> 11624.839 | R56: =$P56*R$5 -> 1773.2805 | S56: =$Q56*S$5 -> 355.72007 | T56: =$Q56*T$5 -> 362.69497 | U56: =$Q56*U$5 -> 1670.4893 | V56: =$P56*V$5 -> 1773.2805 | W56: =SUM(R56:V56) -> 5935.4654 | X56: =SUM(R59:V59) -> 0 | Y56: ='Rateio Custos Fixos'!F62 -> 7.954375 | Z56: ='Rateio Custos Fixos'!G62 -> 18.170833 | AA56: ='Rateio Custos Fixos'!H62 -> 57.367917 | AB56: ='Rateio Custos Fixos'!I62 -> 1.78 | AC56: ='Rateio Custos Fixos'!J62 -> 4.5241667 | AD56: ='Rateio Custos Fixos'!K62 -> 39.788192 | AE56: ='Rateio Custos Fixos'!L62 -> 28.735875 | AF56: ='Rateio Custos Fixos'!M62 -> 1.1050833 | ... AN56: ='Rateio Custos Fixos'!U62 -> 89 | AO56: =SUM(Y56:AN56) -> 579.17751 | AP56: =AO56+W56+P56 -> 16366.201 | AQ56: 2645.3166 | AR56: =AO56+X56+P56 -> 10430.736 | AS56: =(AP56/H56) -> 163.66201 | AT56: =AR56/H56 -> 104.30736 | AU56: =AP56/H56 -> 163.66201 | AV56: =(AR56*#REF!)/'Est. Cust. Naci.'!H56 -> #REF! | AW56: =(J56*9) -> 160.2
B57: ='LISTA DE COMPRAS'!A56 -> 52 | C57: ='LISTA DE COMPRAS'!C56 -> 500387621 | G57: ='LISTA DE COMPRAS'!D57 -> 8708-8000 | H57: ='LISTA DE COMPRAS'!J56 -> 100 | I57: ='LISTA DE COMPRAS'!P56 -> 0.01754386 | J57: ='LISTA DE COMPRAS'!K56 -> 10.2 | K57: =H57*J57 -> 1020 | L57: =K57*$L$4 -> 5263.2 | M57: =L57*50% -> 2631.6 | N57: =$N$4*I57 -> 0 | O57: ='Rateio Custos Fixos'!E63 -> 382.075 | P57: =SUM(L57,O57) -> 5645.275 | Q57: =P57+R57 -> 6661.4245 | R57: =$P57*R$5 -> 1016.1495 | S57: =$Q57*S$5 -> 203.83959 | T57: =$Q57*T$5 -> 207.83644 | U57: =$Q57*U$5 -> 957.2467 | V57: =$P57*V$5 -> 1016.1495 | W57: =SUM(R57:V57) -> 3401.2217 | X57: =SUM(R60:V60) -> 0 | Y57: ='Rateio Custos Fixos'!F63 -> 4.558125 | Z57: ='Rateio Custos Fixos'!G63 -> 10.4125 | AA57: ='Rateio Custos Fixos'!H63 -> 32.87375 | AB57: ='Rateio Custos Fixos'!I63 -> 1.02 | AC57: ='Rateio Custos Fixos'!J63 -> 2.5925 | AD57: ='Rateio Custos Fixos'!K63 -> 22.799975 | AE57: ='Rateio Custos Fixos'!L63 -> 16.466625 | AF57: ='Rateio Custos Fixos'!M63 -> 0.63325 | ... AN57: ='Rateio Custos Fixos'!U63 -> 51 | AO57: =SUM(Y57:AN57) -> 331.88824 | AP57: =AO57+W57+P57 -> 9378.385 | AQ57: 2646.3166 | AR57: =AO57+X57+P57 -> 5977.1632 | AS57: =(AP57/H57) -> 93.78385 | AT57: =AR57/H57 -> 59.771632 | AU57: =AP57/H57 -> 93.78385 | AV57: =(AR57*#REF!)/'Est. Cust. Naci.'!H57 -> #REF! | AW57: =(J57*9) -> 91.8
B58: ='LISTA DE COMPRAS'!A57 -> 53 | C58: ='LISTA DE COMPRAS'!C57 -> 504060241 | G58: ='LISTA DE COMPRAS'!#REF! -> #REF! | H58: ='LISTA DE COMPRAS'!J57 -> 100 | I58: ='LISTA DE COMPRAS'!P57 -> 0.01754386 | J58: ='LISTA DE COMPRAS'!K57 -> 17.8 | K58: =H58*J58 -> 1780 | L58: =K58*$L$4 -> 9184.8 | M58: =L58*50% -> 4592.4 | N58: =$N$4*I58 -> 0 | O58: ='Rateio Custos Fixos'!E64 -> 666.75833 | P58: =SUM(L58,O58) -> 9851.5583 | Q58: =P58+R58 -> 11624.839 | R58: =$P58*R$5 -> 1773.2805 | S58: =$Q58*S$5 -> 355.72007 | T58: =$Q58*T$5 -> 362.69497 | U58: =$Q58*U$5 -> 1670.4893 | V58: =$P58*V$5 -> 1773.2805 | W58: =SUM(R58:V58) -> 5935.4654 | X58: =SUM(R61:V61) -> 0 | Y58: ='Rateio Custos Fixos'!F64 -> 7.954375 | Z58: ='Rateio Custos Fixos'!G64 -> 18.170833 | AA58: ='Rateio Custos Fixos'!H64 -> 57.367917 | AB58: ='Rateio Custos Fixos'!I64 -> 1.78 | AC58: ='Rateio Custos Fixos'!J64 -> 4.5241667 | AD58: ='Rateio Custos Fixos'!K64 -> 39.788192 | AE58: ='Rateio Custos Fixos'!L64 -> 28.735875 | AF58: ='Rateio Custos Fixos'!M64 -> 1.1050833 | ... AN58: ='Rateio Custos Fixos'!U64 -> 89 | AO58: =SUM(Y58:AN58) -> 579.17751 | AP58: =AO58+W58+P58 -> 16366.201 | AQ58: 2647.3166 | AR58: =AO58+X58+P58 -> 10430.736 | AS58: =(AP58/H58) -> 163.66201 | AT58: =AR58/H58 -> 104.30736 | AU58: =AP58/H58 -> 163.66201 | AV58: =(AR58*#REF!)/'Est. Cust. Naci.'!H58 -> #REF! | AW58: =(J58*9) -> 160.2
B59: ='LISTA DE COMPRAS'!A58 -> 0
L62: #VALUE! | N62: 5.16

Sheet Rateio Custos Fixos
A1: CÂMBIO | F1: FRETE | G1: R$
F2: 3000 | G2: =F2*B3 -> 15480
A3: #VALUE! | B3: 5.16 | F3: 2500 | G3: =F3 -> 2500
A4: #VALUE! | B4: {=_FV(A4,"Preço")} -> #NAME? | F4: TOTAL | G4: =SUM(G2:G3) -> 17980
G5: =G4/B3 -> 3484.4961
U8: ='Rateio Custos Fixos'!#REF! -> #REF!
A10: Produto | B10: Quantidade | C10: ='[2]Lista de Compra'!Q2 -> % Rateio Preço | E10: FRETE | F10: TAXA SISCOMEX | G10: LIBERAÇÃO DE B/L | H10: T.H.C| CAPATAZIA | I10: ISPS | J10: DAMAGE PROTECTION | K10: DESCONSOLIDAÇÃO | L10: DEVOLUÇÃO DE CONTAINER | M10: TRS | N10: AFRMM | O10: ARMAZENAGEM TCP | P10: SCANNER TCP | Q10: HANDLING - TCP | R10: PESAGEM TCP | S10: TAXA DO PARCEIRO - PARANAGUÁ | T10: FRETE RODOVIÁRIO | U10: DESEMBARAÇO ADUANEIRO
B11: =SUM(B12:B64) -> 5700 | C11: =SUM(C12:C64) -> 1 | E11: =G4 -> 17980 | F11: 214.5 | G11: 490 | H11: =1547 -> 1547 | I11: 48 | J11: 122 | K11: =1072.94 -> 1072.94 | L11: =774.9 -> 774.9 | M11: 29.8 | N11: 0.08 | O11: 0 | P11: =756.95 -> 756.95 | Q11: =320.33 -> 320.33 | R11: =117.45 -> 117.45 | S11: 286 | T11: =6000 -> 6000 | U11: 2400 | V11: =SUM(E11:U11) -> 32159.95
A12: ='LISTA DE COMPRAS'!A5 -> 1 | B12: ='LISTA DE COMPRAS'!J5 -> 100 | C12: ='LISTA DE COMPRAS'!Q5 -> 0.012083333 | E12: =E$11*$C12 -> 217.25833 | F12: =F$11*$C12 -> 2.591875 | G12: =G$11*$C12 -> 5.9208333 | H12: =H$11*$C12 -> 18.692917 | I12: =I$11*$C12 -> 0.58 | J12: =J$11*$C12 -> 1.4741667 | K12: =K$11*$C12 -> 12.964692 | L12: =L$11*$C12 -> 9.363375 | M12: =M$11*$C12 -> 0.36008333 | N12: =$N$11*E12 -> 17.380667 | O12: =O$11*$C12 -> 0 | P12: =P$11*$C12 -> 9.1464792 | Q12: =Q$11*$C12 -> 3.8706542 | R12: =R$11*$C12 -> 1.4191875 | S12: =S$11*$C12 -> 3.4558333 | T12: =T$11*$C12 -> 72.5 | U12: =U$11*$C12 -> 29
A13: ='LISTA DE COMPRAS'!A6 -> 2 | B13: ='LISTA DE COMPRAS'!J6 -> 300 | C13: ='LISTA DE COMPRAS'!Q6 -> 0.004375 | E13: =E$11*$C13 -> 78.6625 | F13: =F$11*$C13 -> 0.9384375 | G13: =G$11*$C13 -> 2.14375 | H13: =H$11*$C13 -> 6.768125 | I13: =I$11*$C13 -> 0.21 | J13: =J$11*$C13 -> 0.53375 | K13: =K$11*$C13 -> 4.6941125 | L13: =L$11*$C13 -> 3.3901875 | M13: =M$11*$C13 -> 0.130375 | N13: =$N$11*E13 -> 6.293 | O13: =O$11*$C13 -> 0 | P13: =P$11*$C13 -> 3.3116562 | Q13: =Q$11*$C13 -> 1.4014438 | R13: =R$11*$C13 -> 0.51384375 | S13: =S$11*$C13 -> 1.25125 | T13: =T$11*$C13 -> 26.25 | U13: =U$11*$C13 -> 10.5 | V13: =SUM(F13:U13) -> 68.329931
A14: ='LISTA DE COMPRAS'!A7 -> 3 | B14: ='LISTA DE COMPRAS'!J7 -> 300 | C14: ='LISTA DE COMPRAS'!Q7 -> 0.020833333 | E14: =E$11*$C14 -> 374.58333 | F14: =F$11*$C14 -> 4.46875 | G14: =G$11*$C14 -> 10.208333 | H14: =H$11*$C14 -> 32.229167 | I14: =I$11*$C14 -> 1 | J14: =J$11*$C14 -> 2.5416667 | K14: =K$11*$C14 -> 22.352917 | L14: =L$11*$C14 -> 16.14375 | M14: =M$11*$C14 -> 0.62083333 | N14: =$N$11*E14 -> 29.966667 | O14: =O$11*$C14 -> 0 | P14: =P$11*$C14 -> 15.769792 | Q14: =Q$11*$C14 -> 6.6735417 | R14: =R$11*$C14 -> 2.446875 | S14: =S$11*$C14 -> 5.9583333 | T14: =T$11*$C14 -> 125 | U14: =U$11*$C14 -> 50 | V14: =SUM(F14:U14) -> 325.38063
A15: ='LISTA DE COMPRAS'!A8 -> 4 | B15: ='LISTA DE COMPRAS'!J8 -> 300 | C15: ='LISTA DE COMPRAS'!Q8 -> 0.020833333 | E15: =E$11*$C15 -> 374.58333 | F15: =F$11*$C15 -> 4.46875 | G15: =G$11*$C15 -> 10.208333 | H15: =H$11*$C15 -> 32.229167 | I15: =I$11*$C15 -> 1 | J15: =J$11*$C15 -> 2.5416667 | K15: =K$11*$C15 -> 22.352917 | L15: =L$11*$C15 -> 16.14375 | M15: =M$11*$C15 -> 0.62083333 | N15: =$N$11*E15 -> 29.966667 | O15: =O$11*$C15 -> 0 | P15: =P$11*$C15 -> 15.769792 | Q15: =Q$11*$C15 -> 6.6735417 | R15: =R$11*$C15 -> 2.446875 | S15: =S$11*$C15 -> 5.9583333 | T15: =T$11*$C15 -> 125 | U15: =U$11*$C15 -> 50 | V15: =SUM(F15:U15) -> 325.38063
A16: ='LISTA DE COMPRAS'!A9 -> 5 | B16: ='LISTA DE COMPRAS'!J9 -> 300 | C16: ='LISTA DE COMPRAS'!Q9 -> 0.020833333 | E16: =E$11*$C16 -> 374.58333 | F16: =F$11*$C16 -> 4.46875 | G16: =G$11*$C16 -> 10.208333 | H16: =H$11*$C16 -> 32.229167 | I16: =I$11*$C16 -> 1 | J16: =J$11*$C16 -> 2.5416667 | K16: =K$11*$C16 -> 22.352917 | L16: =L$11*$C16 -> 16.14375 | M16: =M$11*$C16 -> 0.62083333 | N16: =$N$11*E16 -> 29.966667 | O16: =O$11*$C16 -> 0 | P16: =P$11*$C16 -> 15.769792 | Q16: =Q$11*$C16 -> 6.6735417 | R16: =R$11*$C16 -> 2.446875 | S16: =S$11*$C16 -> 5.9583333 | T16: =T$11*$C16 -> 125 | U16: =U$11*$C16 -> 50
A17: ='LISTA DE COMPRAS'!A10 -> 6 | B17: ='LISTA DE COMPRAS'!J10 -> 100 | C17: ='LISTA DE COMPRAS'!Q10 -> 0.023958333 | E17: =E$11*$C17 -> 430.77083 | F17: =F$11*$C17 -> 5.1390625 | G17: =G$11*$C17 -> 11.739583 | H17: =H$11*$C17 -> 37.063542 | I17: =I$11*$C17 -> 1.15 | J17: =J$11*$C17 -> 2.9229167 | K17: =K$11*$C17 -> 25.705854 | L17: =L$11*$C17 -> 18.565313 | M17: =M$11*$C17 -> 0.71395833 | N17: =$N$11*E17 -> 34.461667 | O17: =O$11*$C17 -> 0 | P17: =P$11*$C17 -> 18.13526 | Q17: =Q$11*$C17 -> 7.6745729 | R17: =R$11*$C17 -> 2.8139063 | S17: =S$11*$C17 -> 6.8520833 | T17: =T$11*$C17 -> 143.75 | U17: =U$11*$C17 -> 57.5
A18: ='LISTA DE COMPRAS'!A11 -> 7 | B18: ='LISTA DE COMPRAS'!J11 -> 100 | C18: ='LISTA DE COMPRAS'!Q11 -> 0.023958333 | E18: =E$11*$C18 -> 430.77083 | F18: =F$11*$C18 -> 5.1390625 | G18: =G$11*$C18 -> 11.739583 | H18: =H$11*$C18 -> 37.063542 | I18: =I$11*$C18 -> 1.15 | J18: =J$11*$C18 -> 2.9229167 | K18: =K$11*$C18 -> 25.705854 | L18: =L$11*$C18 -> 18.565313 | M18: =M$11*$C18 -> 0.71395833 | N18: =$N$11*E18 -> 34.461667 | O18: =O$11*$C18 -> 0 | P18: =P$11*$C18 -> 18.13526 | Q18: =Q$11*$C18 -> 7.6745729 | R18: =R$11*$C18 -> 2.8139063 | S18: =S$11*$C18 -> 6.8520833 | T18: =T$11*$C18 -> 143.75 | U18: =U$11*$C18 -> 57.5
A19: ='LISTA DE COMPRAS'!A12 -> 8 | B19: ='LISTA DE COMPRAS'!J12 -> 0 | C19: ='LISTA DE COMPRAS'!Q12 -> 0 | E19: =E$11*$C19 -> 0 | F19: =F$11*$C19 -> 0 | G19: =G$11*$C19 -> 0 | H19: =H$11*$C19 -> 0 | I19: =I$11*$C19 -> 0 | J19: =J$11*$C19 -> 0 | K19: =K$11*$C19 -> 0 | L19: =L$11*$C19 -> 0 | M19: =M$11*$C19 -> 0 | N19: =$N$11*E19 -> 0 | O19: =O$11*$C19 -> 0 | P19: =P$11*$C19 -> 0 | Q19: =Q$11*$C19 -> 0 | R19: =R$11*$C19 -> 0 | S19: =S$11*$C19 -> 0 | T19: =T$11*$C19 -> 0 | U19: =U$11*$C19 -> 0
A20: ='LISTA DE COMPRAS'!A13 -> 9 | B20: ='LISTA DE COMPRAS'!J13 -> 100 | C20: ='LISTA DE COMPRAS'!Q13 -> 0.0225 | E20: =E$11*$C20 -> 404.55 | F20: =F$11*$C20 -> 4.82625 | G20: =G$11*$C20 -> 11.025 | H20: =H$11*$C20 -> 34.8075 | I20: =I$11*$C20 -> 1.08 | J20: =J$11*$C20 -> 2.745 | K20: =K$11*$C20 -> 24.14115 | L20: =L$11*$C20 -> 17.43525 | M20: =M$11*$C20 -> 0.6705 | N20: =$N$11*E20 -> 32.364 | O20: =O$11*$C20 -> 0 | P20: =P$11*$C20 -> 17.031375 | Q20: =Q$11*$C20 -> 7.207425 | R20: =R$11*$C20 -> 2.642625 | S20: =S$11*$C20 -> 6.435 | T20: =T$11*$C20 -> 135 | U20: =U$11*$C20 -> 54
A21: ='LISTA DE COMPRAS'!A14 -> 10 | B21: ='LISTA DE COMPRAS'!J14 -> 100 | C21: ='LISTA DE COMPRAS'!Q14 -> 0.0225 | E21: =E$11*$C21 -> 404.55 | F21: =F$11*$C21 -> 4.82625 | G21: =G$11*$C21 -> 11.025 | H21: =H$11*$C21 -> 34.8075 | I21: =I$11*$C21 -> 1.08 | J21: =J$11*$C21 -> 2.745 | K21: =K$11*$C21 -> 24.14115 | L21: =L$11*$C21 -> 17.43525 | M21: =M$11*$C21 -> 0.6705 | N21: =$N$11*E21 -> 32.364 | O21: =O$11*$C21 -> 0 | P21: =P$11*$C21 -> 17.031375 | Q21: =Q$11*$C21 -> 7.207425 | R21: =R$11*$C21 -> 2.642625 | S21: =S$11*$C21 -> 6.435 | T21: =T$11*$C21 -> 135 | U21: =U$11*$C21 -> 54
A22: ='LISTA DE COMPRAS'!A15 -> 11 | B22: ='LISTA DE COMPRAS'!J15 -> 100 | C22: ='LISTA DE COMPRAS'!Q15 -> 0.015833333 | E22: =E$11*$C22 -> 284.68333 | F22: =F$11*$C22 -> 3.39625 | G22: =G$11*$C22 -> 7.7583333 | H22: =H$11*$C22 -> 24.494167 | I22: =I$11*$C22 -> 0.76 | J22: =J$11*$C22 -> 1.9316667 | K22: =K$11*$C22 -> 16.988217 | L22: =L$11*$C22 -> 12.26925 | M22: =M$11*$C22 -> 0.47183333 | N22: =$N$11*E22 -> 22.774667 | O22: =O$11*$C22 -> 0 | P22: =P$11*$C22 -> 11.985042 | Q22: =Q$11*$C22 -> 5.0718917 | R22: =R$11*$C22 -> 1.859625 | S22: =S$11*$C22 -> 4.5283333 | T22: =T$11*$C22 -> 95 | U22: =U$11*$C22 -> 38
A23: ='LISTA DE COMPRAS'!A16 -> 12 | B23: ='LISTA DE COMPRAS'!J16 -> 100 | C23: ='LISTA DE COMPRAS'!Q16 -> 0.03 | E23: =E$11*$C23 -> 539.4 | F23: =F$11*$C23 -> 6.435 | G23: =G$11*$C23 -> 14.7 | H23: =H$11*$C23 -> 46.41 | I23: =I$11*$C23 -> 1.44 | J23: =J$11*$C23 -> 3.66 | K23: =K$11*$C23 -> 32.1882 | L23: =L$11*$C23 -> 23.247 | M23: =M$11*$C23 -> 0.894 | N23: =$N$11*E23 -> 43.152 | O23: =O$11*$C23 -> 0 | P23: =P$11*$C23 -> 22.7085 | Q23: =Q$11*$C23 -> 9.6099 | R23: =R$11*$C23 -> 3.5235 | S23: =S$11*$C23 -> 8.58 | T23: =T$11*$C23 -> 180 | U23: =U$11*$C23 -> 72
A24: ='LISTA DE COMPRAS'!A17 -> 13 | B24: ='LISTA DE COMPRAS'!J17 -> 100 | C24: ='LISTA DE COMPRAS'!Q17 -> 0.015833333 | E24: =E$11*$C24 -> 284.68333 | F24: =F$11*$C24 -> 3.39625 | G24: =G$11*$C24 -> 7.7583333 | H24: =H$11*$C24 -> 24.494167 | I24: =I$11*$C24 -> 0.76 | J24: =J$11*$C24 -> 1.9316667 | K24: =K$11*$C24 -> 16.988217 | L24: =L$11*$C24 -> 12.26925 | M24: =M$11*$C24 -> 0.47183333 | N24: =$N$11*E24 -> 22.774667 | O24: =O$11*$C24 -> 0 | P24: =P$11*$C24 -> 11.985042 | Q24: =Q$11*$C24 -> 5.0718917 | R24: =R$11*$C24 -> 1.859625 | S24: =S$11*$C24 -> 4.5283333 | T24: =T$11*$C24 -> 95 | U24: =U$11*$C24 -> 38
A25: ='LISTA DE COMPRAS'!A18 -> 14 | B25: ='LISTA DE COMPRAS'!J18 -> 100 | C25: ='LISTA DE COMPRAS'!Q18 -> 0.03 | E25: =E$11*$C25 -> 539.4 | F25: =F$11*$C25 -> 6.435 | G25: =G$11*$C25 -> 14.7 | H25: =H$11*$C25 -> 46.41 | I25: =I$11*$C25 -> 1.44 | J25: =J$11*$C25 -> 3.66 | K25: =K$11*$C25 -> 32.1882 | L25: =L$11*$C25 -> 23.247 | M25: =M$11*$C25 -> 0.894 | N25: =$N$11*E25 -> 43.152 | O25: =O$11*$C25 -> 0 | P25: =P$11*$C25 -> 22.7085 | Q25: =Q$11*$C25 -> 9.6099 | R25: =R$11*$C25 -> 3.5235 | S25: =S$11*$C25 -> 8.58 | T25: =T$11*$C25 -> 180 | U25: =U$11*$C25 -> 72
A26: ='LISTA DE COMPRAS'!A19 -> 15 | B26: ='LISTA DE COMPRAS'!J19 -> 100 | C26: ='LISTA DE COMPRAS'!Q19 -> 0.037083333 | E26: =E$11*$C26 -> 666.75833 | F26: =F$11*$C26 -> 7.954375 | G26: =G$11*$C26 -> 18.170833 | H26: =H$11*$C26 -> 57.367917 | I26: =I$11*$C26 -> 1.78 | J26: =J$11*$C26 -> 4.5241667 | K26: =K$11*$C26 -> 39.788192 | L26: =L$11*$C26 -> 28.735875 | M26: =M$11*$C26 -> 1.1050833 | N26: =$N$11*E26 -> 53.340667 | O26: =O$11*$C26 -> 0 | P26: =P$11*$C26 -> 28.070229 | Q26: =Q$11*$C26 -> 11.878904 | R26: =R$11*$C26 -> 4.3554375 | S26: =S$11*$C26 -> 10.605833 | T26: =T$11*$C26 -> 222.5 | U26: =U$11*$C26 -> 89
A27: ='LISTA DE COMPRAS'!A20 -> 16 | B27: ='LISTA DE COMPRAS'!J20 -> 100 | C27: ='LISTA DE COMPRAS'!Q20 -> 0.037083333 | E27: =E$11*$C27 -> 666.75833 | F27: =F$11*$C27 -> 7.954375 | G27: =G$11*$C27 -> 18.170833 | H27: =H$11*$C27 -> 57.367917 | I27: =I$11*$C27 -> 1.78 | J27: =J$11*$C27 -> 4.5241667 | K27: =K$11*$C27 -> 39.788192 | L27: =L$11*$C27 -> 28.735875 | M27: =M$11*$C27 -> 1.1050833 | N27: =$N$11*E27 -> 53.340667 | O27: =O$11*$C27 -> 0 | P27: =P$11*$C27 -> 28.070229 | Q27: =Q$11*$C27 -> 11.878904 | R27: =R$11*$C27 -> 4.3554375 | S27: =S$11*$C27 -> 10.605833 | T27: =T$11*$C27 -> 222.5 | U27: =U$11*$C27 -> 89
... A64: ='LISTA DE COMPRAS'!A57 -> 53 | B64: ='LISTA DE COMPRAS'!J57 -> 100 | C64: ='LISTA DE COMPRAS'!Q57 -> 0.037083333 | E64: =E$11*$C64 -> 666.75833 | F64: =F$11*$C64 -> 7.954375 | G64: =G$11*$C64 -> 18.170833 | H64: =H$11*$C64 -> 57.367917 | I64: =I$11*$C64 -> 1.78 | J64: =J$11*$C64 -> 4.5241667 | K64: =K$11*$C64 -> 39.788192 | L64: =L$11*$C64 -> 28.735875 | M64: =M$11*$C64 -> 1.1050833 | N64: =$N$11*E64 -> 53.340667 | O64: =O$11*$C64 -> 0 | P64: =P$11*$C64 -> 28.070229 | Q64: =Q$11*$C64 -> 11.878904 | R64: =R$11*$C64 -> 4.3554375 | S64: =S$11*$C64 -> 10.605833 | T64: =T$11*$C64 -> 222.5 | U64: =U$11*$C64 -> 89
A65: ='LISTA DE COMPRAS'!A58 -> 0 | B65: ='LISTA DE COMPRAS'!J58 -> 0 | C65: ='LISTA DE COMPRAS'!P58 -> 0 | E65: =E$11*$C65 -> 0 | F65: =F$11*$C65 -> 0 | G65: =G$11*$C65 -> 0 | H65: =H$11*$C65 -> 0 | I65: =I$11*$C65 -> 0 | J65: =J$11*$C65 -> 0 | K65: =K$11*$C65 -> 0 | L65: =L$11*$C65 -> 0 | M65: =M$11*$C65 -> 0 | N65: =$N$11*E65 -> 0 | O65: =O$11*$C65 -> 0 | P65: =P$11*$C65 -> 0 | Q65: =Q$11*$C65 -> 0 | R65: =R$11*$C65 -> 0 | S65: =S$11*$C65 -> 0 | T65: =T$11*$C65 -> 0 | U65: =U$11*$C65 -> 0
N66: =SUM(N12:N65) -> 1438.4
