Workbook

Sheet Resumo 100%
B3: Estimativa de Custo 100% | J3: Quantidade | R3: Preço R$ nacionalizado
J5: 100 | K5: 5.8
J6: 300 | K6: 2.1
J7: 300 | K7: 10
C8: REGIME TRIBUTÁRIO: LUCRO PRESUMIDO/ REAL | E8: USO: REVENDA | G8: CONSIDERAR ICMS 6% | J8: 300 | K8: 10
C9: PRODUTO: FIBRA | E9: PORTO SAÍDA: QINGDAO | G9: =TODAY() -> 46111 | J9: 300 | K9: 10
C10: FRETE: FCL | E10: PORTO ENTRADA: PARANAGUÁ | G10: SIMULAÇÃO 100% | J10: 100 | K10: 11.5
J11: 100 | K11: 11.5
B12: REFERÊNCIA CÁLCULO BASE | C12: R$/USD: | D12: ='Rateio Custos Fixos'!B3 -> 5.23 | E12: NCM: | F12: ='LISTA DE COMPRAS'!D5 -> 55032090 | K12: 0
B13: VALORES ADUANEIROS | I13: ITEM | J13: 100 | K13: 10.8 | L13: QTY | O13: BRL UNIT PRICE
B14: DISCRIMINAÇÃO | D14: UNIDADE | E14: PREÇO USD | F14: PREÇO TOTAL USD | G14: R$ | I14: ='[1]Lista de Compra'!B4 -> 1 | J14: 100 | K14: 10.8 | L14: ='[1]Lista de Compra'!J4 -> 15 | M14: =K14*L14*'[1]Rateio Custos Fixos'!$B$26 -> 777.1464 | N14: =M14+(M14*$K$11) -> 9714.33 | O14: =N14/L14 -> 647.622
B15: ='LISTA DE COMPRAS'!C5 -> FIBRA 0.9DX38MM na versão virgem | D15: ='LISTA DE COMPRAS'!J4 -> 3920 | E15: ='LISTA DE COMPRAS'!K5 -> 1.21 | F15: ='LISTA DE COMPRAS'!M4 -> 4743.2 | G15: =F15*$D$12 -> 24806.936 | J15: 100 | K15: 7.6
B16: TOTAL FOB | F16: =SUM(F15:F15) -> 4743.2 | G16: =SUM(G15:G15) -> 24806.936 | J16: 100 | K16: 14.4
B17: PRODUTO + FRETE | G17: =G16+G19 -> 43442.936 | I17: ='[1]Lista de Compra'!B6 -> 3 | J17: 100 | K17: 7.6 | L17: ='[1]Lista de Compra'!J6 -> 15 | M17: =K17*L17*'[1]Rateio Custos Fixos'!$B$26 -> 546.8808 | N17: =M17+(M17*$K$11) -> 6836.01 | O17: =N17/L17 -> 455.734
B18: Seguro | I18: ='[1]Lista de Compra'!B7 -> 4 | J18: 100 | K18: 14.4 | L18: ='[1]Lista de Compra'!J7 -> 15 | M18: =K18*L18*'[1]Rateio Custos Fixos'!$B$26 -> 1036.1952 | N18: =M18+(M18*$K$11) -> 12952.44 | O18: =N18/L18 -> 863.496
B19: Frete | F19: ='Rateio Custos Fixos'!G5 -> 3563.2887 | G19: =F19*D12 -> 18636 | I19: ='[1]Lista de Compra'!B8 -> 5 | J19: 100 | K19: 17.8 | L19: ='[1]Lista de Compra'!J8 -> 15 | M19: =K19*L19*'[1]Rateio Custos Fixos'!$B$26 -> 1280.8524 | N19: =M19+(M19*$K$11) -> 16010.655 | O19: =N19/L19 -> 1067.377
B20: TOTAL VALOR ADUANEIRO | G20: =G17 -> 43442.936 | I20: ='[1]Lista de Compra'!B9 -> 6 | J20: 100 | K20: 17.8 | L20: ='[1]Lista de Compra'!J9 -> 15 | M20: =K20*L20*'[1]Rateio Custos Fixos'!$B$26 -> 1280.8524 | N20: =M20+(M20*$K$11) -> 16010.655 | O20: =N20/L20 -> 1067.377
B21: IMPOSTOS | J21: 100 | K21: 4.4
B22: IMPOSTOS | C22: PERCENTUAL | G22: VALOR (R$) | J22: 100 | K22: 6.4
B23: IMPOSTO. IMPORTAÇÃO | C23: ='LISTA DE COMPRAS'!E5 -> 0.126 | G23: ='Est. Cust. Naci.'!R$4 -> 5473.8099 | J23: 100 | K23: 4.6
B24: IPI | C24: ='LISTA DE COMPRAS'!F5 -> 0.0365 | G24: ='Est. Cust. Naci.'!S$4 -> 1785.4612 | J24: 100 | K24: 5.1
B25: ='Est. Cust. Naci.'!U3 -> DUMPING | C25: 390/t | G25: ='Est. Cust. Naci.'!U4 -> 47094.5
B26: PIS | C26: ='LISTA DE COMPRAS'!G5 -> 0.021 | G26: ='Est. Cust. Naci.'!T$4 -> 1027.2517 | K26: 0
B27: COFINS | C27: ='LISTA DE COMPRAS'!H5 -> 0.0965 | G27: ='Est. Cust. Naci.'!V$4 -> 4720.466 | J27: 100 | K27: 9.3
B28: ICMS | C28: ='LISTA DE COMPRAS'!I5 -> 0.06 | G28: ='Est. Cust. Naci.'!W$4 -> 2606.5762 | J28: 100 | K28: 9.3
B29: TOTAL VALOR IMPOSTOS | G29: =SUM(G23:G28) -> 62708.065 | J29: 100 | K29: 11
B30: DESPESAS ADUANEIRAS E LOGÍSTICAS | J30: 100 | K30: 11
B31: TAXA SISCOMEX | G31: ='Rateio Custos Fixos'!F$11 -> 214.5 | J31: 100 | K31: 9.8
B32: LIBERAÇÃO DE B/L | G32: ='Rateio Custos Fixos'!G$11 -> 490 | J32: 100 | K32: 10.2
B33: T.H.C|CAPATAZIA | G33: ='Rateio Custos Fixos'!H$11 -> 1547 | J33: 100 | K33: 10.2
B34: ISPS | G34: ='Rateio Custos Fixos'!I$11 -> 48 | J34: 100 | K34: 11
B35: DAMAGE PROTECTION | G35: ='Rateio Custos Fixos'!J$11 -> 122 | J35: 100 | K35: 13.6
B36: DESCONSOLIDAÇÃO | G36: ='Rateio Custos Fixos'!K$11 -> 1072.94 | K36: 0
B37: DEVOLUÇÃO DE CONTAINER | G37: ='Rateio Custos Fixos'!L$11 -> 774.9 | K37: 0
B38: TRS | G38: ='Rateio Custos Fixos'!M$11 -> 29.8 | J38: 100 | K38: 5.4
B39: AFRMM | C39: 0.08 | G39: ='Rateio Custos Fixos'!N17 -> 1490.88 | J39: 100 | K39: 4.7
B40: ARMAZENAGEM TCP | G40: 0 | H40: 5 DIAS DE ARMAZENAGEM | J40: 100 | K40: 9.3
B41: SCANNER TCP | G41: ='Rateio Custos Fixos'!P11 -> 756.95 | K41: 0
B42: HANDLING - TCP | G42: ='Rateio Custos Fixos'!Q11 -> 320.33 | J42: 100 | K42: 4.4
B43: PESAGEM TCP | G43: ='Rateio Custos Fixos'!R11 -> 117.45 | J43: 100 | K43: 13.5
...

Sheet LISTA DE COMPRAS
A1: LISTA DE COMPRA
A3: Item | B3: kg Unitário | C3: Produto | D3: NCM | E3: II | F3: IPI | G3: PIS | H3: COFINS | I3: ICMS | J3: Quantidade | K3: Preço Unitário | L3: Preço Unitário Sub 50% | M3: Preço total por produto | N3: Preço total por produto | O3: Preço total por produto Sub | P3: % Rateio Quantidade | Q3: % Rateio Preço | R3: Preço R$ nacionalizado | S3: Preço R$ nacionalizado por kg
J4: =SUM(J5:J9) -> 3920 | K4: =SUM(K5:K9) -> 1.21 | M4: =SUM(M5:M9) -> 4743.2 | N4: =F11 -> 5.23 | P4: 1 | Q4: 1
A5: 1 | C5: FIBRA 0.9DX38MM na versão virgem | D5: 55032090 | E5: 0.126 | F5: 0.0365 | G5: 0.021 | H5: 0.0965 | I5: 0.06 | J5: 3920 | K5: 1.21 | L5: =K5/2 -> 0.605 | M5: =K5*J5 -> 4743.2 | N5: =M5*$N$4 -> 24806.936 | O5: =L5*J5*$N$4 -> 12403.468 | P5: =(J5*$P$4)/$J$4 -> 1 | Q5: =(K5*$Q$4)/$K$4 -> 1 | R5: ='Est. Cust. Naci.'!AV6 -> 31.076977 | S5: =R5/B5 -> #DIV/0!
A6: 2 | M6: =K6*J6 -> 0 | N6: =M6*$N$4 -> 0 | O6: =L6*J6*$N$4 -> 0 | P6: =(J6*$P$4)/$J$4 -> 0 | Q6: =(K6*$Q$4)/$K$4 -> 0 | R6: ='Est. Cust. Naci.'!AV7 -> #DIV/0! | S6: =R6/B6 -> #DIV/0!
A7: 3 | M7: =K7*J7 -> 0 | N7: =M7*$N$4 -> 0 | O7: =L7*J7*$N$4 -> 0 | P7: =(J7*$P$4)/$J$4 -> 0 | Q7: =(K7*$Q$4)/$K$4 -> 0 | R7: ='Est. Cust. Naci.'!AV8 -> #DIV/0! | S7: =R7/B7 -> #DIV/0!
A8: 4 | M8: =K8*J8 -> 0 | N8: =M8*$N$4 -> 0 | O8: =L8*J8*$N$4 -> 0 | P8: =(J8*$P$4)/$J$4 -> 0 | Q8: =(K8*$Q$4)/$K$4 -> 0 | R8: ='Est. Cust. Naci.'!AV9 -> #DIV/0! | S8: =R8/B8 -> #DIV/0!
A9: 5 | M9: =K9*J9 -> 0 | N9: =M9*$N$4 -> 0 | O9: =L9*J9*$N$4 -> 0 | P9: =(J9*$P$4)/$J$4 -> 0 | Q9: =(K9*$Q$4)/$K$4 -> 0 | R9: ='Est. Cust. Naci.'!AV10 -> #DIV/0! | S9: =R9/B9 -> #DIV/0!
E11: #VALUE! | F11: 5.23

Sheet Est. Cust. Naci.
C2: DETALHES DO PRODUTO | L2: VALOR ADUANEIRO | R2: IMPOSTOS | Z2: TAXAS PORTUÁRIAS
B3: Nº | C3: ITEM | D3: Código | E3: Bitola (mm) | F3: Embal. | G3: NCM | H3: QTD | I3: % Rateio Preço | J3: Preço unitário Fábrica (USD) | K3: Preço x QTD (Valor em USD) | L3: Preço x QTD (valor em BRL) | M3: Preço x QTD (valor em BRL) SUB | N3: THC (valor em BRL) | O3: Valor do frete (Valor em BRL) | P3: TOTAL VALOR ADUANEIRO | Q3: TOTAL VALOR ADUANEIRO + II | R3: IMPOSTO DE IMPORTAÇÃO | S3: IPI | T3: PIS | U3: DUMPING | V3: COFINS | W3: ICMS | X3: TOTAL IMPOSTOS | Y3: TOTAL IMPOSTOS (SUB) | Z3: TAXA SISCOMEX | AA3: LIBERAÇÃO DE B/L | AB3: T.H.C| CAPATAZIA | AC3: ISPS | AD3: DAMAGE PROTECTION | AE3: DESCONSOLIDAÇÃO | AF3: DEVOLUÇÃO DE CONTAINER | AG3: TRS | AH3: AFRMM | AI3: ARMAZENAGEM TCP | AJ3: SCANNER TCP | AK3: HANDLING - TCP | AL3: PESAGEM TCP | AM3: TAXA DO PARCEIRO - PARANAGUÁ | AN3: FRETE RODOVIÁRIO | AO3: DESEMBARAÇO ADUANEIRO | AP3: TOTAL TAXAS DESEMBARAÇO | AQ3: TOTAL | AR3: TOTAL (sub) | AS3: TOTAL (sub) | AT3: MÉTODO ANTIGO | AU3: MÉTODO ANTIGO (sub) | AV3: MÉTODO DANI | AW3: MÉTODO DANI (sub) | AX3: MÉTODO JULIANA | AY3: MÉTODO JULIANA (sub) | BA3: VALOR UNITÁRIO C/ COMISSÃO SEAWISE
A4: Nº | L4: =N14 -> 5.23 | M4: 4.8887 | N4: 0 | P4: =SUM(P6:P10) -> 43442.936 | Q4: =SUM(Q6:Q10) -> 48916.746 | R4: =SUM(R6:R10) -> 5473.8099 | S4: =SUM(S6:S10) -> 1785.4612 | T4: =SUM(T6:T10) -> 1027.2517 | U4: 47094.5 | V4: =SUM(V6:V10) -> 4720.466 | W4: =SUM(W6:W10) -> 2606.5762 | AH4: 0.08
A5: AAA | L5: =SUM(L6:L10) -> 24806.936 | O5: =SUM(O6:O10) -> 18636 | R5: ='LISTA DE COMPRAS'!E5 -> 0.126 | S5: ='LISTA DE COMPRAS'!F5 -> 0.0365 | T5: ='LISTA DE COMPRAS'!G5 -> 0.021 | V5: ='LISTA DE COMPRAS'!H5 -> 0.0965 | W5: ='LISTA DE COMPRAS'!I5 -> 0.06 | X5: =SUM(X6:X10) -> 62708.065 | Y5: =SUM(#REF!,Y6) -> #REF! | Z5: =SUM(Z6:Z10) -> 214.5 | AA5: =SUM(AA6:AA10) -> 490 | AB5: =SUM(AB6:AB10) -> 1547 | AC5: =SUM(AC6:AC10) -> 48 | AD5: =SUM(AD6:AD10) -> 122 | AE5: =SUM(AE6:AE10) -> 1072.94 | AF5: =SUM(AF6:AF10) -> 774.9 | AG5: =SUM(AG6:AG10) -> 29.8 | AH5: =SUM(AH6:AH10) -> 1490.88 | AI5: =SUM(AI6:AI6) -> 0 | AJ5: =SUM(AJ6:AJ10) -> 756.95 | AK5: =SUM(AK6:AK10) -> 320.33 | AL5: =SUM(AL6:AL10) -> 117.45 | AM5: =SUM(AM6:AM10) -> 286 | AN5: =SUM(AN6:AN10) -> 6000 | AO5: =SUM(AO6:AO10) -> 2400 | AP5: =SUM(AP6:AP10) -> 15670.75 | AQ5: =AP5+X5+P4 -> 121821.75 | AR5: 21877.425 | AS5: =AP5+Y5+Q4+#REF! -> #REF!
A6: AAA | B6: ='LISTA DE COMPRAS'!A5 -> 1 | C6: ='LISTA DE COMPRAS'!C5 -> FIBRA 0.9DX38MM na versão virgem | G6: ='LISTA DE COMPRAS'!D6 -> 0 | H6: ='LISTA DE COMPRAS'!J5 -> 3920 | I6: ='LISTA DE COMPRAS'!P5 -> 1 | J6: ='LISTA DE COMPRAS'!K5 -> 1.21 | K6: =H6*J6 -> 4743.2 | L6: =K6*$L$4 -> 24806.936 | M6: =L6*50% -> 12403.468 | N6: =$N$4*I6 -> 0 | O6: ='Rateio Custos Fixos'!E12 -> 18636 | P6: =SUM(L6,O6) -> 43442.936 | Q6: =P6+R6 -> 48916.746 | R6: =$P6*R$5 -> 5473.8099 | S6: =$Q6*S$5 -> 1785.4612 | T6: =$Q6*T$5 -> 1027.2517 | U6: =U4 -> 47094.5 | V6: =$Q6*V$5 -> 4720.466 | W6: =$P6*W$5 -> 2606.5762 | X6: =SUM(R6:W6) -> 62708.065 | Y6: =SUM(#REF!) -> #REF! | Z6: ='Rateio Custos Fixos'!F12 -> 214.5 | AA6: ='Rateio Custos Fixos'!G12 -> 490 | AB6: ='Rateio Custos Fixos'!H12 -> 1547 | AC6: ='Rateio Custos Fixos'!I12 -> 48 | AD6: ='Rateio Custos Fixos'!J12 -> 122 | AE6: ='Rateio Custos Fixos'!K12 -> 1072.94 | AF6: ='Rateio Custos Fixos'!L12 -> 774.9 | AG6: ='Rateio Custos Fixos'!M12 -> 29.8 | ... AO6: ='Rateio Custos Fixos'!U12 -> 2400 | AP6: =SUM(Z6:AO6) -> 15670.75 | AQ6: =AP6+X6+P6 -> 121821.75 | AR6: 2595.3166 | AS6: =AP6+Y6+P6 -> #REF! | AT6: =(AQ6/H6) -> 31.076977 | AU6: =AS6/H6 -> #REF! | AV6: =AQ6/H6 -> 31.076977 | AW6: =(AS6*#REF!)/'Est. Cust. Naci.'!H6 -> #REF! | AX6: =(J6*9) -> 10.89 | AY6: =AX6/2 -> 5.445 | BA6: =AQ6/H6 -> 31.076977
B7: ='LISTA DE COMPRAS'!A6 -> 2 | C7: ='LISTA DE COMPRAS'!C6 -> 0 | G7: ='LISTA DE COMPRAS'!D7 -> 0 | H7: ='LISTA DE COMPRAS'!J6 -> 0 | I7: ='LISTA DE COMPRAS'!P6 -> 0 | J7: ='LISTA DE COMPRAS'!K6 -> 0 | K7: =H7*J7 -> 0 | L7: =K7*$L$4 -> 0 | M7: =L7*50% -> 0 | N7: =$N$4*I7 -> 0 | O7: ='Rateio Custos Fixos'!E13 -> 0 | P7: =SUM(L7,O7) -> 0 | Q7: =P7+R7 -> 0 | R7: =$P7*R$5 -> 0 | S7: =$Q7*S$5 -> 0 | T7: =$Q7*T$5 -> 0 | V7: =$Q7*V$5 -> 0 | W7: =$P7*W$5 -> 0 | X7: =SUM(R7:W7) -> 0 | Y7: =SUM(#REF!) -> #REF! | Z7: ='Rateio Custos Fixos'!F13 -> 0 | AA7: ='Rateio Custos Fixos'!G13 -> 0 | AB7: ='Rateio Custos Fixos'!H13 -> 0 | AC7: ='Rateio Custos Fixos'!I13 -> 0 | AD7: ='Rateio Custos Fixos'!J13 -> 0 | AE7: ='Rateio Custos Fixos'!K13 -> 0 | AF7: ='Rateio Custos Fixos'!L13 -> 0 | AG7: ='Rateio Custos Fixos'!M13 -> 0 | ... AO7: ='Rateio Custos Fixos'!U13 -> 0 | AP7: =SUM(Z7:AO7) -> 0 | AQ7: =AP7+X7+P7 -> 0 | AR7: 2596.3166 | AS7: =AP7+Y7+P7 -> #REF! | AT7: =(AQ7/H7) -> #DIV/0! | AU7: =AS7/H7 -> #REF! | AV7: =AQ7/H7 -> #DIV/0! | AW7: =(AS7*#REF!)/'Est. Cust. Naci.'!H7 -> #REF! | AX7: =(J7*9) -> 0
B8: ='LISTA DE COMPRAS'!A7 -> 3 | C8: ='LISTA DE COMPRAS'!C7 -> 0 | G8: ='LISTA DE COMPRAS'!D8 -> 0 | H8: ='LISTA DE COMPRAS'!J7 -> 0 | I8: ='LISTA DE COMPRAS'!P7 -> 0 | J8: ='LISTA DE COMPRAS'!K7 -> 0 | K8: =H8*J8 -> 0 | L8: =K8*$L$4 -> 0 | M8: =L8*50% -> 0 | N8: =$N$4*I8 -> 0 | O8: ='Rateio Custos Fixos'!E14 -> 0 | P8: =SUM(L8,O8) -> 0 | Q8: =P8+R8 -> 0 | R8: =$P8*R$5 -> 0 | S8: =$Q8*S$5 -> 0 | T8: =$Q8*T$5 -> 0 | V8: =$Q8*V$5 -> 0 | W8: =$P8*W$5 -> 0 | X8: =SUM(R8:W8) -> 0 | Y8: =SUM(#REF!) -> #REF! | Z8: ='Rateio Custos Fixos'!F14 -> 0 | AA8: ='Rateio Custos Fixos'!G14 -> 0 | AB8: ='Rateio Custos Fixos'!H14 -> 0 | AC8: ='Rateio Custos Fixos'!I14 -> 0 | AD8: ='Rateio Custos Fixos'!J14 -> 0 | AE8: ='Rateio Custos Fixos'!K14 -> 0 | AF8: ='Rateio Custos Fixos'!L14 -> 0 | AG8: ='Rateio Custos Fixos'!M14 -> 0 | ... AO8: ='Rateio Custos Fixos'!U14 -> 0 | AP8: =SUM(Z8:AO8) -> 0 | AQ8: =AP8+X8+P8 -> 0 | AR8: 2597.3166 | AS8: =AP8+Y8+P8 -> #REF! | AT8: =(AQ8/H8) -> #DIV/0! | AU8: =AS8/H8 -> #REF! | AV8: =AQ8/H8 -> #DIV/0! | AW8: =(AS8*#REF!)/'Est. Cust. Naci.'!H8 -> #REF! | AX8: =(J8*9) -> 0
B9: ='LISTA DE COMPRAS'!A8 -> 4 | C9: ='LISTA DE COMPRAS'!C8 -> 0 | G9: ='LISTA DE COMPRAS'!D9 -> 0 | H9: ='LISTA DE COMPRAS'!J8 -> 0 | I9: ='LISTA DE COMPRAS'!P8 -> 0 | J9: ='LISTA DE COMPRAS'!K8 -> 0 | K9: =H9*J9 -> 0 | L9: =K9*$L$4 -> 0 | M9: =L9*50% -> 0 | N9: =$N$4*I9 -> 0 | O9: ='Rateio Custos Fixos'!E15 -> 0 | P9: =SUM(L9,O9) -> 0 | Q9: =P9+R9 -> 0 | R9: =$P9*R$5 -> 0 | S9: =$Q9*S$5 -> 0 | T9: =$Q9*T$5 -> 0 | V9: =$Q9*V$5 -> 0 | W9: =$P9*W$5 -> 0 | X9: =SUM(R9:W9) -> 0 | Y9: =SUM(#REF!) -> #REF! | Z9: ='Rateio Custos Fixos'!F15 -> 0 | AA9: ='Rateio Custos Fixos'!G15 -> 0 | AB9: ='Rateio Custos Fixos'!H15 -> 0 | AC9: ='Rateio Custos Fixos'!I15 -> 0 | AD9: ='Rateio Custos Fixos'!J15 -> 0 | AE9: ='Rateio Custos Fixos'!K15 -> 0 | AF9: ='Rateio Custos Fixos'!L15 -> 0 | AG9: ='Rateio Custos Fixos'!M15 -> 0 | ... AO9: ='Rateio Custos Fixos'!U15 -> 0 | AP9: =SUM(Z9:AO9) -> 0 | AQ9: =AP9+X9+P9 -> 0 | AR9: 2598.3166 | AS9: =AP9+Y9+P9 -> #REF! | AT9: =(AQ9/H9) -> #DIV/0! | AU9: =AS9/H9 -> #REF! | AV9: =AQ9/H9 -> #DIV/0! | AW9: =(AS9*#REF!)/'Est. Cust. Naci.'!H9 -> #REF! | AX9: =(J9*9) -> 0
B10: ='LISTA DE COMPRAS'!A9 -> 5 | C10: ='LISTA DE COMPRAS'!C9 -> 0 | G10: ='LISTA DE COMPRAS'!#REF! -> #REF! | H10: ='LISTA DE COMPRAS'!J9 -> 0 | I10: ='LISTA DE COMPRAS'!P9 -> 0 | J10: ='LISTA DE COMPRAS'!K9 -> 0 | K10: =H10*J10 -> 0 | L10: =K10*$L$4 -> 0 | M10: =L10*50% -> 0 | N10: =$N$4*I10 -> 0 | O10: ='Rateio Custos Fixos'!E16 -> 0 | P10: =SUM(L10,O10) -> 0 | Q10: =P10+R10 -> 0 | R10: =$P10*R$5 -> 0 | S10: =$Q10*S$5 -> 0 | T10: =$Q10*T$5 -> 0 | V10: =$Q10*V$5 -> 0 | W10: =$P10*W$5 -> 0 | X10: =SUM(R10:W10) -> 0 | Y10: =SUM(#REF!) -> #REF! | Z10: ='Rateio Custos Fixos'!F16 -> 0 | AA10: ='Rateio Custos Fixos'!G16 -> 0 | AB10: ='Rateio Custos Fixos'!H16 -> 0 | AC10: ='Rateio Custos Fixos'!I16 -> 0 | AD10: ='Rateio Custos Fixos'!J16 -> 0 | AE10: ='Rateio Custos Fixos'!K16 -> 0 | AF10: ='Rateio Custos Fixos'!L16 -> 0 | AG10: ='Rateio Custos Fixos'!M16 -> 0 | ... AO10: ='Rateio Custos Fixos'!U16 -> 0 | AP10: =SUM(Z10:AO10) -> 0 | AQ10: =AP10+X10+P10 -> 0 | AR10: 2599.3166 | AS10: =AP10+Y10+P10 -> #REF! | AT10: =(AQ10/H10) -> #DIV/0! | AU10: =AS10/H10 -> #REF! | AV10: =AQ10/H10 -> #DIV/0! | AW10: =(AS10*#REF!)/'Est. Cust. Naci.'!H10 -> #REF! | AX10: =(J10*9) -> 0
B11: ='LISTA DE COMPRAS'!A10 -> 0
L14: #VALUE! | N14: 5.23

Sheet Rateio Custos Fixos
A1: CÂMBIO | F1: FRETE | G1: R$
F2: 3200 | G2: =F2*B3 -> 16736
A3: #VALUE! | B3: 5.23 | F3: 1900 | G3: =F3 -> 1900
A4: #VALUE! | B4: {=_FV(A4,"Preço")} -> 5.973 | F4: TOTAL | G4: =SUM(G2:G3) -> 18636
G5: =G4/B3 -> 3563.2887
U8: ='Rateio Custos Fixos'!#REF! -> #REF!
A10: Produto | B10: Quantidade | C10: ='[2]Lista de Compra'!Q2 -> % Rateio Preço | E10: FRETE | F10: TAXA SISCOMEX | G10: LIBERAÇÃO DE B/L | H10: T.H.C| CAPATAZIA | I10: ISPS | J10: DAMAGE PROTECTION | K10: DESCONSOLIDAÇÃO | L10: DEVOLUÇÃO DE CONTAINER | M10: TRS | N10: AFRMM | O10: ARMAZENAGEM | P10: SCANNER | Q10: HANDLING | R10: PESAGEM | S10: TAXA DO PARCEIRO - PARANAGUÁ | T10: FRETE RODOVIÁRIO | U10: DESEMBARAÇO ADUANEIRO
B11: =SUM(B12:B16) -> 3920 | C11: =SUM(C12:C16) -> 1 | E11: =G4 -> 18636 | F11: 214.5 | G11: 490 | H11: =1547 -> 1547 | I11: 48 | J11: 122 | K11: =1072.94 -> 1072.94 | L11: =774.9 -> 774.9 | M11: 29.8 | N11: 0.08 | O11: 0 | P11: =756.95 -> 756.95 | Q11: =320.33 -> 320.33 | R11: =117.45 -> 117.45 | S11: 286 | T11: =6000 -> 6000 | U11: 2400 | V11: =SUM(E11:U11) -> 32815.95
A12: ='LISTA DE COMPRAS'!A5 -> 1 | B12: ='LISTA DE COMPRAS'!J5 -> 3920 | C12: ='LISTA DE COMPRAS'!Q5 -> 1 | E12: =E$11*$C12 -> 18636 | F12: =F$11*$C12 -> 214.5 | G12: =G$11*$C12 -> 490 | H12: =H$11*$C12 -> 1547 | I12: =I$11*$C12 -> 48 | J12: =J$11*$C12 -> 122 | K12: =K$11*$C12 -> 1072.94 | L12: =L$11*$C12 -> 774.9 | M12: =M$11*$C12 -> 29.8 | N12: =$N$11*E12 -> 1490.88 | O12: =O$11*$C12 -> 0 | P12: =P$11*$C12 -> 756.95 | Q12: =Q$11*$C12 -> 320.33 | R12: =R$11*$C12 -> 117.45 | S12: =S$11*$C12 -> 286 | T12: =T$11*$C12 -> 6000 | U12: =U$11*$C12 -> 2400
A13: ='LISTA DE COMPRAS'!A6 -> 2 | B13: ='LISTA DE COMPRAS'!J6 -> 0 | C13: ='LISTA DE COMPRAS'!Q6 -> 0 | E13: =E$11*$C13 -> 0 | F13: =F$11*$C13 -> 0 | G13: =G$11*$C13 -> 0 | H13: =H$11*$C13 -> 0 | I13: =I$11*$C13 -> 0 | J13: =J$11*$C13 -> 0 | K13: =K$11*$C13 -> 0 | L13: =L$11*$C13 -> 0 | M13: =M$11*$C13 -> 0 | N13: =$N$11*E13 -> 0 | O13: =O$11*$C13 -> 0 | P13: =P$11*$C13 -> 0 | Q13: =Q$11*$C13 -> 0 | R13: =R$11*$C13 -> 0 | S13: =S$11*$C13 -> 0 | T13: =T$11*$C13 -> 0 | U13: =U$11*$C13 -> 0 | V13: =SUM(F13:U13) -> 0
A14: ='LISTA DE COMPRAS'!A7 -> 3 | B14: ='LISTA DE COMPRAS'!J7 -> 0 | C14: ='LISTA DE COMPRAS'!Q7 -> 0 | E14: =E$11*$C14 -> 0 | F14: =F$11*$C14 -> 0 | G14: =G$11*$C14 -> 0 | H14: =H$11*$C14 -> 0 | I14: =I$11*$C14 -> 0 | J14: =J$11*$C14 -> 0 | K14: =K$11*$C14 -> 0 | L14: =L$11*$C14 -> 0 | M14: =M$11*$C14 -> 0 | N14: =$N$11*E14 -> 0 | O14: =O$11*$C14 -> 0 | P14: =P$11*$C14 -> 0 | Q14: =Q$11*$C14 -> 0 | R14: =R$11*$C14 -> 0 | S14: =S$11*$C14 -> 0 | T14: =T$11*$C14 -> 0 | U14: =U$11*$C14 -> 0 | V14: =SUM(F14:U14) -> 0
A15: ='LISTA DE COMPRAS'!A8 -> 4 | B15: ='LISTA DE COMPRAS'!J8 -> 0 | C15: ='LISTA DE COMPRAS'!Q8 -> 0 | E15: =E$11*$C15 -> 0 | F15: =F$11*$C15 -> 0 | G15: =G$11*$C15 -> 0 | H15: =H$11*$C15 -> 0 | I15: =I$11*$C15 -> 0 | J15: =J$11*$C15 -> 0 | K15: =K$11*$C15 -> 0 | L15: =L$11*$C15 -> 0 | M15: =M$11*$C15 -> 0 | N15: =$N$11*E15 -> 0 | O15: =O$11*$C15 -> 0 | P15: =P$11*$C15 -> 0 | Q15: =Q$11*$C15 -> 0 | R15: =R$11*$C15 -> 0 | S15: =S$11*$C15 -> 0 | T15: =T$11*$C15 -> 0 | U15: =U$11*$C15 -> 0 | V15: =SUM(F15:U15) -> 0
A16: ='LISTA DE COMPRAS'!A9 -> 5 | B16: ='LISTA DE COMPRAS'!J9 -> 0 | C16: ='LISTA DE COMPRAS'!Q9 -> 0 | E16: =E$11*$C16 -> 0 | F16: =F$11*$C16 -> 0 | G16: =G$11*$C16 -> 0 | H16: =H$11*$C16 -> 0 | I16: =I$11*$C16 -> 0 | J16: =J$11*$C16 -> 0 | K16: =K$11*$C16 -> 0 | L16: =L$11*$C16 -> 0 | M16: =M$11*$C16 -> 0 | N16: =$N$11*E16 -> 0 | O16: =O$11*$C16 -> 0 | P16: =P$11*$C16 -> 0 | Q16: =Q$11*$C16 -> 0 | R16: =R$11*$C16 -> 0 | S16: =S$11*$C16 -> 0 | T16: =T$11*$C16 -> 0 | U16: =U$11*$C16 -> 0
N17: =SUM(N12:N16) -> 1490.88
