Workbook
Name OLE_LINK4: 'Lista de Compra'!#REF!

Sheet RESUMO 100%
A3: Estimativa de Custo 100%
B5: CLIENTE: SECAMAQ
B8: REGIME TRIBUTÁRIO: LUCRO REAL | D8: USO: INDUSTRIALIZAÇÃO | F8: CONSIDERAR ICMS 6%
B9: PRODUTO: FLANGES | D9: PORTO SAÍDA: SHANGHAI | F9: =TODAY() -> 46233
B10: FRETE: 1x40HC | D10: PORTO ENTRADA: NAVEGANTES | F10: SIMULAÇÃO 100%
A12: REFERÊNCIA CÁLCULO BASE | B12: #VALUE! | C12: =5.14 -> 5.14 | D12: NCM: | E12: ='Lista de Compra'!C4 -> 7307.93.00
A13: VALORES ADUANEIROS
A14: DISCRIMINAÇÃO | B14: Qtd | D14: PREÇO TOTAL USD | F14: R$
B15: ='Est. Cust. Naci. 100%'!D5 -> 11873 | D15: ='Est. Cust. Naci. 100%'!G5 -> 35053.99 | F15: ='Est. Cust. Naci. 100%'!H5 -> 180177.51
A16: TOTAL FOB
A17: PRODUTO + FRETE
A18: SEGURO
A19: FRETE | D19: ='Rateio Custos Fixos'!G68 -> 5119.4494 | F19: ='Rateio Custos Fixos'!G67 -> 26313.97
A20: TOTAL VALOR ADUANEIRO | F20: =SUM(F15+F19) -> 206491.48
A21: IMPOSTOS
A22: IMPOSTOS | B22: PERCENTUAL | F22: VALOR (R$)
A23: IMPOSTO. IMPORTAÇÃO | B23: ='Lista de Compra'!D4 -> 0.126 | F23: ='Est. Cust. Naci. 100%'!L4 -> 26017.926
A24: PIS | B24: ='Lista de Compra'!F4 -> 0.021 | F24: ='Est. Cust. Naci. 100%'!N4 -> 4882.6975
A25: COFINS | B25: ='Lista de Compra'!G4 -> 0.0965 | F25: ='Est. Cust. Naci. 100%'!O4 -> 22437.158
A26: IPI | B26: ='Lista de Compra'!E4 -> 0.0365 | F26: ='Est. Cust. Naci. 100%'!M4 -> 8486.5933
A27: ICMS | B27: ='Lista de Compra'!H4 -> 0.06 | F27: ='Est. Cust. Naci. 100%'!P4 -> 13950.564
A28: TOTAL VALOR IMPOSTOS | F28: =SUM(F23:F27) -> 75774.939
A29: DESPESAS PORTUÁRIAS E LOGÍSTICAS
A30: ='Rateio Custos Fixos'!F3 -> TAXA SISCOMEX | F30: ='Rateio Custos Fixos'!F4 -> 350
A31: ='Rateio Custos Fixos'!G3 -> B/L | F31: ='Rateio Custos Fixos'!G4 -> 1100
A32: ='Rateio Custos Fixos'!H3 -> T.H.C| CAPATAZIA | F32: ='Rateio Custos Fixos'!H4 -> 1500
A33: ='Rateio Custos Fixos'!I3 -> ISPS | F33: ='Rateio Custos Fixos'!I4 -> 100
A34: ='Rateio Custos Fixos'!J3 -> DAMAGE PROTECTION | F34: ='Rateio Custos Fixos'!J4 -> 180
A35: ='Rateio Custos Fixos'!K3 -> DESCONSOLIDAÇÃO | F35: ='Rateio Custos Fixos'!K4 -> 490
A36: ='Rateio Custos Fixos'!L3 -> SERVIÇO DE ENTREGA DE CONTAINER | F36: ='Rateio Custos Fixos'!L4 -> 1060
A37: ='Rateio Custos Fixos'!M3 -> DELIVERY ORDER | F37: ='Rateio Custos Fixos'!M4 -> 366
A38: ='Rateio Custos Fixos'!N3 -> AFRMM | B38: 0.08 | F38: ='Rateio Custos Fixos'!N2 -> 2105.1176
A39: ='Rateio Custos Fixos'!O3 -> ARMAZENAGEM | F39: ='Rateio Custos Fixos'!O4 -> 1500 | J39: Armazenagem 5 dias
A40: ='Rateio Custos Fixos'!P3 -> IMPORT LOGIST FREE | F40: ='Rateio Custos Fixos'!P4 -> 300
A41: ='Rateio Custos Fixos'!Q3 -> DROP OFF | F41: ='Rateio Custos Fixos'!Q4 -> 320.33
A42: ='Rateio Custos Fixos'!R3 -> TAXA | F42: ='Rateio Custos Fixos'!R4 -> 200
A43: ='Rateio Custos Fixos'!S3 -> FRETE RODOVIÁRIO | F43: ='Rateio Custos Fixos'!S4 -> 4500
A44: COMISSÃO | F44: ='Rateio Custos Fixos'!T4 -> 8303.3
A45: ='Rateio Custos Fixos'!U3 -> DESEMBARAÇO ADUANEIRO | F45: ='Rateio Custos Fixos'!U4 -> 1300
A46: TOTAL VALOR DESEMBARAÇO ADUANEIRO | F46: =SUM(F30:F45) -> 23674.748
...

Sheet Lista de Compra
A2: Item | B2: Produto | C2: NCM | D2: II | E2: IPI | F2: PIS | G2: COFINS | H2: ICMS | I2: Quantidade | J2: Preço | K2: % Rateio Quantidade | L2: % Rateio Preço | M2: Preço Final
I3: =SUM(I4:I58) -> 11873 | J3: =SUM(J4:J58) -> 434.21 | M3: ='Est. Cust. Naci. 100%'!AJ5 -> 0
A4: 1 | B4: FLANGE 1" 150LBS LISO ASTM A105 GR WPB B16.5 RF | C4: 7307.93.00 | D4: 0.126 | E4: 0.0365 | F4: 0.021 | G4: 0.0965 | H4: 0.06 | I4: 200 | J4: 1.04 | K4: =I4/$I$3 -> 0.016844942 | L4: =J4/$J$3 -> 0.0023951544 | M4: ='Est. Cust. Naci. 100%'!AJ6 -> 8.0215377
A5: 2 | B5: FLANGE 1" 300LBS LISO ASTM A105 GR WPB B16.5 RF | C5: 7307.93.01 | D5: 0.126 | E5: 0.0365 | F5: 0.021 | G5: 0.0965 | H5: 0.06 | I5: 50 | J5: 1.84 | K5: =I5/$I$3 -> 0.0042112356 | L5: =J5/$J$3 -> 0.0042375809 | M5: ='Est. Cust. Naci. 100%'!AJ7 -> 17.983209
A6: 3 | B6: FLANGE 1.1/2" 150LBS LISO ASTM A105 GR WPB B16.5 | C6: 7307.93.02 | D6: 0.126 | E6: 0.0365 | F6: 0.021 | G6: 0.0965 | H6: 0.06 | I6: 800 | J6: 1.57 | K6: =I6/$I$3 -> 0.067379769 | L6: =J6/$J$3 -> 0.003615762 | M6: ='Est. Cust. Naci. 100%'!AJ8 -> 11.300704
A7: 4 | B7: FLANGE 1.1/2" 300LBS LISO ASTM A105 GR WPB B16.5 RF | C7: 7307.93.03 | D7: 0.126 | E7: 0.0365 | F7: 0.021 | G7: 0.0965 | H7: 0.06 | I7: 50 | J7: 2.72 | K7: =I7/$I$3 -> 0.0042112356 | L7: =J7/$J$3 -> 0.00626425 | M7: ='Est. Cust. Naci. 100%'!AJ9 -> 26.583874
A8: 5 | B8: FLANGE 1.1/4" 150LBS LISO ASTM A105 GR WPB B16.5 RF | C8: 7307.93.04 | D8: 0.126 | E8: 0.0365 | F8: 0.021 | G8: 0.0965 | H8: 0.06 | I8: 30 | J8: 1.36 | K8: =I8/$I$3 -> 0.0025267413 | L8: =J8/$J$3 -> 0.003132125 | M8: ='Est. Cust. Naci. 100%'!AJ10 -> 15.782811
A9: 6 | B9: FLANGE 2" 150LBS LISO ASTM A105 GR WPB B16.5 RF | C9: 7307.93.05 | D9: 0.126 | E9: 0.0365 | F9: 0.021 | G9: 0.0965 | H9: 0.06 | I9: 1500 | J9: 2.19 | K9: =I9/$I$3 -> 0.12633707 | L9: =J9/$J$3 -> 0.0050436425 | M9: ='Est. Cust. Naci. 100%'!AJ11 -> 15.587919
A10: 7 | B10: FLANGE 2" 300LBS LISO ASTM A105 GR WPB B16.5 RF | C10: 7307.93.06 | D10: 0.126 | E10: 0.0365 | F10: 0.021 | G10: 0.0965 | H10: 0.06 | I10: 400 | J10: 3.3 | K10: =I10/$I$3 -> 0.033689885 | L10: =J10/$J$3 -> 0.0076000092 | M10: ='Est. Cust. Naci. 100%'!AJ12 -> 24.3197
A11: 8 | B11: FLANGE 2.1/2" 150LBS LISO ASTM A105 GR WPB B16.5 RF | C11: 7307.93.07 | D11: 0.126 | E11: 0.0365 | F11: 0.021 | G11: 0.0965 | H11: 0.06 | I11: 50 | J11: 3.3 | K11: =I11/$I$3 -> 0.0042112356 | L11: =J11/$J$3 -> 0.0076000092 | M11: ='Est. Cust. Naci. 100%'!AJ13 -> 32.252494
A12: 9 | B12: FLANGE 2.1/2" 300LBS LISO ASTM A105 GR WPB B16.5 RF | C12: 7307.93.08 | D12: 0.126 | E12: 0.0365 | F12: 0.021 | G12: 0.0965 | H12: 0.06 | I12: 30 | J12: 5.33 | K12: =I12/$I$3 -> 0.0025267413 | L12: =J12/$J$3 -> 0.012275166 | M12: ='Est. Cust. Naci. 100%'!AJ14 -> 61.854695
A13: 10 | B13: FLANGE 3" 150LBS LISO ASTM A105 GR WPB B16.5 RF | C13: 7307.93.09 | D13: 0.126 | E13: 0.0365 | F13: 0.021 | G13: 0.0965 | H13: 0.06 | I13: 150 | J13: 3.87 | K13: =I13/$I$3 -> 0.012633707 | L13: =J13/$J$3 -> 0.0089127381 | M13: ='Est. Cust. Naci. 100%'!AJ15 -> 30.735376
A14: 11 | B14: FLANGE 4" 150LBS LISO ASTM A105 GR WPB B16.5 RF | C14: 7307.93.10 | D14: 0.126 | E14: 0.0365 | F14: 0.021 | G14: 0.0965 | H14: 0.06 | I14: 200 | J14: 5.43 | K14: =I14/$I$3 -> 0.016844942 | L14: =J14/$J$3 -> 0.01250547 | M14: ='Est. Cust. Naci. 100%'!AJ16 -> 41.881682
A15: 12 | B15: FLANGE 4" 300LBS LISO ASTM A105 GR WPB B16.5 RF | C15: 7307.93.11 | D15: 0.126 | E15: 0.0365 | F15: 0.021 | G15: 0.0965 | H15: 0.06 | I15: 60 | J15: 10.66 | K15: =I15/$I$3 -> 0.0050534827 | L15: =J15/$J$3 -> 0.024550333 | M15: ='Est. Cust. Naci. 100%'!AJ17 -> 99.304314
... A58: 55 | B58: FLANGE LISO ASTM A105 GR WPB B16.5 300 LBS 1/2" | C58: 7307.93.54 | D58: 0.126 | E58: 0.0365 | F58: 0.021 | G58: 0.0965 | H58: 0.06 | I58: 300 | J58: 1.25 | K58: =I58/$I$3 -> 0.025267413 | L58: =J58/$J$3 -> 0.0028787914 | M58: ='Est. Cust. Naci. 100%'!AJ60 -> 9.3550954

Sheet Est. Cust. Naci. 100%
B2: DETALHES DO PRODUTO | H2: VALOR ADUANEIRO | L2: IMPOSTOS | R2: TAXAS PORTUÁRIAS
B3: ITEM | C3: NCM | D3: QTD | E3: Participação % | F3: Preço unitário (USD) | G3: Preço x QTD (Valor em USD) | H3: Preço x QTD (valor em BRL) | I3: Valor do frete (Valor em BRL) | J3: TOTAL VALOR ADUANEIRO | K3: VALOR TOTAL + I.I | L3: IMPOSTO DE IMPORTAÇÃO | M3: IPI | N3: PIS | O3: COFINS | P3: ICMS | Q3: TOTAL IMPOSTOS | R3: TAXA SISCOMEX | S3: B/L | T3: T.H.C| CAPATAZIA | U3: ISPS | V3: DAMAGE PROTECTION | W3: DESCONSOLIDAÇÃO | X3: SERVIÇO DE ENTREGA DE CONTAINER | Y3: Delivery order | Z3: AFRMM | AA3: ARMAZENAGEM | AB3: Import logistic fee | AC3: Drop off | AD3: TAXA | AE3: FRETE RODOVIÁRIO | AF3: COMISSÃO | AG3: DESEMBARAÇO ADUANEIRO | AH3: TOTAL DESEMBARAÇO ADUANEIRO | AI3: TOTAL POR CATEGORIA | AJ3: VALOR UNITÁRIO
A4: Nº | H4: ='Rateio Custos Fixos'!B66 -> 5.14 | I4: ='Rateio Custos Fixos'!G67 -> 26313.97 | J4: =SUM(J5:J60) -> 206491.48 | L4: =SUM(L6:L60) -> 26017.926 | M4: =SUM(M6:M60) -> 8486.5933 | N4: =SUM(N6:N60) -> 4882.6975 | O4: =SUM(O6:O60) -> 22437.158 | P4: =SUM(P6:P60) -> 13950.564 | Q4: =SUM(L4:P4) -> 75774.939 | R4: =SUM(R6:R60) -> 350 | S4: =SUM(S6:S60) -> 1100 | T4: =SUM(T6:T60) -> 1500 | U4: =SUM(U6:U60) -> 100 | V4: =SUM(V6:V60) -> 180 | W4: =SUM(W6:W60) -> 490 | X4: =SUM(X6:X60) -> 1060 | Y4: =SUM(Y6:Y60) -> 366 | Z4: 0.08 | AA4: =SUM(AA6:AA60) -> 1500 | AB4: =SUM(AB6:AB60) -> 300 | AC4: =SUM(AC6:AC60) -> 320.33 | AD4: =SUM(AD6:AD60) -> 200 | AE4: =SUM(AE6:AE60) -> 4500 | AF4: =SUM(AF6:AF60) -> 8303.3 | AG4: =SUM(AG6:AG60) -> 1300 | AH4: =SUM(R4:AG4) -> 21569.71
A5: AAA | D5: =SUM(D6:D60) -> 11873 | F5: =SUM(F6:F60) -> 434.21 | G5: =SUM(G6:G60) -> 35053.99 | H5: =SUM(H6:H60) -> 180177.51 | L5: ='Lista de Compra'!D4 -> 0.126 | M5: ='Lista de Compra'!E4 -> 0.0365 | N5: ='Lista de Compra'!F4 -> 0.021 | O5: ='Lista de Compra'!G4 -> 0.0965 | P5: ='Lista de Compra'!H4 -> 0.06
A6: ='Lista de Compra'!A7 -> 4 | B6: ='Lista de Compra'!B4 -> FLANGE 1" 150LBS LISO ASTM A105 GR WPB B16.5 RF | C6: ='Lista de Compra'!C4 -> 7307.93.00 | D6: ='Lista de Compra'!I4 -> 200 | E6: ='Lista de Compra'!L4 -> 0.0023951544 | F6: ='Lista de Compra'!J4 -> 1.04 | G6: =D6*F6 -> 208 | H6: =G6*$H$4 -> 1069.12 | I6: ='Rateio Custos Fixos'!E5 -> 63.026022 | J6: =SUM(H6:I6) -> 1132.146 | K6: =J6+L6 -> 1274.7964 | L6: =L$5*$J6 -> 142.6504 | M6: =M$5*$K6 -> 46.530069 | N6: =N$5*$K6 -> 26.770725 | O6: =O$5*$K6 -> 123.01785 | P6: =P$5*$K6 -> 76.487785 | Q6: =SUM(L6:P6) -> 415.45683 | R6: ='Rateio Custos Fixos'!F5 -> 0.83830405 | S6: ='Rateio Custos Fixos'!G5 -> 2.6346699 | T6: ='Rateio Custos Fixos'!H5 -> 3.5927316 | U6: ='Rateio Custos Fixos'!I5 -> 0.23951544 | V6: ='Rateio Custos Fixos'!J5 -> 0.4311278 | W6: ='Rateio Custos Fixos'!K5 -> 1.1736257 | X6: ='Rateio Custos Fixos'!L5 -> 2.5388637 | Y6: ='Rateio Custos Fixos'!M5 -> 0.87662652 | ... AG6: ='Rateio Custos Fixos'!U5 -> 3.1137007 | AH6: =SUM(R6:AG6) -> 56.704676 | AI6: =J6+Q6+AH6 -> 1604.3075 | AJ6: =AI6/D6 -> 8.0215377
B7: ='Lista de Compra'!B5 -> FLANGE 1" 300LBS LISO ASTM A105 GR WPB B16.5 RF | C7: ='Lista de Compra'!C5 -> 7307.93.01 | D7: ='Lista de Compra'!I5 -> 50 | E7: ='Lista de Compra'!L5 -> 0.0042375809 | F7: ='Lista de Compra'!J5 -> 1.84 | G7: =D7*F7 -> 92 | H7: =G7*$H$4 -> 472.88 | I7: ='Rateio Custos Fixos'!E6 -> 111.50758 | J7: =SUM(H7:I7) -> 584.38758 | K7: =J7+L7 -> 658.02041 | L7: =L$5*$J7 -> 73.632835 | M7: =M$5*$K7 -> 24.017745 | N7: =N$5*$K7 -> 13.818429 | O7: =O$5*$K7 -> 63.49897 | P7: =P$5*$K7 -> 39.481225 | Q7: =SUM(L7:P7) -> 214.4492 | R7: ='Rateio Custos Fixos'!F6 -> 1.4831533 | S7: ='Rateio Custos Fixos'!G6 -> 4.661339 | T7: ='Rateio Custos Fixos'!H6 -> 6.3563713 | U7: ='Rateio Custos Fixos'!I6 -> 0.42375809 | V7: ='Rateio Custos Fixos'!J6 -> 0.76276456 | W7: ='Rateio Custos Fixos'!K6 -> 2.0764146 | X7: ='Rateio Custos Fixos'!L6 -> 4.4918357 | Y7: ='Rateio Custos Fixos'!M6 -> 1.5509546 | ... AG7: ='Rateio Custos Fixos'!U6 -> 5.5088552 | AH7: =SUM(R7:AG7) -> 100.32366 | AI7: =J7+Q7+AH7 -> 899.16044 | AJ7: =AI7/D7 -> 17.983209
B8: ='Lista de Compra'!B6 -> FLANGE 1.1/2" 150LBS LISO ASTM A105 GR WPB B16.5 | C8: ='Lista de Compra'!C6 -> 7307.93.02 | D8: ='Lista de Compra'!I6 -> 800 | E8: ='Lista de Compra'!L6 -> 0.003615762 | F8: ='Lista de Compra'!J6 -> 1.57 | G8: =D8*F8 -> 1256 | H8: =G8*$H$4 -> 6455.84 | I8: ='Rateio Custos Fixos'!E7 -> 95.145052 | J8: =SUM(H8:I8) -> 6550.9851 | K8: =J8+L8 -> 7376.4092 | L8: =L$5*$J8 -> 825.42412 | M8: =M$5*$K8 -> 269.23893 | N8: =N$5*$K8 -> 154.90459 | O8: =O$5*$K8 -> 711.82348 | P8: =P$5*$K8 -> 442.58455 | Q8: =SUM(L8:P8) -> 2403.9757 | R8: ='Rateio Custos Fixos'!F7 -> 1.2655167 | S8: ='Rateio Custos Fixos'!G7 -> 3.9773382 | T8: ='Rateio Custos Fixos'!H7 -> 5.4236429 | U8: ='Rateio Custos Fixos'!I7 -> 0.3615762 | V8: ='Rateio Custos Fixos'!J7 -> 0.65083715 | W8: ='Rateio Custos Fixos'!K7 -> 1.7717234 | X8: ='Rateio Custos Fixos'!L7 -> 3.8327077 | Y8: ='Rateio Custos Fixos'!M7 -> 1.3233689 | ... AG8: ='Rateio Custos Fixos'!U7 -> 4.7004905 | AH8: =SUM(R8:AG8) -> 85.602252 | AI8: =J8+Q8+AH8 -> 9040.563 | AJ8: =AI8/D8 -> 11.300704
B9: ='Lista de Compra'!B7 -> FLANGE 1.1/2" 300LBS LISO ASTM A105 GR WPB B16.5 RF | C9: ='Lista de Compra'!C7 -> 7307.93.03 | D9: ='Lista de Compra'!I7 -> 50 | E9: ='Lista de Compra'!L7 -> 0.00626425 | F9: ='Lista de Compra'!J7 -> 2.72 | G9: =D9*F9 -> 136 | H9: =G9*$H$4 -> 699.04 | I9: ='Rateio Custos Fixos'!E8 -> 164.83729 | J9: =SUM(H9:I9) -> 863.87729 | K9: =J9+L9 -> 972.72583 | L9: =L$5*$J9 -> 108.84854 | M9: =M$5*$K9 -> 35.504493 | N9: =N$5*$K9 -> 20.427242 | O9: =O$5*$K9 -> 93.868042 | P9: =P$5*$K9 -> 58.36355 | Q9: =SUM(L9:P9) -> 317.01186 | R9: ='Rateio Custos Fixos'!F8 -> 2.1924875 | S9: ='Rateio Custos Fixos'!G8 -> 6.890675 | T9: ='Rateio Custos Fixos'!H8 -> 9.396375 | U9: ='Rateio Custos Fixos'!I8 -> 0.626425 | V9: ='Rateio Custos Fixos'!J8 -> 1.127565 | W9: ='Rateio Custos Fixos'!K8 -> 3.0694825 | X9: ='Rateio Custos Fixos'!L8 -> 6.640105 | Y9: ='Rateio Custos Fixos'!M8 -> 2.2927155 | ... AG9: ='Rateio Custos Fixos'!U8 -> 8.143525 | AH9: =SUM(R9:AG9) -> 148.30454 | AI9: =J9+Q9+AH9 -> 1329.1937 | AJ9: =AI9/D9 -> 26.583874
B10: ='Lista de Compra'!B8 -> FLANGE 1.1/4" 150LBS LISO ASTM A105 GR WPB B16.5 RF | C10: ='Lista de Compra'!C8 -> 7307.93.04 | D10: ='Lista de Compra'!I8 -> 30 | E10: ='Lista de Compra'!L8 -> 0.003132125 | F10: ='Lista de Compra'!J8 -> 1.36 | G10: =D10*F10 -> 40.8 | H10: =G10*$H$4 -> 209.712 | I10: ='Rateio Custos Fixos'!E9 -> 82.418644 | J10: =SUM(H10:I10) -> 292.13064 | K10: =J10+L10 -> 328.9391 | L10: =L$5*$J10 -> 36.808461 | M10: =M$5*$K10 -> 12.006277 | N10: =N$5*$K10 -> 6.9077212 | O10: =O$5*$K10 -> 31.742624 | P10: =P$5*$K10 -> 19.736346 | Q10: =SUM(L10:P10) -> 107.20143 | R10: ='Rateio Custos Fixos'!F9 -> 1.0962438 | S10: ='Rateio Custos Fixos'!G9 -> 3.4453375 | T10: ='Rateio Custos Fixos'!H9 -> 4.6981875 | U10: ='Rateio Custos Fixos'!I9 -> 0.3132125 | V10: ='Rateio Custos Fixos'!J9 -> 0.5637825 | W10: ='Rateio Custos Fixos'!K9 -> 1.5347413 | X10: ='Rateio Custos Fixos'!L9 -> 3.3200525 | Y10: ='Rateio Custos Fixos'!M9 -> 1.1463578 | ... AG10: ='Rateio Custos Fixos'!U9 -> 4.0717625 | AH10: =SUM(R10:AG10) -> 74.152269 | AI10: =J10+Q10+AH10 -> 473.48434 | AJ10: =AI10/D10 -> 15.782811
B11: ='Lista de Compra'!B9 -> FLANGE 2" 150LBS LISO ASTM A105 GR WPB B16.5 RF | C11: ='Lista de Compra'!C9 -> 7307.93.05 | D11: ='Lista de Compra'!I9 -> 1500 | E11: ='Lista de Compra'!L9 -> 0.0050436425 | F11: ='Lista de Compra'!J9 -> 2.19 | G11: =D11*F11 -> 3285 | H11: =G11*$H$4 -> 16884.9 | I11: ='Rateio Custos Fixos'!E10 -> 132.71826 | J11: =SUM(H11:I11) -> 17017.618 | K11: =J11+L11 -> 19161.838 | L11: =L$5*$J11 -> 2144.2199 | M11: =M$5*$K11 -> 699.40709 | N11: =N$5*$K11 -> 402.3986 | O11: =O$5*$K11 -> 1849.1174 | P11: =P$5*$K11 -> 1149.7103 | Q11: =SUM(L11:P11) -> 6244.8533 | R11: ='Rateio Custos Fixos'!F10 -> 1.7652749 | S11: ='Rateio Custos Fixos'!G10 -> 5.5480067 | T11: ='Rateio Custos Fixos'!H10 -> 7.5654637 | U11: ='Rateio Custos Fixos'!I10 -> 0.50436425 | V11: ='Rateio Custos Fixos'!J10 -> 0.90785565 | W11: ='Rateio Custos Fixos'!K10 -> 2.4713848 | X11: ='Rateio Custos Fixos'!L10 -> 5.346261 | Y11: ='Rateio Custos Fixos'!M10 -> 1.8459731 | ... AG11: ='Rateio Custos Fixos'!U10 -> 6.5567352 | AH11: =SUM(R11:AG11) -> 119.40696 | AI11: =J11+Q11+AH11 -> 23381.878 | AJ11: =AI11/D11 -> 15.587919
B12: ='Lista de Compra'!B10 -> FLANGE 2" 300LBS LISO ASTM A105 GR WPB B16.5 RF | C12: ='Lista de Compra'!C10 -> 7307.93.06 | D12: ='Lista de Compra'!I10 -> 400 | E12: ='Lista de Compra'!L10 -> 0.0076000092 | F12: ='Lista de Compra'!J10 -> 3.3 | G12: =D12*F12 -> 1320 | H12: =G12*$H$4 -> 6784.8 | I12: ='Rateio Custos Fixos'!E11 -> 199.98641 | J12: =SUM(H12:I12) -> 6984.7864 | K12: =J12+L12 -> 7864.8695 | L12: =L$5*$J12 -> 880.08309 | M12: =M$5*$K12 -> 287.06774 | N12: =N$5*$K12 -> 165.16226 | O12: =O$5*$K12 -> 758.95991 | P12: =P$5*$K12 -> 471.89217 | Q12: =SUM(L12:P12) -> 2563.1652 | R12: ='Rateio Custos Fixos'!F11 -> 2.6600032 | S12: ='Rateio Custos Fixos'!G11 -> 8.3600101 | T12: ='Rateio Custos Fixos'!H11 -> 11.400014 | U12: ='Rateio Custos Fixos'!I11 -> 0.76000092 | V12: ='Rateio Custos Fixos'!J11 -> 1.3680017 | W12: ='Rateio Custos Fixos'!K11 -> 3.7240045 | X12: ='Rateio Custos Fixos'!L11 -> 8.0560098 | Y12: ='Rateio Custos Fixos'!M11 -> 2.7816034 | ... AG12: ='Rateio Custos Fixos'!U11 -> 9.880012 | AH12: =SUM(R12:AG12) -> 179.9283 | AI12: =J12+Q12+AH12 -> 9727.8799 | AJ12: =AI12/D12 -> 24.3197
B13: ='Lista de Compra'!B11 -> FLANGE 2.1/2" 150LBS LISO ASTM A105 GR WPB B16.5 RF | C13: ='Lista de Compra'!C11 -> 7307.93.07 | D13: ='Lista de Compra'!I11 -> 50 | E13: ='Lista de Compra'!L11 -> 0.0076000092 | F13: ='Lista de Compra'!J11 -> 3.3 | G13: =D13*F13 -> 165 | H13: =G13*$H$4 -> 848.1 | I13: ='Rateio Custos Fixos'!E12 -> 199.98641 | J13: =SUM(H13:I13) -> 1048.0864 | K13: =J13+L13 -> 1180.1453 | L13: =L$5*$J13 -> 132.05889 | M13: =M$5*$K13 -> 43.075304 | N13: =N$5*$K13 -> 24.783051 | O13: =O$5*$K13 -> 113.88402 | P13: =P$5*$K13 -> 70.808718 | Q13: =SUM(L13:P13) -> 384.60998 | R13: ='Rateio Custos Fixos'!F12 -> 2.6600032 | S13: ='Rateio Custos Fixos'!G12 -> 8.3600101 | T13: ='Rateio Custos Fixos'!H12 -> 11.400014 | U13: ='Rateio Custos Fixos'!I12 -> 0.76000092 | V13: ='Rateio Custos Fixos'!J12 -> 1.3680017 | W13: ='Rateio Custos Fixos'!K12 -> 3.7240045 | X13: ='Rateio Custos Fixos'!L12 -> 8.0560098 | Y13: ='Rateio Custos Fixos'!M12 -> 2.7816034 | ... AG13: ='Rateio Custos Fixos'!U12 -> 9.880012 | AH13: =SUM(R13:AG13) -> 179.9283 | AI13: =J13+Q13+AH13 -> 1612.6247 | AJ13: =AI13/D13 -> 32.252494
B14: ='Lista de Compra'!B12 -> FLANGE 2.1/2" 300LBS LISO ASTM A105 GR WPB B16.5 RF | C14: ='Lista de Compra'!C12 -> 7307.93.08 | D14: ='Lista de Compra'!I12 -> 30 | E14: ='Lista de Compra'!L12 -> 0.012275166 | F14: ='Lista de Compra'!J12 -> 5.33 | G14: =D14*F14 -> 159.9 | H14: =G14*$H$4 -> 821.886 | I14: ='Rateio Custos Fixos'!E13 -> 323.00836 | J14: =SUM(H14:I14) -> 1144.8944 | K14: =J14+L14 -> 1289.151 | L14: =L$5*$J14 -> 144.25669 | M14: =M$5*$K14 -> 47.054013 | N14: =N$5*$K14 -> 27.072172 | O14: =O$5*$K14 -> 124.40308 | P14: =P$5*$K14 -> 77.349063 | Q14: =SUM(L14:P14) -> 420.13501 | R14: ='Rateio Custos Fixos'!F13 -> 4.2963082 | S14: ='Rateio Custos Fixos'!G13 -> 13.502683 | T14: ='Rateio Custos Fixos'!H13 -> 18.41275 | U14: ='Rateio Custos Fixos'!I13 -> 1.2275166 | V14: ='Rateio Custos Fixos'!J13 -> 2.20953 | W14: ='Rateio Custos Fixos'!K13 -> 6.0148315 | X14: ='Rateio Custos Fixos'!L13 -> 13.011676 | Y14: ='Rateio Custos Fixos'!M13 -> 4.4927109 | ... AG14: ='Rateio Custos Fixos'!U13 -> 15.957716 | AH14: =SUM(R14:AG14) -> 290.61147 | AI14: =J14+Q14+AH14 -> 1855.6408 | AJ14: =AI14/D14 -> 61.854695
B15: ='Lista de Compra'!B13 -> FLANGE 3" 150LBS LISO ASTM A105 GR WPB B16.5 RF | C15: ='Lista de Compra'!C13 -> 7307.93.09 | D15: ='Lista de Compra'!I13 -> 150 | E15: ='Lista de Compra'!L13 -> 0.0089127381 | F15: ='Lista de Compra'!J13 -> 3.87 | G15: =D15*F15 -> 580.5 | H15: =G15*$H$4 -> 2983.77 | I15: ='Rateio Custos Fixos'!E14 -> 234.52952 | J15: =SUM(H15:I15) -> 3218.2995 | K15: =J15+L15 -> 3623.8053 | L15: =L$5*$J15 -> 405.50574 | M15: =M$5*$K15 -> 132.26889 | N15: =N$5*$K15 -> 76.099911 | O15: =O$5*$K15 -> 349.69721 | P15: =P$5*$K15 -> 217.42832 | Q15: =SUM(L15:P15) -> 1181.0001 | R15: ='Rateio Custos Fixos'!F14 -> 3.1194583 | S15: ='Rateio Custos Fixos'!G14 -> 9.8040119 | T15: ='Rateio Custos Fixos'!H14 -> 13.369107 | U15: ='Rateio Custos Fixos'!I14 -> 0.89127381 | V15: ='Rateio Custos Fixos'!J14 -> 1.6042929 | W15: ='Rateio Custos Fixos'!K14 -> 4.3672417 | X15: ='Rateio Custos Fixos'!L14 -> 9.4475024 | Y15: ='Rateio Custos Fixos'!M14 -> 3.2620621 | ... AG15: ='Rateio Custos Fixos'!U14 -> 11.586559 | AH15: =SUM(R15:AG15) -> 211.00682 | AI15: =J15+Q15+AH15 -> 4610.3064 | AJ15: =AI15/D15 -> 30.735376
B16: ='Lista de Compra'!B14 -> FLANGE 4" 150LBS LISO ASTM A105 GR WPB B16.5 RF | C16: ='Lista de Compra'!C14 -> 7307.93.10 | D16: ='Lista de Compra'!I14 -> 200 | E16: ='Lista de Compra'!L14 -> 0.01250547 | F16: ='Lista de Compra'!J14 -> 5.43 | G16: =D16*F16 -> 1086 | H16: =G16*$H$4 -> 5582.04 | I16: ='Rateio Custos Fixos'!E15 -> 329.06855 | J16: =SUM(H16:I16) -> 5911.1086 | K16: =J16+L16 -> 6655.9082 | L16: =L$5*$J16 -> 744.79968 | M16: =M$5*$K16 -> 242.94065 | N16: =N$5*$K16 -> 139.77407 | O16: =O$5*$K16 -> 642.29514 | P16: =P$5*$K16 -> 399.35449 | Q16: =SUM(L16:P16) -> 2169.164 | R16: ='Rateio Custos Fixos'!F15 -> 4.3769144 | S16: ='Rateio Custos Fixos'!G15 -> 13.756017 | T16: ='Rateio Custos Fixos'!H15 -> 18.758205 | U16: ='Rateio Custos Fixos'!I15 -> 1.250547 | V16: ='Rateio Custos Fixos'!J15 -> 2.2509845 | W16: ='Rateio Custos Fixos'!K15 -> 6.1276802 | X16: ='Rateio Custos Fixos'!L15 -> 13.255798 | Y16: ='Rateio Custos Fixos'!M15 -> 4.5770019 | ... AG16: ='Rateio Custos Fixos'!U15 -> 16.257111 | AH16: =SUM(R16:AG16) -> 296.06384 | AI16: =J16+Q16+AH16 -> 8376.3364 | AJ16: =AI16/D16 -> 41.881682
B17: ='Lista de Compra'!B15 -> FLANGE 4" 300LBS LISO ASTM A105 GR WPB B16.5 RF | C17: ='Lista de Compra'!C15 -> 7307.93.11 | D17: ='Lista de Compra'!I15 -> 60 | E17: ='Lista de Compra'!L15 -> 0.024550333 | F17: ='Lista de Compra'!J15 -> 10.66 | G17: =D17*F17 -> 639.6 | H17: =G17*$H$4 -> 3287.544 | I17: ='Rateio Custos Fixos'!E16 -> 646.01672 | J17: =SUM(H17:I17) -> 3933.5607 | K17: =J17+L17 -> 4429.1894 | L17: =L$5*$J17 -> 495.62865 | M17: =M$5*$K17 -> 161.66541 | N17: =N$5*$K17 -> 93.012977 | O17: =O$5*$K17 -> 427.41677 | P17: =P$5*$K17 -> 265.75136 | Q17: =SUM(L17:P17) -> 1443.4752 | R17: ='Rateio Custos Fixos'!F16 -> 8.5926165 | S17: ='Rateio Custos Fixos'!G16 -> 27.005366 | T17: ='Rateio Custos Fixos'!H16 -> 36.825499 | U17: ='Rateio Custos Fixos'!I16 -> 2.4550333 | V17: ='Rateio Custos Fixos'!J16 -> 4.4190599 | W17: ='Rateio Custos Fixos'!K16 -> 12.029663 | X17: ='Rateio Custos Fixos'!L16 -> 26.023353 | Y17: ='Rateio Custos Fixos'!M16 -> 8.9854218 | ... AG17: ='Rateio Custos Fixos'!U16 -> 31.915433 | AH17: =SUM(R17:AG17) -> 581.22293 | AI17: =J17+Q17+AH17 -> 5958.2588 | AJ17: =AI17/D17 -> 99.304314
B18: ='Lista de Compra'!B16 -> CURVA 1.1/2" SCH40 RL 90° ASTM A-234 ASME B16.9 | C18: ='Lista de Compra'!C16 -> 7307.93.12 | D18: ='Lista de Compra'!I16 -> 1300 | E18: ='Lista de Compra'!L16 -> 0.00092121324 | F18: ='Lista de Compra'!J16 -> 0.4 | G18: =D18*F18 -> 520 | H18: =G18*$H$4 -> 2672.8 | I18: ='Rateio Custos Fixos'!E17 -> 24.240778 | J18: =SUM(H18:I18) -> 2697.0408 | K18: =J18+L18 -> 3036.8679 | L18: =L$5*$J18 -> 339.82714 | M18: =M$5*$K18 -> 110.84568 | N18: =N$5*$K18 -> 63.774226 | O18: =O$5*$K18 -> 293.05775 | P18: =P$5*$K18 -> 182.21207 | Q18: =SUM(L18:P18) -> 989.71687 | R18: ='Rateio Custos Fixos'!F17 -> 0.32242463 | S18: ='Rateio Custos Fixos'!G17 -> 1.0133346 | T18: ='Rateio Custos Fixos'!H17 -> 1.3818199 | U18: ='Rateio Custos Fixos'!I17 -> 0.092121324 | V18: ='Rateio Custos Fixos'!J17 -> 0.16581838 | W18: ='Rateio Custos Fixos'!K17 -> 0.45139449 | X18: ='Rateio Custos Fixos'!L17 -> 0.97648603 | Y18: ='Rateio Custos Fixos'!M17 -> 0.33716405 | ... AG18: ='Rateio Custos Fixos'!U17 -> 1.1975772 | AH18: =SUM(R18:AG18) -> 21.809491 | AI18: =J18+Q18+AH18 -> 3708.5671 | AJ18: =AI18/D18 -> 2.852744
... B60: ='Lista de Compra'!B58 -> FLANGE LISO ASTM A105 GR WPB B16.5 300 LBS 1/2" | C60: ='Lista de Compra'!C58 -> 7307.93.54 | D60: ='Lista de Compra'!I58 -> 300 | E60: ='Lista de Compra'!L58 -> 0.0028787914 | F60: ='Lista de Compra'!J58 -> 1.25 | G60: =D60*F60 -> 375 | H60: =G60*$H$4 -> 1927.5 | I60: ='Rateio Custos Fixos'!E59 -> 75.75243 | J60: =SUM(H60:I60) -> 2003.2524 | K60: =J60+L60 -> 2255.6622 | L60: =L$5*$J60 -> 252.40981 | M60: =M$5*$K60 -> 82.331672 | N60: =N$5*$K60 -> 47.368907 | O60: =O$5*$K60 -> 217.67141 | P60: =P$5*$K60 -> 135.33973 | Q60: =SUM(L60:P60) -> 735.12152 | R60: ='Rateio Custos Fixos'!F59 -> 1.007577 | S60: ='Rateio Custos Fixos'!G59 -> 3.1666705 | T60: ='Rateio Custos Fixos'!H59 -> 4.3181871 | U60: ='Rateio Custos Fixos'!I59 -> 0.28787914 | V60: ='Rateio Custos Fixos'!J59 -> 0.51818245 | W60: ='Rateio Custos Fixos'!K59 -> 1.4106078 | X60: ='Rateio Custos Fixos'!L59 -> 3.0515189 | Y60: ='Rateio Custos Fixos'!M59 -> 1.0536376 | ... AG60: ='Rateio Custos Fixos'!U59 -> 3.7424288 | AH60: =SUM(R60:AG60) -> 68.154659 | AI60: =J60+Q60+AH60 -> 2806.5286 | AJ60: =AI60/D60 -> 9.3550954

Sheet Rateio Custos Fixos
N2: =SUM(N5:N59) -> 2105.1176
A3: Produto | B3: Quantidade | C3: ='Lista de Compra'!K2 -> % Rateio Quantidade | E3: FRETE | F3: TAXA SISCOMEX | G3: B/L | H3: T.H.C| CAPATAZIA | I3: ISPS | J3: DAMAGE PROTECTION | K3: DESCONSOLIDAÇÃO | L3: SERVIÇO DE ENTREGA DE CONTAINER | M3: DELIVERY ORDER | N3: AFRMM | O3: ARMAZENAGEM | P3: IMPORT LOGIST FREE | Q3: DROP OFF | R3: TAXA | S3: FRETE RODOVIÁRIO | T3: Comissão | U3: DESEMBARAÇO ADUANEIRO
B4: =SUM(B5:B64) -> 11873 | C4: =SUM(C5:C64) -> 1 | E4: =G67 -> 26313.97 | F4: 350 | G4: 1100 | H4: 1500 | I4: 100 | J4: 180 | K4: 490 | L4: 1060 | M4: 366 | N4: 0.08 | O4: 1500 | P4: 300 | Q4: 320.33 | R4: 200 | S4: 4500 | T4: 8303.3 | U4: 1300 | V4: =SUM(F4:U4) -> 21569.71
A5: ='Lista de Compra'!A4 -> 1 | B5: ='Lista de Compra'!I4 -> 200 | C5: ='Lista de Compra'!L4 -> 0.0023951544 | E5: =E$4*$C5 -> 63.026022 | F5: =F$4*$C5 -> 0.83830405 | G5: =G$4*$C5 -> 2.6346699 | H5: =H$4*$C5 -> 3.5927316 | I5: =I$4*$C5 -> 0.23951544 | J5: =J$4*$C5 -> 0.4311278 | K5: =K$4*$C5 -> 1.1736257 | L5: =L$4*$C5 -> 2.5388637 | M5: =M$4*$C5 -> 0.87662652 | N5: =$N$4*E5 -> 5.0420817 | O5: =O$4*$C5 -> 3.5927316 | P5: =P$4*$C5 -> 0.71854633 | Q5: =Q$4*$C5 -> 0.76723981 | R5: =R$4*$C5 -> 0.47903088 | S5: =S$4*$C5 -> 10.778195 | T5: =T$4*C5 -> 19.887686 | U5: =U$4*$C5 -> 3.1137007 | V5: =SUM(F5:U5) -> 56.704676
A6: ='Lista de Compra'!A5 -> 2 | B6: ='Lista de Compra'!I5 -> 50 | C6: ='Lista de Compra'!L5 -> 0.0042375809 | E6: =E$4*$C6 -> 111.50758 | F6: =F$4*$C6 -> 1.4831533 | G6: =G$4*$C6 -> 4.661339 | H6: =H$4*$C6 -> 6.3563713 | I6: =I$4*$C6 -> 0.42375809 | J6: =J$4*$C6 -> 0.76276456 | K6: =K$4*$C6 -> 2.0764146 | L6: =L$4*$C6 -> 4.4918357 | M6: =M$4*$C6 -> 1.5509546 | N6: =$N$4*E6 -> 8.9206061 | O6: =O$4*$C6 -> 6.3563713 | P6: =P$4*$C6 -> 1.2712743 | Q6: =Q$4*$C6 -> 1.3574243 | R6: =R$4*$C6 -> 0.84751618 | S6: =S$4*$C6 -> 19.069114 | T6: =T$4*C6 -> 35.185905 | U6: =U$4*$C6 -> 5.5088552 | V6: =SUM(F6:U6) -> 100.32366
A7: ='Lista de Compra'!A6 -> 3 | B7: ='Lista de Compra'!I6 -> 800 | C7: ='Lista de Compra'!L6 -> 0.003615762 | E7: =E$4*$C7 -> 95.145052 | F7: =F$4*$C7 -> 1.2655167 | G7: =G$4*$C7 -> 3.9773382 | H7: =H$4*$C7 -> 5.4236429 | I7: =I$4*$C7 -> 0.3615762 | J7: =J$4*$C7 -> 0.65083715 | K7: =K$4*$C7 -> 1.7717234 | L7: =L$4*$C7 -> 3.8327077 | M7: =M$4*$C7 -> 1.3233689 | N7: =$N$4*E7 -> 7.6116041 | O7: =O$4*$C7 -> 5.4236429 | P7: =P$4*$C7 -> 1.0847286 | Q7: =Q$4*$C7 -> 1.158237 | R7: =R$4*$C7 -> 0.72315239 | S7: =S$4*$C7 -> 16.270929 | T7: =T$4*C7 -> 30.022756 | U7: =U$4*$C7 -> 4.7004905 | V7: =SUM(F7:U7) -> 85.602252
A8: ='Lista de Compra'!A7 -> 4 | B8: ='Lista de Compra'!I7 -> 50 | C8: ='Lista de Compra'!L7 -> 0.00626425 | E8: =E$4*$C8 -> 164.83729 | F8: =F$4*$C8 -> 2.1924875 | G8: =G$4*$C8 -> 6.890675 | H8: =H$4*$C8 -> 9.396375 | I8: =I$4*$C8 -> 0.626425 | J8: =J$4*$C8 -> 1.127565 | K8: =K$4*$C8 -> 3.0694825 | L8: =L$4*$C8 -> 6.640105 | M8: =M$4*$C8 -> 2.2927155 | N8: =$N$4*E8 -> 13.186983 | O8: =O$4*$C8 -> 9.396375 | P8: =P$4*$C8 -> 1.879275 | Q8: =Q$4*$C8 -> 2.0066272 | R8: =R$4*$C8 -> 1.25285 | S8: =S$4*$C8 -> 28.189125 | T8: =T$4*C8 -> 52.013947 | U8: =U$4*$C8 -> 8.143525 | V8: =SUM(F8:U8) -> 148.30454
A9: ='Lista de Compra'!A8 -> 5 | B9: ='Lista de Compra'!I8 -> 30 | C9: ='Lista de Compra'!L8 -> 0.003132125 | E9: =E$4*$C9 -> 82.418644 | F9: =F$4*$C9 -> 1.0962438 | G9: =G$4*$C9 -> 3.4453375 | H9: =H$4*$C9 -> 4.6981875 | I9: =I$4*$C9 -> 0.3132125 | J9: =J$4*$C9 -> 0.5637825 | K9: =K$4*$C9 -> 1.5347413 | L9: =L$4*$C9 -> 3.3200525 | M9: =M$4*$C9 -> 1.1463578 | N9: =$N$4*E9 -> 6.5934915 | O9: =O$4*$C9 -> 4.6981875 | P9: =P$4*$C9 -> 0.9396375 | Q9: =Q$4*$C9 -> 1.0033136 | R9: =R$4*$C9 -> 0.626425 | S9: =S$4*$C9 -> 14.094563 | T9: =T$4*C9 -> 26.006974 | U9: =U$4*$C9 -> 4.0717625 | V9: =SUM(F9:U9) -> 74.152269
A10: ='Lista de Compra'!A9 -> 6 | B10: ='Lista de Compra'!I9 -> 1500 | C10: ='Lista de Compra'!L9 -> 0.0050436425 | E10: =E$4*$C10 -> 132.71826 | F10: =F$4*$C10 -> 1.7652749 | G10: =G$4*$C10 -> 5.5480067 | H10: =H$4*$C10 -> 7.5654637 | I10: =I$4*$C10 -> 0.50436425 | J10: =J$4*$C10 -> 0.90785565 | K10: =K$4*$C10 -> 2.4713848 | L10: =L$4*$C10 -> 5.346261 | M10: =M$4*$C10 -> 1.8459731 | N10: =$N$4*E10 -> 10.617461 | O10: =O$4*$C10 -> 7.5654637 | P10: =P$4*$C10 -> 1.5130927 | Q10: =Q$4*$C10 -> 1.61563 | R10: =R$4*$C10 -> 1.0087285 | S10: =S$4*$C10 -> 22.696391 | T10: =T$4*C10 -> 41.878877 | U10: =U$4*$C10 -> 6.5567352 | V10: =SUM(F10:U10) -> 119.40696
A11: ='Lista de Compra'!A10 -> 7 | B11: ='Lista de Compra'!I10 -> 400 | C11: ='Lista de Compra'!L10 -> 0.0076000092 | E11: =E$4*$C11 -> 199.98641 | F11: =F$4*$C11 -> 2.6600032 | G11: =G$4*$C11 -> 8.3600101 | H11: =H$4*$C11 -> 11.400014 | I11: =I$4*$C11 -> 0.76000092 | J11: =J$4*$C11 -> 1.3680017 | K11: =K$4*$C11 -> 3.7240045 | L11: =L$4*$C11 -> 8.0560098 | M11: =M$4*$C11 -> 2.7816034 | N11: =$N$4*E11 -> 15.998913 | O11: =O$4*$C11 -> 11.400014 | P11: =P$4*$C11 -> 2.2800028 | Q11: =Q$4*$C11 -> 2.434511 | R11: =R$4*$C11 -> 1.5200018 | S11: =S$4*$C11 -> 34.200041 | T11: =T$4*C11 -> 63.105156 | U11: =U$4*$C11 -> 9.880012 | V11: =SUM(F11:U11) -> 179.9283
A12: ='Lista de Compra'!A11 -> 8 | B12: ='Lista de Compra'!I11 -> 50 | C12: ='Lista de Compra'!L11 -> 0.0076000092 | E12: =E$4*$C12 -> 199.98641 | F12: =F$4*$C12 -> 2.6600032 | G12: =G$4*$C12 -> 8.3600101 | H12: =H$4*$C12 -> 11.400014 | I12: =I$4*$C12 -> 0.76000092 | J12: =J$4*$C12 -> 1.3680017 | K12: =K$4*$C12 -> 3.7240045 | L12: =L$4*$C12 -> 8.0560098 | M12: =M$4*$C12 -> 2.7816034 | N12: =$N$4*E12 -> 15.998913 | O12: =O$4*$C12 -> 11.400014 | P12: =P$4*$C12 -> 2.2800028 | Q12: =Q$4*$C12 -> 2.434511 | R12: =R$4*$C12 -> 1.5200018 | S12: =S$4*$C12 -> 34.200041 | T12: =T$4*C12 -> 63.105156 | U12: =U$4*$C12 -> 9.880012 | V12: =SUM(F12:U12) -> 179.9283
A13: ='Lista de Compra'!A12 -> 9 | B13: ='Lista de Compra'!I12 -> 30 | C13: ='Lista de Compra'!L12 -> 0.012275166 | E13: =E$4*$C13 -> 323.00836 | F13: =F$4*$C13 -> 4.2963082 | G13: =G$4*$C13 -> 13.502683 | H13: =H$4*$C13 -> 18.41275 | I13: =I$4*$C13 -> 1.2275166 | J13: =J$4*$C13 -> 2.20953 | K13: =K$4*$C13 -> 6.0148315 | L13: =L$4*$C13 -> 13.011676 | M13: =M$4*$C13 -> 4.4927109 | N13: =$N$4*E13 -> 25.840669 | O13: =O$4*$C13 -> 18.41275 | P13: =P$4*$C13 -> 3.6825499 | Q13: =Q$4*$C13 -> 3.9321041 | R13: =R$4*$C13 -> 2.4550333 | S13: =S$4*$C13 -> 55.238249 | T13: =T$4*C13 -> 101.92439 | U13: =U$4*$C13 -> 15.957716 | V13: =SUM(F13:U13) -> 290.61147
A14: ='Lista de Compra'!A13 -> 10 | B14: ='Lista de Compra'!I13 -> 150 | C14: ='Lista de Compra'!L13 -> 0.0089127381 | E14: =E$4*$C14 -> 234.52952 | F14: =F$4*$C14 -> 3.1194583 | G14: =G$4*$C14 -> 9.8040119 | H14: =H$4*$C14 -> 13.369107 | I14: =I$4*$C14 -> 0.89127381 | J14: =J$4*$C14 -> 1.6042929 | K14: =K$4*$C14 -> 4.3672417 | L14: =L$4*$C14 -> 9.4475024 | M14: =M$4*$C14 -> 3.2620621 | N14: =$N$4*E14 -> 18.762362 | O14: =O$4*$C14 -> 13.369107 | P14: =P$4*$C14 -> 2.6738214 | Q14: =Q$4*$C14 -> 2.8550174 | R14: =R$4*$C14 -> 1.7825476 | S14: =S$4*$C14 -> 40.107321 | T14: =T$4*C14 -> 74.005138 | U14: =U$4*$C14 -> 11.586559 | V14: =SUM(F14:U14) -> 211.00682
A15: ='Lista de Compra'!A14 -> 11 | B15: ='Lista de Compra'!I14 -> 200 | C15: ='Lista de Compra'!L14 -> 0.01250547 | E15: =E$4*$C15 -> 329.06855 | F15: =F$4*$C15 -> 4.3769144 | G15: =G$4*$C15 -> 13.756017 | H15: =H$4*$C15 -> 18.758205 | I15: =I$4*$C15 -> 1.250547 | J15: =J$4*$C15 -> 2.2509845 | K15: =K$4*$C15 -> 6.1276802 | L15: =L$4*$C15 -> 13.255798 | M15: =M$4*$C15 -> 4.5770019 | N15: =$N$4*E15 -> 26.325484 | O15: =O$4*$C15 -> 18.758205 | P15: =P$4*$C15 -> 3.7516409 | Q15: =Q$4*$C15 -> 4.0058771 | R15: =R$4*$C15 -> 2.5010939 | S15: =S$4*$C15 -> 56.274614 | T15: =T$4*C15 -> 103.83667 | U15: =U$4*$C15 -> 16.257111 | V15: =SUM(F15:U15) -> 296.06384
A16: ='Lista de Compra'!A15 -> 12 | B16: ='Lista de Compra'!I15 -> 60 | C16: ='Lista de Compra'!L15 -> 0.024550333 | E16: =E$4*$C16 -> 646.01672 | F16: =F$4*$C16 -> 8.5926165 | G16: =G$4*$C16 -> 27.005366 | H16: =H$4*$C16 -> 36.825499 | I16: =I$4*$C16 -> 2.4550333 | J16: =J$4*$C16 -> 4.4190599 | K16: =K$4*$C16 -> 12.029663 | L16: =L$4*$C16 -> 26.023353 | M16: =M$4*$C16 -> 8.9854218 | N16: =$N$4*E16 -> 51.681338 | O16: =O$4*$C16 -> 36.825499 | P16: =P$4*$C16 -> 7.3650998 | Q16: =Q$4*$C16 -> 7.8642081 | R16: =R$4*$C16 -> 4.9100666 | S16: =S$4*$C16 -> 110.4765 | T16: =T$4*C16 -> 203.84878 | U16: =U$4*$C16 -> 31.915433 | V16: =SUM(F16:U16) -> 581.22293
... A59: ='Lista de Compra'!A58 -> 55 | B59: ='Lista de Compra'!I58 -> 300 | C59: ='Lista de Compra'!L58 -> 0.0028787914 | E59: =E$4*$C59 -> 75.75243 | F59: =F$4*$C59 -> 1.007577 | G59: =G$4*$C59 -> 3.1666705 | H59: =H$4*$C59 -> 4.3181871 | I59: =I$4*$C59 -> 0.28787914 | J59: =J$4*$C59 -> 0.51818245 | K59: =K$4*$C59 -> 1.4106078 | L59: =L$4*$C59 -> 3.0515189 | M59: =M$4*$C59 -> 1.0536376 | N59: =$N$4*E59 -> 6.0601944 | O59: =O$4*$C59 -> 4.3181871 | P59: =P$4*$C59 -> 0.86363741 | Q59: =Q$4*$C59 -> 0.92216324 | R59: =R$4*$C59 -> 0.57575827 | S59: =S$4*$C59 -> 12.954561 | T59: =T$4*C59 -> 23.903468 | U59: =U$4*$C59 -> 3.7424288 | V59: =SUM(F59:U59) -> 68.154659
A64: CÂMBIO | F64: FRETE | G64: R$
F65: 4710.5 | G65: =F65*B66 -> 24211.97
A66: #VALUE! | B66: 5.14 | F66: 2102 | G66: =F66 -> 2102
A67: #VALUE! | B67: {=_FV(A67,"Preço")} -> 5.8452 | F67: TOTAL | G67: =SUM(G65:G66) -> 26313.97
G68: =G67/B66 -> 5119.4494

Sheet Formulário EDC
B8: INFORMAÇÕES PARA CÁLCULO DE ESTIMATIVA DE CUSTO DE NACIONALIZAÇÃO
B9: NOME EMPRESA IMPORTADORA | C9: SECAMAQ
B10: NOME FORNECEDOR | C10: Flanges e conexões soldaveis
B11: REGIME TRIBUTÁRIO | C11: Lucro Real
B12: FUNÇÃO | C12: Revenda
B13: FRETE | C13: 40 HC
B14: PORTO SAÍDA | C14: Tianjin
B15: PORTO ENTRADA | C15: Paranagua
B16: QUANTIDADE DE PRODUTO | C16: 2
B17: PRODUTO | C17: QTD | D17: PREÇO UNITÁRIO | E17: NCM | F17: II | G17: IPI | H17: PIS | I17: COFINS | J17: ICMS
B18: 1 | E18: 7307.93.00 | F18: 11.2 | G18: 3.25 | H18: 2.1 | I18: 9.65 | J18: 6
B19: 2 | E19: 7307.91.00 | F19: 11.2 | G19: 3.25 | H19: 2.1 | I19: 9.65 | J19: 6
B20: NOME SOLICITANTE | C20: Fernando Takiuti
B21: NOME SOLICITADA | C21: Mariane
B22: NOME REVISORA | C22: Juliana
B23: DATA SOLICITAÇÃO | C23: 8/28/2023
B24: DATA DE ENTREGA | C24: 45025
B25: DATA DE REVISÃO | C25: -
B26: TEVE REVISÃO? | C26: SIM | G26: NÃO
B27: JUSTIFICATIVA CASO NÃO TEVE REVISÃO
B28: OBSERVAÇÃO
B29: QUAL FOI SUA IMPRESSÃO AO APRESENTAR O CÁLCULO AO CLIENTE?
B30: RELATÓRIO AVALIAÇÃO CLIENTE
