Workbook

Sheet Resumo 100%
B3: Estimativa de Custo 100%
C5: CLIENTE: SECAMAQ
C8: REGIME TRIBUTÁRIO: LUCRO REAL | E8: USO: INDUSTRIALIZAÇÃO | G8: CONSIDERAR ICMS 6% | J8: Valor das despesas | K8: 52965.362
C9: PRODUTO: ARAME | E9: PORTO SAÍDA: SHANGHAI | G9: =TODAY() -> 46233 | J9: Custo total | K9: 90312.509
C10: FRETE: 1x20DRY | E10: PORTO ENTRADA: NAVEGANTES | G10: SIMULAÇÃO 100%
K11: 1.4181903
B12: REFERÊNCIA CÁLCULO BASE | C12: R$/USD: | D12: ='Rateio Custos Fixos'!B3 -> 5.09 | E12: NCM: | F12: 7229.20.00
B13: VALORES ADUANEIROS | I13: ITEM | J13: DESCRIÇÃO | K13: USD UNIT PRICE | L13: QTY | O13: BRL UNIT PRICE
B14: DISCRIMINAÇÃO | C14: PESO BRUTO | D14: UNIDADE (ROLO 15KG) | E14: PREÇO KG USD | F14: PREÇO TOTAL USD | G14: R$ | I14: ='LISTA DE COMPRAS'!B4 -> 0 | J14: ='LISTA DE COMPRAS'!C4 -> 0 | K14: ='LISTA DE COMPRAS'!K4 -> 0.815 | L14: ='LISTA DE COMPRAS'!J4 -> 23760 | M14: =K14*L14*'Rateio Custos Fixos'!$B$26 -> 0 | N14: =M14+(M14*$K$11) -> 0 | O14: =N14/L14 -> 0
B15: ARAME 1,0MM | C15: 23760 | E15: ='LISTA DE COMPRAS'!K5 -> 0.815 | F15: =E15*C15 -> 19364.4 | G15: =F15*$D$12 -> 98564.796
B16: TOTAL FOB | F16: =SUM(F15) -> 19364.4 | G16: =SUM(G15) -> 98564.796
B17: PRODUTO + FRETE | G17: =G16+G19 -> 124987.8
B18: SEGURO
B19: FRETE | F19: ='Rateio Custos Fixos'!G5 -> 5191.1591 | G19: =F19*D12 -> 26423
B20: TOTAL VALOR ADUANEIRO | G20: =G17 -> 124987.8 | H20: 0.725
B21: IMPOSTOS
B22: IMPOSTOS | C22: PERCENTUAL | G22: VALOR (R$)
B23: IMPOSTO. IMPORTAÇÃO | C23: 0.112 | G23: ='Est. Cust. Naci.'!R$7 -> 13998.633
B24: PIS | C24: 0.021 | G24: ='Est. Cust. Naci.'!U$7 -> 2918.715
B25: COFINS | C25: 0.0965 | G25: ='Est. Cust. Naci.'!V$7 -> 13412.19
B26: IPI | C26: 0.0325 | G26: ='Est. Cust. Naci.'!T$7 -> 4517.0589
B27: ICMS | C27: 0.06 | G27: ='Est. Cust. Naci.'!W$7 -> 8339.1857
B28: TOTAL VALOR IMPOSTOS | G28: =SUM(G23:G27) -> 43185.783
B29: DESPESAS PORTUÁRIAS E LOGÍSTICAS
B30: ='Rateio Custos Fixos'!F10 -> TAXA SISCOMEX | G30: ='Rateio Custos Fixos'!F11 -> 350
A31: F10 | B31: ='Rateio Custos Fixos'!G10 -> B/L | G31: ='Rateio Custos Fixos'!G11 -> 1000
B32: ='Rateio Custos Fixos'!H10 -> T.H.C| CAPATAZIA | G32: ='Rateio Custos Fixos'!H11 -> 1500
B33: ='Rateio Custos Fixos'!I10 -> ISPS | G33: ='Rateio Custos Fixos'!I11 -> 100
B34: ='Rateio Custos Fixos'!J10 -> DAMAGE PROTECTION | G34: ='Rateio Custos Fixos'!J11 -> 180
B35: ='Rateio Custos Fixos'!K10 -> DESCONSOLIDAÇÃO | G35: ='Rateio Custos Fixos'!K11 -> 1072.94
B36: ='Rateio Custos Fixos'!L10 -> SERVIÇO DE ENTREGA DE CONTAINER | G36: ='Rateio Custos Fixos'!L11 -> 1060
B37: ='Rateio Custos Fixos'!M10 -> TRS | G37: ='Rateio Custos Fixos'!M11 -> 29.8
B38: ='Rateio Custos Fixos'!N10 -> AFRMM | C38: 0.08 | G38: =C38*G19 -> 2113.84
B39: ='Rateio Custos Fixos'!O10 -> ARMAZENAGEM | G39: ='Rateio Custos Fixos'!O11 -> 5200
B40: ='Rateio Custos Fixos'!P10 -> IMPORT LOGISTIC FEE | G40: ='Rateio Custos Fixos'!P11 -> 300
B41: ='Rateio Custos Fixos'!Q10 -> DROP OFF | G41: ='Rateio Custos Fixos'!Q11 -> 320.33
B42: ='Rateio Custos Fixos'!R10 -> PESAGEM | G42: ='Rateio Custos Fixos'!R11 -> 117.45
B43: ='Rateio Custos Fixos'!S10 -> TAXA DO PARCEIRO | G43: ='Rateio Custos Fixos'!S11 -> 286
B44: ='Rateio Custos Fixos'!T10 -> FRETE RODOVIÁRIO | G44: ='Rateio Custos Fixos'!T11 -> 3180
B45: ='Rateio Custos Fixos'!U10 -> DESEMBARAÇO ADUANEIRO | G45: ='Rateio Custos Fixos'!U11 -> 1270
...

Sheet LISTA DE COMPRAS
A1: LISTA DE COMPRA
A3: Item | B3: Estimativa de Custo 100% | C3: Produto | D3: NCM | E3: II | F3: IPI | G3: PIS | H3: COFINS | I3: ICMS | J3: Quantidade (kg) | K3: Preço Unitário | L3: Preço Unitário Sub 50% | M3: Preço total por produto | N3: Preço total por produto | O3: Preço total por produto Sub | P3: % Rateio Quantidade | Q3: % Rateio Preço | R3: Preço R$ Quilo nacionalizado | S3: Preço R$ Rolo nancionalizado
J4: =SUM(J5) -> 23760 | K4: =SUM(K5) -> 0.815 | M4: =SUM(M5) -> 19364.4 | N4: =F16 -> 5.09 | P4: 1 | Q4: 1
A5: 1 | C5: Arame 1,0mm | D5: 7229.20.00 | E5: 0.112 | F5: 0.0325 | G5: 0.021 | H5: 0.0965 | I5: 0.06 | J5: 23760 | K5: 0.815 | L5: =K5/2 -> 0.4075 | M5: =K5*J5 -> 19364.4 | N5: =M5*$N$4 -> 98564.796 | O5: =L5*J5*$N$4 -> 49282.398 | P5: =(J5*$P$4)/$J$4 -> 1 | Q5: =(K5*$Q$4)/$K$4 -> 1 | R5: ='Est. Cust. Naci.'!AV6 -> 7.8389705 | S5: ='Resumo 100%'!G49 -> 117.58456
F16: =5.09 -> 5.09

Sheet Est. Cust. Naci.
C2: DETALHES DO PRODUTO | L2: VALOR ADUANEIRO | R2: IMPOSTOS | Z2: TAXAS PORTUÁRIAS
B3: Nº | C3: ITEM | D3: Código | E3: Bitola (mm) | F3: Embal. | G3: NCM | H3: QTD | I3: % Rateio Preço | J3: Preço unitário Fábrica (USD) | K3: Preço x QTD (Valor em USD) | L3: Preço x QTD (valor em BRL) | M3: Preço x QTD (valor em BRL) SUB | N3: THC (valor em BRL) | O3: Valor do frete (Valor em BRL) | P3: TOTAL VALOR ADUANEIRO | Q3: TOTAL VALOR ADUANEIRO (SUB) | R3: IMPOSTO DE IMPORTAÇÃO | S3: Total valor aduaneiro + Imposto de importação | T3: IPI | U3: PIS | V3: COFINS | W3: ICMS | X3: TOTAL IMPOSTOS | Y3: TOTAL IMPOSTOS (SUB) | Z3: TAXA SISCOMEX | AA3: LIBERAÇÃO DE B/L | AB3: T.H.C| CAPATAZIA | AC3: ISPS | AD3: DAMAGE PROTECTION | AE3: DESCONSOLIDAÇÃO | AF3: DEVOLUÇÃO DE CONTAINER | AG3: TRS | AH3: AFRMM | AI3: ARMAZENAGEM TCP | AJ3: SCANNER TCP | AK3: HANDLING - TCP | AL3: PESAGEM TCP | AM3: TAXA DO PARCEIRO - PARANAGUÁ | AN3: FRETE RODOVIÁRIO | AO3: DESEMBARAÇO ADUANEIRO | AP3: TOTAL TAXAS DESEMBARAÇO | AQ3: TOTAL | AR3: TOTAL (sub) | AS3: TOTAL (sub) | AT3: MÉTODO ANTIGO | AU3: MÉTODO ANTIGO (sub) | AV3: MÉTODO DANI | AW3: MÉTODO DANI (sub) | AX3: MÉTODO JULIANA | AY3: MÉTODO JULIANA (sub) | BA3: VALOR UNITÁRIO C/ COMISSÃO SEAWISE
A4: Nº | L4: =N13 -> 5.09 | M4: 4.8887 | N4: 0 | P4: =SUM(P6) -> 124987.8 | Q4: =SUM(Q6) -> 75705.398 | R4: 0.112 | S4: =P4+R6 -> 138986.43 | T4: 0.0325 | U4: 0.021 | V4: 0.0965 | W4: 0.06 | AH4: 0.08
A5: AAA | R5: =R4 -> 0.112 | T5: =T4 -> 0.0325 | U5: =U4 -> 0.021 | V5: =V4 -> 0.0965 | W5: =W4 -> 0.06 | X5: =X6 -> 43185.783 | Y5: =SUM(Y6) -> 24377.138 | AP5: =SUM(AP6) -> 18080.36 | AQ5: =AP5+X5+P4 -> 186253.94 | AR5: 21877.425 | AS5: =AP5+Y5+Q4 -> 118162.9
A6: AAA | B6: ='LISTA DE COMPRAS'!A5 -> 1 | C6: ='LISTA DE COMPRAS'!C5 -> Arame 1,0mm | G6: 7229.20.00 | H6: ='LISTA DE COMPRAS'!J5 -> 23760 | I6: ='LISTA DE COMPRAS'!Q5 -> 1 | J6: ='LISTA DE COMPRAS'!K5 -> 0.815 | K6: =H6*J6 -> 19364.4 | L6: =K6*$L$4 -> 98564.796 | M6: =L6*50% -> 49282.398 | N6: =$N$4*I6 -> 0 | O6: ='Rateio Custos Fixos'!E12 -> 26423 | P6: =SUM(L6,O6) -> 124987.8 | Q6: =M6+O6 -> 75705.398 | R6: =$P6*R$5 -> 13998.633 | T6: =$S4*T$4 -> 4517.0589 | U6: =$S4*U$5 -> 2918.715 | V6: =$S4*V$5 -> 13412.19 | W6: =$S4*W$5 -> 8339.1857 | X6: =SUM(R6:W6) -> 43185.783 | Y6: =SUM(R12:W12) -> 24377.138 | Z6: ='Rateio Custos Fixos'!F12 -> 350 | AA6: ='Rateio Custos Fixos'!G12 -> 1000 | AB6: ='Rateio Custos Fixos'!H12 -> 1500 | AC6: ='Rateio Custos Fixos'!I12 -> 100 | AD6: ='Rateio Custos Fixos'!J12 -> 180 | AE6: ='Rateio Custos Fixos'!K12 -> 1072.94 | AF6: ='Rateio Custos Fixos'!L12 -> 1060 | AG6: ='Rateio Custos Fixos'!M12 -> 29.8 | ... AO6: ='Rateio Custos Fixos'!U12 -> 1270 | AP6: =SUM(Z6:AO6) -> 18080.36 | AQ6: =AP6+X6+P6 -> 186253.94 | AR6: 2595.3166 | AS6: =AP6+Y6+P6 -> 167445.29 | AT6: =(AQ6/H6) -> 7.8389705 | AU6: =AS6/H6 -> 7.0473609 | AV6: =AQ6/H6 -> 7.8389705 | AW6: =AS6/H6 -> 7.0473609 | AX6: =(J6*9) -> 7.335 | AY6: =AX6/2 -> 3.6675 | BA6: =AQ6/H6 -> 7.8389705
R7: =SUM(R6) -> 13998.633 | T7: =SUM(T6) -> 4517.0589 | U7: =SUM(U6) -> 2918.715 | V7: =SUM(V6) -> 13412.19 | W7: =SUM(W6) -> 8339.1857
R11: =$Q6*R$5 -> 8479.0046 | T11: =$Q6*T$5 -> 2460.4254 | U11: =$Q6*U$5 -> 1589.8134 | V11: =$Q6*V$5 -> 7305.5709 | W11: =$Q6*W$5 -> 4542.3239
R12: =$Q6*R$5 -> 8479.0046 | T12: =$Q6*T$5 -> 2460.4254 | U12: =$Q6*U$5 -> 1589.8134 | V12: =$Q6*V$5 -> 7305.5709 | W12: =$Q6*W$5 -> 4542.3239
N13: =5.09 -> 5.09
O14: =P4+X5+AP5 -> 186253.94 | AP14: fob | AQ14: =SUM(L6) -> 98564.796
AP15: despesas | AQ15: =AQ16-AQ14 -> 87689.143
AP16: total | AQ16: =AQ5 -> 186253.94
P17: =P4='Resumo 100%'!G20 -> TRUE | AP17: despesas/fob | AQ17: =AQ15/AQ14 -> 0.88965987
P18: =X5='Resumo 100%'!G28 -> TRUE
P19: =AP5='Resumo 100%'!G46 -> TRUE
T35: 13890.636 | U35: 4030.765 | V35: 2604.4943 | W35: 11968.271 | X35: 7441.4123 | Z35: =SUM(T35:Y35) -> 39935.579
P38: 13890.636 | R38: II | T38: =P38=T35 -> TRUE
P39: 2604.4943 | R39: PIS | T39: =P39=U35 -> FALSE
P40: 11968.271 | R40: COFINS | T40: =P40=V35 -> FALSE
P41: 4092.7768 | R41: IPI | T41: =P41=T35 -> FALSE
P42: 7441.4123 | R42: ICMS | T42: =P42=W35 -> FALSE
P43: =SUM(P38:P42) -> 39997.591

Sheet Rateio Custos Fixos
A1: CÂMBIO | F1: FRETE | G1: R$
F2: 4700 | G2: =F2*B3 -> 23923
B3: =5.09 -> 5.09 | F3: 2500 | G3: =F3 -> 2500
F4: TOTAL | G4: =SUM(G2:G3) -> 26423
G5: =G4/B3 -> 5191.1591
A10: Produto | B10: Quantidade | C10: ='LISTA DE COMPRAS'!Q2 -> 0 | E10: FRETE | F10: TAXA SISCOMEX | G10: B/L | H10: T.H.C| CAPATAZIA | I10: ISPS | J10: DAMAGE PROTECTION | K10: DESCONSOLIDAÇÃO | L10: SERVIÇO DE ENTREGA DE CONTAINER | M10: TRS | N10: AFRMM | O10: ARMAZENAGEM | P10: IMPORT LOGISTIC FEE | Q10: DROP OFF | R10: PESAGEM | S10: TAXA DO PARCEIRO | T10: FRETE RODOVIÁRIO | U10: DESEMBARAÇO ADUANEIRO
B11: =SUM(B12) -> 23760 | C11: =SUM(C12) -> 1 | E11: =G4 -> 26423 | F11: 350 | G11: 1000 | H11: 1500 | I11: 100 | J11: 180 | K11: 1072.94 | L11: 1060 | M11: 29.8 | N11: 0.08 | O11: 5200 | P11: 300 | Q11: 320.33 | R11: 117.45 | S11: 286 | T11: 3180 | U11: 1270
A12: ='LISTA DE COMPRAS'!A5 -> 1 | B12: ='LISTA DE COMPRAS'!J5 -> 23760 | C12: ='LISTA DE COMPRAS'!Q5 -> 1 | E12: =E$11*$C12 -> 26423 | F12: =F$11*$C12 -> 350 | G12: =G$11*$C12 -> 1000 | H12: =H$11*$C12 -> 1500 | I12: =I$11*$C12 -> 100 | J12: =J$11*$C12 -> 180 | K12: =K$11*$C12 -> 1072.94 | L12: =L$11*$C12 -> 1060 | M12: =M$11*$C12 -> 29.8 | N12: =$N$11*E12 -> 2113.84 | O12: =O$11*$C12 -> 5200 | P12: =P$11*$C12 -> 300 | Q12: =Q$11*$C12 -> 320.33 | R12: =R$11*$C12 -> 117.45 | S12: =S$11*$C12 -> 286 | T12: =T$11*$C12 -> 3180 | U12: =U$11*$C12 -> 1270 | V12: =SUM(F12:U12) -> 18080.36
N13: =E11*8% -> 2113.84
N14: =N12=N13 -> TRUE
