Workbook

Sheet Resumo 100%
C4: Estimativa de Custo
D9: OPTANTE PELO SIMPLES: NÃO | F9: FINALIDADE: REVENDA | H9: CONSIDERAR ICMS 6% | L9: 5.12
D10: PRODUTO:ROLAMENTOS | F10: PORTO DE ORIGEM: QINGDAO | H10: =TODAY() -> 46233
D11: FRETE: LCL | F11: PORTO DE DESTINO: PARANAGUÁ | H11: SIMULAÇÃO 100%
C13: REFERÊNCIA CÁLCULO BASE | D13: R$/USD: | E13: =L9 -> 5.12 | F13: NCM:
C14: VALORES ADUANEIROS
C15: DISCRIMINAÇÃO | D15: PESO BRUTO | E15: UNIDADE | F15: PREÇO Uni. USD | G15: PREÇO TOTAL USD | H15: R$
C16: PRODUTOS | E16: ='Lista de Compra'!K9 -> 10000 | G16: ='Est. Cust. Naci.'!G4 -> 2579 | H16: =G16*$E$13 -> 13204.48
C17: TOTAL FOB | H17: =H16 -> 13204.48
C18: Seguro
C19: Frete | G19: ='Rateio Custos Fixos'!G7 -> 117.3375 | H19: ='Rateio Custos Fixos'!G6 -> 600.768
C20: TOTAL VALOR ADUANEIRO | H20: =H17+H19 -> 13805.248
C21: IMPOSTOS
C22: IMPOSTOS | H22: VALOR (R$)
C23: ='Est. Cust. Naci.'!M3 -> IMPOSTO DE IMPORTAÇÃO | H23: ='Est. Cust. Naci.'!M4 -> 1546.1878
C24: ='Est. Cust. Naci.'!N3 -> IPI | H24: ='Est. Cust. Naci.'!N4 -> 0
C25: ='Est. Cust. Naci.'!O3 -> PIS | H25: ='Est. Cust. Naci.'!O4 -> 322.38015
C26: ='Est. Cust. Naci.'!P3 -> COFINS | H26: ='Est. Cust. Naci.'!P4 -> 1634.9279
C27: ='Est. Cust. Naci.'!Q3 -> ICMS | H27: ='Est. Cust. Naci.'!Q4 -> 921.08615
C28: TOTAL DE IMPOSTOS | H28: =SUM(H23:H27) -> 4424.582
C29: TOTAL DESPESAS LOGÍSTICAS E ADUANEIRAS
C30: TAXA SISCOMEX | H30: ='Rateio Custos Fixos'!F11 -> 214.5
C31: LIBERAÇÃO DE B/L | H31: ='Rateio Custos Fixos'!G11 -> 10
C32: T.H.C|CAPATAZIA | H32: ='Rateio Custos Fixos'!H11 -> 990
C33: ISPS | H33: ='Rateio Custos Fixos'!I11 -> 48
C34: DAMAGE PROTECTION | H34: ='Rateio Custos Fixos'!J11 -> 122
C35: DESCONSOLIDAÇÃO | H35: ='Rateio Custos Fixos'!K11 -> 10
C36: DEVOLUÇÃO DE CONTAINER | H36: ='Rateio Custos Fixos'!L11 -> 774.9
C37: TRS | H37: ='Rateio Custos Fixos'!M11 -> 153.6
C38: AFRMM | D38: 0.08 | H38: ='Rateio Custos Fixos'!E11*'Rateio Custos Fixos'!N11 -> 48.06144
C39: ARMAZENAGEM TCP | H39: ='Rateio Custos Fixos'!O11 -> 0 | I39: 5 dias de armazenagem
C40: SCANNER TCP | H40: ='Rateio Custos Fixos'!P11 -> 756.95
C41: HANDLING - TCP | H41: ='Rateio Custos Fixos'!Q11 -> 20
C42: PESAGEM TCP | H42: ='Rateio Custos Fixos'!R11 -> 117.45
C43: TAXA DO PARCEIRO - PARANAGUÁ | H43: ='Rateio Custos Fixos'!S11 -> 286
C44: FRETE RODOVIÁRIO | H44: ='Rateio Custos Fixos'!T11 -> 3000
C45: DESEMBARAÇO ADUANEIRO | H45: ='Rateio Custos Fixos'!U11 -> 2600
C46: VALOR ADUANEIRO TOTAL | H46: =SUM(H30:H45) -> 9151.4614
C47: TOTAL (PARTE 1 + PARTE 2 + PARTE 3) ........................................................: | H47: =H20+H28+H46 -> 27381.291
C48: PREÇO FOB | D48: =H17 -> 13204.48
...

Sheet Lista de Compra
B3: LISTA DE PRODUTOS
B4: NOME: PINZAN & SILVA | E4: FINALIDADE: REVENDA
E5: FRETE: LCL
B6: REGIME TRIBUTÁRIO: LUCRO PRESUMIDO | E6: PORTO SAÍDA: QINGDAO
B7: PRODUTO: ROLAMENTOS | E7: PORTO ENTRADA: PARANAGUÁ
B8: Item | C8: Produto | D8: Coluna1 | E8: NCM | F8: II | G8: IPI | H8: PIS | I8: COFINS | J8: ICMS | K8: Quantidade | L8: Coluna2 | M8: Preço | N8: Preço Sub | O8: % Rateio Quantidade | P8: % Rateio Preço | Q8: Preço R$ nacionalizado
K9: =SUM(K10:K29) -> 10000 | M9: =SUMPRODUCT(K10:K29,M10:M29) -> 2579 | N9: 0.5 | O9: =SUM(O10:O29) -> 1 | P9: =SUM(P10:P29) -> 1
B10: 6201-DDU | E10: 8466.93.50 | F10: 0.112 | G10: 0 | H10: 0.021 | I10: 0.1065 | J10: 0.06 | K10: 500 | M10: 0.101 | N10: =M10-(M10*$N$9) -> 0.0505 | O10: =IFERROR(K10/$K$9,0) -> 0.05 | P10: =IFERROR((K10*M10)/$M$9,0) -> 0.019581233 | Q10: ='Est. Cust. Naci.'!AL11 -> 1.0723189
B11: 6204-DDU | E11: 8466.93.50 | F11: 0.112 | G11: 0 | H11: 0.021 | I11: 0.1065 | J11: 0.06 | K11: 500 | M11: 0.166 | N11: =M11-(M11*$N$9) -> 0.083 | O11: =IFERROR(K11/$K$9,0) -> 0.05 | P11: =IFERROR((K11*M11)/$M$9,0) -> 0.032183017 | Q11: ='Est. Cust. Naci.'!AL12 -> 1.7624251
B12: 6205-DDU | E12: 8466.93.50 | F12: 0.112 | G12: 0 | H12: 0.021 | I12: 0.1065 | J12: 0.06 | K12: 500 | M12: 0.203 | N12: =M12-(M12*$N$9) -> 0.1015 | O12: =IFERROR(K12/$K$9,0) -> 0.05 | P12: =IFERROR((K12*M12)/$M$9,0) -> 0.03935634 | Q12: ='Est. Cust. Naci.'!AL13 -> 2.1552548
B13: 6206-DDU | E13: 8466.93.50 | F13: 0.112 | G13: 0 | H13: 0.021 | I13: 0.1065 | J13: 0.06 | K13: 500 | M13: 0.3 | N13: =M13-(M13*$N$9) -> 0.15 | O13: =IFERROR(K13/$K$9,0) -> 0.05 | P13: =IFERROR((K13*M13)/$M$9,0) -> 0.058162078 | Q13: ='Est. Cust. Naci.'!AL14 -> 3.1851056
B14: 6004-DDU | E14: 8466.93.50 | F14: 0.112 | G14: 0 | H14: 0.021 | I14: 0.1065 | J14: 0.06 | K14: 500 | M14: 0.139 | N14: =M14-(M14*$N$9) -> 0.0695 | O14: =IFERROR(K14/$K$9,0) -> 0.05 | P14: =IFERROR((K14*M14)/$M$9,0) -> 0.02694843 | Q14: ='Est. Cust. Naci.'!AL15 -> 1.4757656
B15: 6001-DDU | E15: 8466.93.50 | F15: 0.112 | G15: 0 | H15: 0.021 | I15: 0.1065 | J15: 0.06 | K15: 500 | M15: 0.083 | N15: =M15-(M15*$N$9) -> 0.0415 | O15: =IFERROR(K15/$K$9,0) -> 0.05 | P15: =IFERROR((K15*M15)/$M$9,0) -> 0.016091508 | Q15: ='Est. Cust. Naci.'!AL16 -> 0.88121256
B16: 6002-DDU | E16: 8466.93.50 | F16: 0.112 | G16: 0 | H16: 0.021 | I16: 0.1065 | J16: 0.06 | K16: 500 | M16: 0.101 | N16: =M16-(M16*$N$9) -> 0.0505 | O16: =IFERROR(K16/$K$9,0) -> 0.05 | P16: =IFERROR((K16*M16)/$M$9,0) -> 0.019581233 | Q16: ='Est. Cust. Naci.'!AL17 -> 1.0723189
B17: 6003-DDU | E17: 8466.93.50 | F17: 0.112 | G17: 0 | H17: 0.021 | I17: 0.1065 | J17: 0.06 | K17: 500 | M17: 0.116 | N17: =M17-(M17*$N$9) -> 0.058 | O17: =IFERROR(K17/$K$9,0) -> 0.05 | P17: =IFERROR((K17*M17)/$M$9,0) -> 0.022489337 | Q17: ='Est. Cust. Naci.'!AL18 -> 1.2315742
B18: 6005-DDU | E18: 8466.93.50 | F18: 0.112 | G18: 0 | H18: 0.021 | I18: 0.1065 | J18: 0.06 | K18: 500 | M18: 0.174 | N18: =M18-(M18*$N$9) -> 0.087 | O18: =IFERROR(K18/$K$9,0) -> 0.05 | P18: =IFERROR((K18*M18)/$M$9,0) -> 0.033734005 | Q18: ='Est. Cust. Naci.'!AL19 -> 1.8473613
B19: 6006-DDU | E19: 8466.93.50 | F19: 0.112 | G19: 0 | H19: 0.021 | I19: 0.1065 | J19: 0.06 | K19: 500 | M19: 0.242 | N19: =M19-(M19*$N$9) -> 0.121 | O19: =IFERROR(K19/$K$9,0) -> 0.05 | P19: =IFERROR((K19*M19)/$M$9,0) -> 0.04691741 | Q19: ='Est. Cust. Naci.'!AL20 -> 2.5693185
B20: 6301-DDU | E20: 8466.93.50 | F20: 0.112 | G20: 0 | H20: 0.021 | I20: 0.1065 | J20: 0.06 | K20: 500 | M20: 0.145 | N20: =M20-(M20*$N$9) -> 0.0725 | O20: =IFERROR(K20/$K$9,0) -> 0.05 | P20: =IFERROR((K20*M20)/$M$9,0) -> 0.028111671 | Q20: ='Est. Cust. Naci.'!AL21 -> 1.5394677
B21: 6302-DDU | E21: 8466.93.50 | F21: 0.112 | G21: 0 | H21: 0.021 | I21: 0.1065 | J21: 0.06 | K21: 500 | M21: 0.174 | N21: =M21-(M21*$N$9) -> 0.087 | O21: =IFERROR(K21/$K$9,0) -> 0.05 | P21: =IFERROR((K21*M21)/$M$9,0) -> 0.033734005 | Q21: ='Est. Cust. Naci.'!AL22 -> 1.8473613
... B26: 608-DDU | E26: 8466.93.50 | F26: 0.112 | G26: 0 | H26: 0.021 | I26: 0.1065 | J26: 0.06 | K26: 500 | M26: 0.058 | N26: =M26-(M26*$N$9) -> 0.029 | O26: =IFERROR(K26/$K$9,0) -> 0.05 | P26: =IFERROR((K26*M26)/$M$9,0) -> 0.011244668 | Q26: ='Est. Cust. Naci.'!AL27 -> 0.61578709
B27: 32010 | E27: 8466.93.50 | F27: 0.112 | G27: 0 | H27: 0.021 | I27: 0.1065 | J27: 0.06 | K27: 500 | M27: 0.852 | N27: =M27-(M27*$N$9) -> 0.426 | O27: =IFERROR(K27/$K$9,0) -> 0.05 | P27: =IFERROR((K27*M27)/$M$9,0) -> 0.1651803 | Q27: ='Est. Cust. Naci.'!AL28 -> 9.0457
B28: 6007-DDU | E28: 8466.93.50 | F28: 0.112 | G28: 0 | H28: 0.021 | I28: 0.1065 | J28: 0.06 | K28: 500 | M28: 0.31 | N28: =M28-(M28*$N$9) -> 0.155 | O28: =IFERROR(K28/$K$9,0) -> 0.05 | P28: =IFERROR((K28*M28)/$M$9,0) -> 0.060100814 | Q28: ='Est. Cust. Naci.'!AL29 -> 3.2912758
B29: 6010-DDU | E29: 8466.93.50 | F29: 0.112 | G29: 0 | H29: 0.021 | I29: 0.1065 | J29: 0.06 | K29: 500 | M29: 0.619 | N29: =M29-(M29*$N$9) -> 0.3095 | O29: =IFERROR(K29/$K$9,0) -> 0.05 | P29: =IFERROR((K29*M29)/$M$9,0) -> 0.12000775 | Q29: ='Est. Cust. Naci.'!AL30 -> 6.5719346

Sheet Est. Cust. Naci.
B2: DETALHES DO PRODUTO | H2: VALOR ADUANEIRO | M2: IMPOSTOS | S2: TAXAS PORTUÁRIAS
B3: ITEM | C3: NCM | D3: QTD | E3: Participação % | F3: Preço unitário (USD) | G3: Preço x QTD (Valor em USD) | H3: Preço x QTD (valor em BRL) | I3: THC (valor em BRL) | J3: Valor do frete (Valor em BRL) | K3: TOTAL VALOR ADUANEIRO | L3: TOTAL VALOR ADUANEIRO +IMPOSTO DE IMPORTAÇÃO | M3: IMPOSTO DE IMPORTAÇÃO | N3: IPI | O3: PIS | P3: COFINS | Q3: ICMS | R3: TOTAL IMPOSTOS | S3: TAXA SISCOMEX | T3: LIBERAÇÃO DE B/L | U3: T.H.C| CAPATAZIA | V3: ISPS | W3: DAMAGE PROTECTION | X3: DESCONSOLIDAÇÃO | Y3: DEVOLUÇÃO DE CONTAINER | Z3: TRS | AA3: AFRMM | AB3: ARMAZENAGEM TCP | AC3: SCANNER TCP | AD3: HANDLING - TCP | AE3: PESAGEM TCP | AF3: TAXA DO PARCEIRO - PARANAGUÁ | AG3: FRETE RODOVIÁRIO | AH3: DESEMBARAÇO ADUANEIRO | AI3: TOTAL DESEMBARAÇO ADUANEIRO | AJ3: TOTAL AC | AK3: VALOR UNITÁRIO | AL3: Método Dani
A4: Nº | G4: =SUM(G11:G30) -> 2579 | H4: ='Resumo 100%'!$E$13 -> 5.12 | I4: ='Rateio Custos Fixos'!H11 -> 990 | J4: =SUM(J11:J30) -> 600.768 | K4: =SUM(K11:K30) -> 13805.248 | L4: =SUM(L11:L30) -> 15351.436 | M4: =SUM(M11:M30) -> 1546.1878 | N4: =SUM(N11:N30) -> 0 | O4: =SUM(O11:O30) -> 322.38015 | P4: =SUM(P11:P30) -> 1634.9279 | Q4: =SUM(Q11:Q30) -> 921.08615 | R4: =SUM(R11:R30) -> 4424.582 | AA4: 0.08 | AI4: =SUM(AI11:AI30) -> 9151.4614 | AQ4: Preço FOB | AR4: =SUM(H11:H30) -> 13204.48
A5: AAA | C5: 8466.93.50 | H5: =SUM(H11:H30) -> 13204.48 | M5: ='Lista de Compra'!F10 -> 0.112 | N5: 0 | O5: ='Lista de Compra'!H10 -> 0.021 | P5: ='Lista de Compra'!I10 -> 0.1065 | Q5: ='Lista de Compra'!J10 -> 0.06 | AI5: =SUM(AI11:AI30) -> 9151.4614 | AJ5: =SUM(AJ11:AJ30) -> 27381.291 | AQ5: Despesas | AR5: =AJ5-AR4 -> 14176.811
B11: ='Lista de Compra'!B10 -> 6201-DDU | C11: ='Lista de Compra'!E10 -> 8466.93.50 | D11: ='Lista de Compra'!K10 -> 500 | E11: ='Lista de Compra'!P10 -> 0.019581233 | F11: ='Lista de Compra'!M10 -> 0.101 | G11: =D11*F11 -> 50.5 | H11: =G11*$H$4 -> 258.56 | I11: =$I$4*E11 -> 19.385421 | J11: ='Rateio Custos Fixos'!E12 -> 11.763778 | K11: =SUM(H11,J11) -> 270.32378 | L11: =K11+M11 -> 300.60004 | M11: =K11*IFERROR(VLOOKUP(C11,$C$5:$Q$5,11,FALSE()),0) -> 30.276263 | N11: =L11*IFERROR(VLOOKUP(C11,$C$5:$Q$5,12,FALSE()),0) -> 0 | O11: =L11*IFERROR(VLOOKUP(C11,$C$5:$Q$5,13,FALSE()),0) -> 6.3126009 | P11: =L11*IFERROR(VLOOKUP(C11,$C$5:$Q$5,14,FALSE()),0) -> 32.013904 | Q11: =L11*IFERROR(VLOOKUP(C11,$C$5:$Q$5,15,FALSE()),0) -> 18.036002 | R11: =SUM(M11:Q11) -> 86.638771 | S11: ='Rateio Custos Fixos'!F12 -> 4.2001745 | T11: ='Rateio Custos Fixos'!G12 -> 0.19581233 | U11: ='Rateio Custos Fixos'!H12 -> 19.385421 | V11: ='Rateio Custos Fixos'!I12 -> 0.93989919 | W11: ='Rateio Custos Fixos'!J12 -> 2.3889104 | X11: ='Rateio Custos Fixos'!K12 -> 0.19581233 | Y11: ='Rateio Custos Fixos'!L12 -> 15.173497 | Z11: ='Rateio Custos Fixos'!M12 -> 3.0076774 | ... AH11: ='Rateio Custos Fixos'!U12 -> 50.911206 | AI11: =SUM(S11:AH11) -> 179.1969 | AJ11: =K11+R11+AI11 -> 536.15945 | AK11: =IFERROR(AJ11/D11,0) -> 1.0723189 | AL11: =IFERROR(AJ11/D11,0) -> 1.0723189
B12: ='Lista de Compra'!B11 -> 6204-DDU | C12: ='Lista de Compra'!E11 -> 8466.93.50 | D12: ='Lista de Compra'!K11 -> 500 | E12: ='Lista de Compra'!P11 -> 0.032183017 | F12: ='Lista de Compra'!M11 -> 0.166 | G12: =D12*F12 -> 83 | H12: =G12*$H$4 -> 424.96 | I12: =$I$4*E12 -> 31.861187 | J12: ='Rateio Custos Fixos'!E13 -> 19.334527 | K12: =SUM(H12,J12) -> 444.29453 | L12: =K12+M12 -> 494.05551 | M12: =K12*IFERROR(VLOOKUP(C12,$C$5:$Q$5,11,FALSE()),0) -> 49.760987 | N12: =L12*IFERROR(VLOOKUP(C12,$C$5:$Q$5,12,FALSE()),0) -> 0 | O12: =L12*IFERROR(VLOOKUP(C12,$C$5:$Q$5,13,FALSE()),0) -> 10.375166 | P12: =L12*IFERROR(VLOOKUP(C12,$C$5:$Q$5,14,FALSE()),0) -> 52.616912 | Q12: =L12*IFERROR(VLOOKUP(C12,$C$5:$Q$5,15,FALSE()),0) -> 29.643331 | R12: =SUM(M12:Q12) -> 142.3964 | S12: ='Rateio Custos Fixos'!F13 -> 6.9032571 | T12: ='Rateio Custos Fixos'!G13 -> 0.32183017 | U12: ='Rateio Custos Fixos'!H13 -> 31.861187 | V12: ='Rateio Custos Fixos'!I13 -> 1.5447848 | W12: ='Rateio Custos Fixos'!J13 -> 3.926328 | X12: ='Rateio Custos Fixos'!K13 -> 0.32183017 | Y12: ='Rateio Custos Fixos'!L13 -> 24.93862 | Z12: ='Rateio Custos Fixos'!M13 -> 4.9433114 | ... AH12: ='Rateio Custos Fixos'!U13 -> 83.675843 | AI12: =SUM(S12:AH12) -> 294.52164 | AJ12: =K12+R12+AI12 -> 881.21256 | AK12: =IFERROR(AJ12/D12,0) -> 1.7624251 | AL12: =IFERROR(AJ12/D12,0) -> 1.7624251
B13: ='Lista de Compra'!B12 -> 6205-DDU | C13: ='Lista de Compra'!E12 -> 8466.93.50 | D13: ='Lista de Compra'!K12 -> 500 | E13: ='Lista de Compra'!P12 -> 0.03935634 | F13: ='Lista de Compra'!M12 -> 0.203 | G13: =D13*F13 -> 101.5 | H13: =G13*$H$4 -> 519.68 | I13: =$I$4*E13 -> 38.962776 | J13: ='Rateio Custos Fixos'!E14 -> 23.644029 | K13: =SUM(H13,J13) -> 543.32403 | L13: =K13+M13 -> 604.17632 | M13: =K13*IFERROR(VLOOKUP(C13,$C$5:$Q$5,11,FALSE()),0) -> 60.852291 | N13: =L13*IFERROR(VLOOKUP(C13,$C$5:$Q$5,12,FALSE()),0) -> 0 | O13: =L13*IFERROR(VLOOKUP(C13,$C$5:$Q$5,13,FALSE()),0) -> 12.687703 | P13: =L13*IFERROR(VLOOKUP(C13,$C$5:$Q$5,14,FALSE()),0) -> 64.344778 | Q13: =L13*IFERROR(VLOOKUP(C13,$C$5:$Q$5,15,FALSE()),0) -> 36.250579 | R13: =SUM(M13:Q13) -> 174.13535 | S13: ='Rateio Custos Fixos'!F14 -> 8.4419349 | T13: ='Rateio Custos Fixos'!G14 -> 0.3935634 | U13: ='Rateio Custos Fixos'!H14 -> 38.962776 | V13: ='Rateio Custos Fixos'!I14 -> 1.8891043 | W13: ='Rateio Custos Fixos'!J14 -> 4.8014734 | X13: ='Rateio Custos Fixos'!K14 -> 0.3935634 | Y13: ='Rateio Custos Fixos'!L14 -> 30.497228 | Z13: ='Rateio Custos Fixos'!M14 -> 6.0451338 | ... AH13: ='Rateio Custos Fixos'!U14 -> 102.32648 | AI13: =SUM(S13:AH13) -> 360.16802 | AJ13: =K13+R13+AI13 -> 1077.6274 | AK13: =IFERROR(AJ13/D13,0) -> 2.1552548 | AL13: =IFERROR(AJ13/D13,0) -> 2.1552548
B14: ='Lista de Compra'!B13 -> 6206-DDU | C14: ='Lista de Compra'!E13 -> 8466.93.50 | D14: ='Lista de Compra'!K13 -> 500 | E14: ='Lista de Compra'!P13 -> 0.058162078 | F14: ='Lista de Compra'!M13 -> 0.3 | G14: =D14*F14 -> 150 | H14: =G14*$H$4 -> 768 | I14: =$I$4*E14 -> 57.580458 | J14: ='Rateio Custos Fixos'!E15 -> 34.941915 | K14: =SUM(H14,J14) -> 802.94192 | L14: =K14+M14 -> 892.87141 | M14: =K14*IFERROR(VLOOKUP(C14,$C$5:$Q$5,11,FALSE()),0) -> 89.929495 | N14: =L14*IFERROR(VLOOKUP(C14,$C$5:$Q$5,12,FALSE()),0) -> 0 | O14: =L14*IFERROR(VLOOKUP(C14,$C$5:$Q$5,13,FALSE()),0) -> 18.7503 | P14: =L14*IFERROR(VLOOKUP(C14,$C$5:$Q$5,14,FALSE()),0) -> 95.090805 | Q14: =L14*IFERROR(VLOOKUP(C14,$C$5:$Q$5,15,FALSE()),0) -> 53.572285 | R14: =SUM(M14:Q14) -> 257.34288 | S14: ='Rateio Custos Fixos'!F15 -> 12.475766 | T14: ='Rateio Custos Fixos'!G15 -> 0.58162078 | U14: ='Rateio Custos Fixos'!H15 -> 57.580458 | V14: ='Rateio Custos Fixos'!I15 -> 2.7917798 | W14: ='Rateio Custos Fixos'!J15 -> 7.0957736 | X14: ='Rateio Custos Fixos'!K15 -> 0.58162078 | Y14: ='Rateio Custos Fixos'!L15 -> 45.069794 | Z14: ='Rateio Custos Fixos'!M15 -> 8.9336952 | ... AH14: ='Rateio Custos Fixos'!U15 -> 151.2214 | AI14: =SUM(S14:AH14) -> 532.26802 | AJ14: =K14+R14+AI14 -> 1592.5528 | AK14: =IFERROR(AJ14/D14,0) -> 3.1851056 | AL14: =IFERROR(AJ14/D14,0) -> 3.1851056
B15: ='Lista de Compra'!B14 -> 6004-DDU | C15: ='Lista de Compra'!E14 -> 8466.93.50 | D15: ='Lista de Compra'!K14 -> 500 | E15: ='Lista de Compra'!P14 -> 0.02694843 | F15: ='Lista de Compra'!M14 -> 0.139 | G15: =D15*F15 -> 69.5 | H15: =G15*$H$4 -> 355.84 | I15: =$I$4*E15 -> 26.678945 | J15: ='Rateio Custos Fixos'!E16 -> 16.189754 | K15: =SUM(H15,J15) -> 372.02975 | L15: =K15+M15 -> 413.69709 | M15: =K15*IFERROR(VLOOKUP(C15,$C$5:$Q$5,11,FALSE()),0) -> 41.667332 | N15: =L15*IFERROR(VLOOKUP(C15,$C$5:$Q$5,12,FALSE()),0) -> 0 | O15: =L15*IFERROR(VLOOKUP(C15,$C$5:$Q$5,13,FALSE()),0) -> 8.6876388 | P15: =L15*IFERROR(VLOOKUP(C15,$C$5:$Q$5,14,FALSE()),0) -> 44.05874 | Q15: =L15*IFERROR(VLOOKUP(C15,$C$5:$Q$5,15,FALSE()),0) -> 24.821825 | R15: =SUM(M15:Q15) -> 119.23554 | S15: ='Rateio Custos Fixos'!F16 -> 5.7804382 | T15: ='Rateio Custos Fixos'!G16 -> 0.2694843 | U15: ='Rateio Custos Fixos'!H16 -> 26.678945 | V15: ='Rateio Custos Fixos'!I16 -> 1.2935246 | W15: ='Rateio Custos Fixos'!J16 -> 3.2877084 | X15: ='Rateio Custos Fixos'!K16 -> 0.2694843 | Y15: ='Rateio Custos Fixos'!L16 -> 20.882338 | Z15: ='Rateio Custos Fixos'!M16 -> 4.1392788 | ... AH15: ='Rateio Custos Fixos'!U16 -> 70.065917 | AI15: =SUM(S15:AH15) -> 246.61751 | AJ15: =K15+R15+AI15 -> 737.8828 | AK15: =IFERROR(AJ15/D15,0) -> 1.4757656 | AL15: =IFERROR(AJ15/D15,0) -> 1.4757656
B16: ='Lista de Compra'!B15 -> 6001-DDU | C16: ='Lista de Compra'!E15 -> 8466.93.50 | D16: ='Lista de Compra'!K15 -> 500 | E16: ='Lista de Compra'!P15 -> 0.016091508 | F16: ='Lista de Compra'!M15 -> 0.083 | G16: =D16*F16 -> 41.5 | H16: =G16*$H$4 -> 212.48 | I16: =$I$4*E16 -> 15.930593 | J16: ='Rateio Custos Fixos'!E17 -> 9.6672633 | K16: =SUM(H16,J16) -> 222.14726 | L16: =K16+M16 -> 247.02776 | M16: =K16*IFERROR(VLOOKUP(C16,$C$5:$Q$5,11,FALSE()),0) -> 24.880493 | N16: =L16*IFERROR(VLOOKUP(C16,$C$5:$Q$5,12,FALSE()),0) -> 0 | O16: =L16*IFERROR(VLOOKUP(C16,$C$5:$Q$5,13,FALSE()),0) -> 5.1875829 | P16: =L16*IFERROR(VLOOKUP(C16,$C$5:$Q$5,14,FALSE()),0) -> 26.308456 | Q16: =L16*IFERROR(VLOOKUP(C16,$C$5:$Q$5,15,FALSE()),0) -> 14.821665 | R16: =SUM(M16:Q16) -> 71.198198 | S16: ='Rateio Custos Fixos'!F17 -> 3.4516285 | T16: ='Rateio Custos Fixos'!G17 -> 0.16091508 | U16: ='Rateio Custos Fixos'!H17 -> 15.930593 | V16: ='Rateio Custos Fixos'!I17 -> 0.7723924 | W16: ='Rateio Custos Fixos'!J17 -> 1.963164 | X16: ='Rateio Custos Fixos'!K17 -> 0.16091508 | Y16: ='Rateio Custos Fixos'!L17 -> 12.46931 | Z16: ='Rateio Custos Fixos'!M17 -> 2.4716557 | ... AH16: ='Rateio Custos Fixos'!U17 -> 41.837922 | AI16: =SUM(S16:AH16) -> 147.26082 | AJ16: =K16+R16+AI16 -> 440.60628 | AK16: =IFERROR(AJ16/D16,0) -> 0.88121256 | AL16: =IFERROR(AJ16/D16,0) -> 0.88121256
B17: ='Lista de Compra'!B16 -> 6002-DDU | C17: ='Lista de Compra'!E16 -> 8466.93.50 | D17: ='Lista de Compra'!K16 -> 500 | E17: ='Lista de Compra'!P16 -> 0.019581233 | F17: ='Lista de Compra'!M16 -> 0.101 | G17: =D17*F17 -> 50.5 | H17: =G17*$H$4 -> 258.56 | I17: =$I$4*E17 -> 19.385421 | J17: ='Rateio Custos Fixos'!E18 -> 11.763778 | K17: =SUM(H17,J17) -> 270.32378 | L17: =K17+M17 -> 300.60004 | M17: =K17*IFERROR(VLOOKUP(C17,$C$5:$Q$5,11,FALSE()),0) -> 30.276263 | N17: =L17*IFERROR(VLOOKUP(C17,$C$5:$Q$5,12,FALSE()),0) -> 0 | O17: =L17*IFERROR(VLOOKUP(C17,$C$5:$Q$5,13,FALSE()),0) -> 6.3126009 | P17: =L17*IFERROR(VLOOKUP(C17,$C$5:$Q$5,14,FALSE()),0) -> 32.013904 | Q17: =L17*IFERROR(VLOOKUP(C17,$C$5:$Q$5,15,FALSE()),0) -> 18.036002 | R17: =SUM(M17:Q17) -> 86.638771 | S17: ='Rateio Custos Fixos'!F18 -> 4.2001745 | T17: ='Rateio Custos Fixos'!G18 -> 0.19581233 | U17: ='Rateio Custos Fixos'!H18 -> 19.385421 | V17: ='Rateio Custos Fixos'!I18 -> 0.93989919 | W17: ='Rateio Custos Fixos'!J18 -> 2.3889104 | X17: ='Rateio Custos Fixos'!K18 -> 0.19581233 | Y17: ='Rateio Custos Fixos'!L18 -> 15.173497 | Z17: ='Rateio Custos Fixos'!M18 -> 3.0076774 | ... AH17: ='Rateio Custos Fixos'!U18 -> 50.911206 | AI17: =SUM(S17:AH17) -> 179.1969 | AJ17: =K17+R17+AI17 -> 536.15945 | AK17: =IFERROR(AJ17/D17,0) -> 1.0723189 | AL17: =IFERROR(AJ17/D17,0) -> 1.0723189
B18: ='Lista de Compra'!B17 -> 6003-DDU | C18: ='Lista de Compra'!E17 -> 8466.93.50 | D18: ='Lista de Compra'!K17 -> 500 | E18: ='Lista de Compra'!P17 -> 0.022489337 | F18: ='Lista de Compra'!M17 -> 0.116 | G18: =D18*F18 -> 58 | H18: =G18*$H$4 -> 296.96 | I18: =$I$4*E18 -> 22.264444 | J18: ='Rateio Custos Fixos'!E19 -> 13.510874 | K18: =SUM(H18,J18) -> 310.47087 | L18: =K18+M18 -> 345.24361 | M18: =K18*IFERROR(VLOOKUP(C18,$C$5:$Q$5,11,FALSE()),0) -> 34.772738 | N18: =L18*IFERROR(VLOOKUP(C18,$C$5:$Q$5,12,FALSE()),0) -> 0 | O18: =L18*IFERROR(VLOOKUP(C18,$C$5:$Q$5,13,FALSE()),0) -> 7.2501158 | P18: =L18*IFERROR(VLOOKUP(C18,$C$5:$Q$5,14,FALSE()),0) -> 36.768445 | Q18: =L18*IFERROR(VLOOKUP(C18,$C$5:$Q$5,15,FALSE()),0) -> 20.714617 | R18: =SUM(M18:Q18) -> 99.505915 | S18: ='Rateio Custos Fixos'!F19 -> 4.8239628 | T18: ='Rateio Custos Fixos'!G19 -> 0.22489337 | U18: ='Rateio Custos Fixos'!H19 -> 22.264444 | V18: ='Rateio Custos Fixos'!I19 -> 1.0794882 | W18: ='Rateio Custos Fixos'!J19 -> 2.7436991 | X18: ='Rateio Custos Fixos'!K19 -> 0.22489337 | Y18: ='Rateio Custos Fixos'!L19 -> 17.426987 | Z18: ='Rateio Custos Fixos'!M19 -> 3.4543622 | ... AH18: ='Rateio Custos Fixos'!U19 -> 58.472276 | AI18: =SUM(S18:AH18) -> 205.8103 | AJ18: =K18+R18+AI18 -> 615.78709 | AK18: =IFERROR(AJ18/D18,0) -> 1.2315742 | AL18: =IFERROR(AJ18/D18,0) -> 1.2315742
B19: ='Lista de Compra'!B18 -> 6005-DDU | C19: ='Lista de Compra'!E18 -> 8466.93.50 | D19: ='Lista de Compra'!K18 -> 500 | E19: ='Lista de Compra'!P18 -> 0.033734005 | F19: ='Lista de Compra'!M18 -> 0.174 | G19: =D19*F19 -> 87 | H19: =G19*$H$4 -> 445.44 | I19: =$I$4*E19 -> 33.396665 | J19: ='Rateio Custos Fixos'!E20 -> 20.266311 | K19: =SUM(H19,J19) -> 465.70631 | L19: =K19+M19 -> 517.86542 | M19: =K19*IFERROR(VLOOKUP(C19,$C$5:$Q$5,11,FALSE()),0) -> 52.159107 | N19: =L19*IFERROR(VLOOKUP(C19,$C$5:$Q$5,12,FALSE()),0) -> 0 | O19: =L19*IFERROR(VLOOKUP(C19,$C$5:$Q$5,13,FALSE()),0) -> 10.875174 | P19: =L19*IFERROR(VLOOKUP(C19,$C$5:$Q$5,14,FALSE()),0) -> 55.152667 | Q19: =L19*IFERROR(VLOOKUP(C19,$C$5:$Q$5,15,FALSE()),0) -> 31.071925 | R19: =SUM(M19:Q19) -> 149.25887 | S19: ='Rateio Custos Fixos'!F20 -> 7.2359442 | T19: ='Rateio Custos Fixos'!G20 -> 0.33734005 | U19: ='Rateio Custos Fixos'!H20 -> 33.396665 | V19: ='Rateio Custos Fixos'!I20 -> 1.6192323 | W19: ='Rateio Custos Fixos'!J20 -> 4.1155487 | X19: ='Rateio Custos Fixos'!K20 -> 0.33734005 | Y19: ='Rateio Custos Fixos'!L20 -> 26.140481 | Z19: ='Rateio Custos Fixos'!M20 -> 5.1815432 | ... AH19: ='Rateio Custos Fixos'!U20 -> 87.708414 | AI19: =SUM(S19:AH19) -> 308.71545 | AJ19: =K19+R19+AI19 -> 923.68063 | AK19: =IFERROR(AJ19/D19,0) -> 1.8473613 | AL19: =IFERROR(AJ19/D19,0) -> 1.8473613
B20: ='Lista de Compra'!B19 -> 6006-DDU | C20: ='Lista de Compra'!E19 -> 8466.93.50 | D20: ='Lista de Compra'!K19 -> 500 | E20: ='Lista de Compra'!P19 -> 0.04691741 | F20: ='Lista de Compra'!M19 -> 0.242 | G20: =D20*F20 -> 121 | H20: =G20*$H$4 -> 619.52 | I20: =$I$4*E20 -> 46.448236 | J20: ='Rateio Custos Fixos'!E21 -> 28.186478 | K20: =SUM(H20,J20) -> 647.70648 | L20: =K20+M20 -> 720.2496 | M20: =K20*IFERROR(VLOOKUP(C20,$C$5:$Q$5,11,FALSE()),0) -> 72.543126 | N20: =L20*IFERROR(VLOOKUP(C20,$C$5:$Q$5,12,FALSE()),0) -> 0 | O20: =L20*IFERROR(VLOOKUP(C20,$C$5:$Q$5,13,FALSE()),0) -> 15.125242 | P20: =L20*IFERROR(VLOOKUP(C20,$C$5:$Q$5,14,FALSE()),0) -> 76.706583 | Q20: =L20*IFERROR(VLOOKUP(C20,$C$5:$Q$5,15,FALSE()),0) -> 43.214976 | R20: =SUM(M20:Q20) -> 207.58993 | S20: ='Rateio Custos Fixos'!F21 -> 10.063784 | T20: ='Rateio Custos Fixos'!G21 -> 0.4691741 | U20: ='Rateio Custos Fixos'!H21 -> 46.448236 | V20: ='Rateio Custos Fixos'!I21 -> 2.2520357 | W20: ='Rateio Custos Fixos'!J21 -> 5.723924 | X20: ='Rateio Custos Fixos'!K21 -> 0.4691741 | Y20: ='Rateio Custos Fixos'!L21 -> 36.356301 | Z20: ='Rateio Custos Fixos'!M21 -> 7.2065142 | ... AH20: ='Rateio Custos Fixos'!U21 -> 121.98527 | AI20: =SUM(S20:AH20) -> 429.36287 | AJ20: =K20+R20+AI20 -> 1284.6593 | AK20: =IFERROR(AJ20/D20,0) -> 2.5693185 | AL20: =IFERROR(AJ20/D20,0) -> 2.5693185
B21: ='Lista de Compra'!B20 -> 6301-DDU | C21: ='Lista de Compra'!E20 -> 8466.93.50 | D21: ='Lista de Compra'!K20 -> 500 | E21: ='Lista de Compra'!P20 -> 0.028111671 | F21: ='Lista de Compra'!M20 -> 0.145 | G21: =D21*F21 -> 72.5 | H21: =G21*$H$4 -> 371.2 | I21: =$I$4*E21 -> 27.830554 | J21: ='Rateio Custos Fixos'!E22 -> 16.888592 | K21: =SUM(H21,J21) -> 388.08859 | L21: =K21+M21 -> 431.55451 | M21: =K21*IFERROR(VLOOKUP(C21,$C$5:$Q$5,11,FALSE()),0) -> 43.465922 | N21: =L21*IFERROR(VLOOKUP(C21,$C$5:$Q$5,12,FALSE()),0) -> 0 | O21: =L21*IFERROR(VLOOKUP(C21,$C$5:$Q$5,13,FALSE()),0) -> 9.0626448 | P21: =L21*IFERROR(VLOOKUP(C21,$C$5:$Q$5,14,FALSE()),0) -> 45.960556 | Q21: =L21*IFERROR(VLOOKUP(C21,$C$5:$Q$5,15,FALSE()),0) -> 25.893271 | R21: =SUM(M21:Q21) -> 124.38239 | S21: ='Rateio Custos Fixos'!F22 -> 6.0299535 | T21: ='Rateio Custos Fixos'!G22 -> 0.28111671 | U21: ='Rateio Custos Fixos'!H22 -> 27.830554 | V21: ='Rateio Custos Fixos'!I22 -> 1.3493602 | W21: ='Rateio Custos Fixos'!J22 -> 3.4296239 | X21: ='Rateio Custos Fixos'!K22 -> 0.28111671 | Y21: ='Rateio Custos Fixos'!L22 -> 21.783734 | Z21: ='Rateio Custos Fixos'!M22 -> 4.3179527 | ... AH21: ='Rateio Custos Fixos'!U22 -> 73.090345 | AI21: =SUM(S21:AH21) -> 257.26287 | AJ21: =K21+R21+AI21 -> 769.73386 | AK21: =IFERROR(AJ21/D21,0) -> 1.5394677 | AL21: =IFERROR(AJ21/D21,0) -> 1.5394677
B22: ='Lista de Compra'!B21 -> 6302-DDU | C22: ='Lista de Compra'!E21 -> 8466.93.50 | D22: ='Lista de Compra'!K21 -> 500 | E22: ='Lista de Compra'!P21 -> 0.033734005 | F22: ='Lista de Compra'!M21 -> 0.174 | G22: =D22*F22 -> 87 | H22: =G22*$H$4 -> 445.44 | I22: =$I$4*E22 -> 33.396665 | J22: ='Rateio Custos Fixos'!E23 -> 20.266311 | K22: =SUM(H22,J22) -> 465.70631 | L22: =K22+M22 -> 517.86542 | M22: =K22*IFERROR(VLOOKUP(C22,$C$5:$Q$5,11,FALSE()),0) -> 52.159107 | N22: =L22*IFERROR(VLOOKUP(C22,$C$5:$Q$5,12,FALSE()),0) -> 0 | O22: =L22*IFERROR(VLOOKUP(C22,$C$5:$Q$5,13,FALSE()),0) -> 10.875174 | P22: =L22*IFERROR(VLOOKUP(C22,$C$5:$Q$5,14,FALSE()),0) -> 55.152667 | Q22: =L22*IFERROR(VLOOKUP(C22,$C$5:$Q$5,15,FALSE()),0) -> 31.071925 | R22: =SUM(M22:Q22) -> 149.25887 | S22: ='Rateio Custos Fixos'!F23 -> 7.2359442 | T22: ='Rateio Custos Fixos'!G23 -> 0.33734005 | U22: ='Rateio Custos Fixos'!H23 -> 33.396665 | V22: ='Rateio Custos Fixos'!I23 -> 1.6192323 | W22: ='Rateio Custos Fixos'!J23 -> 4.1155487 | X22: ='Rateio Custos Fixos'!K23 -> 0.33734005 | Y22: ='Rateio Custos Fixos'!L23 -> 26.140481 | Z22: ='Rateio Custos Fixos'!M23 -> 5.1815432 | ... AH22: ='Rateio Custos Fixos'!U23 -> 87.708414 | AI22: =SUM(S22:AH22) -> 308.71545 | AJ22: =K22+R22+AI22 -> 923.68063 | AK22: =IFERROR(AJ22/D22,0) -> 1.8473613 | AL22: =IFERROR(AJ22/D22,0) -> 1.8473613
... B30: ='Lista de Compra'!B29 -> 6010-DDU | C30: ='Lista de Compra'!E29 -> 8466.93.50 | D30: ='Lista de Compra'!K29 -> 500 | E30: ='Lista de Compra'!P29 -> 0.12000775 | F30: ='Lista de Compra'!M29 -> 0.619 | G30: =D30*F30 -> 309.5 | H30: =G30*$H$4 -> 1584.64 | I30: =$I$4*E30 -> 118.80768 | J30: ='Rateio Custos Fixos'!E31 -> 72.096819 | K30: =SUM(H30,J30) -> 1656.7368 | L30: =K30+M30 -> 1842.2913 | M30: =K30*IFERROR(VLOOKUP(C30,$C$5:$Q$5,11,FALSE()),0) -> 185.55452 | N30: =L30*IFERROR(VLOOKUP(C30,$C$5:$Q$5,12,FALSE()),0) -> 0 | O30: =L30*IFERROR(VLOOKUP(C30,$C$5:$Q$5,13,FALSE()),0) -> 38.688118 | P30: =L30*IFERROR(VLOOKUP(C30,$C$5:$Q$5,14,FALSE()),0) -> 196.20403 | Q30: =L30*IFERROR(VLOOKUP(C30,$C$5:$Q$5,15,FALSE()),0) -> 110.53748 | R30: =SUM(M30:Q30) -> 530.98415 | S30: ='Rateio Custos Fixos'!F31 -> 25.741663 | T30: ='Rateio Custos Fixos'!G31 -> 1.2000775 | U30: ='Rateio Custos Fixos'!H31 -> 118.80768 | V30: ='Rateio Custos Fixos'!I31 -> 5.7603722 | W30: ='Rateio Custos Fixos'!J31 -> 14.640946 | X30: ='Rateio Custos Fixos'!K31 -> 1.2000775 | Y30: ='Rateio Custos Fixos'!L31 -> 92.994009 | Z30: ='Rateio Custos Fixos'!M31 -> 18.433191 | ... AH30: ='Rateio Custos Fixos'!U31 -> 312.02016 | AI30: =SUM(S30:AH30) -> 1098.2463 | AJ30: =K30+R30+AI30 -> 3285.9673 | AK30: =IFERROR(AJ30/D30,0) -> 6.5719346 | AL30: =IFERROR(AJ30/D30,0) -> 6.5719346

Sheet Rateio Custos Fixos
A3: CÂMBIO | F3: FRETE | G3: R$
F4: =106.4 -> 106.4 | G4: =F4*B5 -> 544.768
B5: =5.12 -> 5.12 | F5: 56 | G5: =F5 -> 56
F6: TOTAL | G6: =SUM(G4:G5) -> 600.768
G7: =IFERROR(G6/$B$5,0) -> 117.3375
A10: Produto | B10: Quantidade | C10: ='Lista de Compra'!P8 -> % Rateio Preço | E10: FRETE | F10: TAXA SISCOMEX | G10: LIBERAÇÃO DE B/L | H10: T.H.C| CAPATAZIA | I10: ISPS | J10: DAMAGE PROTECTION | K10: DESCONSOLIDAÇÃO | L10: DEVOLUÇÃO DE CONTAINER | M10: TRS | N10: AFRMM | O10: ARMAZENAGEM TCP | P10: SCANNER TCP | Q10: HANDLING - TCP | R10: PESAGEM TCP | S10: TAXA DO PARCEIRO - PARANAGUÁ | T10: FRETE RODOVIÁRIO | U10: DESEMBARAÇO ADUANEIRO
B11: =SUM(B12:B31) -> 10000 | C11: =SUM(C12:C31) -> 1 | E11: =G6 -> 600.768 | F11: 214.5 | G11: 10 | H11: 990 | I11: 48 | J11: 122 | K11: 10 | L11: 774.9 | M11: 153.6 | N11: 0.08 | O11: 0 | P11: 756.95 | Q11: 20 | R11: 117.45 | S11: 286 | T11: 3000 | U11: 2600
A12: ='Lista de Compra'!B10 -> 6201-DDU | B12: ='Lista de Compra'!K10 -> 500 | C12: ='Lista de Compra'!P10 -> 0.019581233 | E12: =E$11*$C12 -> 11.763778 | F12: =F$11*$C12 -> 4.2001745 | G12: =G$11*$C12 -> 0.19581233 | H12: =H$11*$C12 -> 19.385421 | I12: =I$11*$C12 -> 0.93989919 | J12: =J$11*$C12 -> 2.3889104 | K12: =K$11*$C12 -> 0.19581233 | L12: =L$11*$C12 -> 15.173497 | M12: =M$11*$C12 -> 3.0076774 | N12: =E12*$N$11 -> 0.94110226 | O12: =O$11*$C12 -> 0 | P12: =P$11*$C12 -> 14.822014 | Q12: =Q$11*$C12 -> 0.39162466 | R12: =R$11*$C12 -> 2.2998158 | S12: =S$11*$C12 -> 5.6002326 | T12: =T$11*$C12 -> 58.743699 | U12: =U$11*$C12 -> 50.911206
A13: ='Lista de Compra'!B11 -> 6204-DDU | B13: ='Lista de Compra'!K11 -> 500 | C13: ='Lista de Compra'!P11 -> 0.032183017 | E13: =E$11*$C13 -> 19.334527 | F13: =F$11*$C13 -> 6.9032571 | G13: =G$11*$C13 -> 0.32183017 | H13: =H$11*$C13 -> 31.861187 | I13: =I$11*$C13 -> 1.5447848 | J13: =J$11*$C13 -> 3.926328 | K13: =K$11*$C13 -> 0.32183017 | L13: =L$11*$C13 -> 24.93862 | M13: =M$11*$C13 -> 4.9433114 | N13: =E13*$N$11 -> 1.5467621 | O13: =O$11*$C13 -> 0 | P13: =P$11*$C13 -> 24.360934 | Q13: =Q$11*$C13 -> 0.64366033 | R13: =R$11*$C13 -> 3.7798953 | S13: =S$11*$C13 -> 9.2043428 | T13: =T$11*$C13 -> 96.54905 | U13: =U$11*$C13 -> 83.675843
A14: ='Lista de Compra'!B12 -> 6205-DDU | B14: ='Lista de Compra'!K12 -> 500 | C14: ='Lista de Compra'!P12 -> 0.03935634 | E14: =E$11*$C14 -> 23.644029 | F14: =F$11*$C14 -> 8.4419349 | G14: =G$11*$C14 -> 0.3935634 | H14: =H$11*$C14 -> 38.962776 | I14: =I$11*$C14 -> 1.8891043 | J14: =J$11*$C14 -> 4.8014734 | K14: =K$11*$C14 -> 0.3935634 | L14: =L$11*$C14 -> 30.497228 | M14: =M$11*$C14 -> 6.0451338 | N14: =E14*$N$11 -> 1.8915224 | O14: =O$11*$C14 -> 0 | P14: =P$11*$C14 -> 29.790781 | Q14: =Q$11*$C14 -> 0.78712679 | R14: =R$11*$C14 -> 4.6224021 | S14: =S$11*$C14 -> 11.255913 | T14: =T$11*$C14 -> 118.06902 | U14: =U$11*$C14 -> 102.32648
A15: ='Lista de Compra'!B13 -> 6206-DDU | B15: ='Lista de Compra'!K13 -> 500 | C15: ='Lista de Compra'!P13 -> 0.058162078 | E15: =E$11*$C15 -> 34.941915 | F15: =F$11*$C15 -> 12.475766 | G15: =G$11*$C15 -> 0.58162078 | H15: =H$11*$C15 -> 57.580458 | I15: =I$11*$C15 -> 2.7917798 | J15: =J$11*$C15 -> 7.0957736 | K15: =K$11*$C15 -> 0.58162078 | L15: =L$11*$C15 -> 45.069794 | M15: =M$11*$C15 -> 8.9336952 | N15: =E15*$N$11 -> 2.7953532 | O15: =O$11*$C15 -> 0 | P15: =P$11*$C15 -> 44.025785 | Q15: =Q$11*$C15 -> 1.1632416 | R15: =R$11*$C15 -> 6.8311361 | S15: =S$11*$C15 -> 16.634354 | T15: =T$11*$C15 -> 174.48623 | U15: =U$11*$C15 -> 151.2214
A16: ='Lista de Compra'!B14 -> 6004-DDU | B16: ='Lista de Compra'!K14 -> 500 | C16: ='Lista de Compra'!P14 -> 0.02694843 | E16: =E$11*$C16 -> 16.189754 | F16: =F$11*$C16 -> 5.7804382 | G16: =G$11*$C16 -> 0.2694843 | H16: =H$11*$C16 -> 26.678945 | I16: =I$11*$C16 -> 1.2935246 | J16: =J$11*$C16 -> 3.2877084 | K16: =K$11*$C16 -> 0.2694843 | L16: =L$11*$C16 -> 20.882338 | M16: =M$11*$C16 -> 4.1392788 | N16: =E16*$N$11 -> 1.2951803 | O16: =O$11*$C16 -> 0 | P16: =P$11*$C16 -> 20.398614 | Q16: =Q$11*$C16 -> 0.53896859 | R16: =R$11*$C16 -> 3.1650931 | S16: =S$11*$C16 -> 7.7072509 | T16: =T$11*$C16 -> 80.845289 | U16: =U$11*$C16 -> 70.065917
A17: ='Lista de Compra'!B15 -> 6001-DDU | B17: ='Lista de Compra'!K15 -> 500 | C17: ='Lista de Compra'!P15 -> 0.016091508 | E17: =E$11*$C17 -> 9.6672633 | F17: =F$11*$C17 -> 3.4516285 | G17: =G$11*$C17 -> 0.16091508 | H17: =H$11*$C17 -> 15.930593 | I17: =I$11*$C17 -> 0.7723924 | J17: =J$11*$C17 -> 1.963164 | K17: =K$11*$C17 -> 0.16091508 | L17: =L$11*$C17 -> 12.46931 | M17: =M$11*$C17 -> 2.4716557 | N17: =E17*$N$11 -> 0.77338106 | O17: =O$11*$C17 -> 0 | P17: =P$11*$C17 -> 12.180467 | Q17: =Q$11*$C17 -> 0.32183017 | R17: =R$11*$C17 -> 1.8899477 | S17: =S$11*$C17 -> 4.6021714 | T17: =T$11*$C17 -> 48.274525 | U17: =U$11*$C17 -> 41.837922
A18: ='Lista de Compra'!B16 -> 6002-DDU | B18: ='Lista de Compra'!K16 -> 500 | C18: ='Lista de Compra'!P16 -> 0.019581233 | E18: =E$11*$C18 -> 11.763778 | F18: =F$11*$C18 -> 4.2001745 | G18: =G$11*$C18 -> 0.19581233 | H18: =H$11*$C18 -> 19.385421 | I18: =I$11*$C18 -> 0.93989919 | J18: =J$11*$C18 -> 2.3889104 | K18: =K$11*$C18 -> 0.19581233 | L18: =L$11*$C18 -> 15.173497 | M18: =M$11*$C18 -> 3.0076774 | N18: =E18*$N$11 -> 0.94110226 | O18: =O$11*$C18 -> 0 | P18: =P$11*$C18 -> 14.822014 | Q18: =Q$11*$C18 -> 0.39162466 | R18: =R$11*$C18 -> 2.2998158 | S18: =S$11*$C18 -> 5.6002326 | T18: =T$11*$C18 -> 58.743699 | U18: =U$11*$C18 -> 50.911206
A19: ='Lista de Compra'!B17 -> 6003-DDU | B19: ='Lista de Compra'!K17 -> 500 | C19: ='Lista de Compra'!P17 -> 0.022489337 | E19: =E$11*$C19 -> 13.510874 | F19: =F$11*$C19 -> 4.8239628 | G19: =G$11*$C19 -> 0.22489337 | H19: =H$11*$C19 -> 22.264444 | I19: =I$11*$C19 -> 1.0794882 | J19: =J$11*$C19 -> 2.7436991 | K19: =K$11*$C19 -> 0.22489337 | L19: =L$11*$C19 -> 17.426987 | M19: =M$11*$C19 -> 3.4543622 | N19: =E19*$N$11 -> 1.0808699 | O19: =O$11*$C19 -> 0 | P19: =P$11*$C19 -> 17.023304 | Q19: =Q$11*$C19 -> 0.44978674 | R19: =R$11*$C19 -> 2.6413726 | S19: =S$11*$C19 -> 6.4319504 | T19: =T$11*$C19 -> 67.468011 | U19: =U$11*$C19 -> 58.472276
A20: ='Lista de Compra'!B18 -> 6005-DDU | B20: ='Lista de Compra'!K18 -> 500 | C20: ='Lista de Compra'!P18 -> 0.033734005 | E20: =E$11*$C20 -> 20.266311 | F20: =F$11*$C20 -> 7.2359442 | G20: =G$11*$C20 -> 0.33734005 | H20: =H$11*$C20 -> 33.396665 | I20: =I$11*$C20 -> 1.6192323 | J20: =J$11*$C20 -> 4.1155487 | K20: =K$11*$C20 -> 0.33734005 | L20: =L$11*$C20 -> 26.140481 | M20: =M$11*$C20 -> 5.1815432 | N20: =E20*$N$11 -> 1.6213049 | O20: =O$11*$C20 -> 0 | P20: =P$11*$C20 -> 25.534955 | Q20: =Q$11*$C20 -> 0.67468011 | R20: =R$11*$C20 -> 3.9620589 | S20: =S$11*$C20 -> 9.6479256 | T20: =T$11*$C20 -> 101.20202 | U20: =U$11*$C20 -> 87.708414
A21: ='Lista de Compra'!B19 -> 6006-DDU | B21: ='Lista de Compra'!K19 -> 500 | C21: ='Lista de Compra'!P19 -> 0.04691741 | E21: =E$11*$C21 -> 28.186478 | F21: =F$11*$C21 -> 10.063784 | G21: =G$11*$C21 -> 0.4691741 | H21: =H$11*$C21 -> 46.448236 | I21: =I$11*$C21 -> 2.2520357 | J21: =J$11*$C21 -> 5.723924 | K21: =K$11*$C21 -> 0.4691741 | L21: =L$11*$C21 -> 36.356301 | M21: =M$11*$C21 -> 7.2065142 | N21: =E21*$N$11 -> 2.2549183 | O21: =O$11*$C21 -> 0 | P21: =P$11*$C21 -> 35.514133 | Q21: =Q$11*$C21 -> 0.9383482 | R21: =R$11*$C21 -> 5.5104498 | S21: =S$11*$C21 -> 13.418379 | T21: =T$11*$C21 -> 140.75223 | U21: =U$11*$C21 -> 121.98527
A22: ='Lista de Compra'!B20 -> 6301-DDU | B22: ='Lista de Compra'!K20 -> 500 | C22: ='Lista de Compra'!P20 -> 0.028111671 | E22: =E$11*$C22 -> 16.888592 | F22: =F$11*$C22 -> 6.0299535 | G22: =G$11*$C22 -> 0.28111671 | H22: =H$11*$C22 -> 27.830554 | I22: =I$11*$C22 -> 1.3493602 | J22: =J$11*$C22 -> 3.4296239 | K22: =K$11*$C22 -> 0.28111671 | L22: =L$11*$C22 -> 21.783734 | M22: =M$11*$C22 -> 4.3179527 | N22: =E22*$N$11 -> 1.3510874 | O22: =O$11*$C22 -> 0 | P22: =P$11*$C22 -> 21.27913 | Q22: =Q$11*$C22 -> 0.56223342 | R22: =R$11*$C22 -> 3.3017158 | S22: =S$11*$C22 -> 8.039938 | T22: =T$11*$C22 -> 84.335014 | U22: =U$11*$C22 -> 73.090345
A23: ='Lista de Compra'!B21 -> 6302-DDU | B23: ='Lista de Compra'!K21 -> 500 | C23: ='Lista de Compra'!P21 -> 0.033734005 | E23: =E$11*$C23 -> 20.266311 | F23: =F$11*$C23 -> 7.2359442 | G23: =G$11*$C23 -> 0.33734005 | H23: =H$11*$C23 -> 33.396665 | I23: =I$11*$C23 -> 1.6192323 | J23: =J$11*$C23 -> 4.1155487 | K23: =K$11*$C23 -> 0.33734005 | L23: =L$11*$C23 -> 26.140481 | M23: =M$11*$C23 -> 5.1815432 | N23: =E23*$N$11 -> 1.6213049 | O23: =O$11*$C23 -> 0 | P23: =P$11*$C23 -> 25.534955 | Q23: =Q$11*$C23 -> 0.67468011 | R23: =R$11*$C23 -> 3.9620589 | S23: =S$11*$C23 -> 9.6479256 | T23: =T$11*$C23 -> 101.20202 | U23: =U$11*$C23 -> 87.708414
... A31: ='Lista de Compra'!B29 -> 6010-DDU | B31: ='Lista de Compra'!K29 -> 500 | C31: ='Lista de Compra'!P29 -> 0.12000775 | E31: =E$11*$C31 -> 72.096819 | F31: =F$11*$C31 -> 25.741663 | G31: =G$11*$C31 -> 1.2000775 | H31: =H$11*$C31 -> 118.80768 | I31: =I$11*$C31 -> 5.7603722 | J31: =J$11*$C31 -> 14.640946 | K31: =K$11*$C31 -> 1.2000775 | L31: =L$11*$C31 -> 92.994009 | M31: =M$11*$C31 -> 18.433191 | N31: =E31*$N$11 -> 5.7677455 | O31: =O$11*$C31 -> 0 | P31: =P$11*$C31 -> 90.83987 | Q31: =Q$11*$C31 -> 2.4001551 | R31: =R$11*$C31 -> 14.094911 | S31: =S$11*$C31 -> 34.322218 | T31: =T$11*$C31 -> 360.02326 | U31: =U$11*$C31 -> 312.02016
