Workbook

Sheet Resumo 100%
B3: Estimativa de Custo 100%
J4: =SUM(J6:J24) -> 457 | K4: =SUM(K6:K24) -> 6565 | M4: =SUM(M6:M24) -> 84046.944
J6: 75 | K6: 269
J7: 50 | K7: 269
C8: REGIME TRIBUTÁRIO: LUCRO REAL/PRESUMIDO | E8: USO: REVENDA | G8: CONSIDERAR ICMS 2,6% | J8: 20 | K8: 456
C9: PRODUTO: COOLER | E9: PORTO SAÍDA: SHANGHAI | G9: =TODAY() -> 45987 | J9: 34 | K9: 456
C10: FRETE: 4x40HC | E10: PORTO ENTRADA:ITAPOA | G10: SIMULAÇÃO 100% | J10: 15 | K10: 823
J11: 12 | K11: 818
B12: REFERÊNCIA CÁLCULO BASE | C12: R$/USD: | D12: ='Rateio Custos Fixos'!B3 -> 5.3797 | J12: 40 | K12: 234
B13: VALORES ADUANEIROS | I13: ITEM | J13: 20 | K13: 234 | L13: QTY | O13: BRL UNIT PRICE
B14: DISCRIMINAÇÃO | C14: QUANTIDADE | F14: PREÇO TOTAL USD | G14: R$ | I14: ='[1]Lista de Compra'!B4 -> 1 | J14: 20 | K14: 332 | L14: ='[1]Lista de Compra'!J4 -> 15 | M14: =K14*L14*'[1]Rateio Custos Fixos'!$B$26 -> 23890.056 | N14: =M14+(M14*$K$11) -> 19565956 | O14: =N14/L14 -> 1304397.1
C15: ='LISTA DE COMPRAS'!J4 -> 462 | F15: ='LISTA DE COMPRAS'!M4 -> 152021 | G15: ='Est. Cust. Naci.'!L4 -> 817827.37 | J15: 34 | K15: 332
B16: TOTAL FOB | F16: =SUM(F15:F15) -> 152021 | G16: =SUM(G15:G15) -> 817827.37 | J16: 14 | K16: 730
B17: PRODUTO + FRETE | G17: =G16+G19 -> 875174.97 | I17: ='[1]Lista de Compra'!B6 -> 3 | J17: 45 | K17: 240 | L17: ='[1]Lista de Compra'!J6 -> 15 | M17: =K17*L17*'[1]Rateio Custos Fixos'!$B$26 -> 17269.92 | N17: =M17+(M17*$K$11) -> 14144064 | O17: =N17/L17 -> 942937.63
B18: Seguro | I18: ='[1]Lista de Compra'!B7 -> 4 | J18: 20 | K18: 240 | L18: ='[1]Lista de Compra'!J7 -> 15 | M18: =K18*L18*'[1]Rateio Custos Fixos'!$B$26 -> 17269.92 | N18: =M18+(M18*$K$11) -> 14144064 | O18: =N18/L18 -> 942937.63
B19: Frete | F19: ='Rateio Custos Fixos'!G5 -> 10660 | G19: =F19*D12 -> 57347.6 | I19: ='[1]Lista de Compra'!B8 -> 5 | J19: 36 | K19: 243 | L19: ='[1]Lista de Compra'!J8 -> 15 | M19: =K19*L19*'[1]Rateio Custos Fixos'!$B$26 -> 17485.794 | N19: =M19+(M19*$K$11) -> 14320865 | O19: =N19/L19 -> 954724.35
B20: TOTAL VALOR ADUANEIRO | G20: =G17 -> 875174.97 | I20: ='[1]Lista de Compra'!B9 -> 6 | J20: 5 | K20: 113 | L20: ='[1]Lista de Compra'!J9 -> 15 | M20: =K20*L20*'[1]Rateio Custos Fixos'!$B$26 -> 8131.254 | N20: =M20+(M20*$K$11) -> 6659497 | O20: =N20/L20 -> 443966.47
B21: IMPOSTOS | J21: 2 | K21: 339
B22: IMPOSTOS | C22: PERCENTUAL | G22: VALOR (R$) | J22: 13 | K22: 243
B23: IMPOSTO. IMPORTAÇÃO | G23: ='Est. Cust. Naci.'!R4 -> 110509.29 | K23: 95
B24: IPI | C24: SPARE PARTS | G24: ='Est. Cust. Naci.'!S4 -> 96287.798 | J24: 2 | K24: 99
B25: COFINS | G25: ='Est. Cust. Naci.'!U4 -> 84636.084
B26: ICMS | G26: ='Est. Cust. Naci.'!V4 -> 35082.315
B27: TOTAL VALOR IMPOSTOS | G27: =SUM(G23:G26) -> 326515.49
B28: TAXAS PORTUÁRIAS
B29: ='Rateio Custos Fixos'!F10 -> TAXA SISCOMEX | G29: ='Rateio Custos Fixos'!F11 -> 224
B30: ='Rateio Custos Fixos'!G10 -> ANUENCIA DE LI | G30: ='Rateio Custos Fixos'!G11 -> 107.06
B31: ='Rateio Custos Fixos'!H10 -> DIFERENÇA DO VALOR DO FRETE | G31: ='Rateio Custos Fixos'!H11 -> 11657.97
B32: ='Rateio Custos Fixos'!I10 -> T.H.C| CAPATAZIA | G32: ='Rateio Custos Fixos'!I11 -> 0
B33: ='Rateio Custos Fixos'!J10 -> LICENÇA DE IMPORTAÇÃO | G33: ='Rateio Custos Fixos'!J11 -> 130
B34: ='Rateio Custos Fixos'!K10 -> ISPS | G34: ='Rateio Custos Fixos'!K11 -> 0
B35: ='Rateio Custos Fixos'!L10 -> DAMAGE PROTECTION | G35: ='Rateio Custos Fixos'!L11 -> 0
B36: ='Rateio Custos Fixos'!M10 -> DESCONSOLIDAÇÃO | G36: ='Rateio Custos Fixos'!M11 -> 0
B37: ='Rateio Custos Fixos'!N10 -> SERVIÇO DE ENTREGA DE CONTAINER | G37: ='Rateio Custos Fixos'!N11 -> 0
B38: ='Rateio Custos Fixos'!O10 -> Delivery order | G38: ='Rateio Custos Fixos'!O11 -> 0
B39: ='Rateio Custos Fixos'!P10 -> AFRMM | C39: 0.08 | G39: ='Rateio Custos Fixos'!P24 -> 226.01732
B40: ='Rateio Custos Fixos'!Q10 -> ARMAZENAGEM | G40: ='Rateio Custos Fixos'!Q11 -> 24000
B41: ='Rateio Custos Fixos'!R10 -> Import logistic fee | G41: ='Rateio Custos Fixos'!R11 -> 0
B42: ='Rateio Custos Fixos'!S10 -> Drop off | G42: ='Rateio Custos Fixos'!S11 -> 0
B43: ='Rateio Custos Fixos'!T10 -> TAXA | G43: ='Rateio Custos Fixos'!T11 -> 0
...

Sheet LISTA DE COMPRAS
A1: LISTA DE COMPRA
A3: Item | B3: Estimativa de Custo 100% | C3: Produto | D3: NCM | E3: II | F3: IPI | G3: PIS | H3: COFINS | I3: ICMS | J3: Quantidade | K3: Preço Unitário | L3: Preço Unitário Sub 50% | M3: Preço total por produto | N3: Preço total por produto | O3: Preço total por produto Sub | P3: % Rateio Quantidade | Q3: % Rateio Preço | R3: Preço nacionalizado | S3: Preço R$ Rolo nancionalizado
J4: =SUM(J6:J24) -> 462 | K4: =SUM(K6:K24) -> 6565 | M4: =SUM(M6:M24) -> 152021 | N4: =F28 -> 5.3797 | P4: 1 | Q4: 1
A6: 1 | C6: BAC 51 LR (127V) | D6: 84186999 | E6: 0.126 | F6: 0.0975 | G6: 0.021 | H6: 0.0965 | I6: 0.04 | J6: 75 | K6: 269 | L6: =K6/2 -> 134.5 | M6: =K6*J6 -> 20175 | N6: =M6*$N$4 -> 108535.45 | O6: =L6*J6*$N$4 -> 54267.724 | P6: =(J6*$P$4)/$J$4 -> 0.16233766 | Q6: =(K6*$Q$4)/$K$4 -> 0.040974867 | R6: ='Est. Cust. Naci.'!AV7 -> 2261.3488 | S6: ='Resumo 100%'!G50 -> 2261.3488
A7: 2 | C7: BAC 51 RL (127V) | D7: 84186999 | E7: 0.126 | F7: 0.0975 | G7: 0.021 | H7: 0.0965 | I7: 0.04 | J7: 50 | K7: 269 | M7: =K7*J7 -> 13450 | N7: =M7*$N$4 -> 72356.965 | P7: =(J7*$P$4)/$J$4 -> 0.10822511 | Q7: =(K7*$Q$4)/$K$4 -> 0.040974867 | R7: ='Est. Cust. Naci.'!AV8 -> 2261.3488 | S7: ='Resumo 100%'!G51 -> 2261.3488
A8: 3 | C8: BAC 209A (220V) | D8: 84186999 | E8: 0.126 | F8: 0.0975 | G8: 0.021 | H8: 0.0965 | I8: 0.026 | J8: 20 | K8: 456 | M8: =K8*J8 -> 9120 | N8: =M8*$N$4 -> 49062.864 | P8: =(J8*$P$4)/$J$4 -> 0.043290043 | Q8: =(K8*$Q$4)/$K$4 -> 0.069459254 | R8: ='Est. Cust. Naci.'!AV9 -> 3833.3645 | S8: ='Resumo 100%'!G52 -> 3833.3645
A9: 4 | C9: BAC 209 (127V) | D9: 84186999 | E9: 0.126 | F9: 0.0975 | G9: 0.021 | H9: 0.0965 | I9: 0.026 | J9: 34 | K9: 456 | M9: =K9*J9 -> 15504 | N9: =M9*$N$4 -> 83406.869 | P9: =(J9*$P$4)/$J$4 -> 0.073593074 | Q9: =(K9*$Q$4)/$K$4 -> 0.069459254 | R9: ='Est. Cust. Naci.'!AV10 -> 3833.3645 | S9: ='Resumo 100%'!G53 -> 3833.3645
A10: 5 | C10: BAC 218SA (220V) | D10: 84186999 | E10: 0.126 | F10: 0.0975 | G10: 0.021 | H10: 0.0965 | I10: 0.026 | J10: 15 | K10: 823 | M10: =K10*J10 -> 12345 | N10: =M10*$N$4 -> 66412.397 | P10: =(J10*$P$4)/$J$4 -> 0.032467532 | Q10: =(K10*$Q$4)/$K$4 -> 0.12536177 | R10: ='Est. Cust. Naci.'!AV11 -> 6918.5504 | S10: ='Resumo 100%'!G54 -> 6918.5504
A11: 6 | C11: BAC 218BA (220V) | D11: 84186999 | E11: 0.126 | F11: 0.0975 | G11: 0.021 | H11: 0.0965 | I11: 0.026 | J11: 12 | K11: 818 | M11: =K11*J11 -> 9816 | N11: =M11*$N$4 -> 52807.135 | P11: =(J11*$P$4)/$J$4 -> 0.025974026 | Q11: =(K11*$Q$4)/$K$4 -> 0.12460015 | R11: ='Est. Cust. Naci.'!AV12 -> 6876.5179 | S11: ='Resumo 100%'!G55 -> 6876.5179
A12: 7 | C12: BAC 28 (127V) | D12: 84186999 | E12: 0.126 | F12: 0.0975 | G12: 0.021 | H12: 0.0965 | I12: 0.026 | J12: 40 | K12: 234 | M12: =K12*J12 -> 9360 | N12: =M12*$N$4 -> 50353.992 | P12: =(J12*$P$4)/$J$4 -> 0.086580087 | Q12: =(K12*$Q$4)/$K$4 -> 0.035643564 | R12: ='Est. Cust. Naci.'!AV13 -> 1967.1213 | S12: ='Resumo 100%'!G56 -> 1967.1213
A13: 8 | C13: BAC 28A (220V) | D13: 84186999 | E13: 0.126 | F13: 0.0975 | G13: 0.021 | H13: 0.0965 | I13: 0.026 | J13: 20 | K13: 234 | M13: =K13*J13 -> 4680 | N13: =M13*$N$4 -> 25176.996 | P13: =(J13*$P$4)/$J$4 -> 0.043290043 | Q13: =(K13*$Q$4)/$K$4 -> 0.035643564 | R13: ='Est. Cust. Naci.'!AV14 -> 1967.1213 | S13: ='Resumo 100%'!G57 -> 1967.1213
A14: 9 | C14: BAC 120A (220V) | D14: 84186999 | E14: 0.126 | F14: 0.0975 | G14: 0.021 | H14: 0.0965 | I14: 0.026 | J14: 20 | K14: 332 | M14: =K14*J14 -> 6640 | N14: =M14*$N$4 -> 35721.208 | P14: =(J14*$P$4)/$J$4 -> 0.043290043 | Q14: =(K14*$Q$4)/$K$4 -> 0.050571211 | R14: ='Est. Cust. Naci.'!AV15 -> 2790.9584 | S14: ='Resumo 100%'!G58 -> 2790.9584
A15: 10 | C15: BAC 120 (127V) | D15: 84186999 | E15: 0.126 | F15: 0.0975 | G15: 0.021 | H15: 0.0965 | I15: 0.026 | J15: 34 | K15: 332 | M15: =K15*J15 -> 11288 | N15: =M15*$N$4 -> 60726.054 | P15: =(J15*$P$4)/$J$4 -> 0.073593074 | Q15: =(K15*$Q$4)/$K$4 -> 0.050571211 | R15: ='Est. Cust. Naci.'!AV16 -> 2790.9584 | S15: ='Resumo 100%'!G59 -> 2790.9584
A16: 11 | C16: BAC111 (220V) | D16: 84186999 | E16: 0.126 | F16: 0.0975 | G16: 0.021 | H16: 0.0965 | I16: 0.026 | J16: 14 | K16: 730 | M16: =K16*J16 -> 10220 | N16: =M16*$N$4 -> 54980.534 | P16: =(J16*$P$4)/$J$4 -> 0.03030303 | Q16: =(K16*$Q$4)/$K$4 -> 0.11119573 | R16: ='Est. Cust. Naci.'!AV17 -> 6136.7458 | S16: ='Resumo 100%'!G60 -> 6136.7458
A17: 12 | C17: BEC 100GD (127V) | D17: 84186999 | E17: 0.126 | F17: 0.0975 | G17: 0.021 | H17: 0.0965 | I17: 0.026 | J17: 45 | K17: 240 | M17: =K17*J17 -> 10800 | N17: =M17*$N$4 -> 58100.76 | P17: =(J17*$P$4)/$J$4 -> 0.097402597 | Q17: =(K17*$Q$4)/$K$4 -> 0.036557502 | R17: ='Est. Cust. Naci.'!AV18 -> 2017.5603 | S17: ='Resumo 100%'!G61 -> 2017.5603
A18: 13 | C18: BEC 100GDA (220V) | D18: 84186999 | E18: 0.126 | F18: 0.0975 | G18: 0.021 | H18: 0.0965 | I18: 0.026 | J18: 20 | K18: 240 | M18: =K18*J18 -> 4800 | N18: =M18*$N$4 -> 25822.56 | P18: =(J18*$P$4)/$J$4 -> 0.043290043 | Q18: =(K18*$Q$4)/$K$4 -> 0.036557502 | R18: ='Est. Cust. Naci.'!AV19 -> 2017.5603
A19: 14 | C19: BEC 100SD (127V) | D19: 84186999 | E19: 0.126 | F19: 0.0975 | G19: 0.021 | H19: 0.0965 | I19: 0.026 | J19: 36 | K19: 243 | M19: =K19*J19 -> 8748 | N19: =M19*$N$4 -> 47061.616 | P19: =(J19*$P$4)/$J$4 -> 0.077922078 | Q19: =(K19*$Q$4)/$K$4 -> 0.037014471 | R19: ='Est. Cust. Naci.'!AV20 -> 2042.7798
A20: 15 | C20: UCH50BA (220V) | D20: 84186999 | E20: 0.126 | F20: 0.0975 | G20: 0.021 | H20: 0.0965 | I20: 0.026 | J20: 5 | K20: 113 | M20: =K20*J20 -> 565 | N20: =M20*$N$4 -> 3039.5305 | P20: =(J20*$P$4)/$J$4 -> 0.010822511 | Q20: =(K20*$Q$4)/$K$4 -> 0.01721249 | R20: ='Est. Cust. Naci.'!AV21 -> 949.93462
A21: 16 | C21: UCH150SA (220V) | D21: 84186999 | E21: 0.126 | F21: 0.0975 | G21: 0.021 | H21: 0.0965 | I21: 0.026 | J21: 2 | K21: 339 | M21: =K21*J21 -> 678 | N21: =M21*$N$4 -> 3647.4366 | P21: =(J21*$P$4)/$J$4 -> 0.0043290043 | Q21: =(K21*$Q$4)/$K$4 -> 0.051637471 | R21: ='Est. Cust. Naci.'!AV22 -> 2849.8039
A22: 17 | C22: BEC 100SDA (220V) | D22: 84186999 | E22: 0.126 | F22: 0.0975 | G22: 0.021 | H22: 0.0965 | I22: 0.026 | J22: 13 | K22: 243 | M22: =K22*J22 -> 3159 | N22: =M22*$N$4 -> 16994.472 | P22: =(J22*$P$4)/$J$4 -> 0.028138528 | Q22: =(K22*$Q$4)/$K$4 -> 0.037014471 | R22: ='Est. Cust. Naci.'!AV23 -> 2042.7798
A23: 18 | C23: SPARE PARTS | D23: 84186999 | E23: 0.126 | F23: 0.0975 | G23: 0.021 | H23: 0.0965 | I23: 0.026 | J23: 5 | K23: 95 | M23: =K23*J23 -> 475 | N23: =M23*$N$4 -> 2555.3575 | P23: =(J23*$P$4)/$J$4 -> 0.010822511 | Q23: =(K23*$Q$4)/$K$4 -> 0.014470678 | R23: ='Est. Cust. Naci.'!AV24 -> 798.6176
C24: SPARE PARTS | D24: 84186999 | E24: 0.126 | F24: 0.0975 | G24: 0.021 | H24: 0.0965 | I24: 0.026 | J24: 2 | K24: 99 | M24: =K24*J24 -> 198 | N24: =M24*$N$4 -> 1065.1806 | P24: =(J24*$P$4)/$J$4 -> 0.0043290043 | Q24: =(K24*$Q$4)/$K$4 -> 0.01507997 | R24: ='Est. Cust. Naci.'!AV25 -> 832.24361
E28: #VALUE! | F28: 5.3797

Sheet Est. Cust. Naci.
C2: DETALHES DO PRODUTO | L2: VALOR ADUANEIRO | R2: IMPOSTOS | Y2: TAXAS PORTUÁRIAS
B3: Nº | C3: ITEM | D3: Código | E3: Bitola (mm) | F3: Embal. | G3: NCM | H3: QTD | I3: % Rateio Preço | J3: Preço unitário Fábrica (USD) | K3: Preço x QTD (Valor em USD) | L3: Preço x QTD (valor em BRL) | M3: Preço x QTD (valor em BRL) SUB | N3: THC (valor em BRL) | O3: Valor do frete (Valor em BRL) | P3: TOTAL VALOR ADUANEIRO | Q3: TOTAL VALOR COM I.I | R3: IMPOSTO DE IMPORTAÇÃO | S3: IPI | T3: PIS | U3: COFINS | V3: ICMS | W3: TOTAL IMPOSTOS | X3: TOTAL IMPOSTOS (SUB) | Y3: ='Rateio Custos Fixos'!F10 -> TAXA SISCOMEX | Z3: ='Rateio Custos Fixos'!G10 -> ANUENCIA DE LI | AA3: ='Rateio Custos Fixos'!H10 -> DIFERENÇA DO VALOR DO FRETE | AB3: ='Rateio Custos Fixos'!I10 -> T.H.C| CAPATAZIA | AC3: ='Rateio Custos Fixos'!J10 -> LICENÇA DE IMPORTAÇÃO | AD3: ='Rateio Custos Fixos'!K10 -> ISPS | AE3: ='Rateio Custos Fixos'!L10 -> DAMAGE PROTECTION | AF3: ='Rateio Custos Fixos'!M10 -> DESCONSOLIDAÇÃO | ... AO3: ='Rateio Custos Fixos'!V10 -> DESEMBARAÇO ADUANEIRO | AP3: TOTAL TAXAS DESEMBARAÇO | AQ3: TOTAL | AR3: TOTAL (sub) | AS3: TOTAL (sub) | AT3: MÉTODO ANTIGO | AU3: MÉTODO ANTIGO (sub) | AV3: MÉTODO DANI | AW3: MÉTODO DANI (sub) | AX3: MÉTODO JULIANA | AY3: MÉTODO JULIANA (sub) | BA3: VALOR UNITÁRIO C/ COMISSÃO SEAWISE
A4: Nº | L4: =SUM(L7:L25) -> 817827.37 | M4: 4.8887 | N4: 0 | O4: =SUM(O7:O25) -> 59230.495 | P4: =SUM(P7:P25) -> 877057.87 | Q4: =SUM(P4+R4) -> 987567.16 | R4: =SUM(R7:R25) -> 110509.29 | S4: =SUM(S7:S25) -> 96287.798 | T4: =SUM(T7:T25) -> 18418.215 | U4: =SUM(U7:U25) -> 84636.084 | V4: =SUM(V7:V25) -> 35082.315 | W4: =SUM(W7:W25) -> 344933.7 | Y4: ='Rateio Custos Fixos'!F11 -> 224 | Z4: ='Rateio Custos Fixos'!G11 -> 107.06 | AA4: ='Rateio Custos Fixos'!H11 -> 11657.97 | AB4: ='Rateio Custos Fixos'!I11 -> 0 | AC4: ='Rateio Custos Fixos'!J11 -> 130 | AD4: ='Rateio Custos Fixos'!K11 -> 0 | AE4: ='Rateio Custos Fixos'!L11 -> 0 | AF4: ='Rateio Custos Fixos'!M11 -> 0 | ... AH4: ='Rateio Custos Fixos'!O11 -> 0 | AI4: =SUM(AI7:AI18) -> 4283.0281 | AJ4: ='Rateio Custos Fixos'!Q11 -> 24000 | AK4: ='Rateio Custos Fixos'!R11 -> 0 | AL4: ='Rateio Custos Fixos'!S11 -> 0 | AM4: ='Rateio Custos Fixos'!T11 -> 0 | AN4: ='Rateio Custos Fixos'!U11 -> 12200 | AO4: ='Rateio Custos Fixos'!V11 -> 1390 | AP4: =SUM(AP7:AP25) -> 55973.128 | AQ4: =SUM(AP4+W4+P4) -> 1277964.7
A5: AAA | K5: #VALUE! | L5: 5.3797 | P5: 84186999 | R5: ='LISTA DE COMPRAS'!E6 -> 0.126 | S5: ='LISTA DE COMPRAS'!F6 -> 0.0975 | T5: ='LISTA DE COMPRAS'!G6 -> 0.021 | U5: ='LISTA DE COMPRAS'!H6 -> 0.0965 | V5: ='LISTA DE COMPRAS'!I6 -> 0.04 | X5: =SUM(#REF!,X7) -> #REF! | AI5: 8%% | AR5: 21877.425 | AS5: =AP5+X5+Q4+#REF! -> #REF!
P6: 84189900 | R6: ='LISTA DE COMPRAS'!E12 -> 0.126 | S6: ='LISTA DE COMPRAS'!F12 -> 0.0975 | T6: ='LISTA DE COMPRAS'!G12 -> 0.021 | U6: ='LISTA DE COMPRAS'!H12 -> 0.0965 | V6: ='LISTA DE COMPRAS'!I12 -> 0.026
A7: AAA | B7: ='LISTA DE COMPRAS'!A6 -> 1 | C7: ='LISTA DE COMPRAS'!C6 -> BAC 51 LR (127V) | G7: ='LISTA DE COMPRAS'!D6 -> 84186999 | H7: ='LISTA DE COMPRAS'!J6 -> 75 | I7: ='LISTA DE COMPRAS'!Q6 -> 0.040974867 | J7: ='LISTA DE COMPRAS'!K6 -> 269 | K7: =H7*J7 -> 20175 | L7: =K7*L$5 -> 108535.45 | M7: =L7*50% -> 54267.724 | N7: =$N$4*I7 -> 0 | O7: ='Rateio Custos Fixos'!E12 -> 9615.3401 | P7: =SUM(L7,O7) -> 118150.79 | Q7: =SUM(P7+R7) -> 133037.79 | R7: =$P7*R$5 -> 14886.999 | S7: =$Q7*S$5 -> 12971.184 | T7: =$P7*T$5 -> 2481.1665 | U7: =$P7*U$5 -> 11401.551 | V7: =$P7*V$5 -> 4726.0315 | W7: =SUM(R7:V7) -> 46466.933 | X7: =SUM(R13:V13) -> 21820.307 | Y7: ='Rateio Custos Fixos'!F12 -> 36.363636 | Z7: ='Rateio Custos Fixos'!G12 -> 17.37987 | AA7: ='Rateio Custos Fixos'!H12 -> 1892.5276 | AB7: ='Rateio Custos Fixos'!I12 -> 0 | AC7: ='Rateio Custos Fixos'!J12 -> 21.103896 | AD7: ='Rateio Custos Fixos'!K12 -> 0 | AE7: ='Rateio Custos Fixos'!L12 -> 0 | AF7: ='Rateio Custos Fixos'!M12 -> 0 | ... AO7: ='Rateio Custos Fixos'!V12 -> 225.64935 | AP7: =SUM(Y7:AO7) -> 8917.2127 | AQ7: =AP7+W7+P7 -> 173534.93 | AR7: 2595.3166 | AS7: =AP7+X7+P7 -> 148888.31 | AT7: =(AQ7/H7) -> 2313.7991 | AU7: =AS7/H7 -> 1985.1774 | AV7: =(L7+(L7*AP$29))/H7 -> 2261.3488 | AW7: =(AS7*#REF!)/'Est. Cust. Naci.'!H7 -> #REF! | AX7: =(J7*9) -> 2421 | AY7: =AX7/2 -> 1210.5 | BA7: =AQ7/H7 -> 2313.7991
B8: 2 | C8: ='LISTA DE COMPRAS'!C7 -> BAC 51 RL (127V) | G8: ='LISTA DE COMPRAS'!D7 -> 84186999 | H8: ='LISTA DE COMPRAS'!J7 -> 50 | I8: ='LISTA DE COMPRAS'!Q7 -> 0.040974867 | J8: ='LISTA DE COMPRAS'!K7 -> 269 | K8: =H8*J8 -> 13450 | L8: =K8*L$5 -> 72356.965 | N8: =$N$4*I8 -> 0 | O8: ='Rateio Custos Fixos'!E13 -> 6410.2267 | P8: =SUM(L8,O8) -> 78767.192 | Q8: =SUM(P8+R8) -> 88691.858 | R8: =$P8*R$5 -> 9924.6662 | S8: =$Q8*S$5 -> 8647.4561 | T8: =$P8*T$5 -> 1654.111 | U8: =$P8*U$5 -> 7601.034 | V8: =$P8*V$5 -> 3150.6877 | W8: =SUM(R8:V8) -> 30977.955 | Y8: ='Rateio Custos Fixos'!F13 -> 24.242424 | Z8: ='Rateio Custos Fixos'!G13 -> 11.58658 | AA8: ='Rateio Custos Fixos'!H13 -> 1261.6851 | AB8: ='Rateio Custos Fixos'!I13 -> 0 | AC8: ='Rateio Custos Fixos'!J13 -> 14.069264 | AD8: ='Rateio Custos Fixos'!K13 -> 0 | AE8: ='Rateio Custos Fixos'!L13 -> 0 | AF8: ='Rateio Custos Fixos'!M13 -> 0 | ... AO8: ='Rateio Custos Fixos'!V13 -> 150.4329 | AP8: =SUM(Y8:AO8) -> 5944.8084 | AQ8: =AP8+W8+P8 -> 115689.96 | AV8: =(L8+(L8*AP$29))/H8 -> 2261.3488 | AX8: =(J8*9) -> 2421
B9: 3 | C9: ='LISTA DE COMPRAS'!C8 -> BAC 209A (220V) | G9: ='LISTA DE COMPRAS'!D8 -> 84186999 | H9: ='LISTA DE COMPRAS'!J8 -> 20 | I9: ='LISTA DE COMPRAS'!Q8 -> 0.069459254 | J9: ='LISTA DE COMPRAS'!K8 -> 456 | K9: =H9*J9 -> 9120 | L9: =K9*L$5 -> 49062.864 | N9: =$N$4*I9 -> 0 | O9: ='Rateio Custos Fixos'!E14 -> 2564.0907 | P9: =SUM(L9,O9) -> 51626.955 | Q9: =SUM(P9+R9) -> 58131.951 | R9: =$P9*R$5 -> 6504.9963 | S9: =$Q9*S$5 -> 5667.8652 | T9: =$P9*T$5 -> 1084.166 | U9: =$P9*U$5 -> 4982.0011 | V9: =$P9*V$5 -> 2065.0782 | W9: =SUM(R9:V9) -> 20304.107 | Y9: ='Rateio Custos Fixos'!F14 -> 9.6969697 | Z9: ='Rateio Custos Fixos'!G14 -> 4.634632 | AA9: ='Rateio Custos Fixos'!H14 -> 504.67403 | AB9: ='Rateio Custos Fixos'!I14 -> 0 | AC9: ='Rateio Custos Fixos'!J14 -> 5.6277056 | AD9: ='Rateio Custos Fixos'!K14 -> 0 | AE9: ='Rateio Custos Fixos'!L14 -> 0 | AF9: ='Rateio Custos Fixos'!M14 -> 0 | ... AO9: ='Rateio Custos Fixos'!V14 -> 60.17316 | AP9: =SUM(Y9:AO9) -> 2377.9234 | AQ9: =AP9+W9+P9 -> 74308.985 | AV9: =(L9+(L9*AP$29))/H9 -> 3833.3645 | AX9: =(J9*9) -> 4104
B10: 4 | C10: ='LISTA DE COMPRAS'!C9 -> BAC 209 (127V) | G10: ='LISTA DE COMPRAS'!D9 -> 84186999 | H10: ='LISTA DE COMPRAS'!J9 -> 34 | I10: ='LISTA DE COMPRAS'!Q9 -> 0.069459254 | J10: ='LISTA DE COMPRAS'!K9 -> 456 | K10: =H10*J10 -> 15504 | L10: =K10*L$5 -> 83406.869 | N10: =$N$4*I10 -> 0 | O10: ='Rateio Custos Fixos'!E15 -> 4358.9542 | P10: =SUM(L10,O10) -> 87765.823 | Q10: =SUM(P10+R10) -> 98824.317 | R10: =$P10*R$5 -> 11058.494 | S10: =$Q10*S$5 -> 9635.3709 | T10: =$P10*T$5 -> 1843.0823 | U10: =$P10*U$5 -> 8469.4019 | V10: =$P10*V$5 -> 3510.6329 | W10: =SUM(R10:V10) -> 34516.982 | Y10: ='Rateio Custos Fixos'!F15 -> 224 | Z10: ='Rateio Custos Fixos'!G15 -> 0 | AA10: ='Rateio Custos Fixos'!H15 -> 857.94584 | AB10: ='Rateio Custos Fixos'!I15 -> 0 | AC10: ='Rateio Custos Fixos'!J15 -> 9.5670996 | AD10: ='Rateio Custos Fixos'!K15 -> 0 | AE10: ='Rateio Custos Fixos'!L15 -> 0 | AF10: ='Rateio Custos Fixos'!M15 -> 0 | ... AO10: ='Rateio Custos Fixos'!V15 -> 102.29437 | AP10: =SUM(Y10:AO10) -> 4242.106 | AQ10: =AP10+W10+P10 -> 126524.91 | AV10: =(L10+(L10*AP$29))/H10 -> 3833.3645 | AX10: =(J10*9) -> 4104
B11: 5 | C11: ='LISTA DE COMPRAS'!C10 -> BAC 218SA (220V) | G11: ='LISTA DE COMPRAS'!D10 -> 84186999 | H11: ='LISTA DE COMPRAS'!J10 -> 15 | I11: ='LISTA DE COMPRAS'!Q10 -> 0.12536177 | J11: ='LISTA DE COMPRAS'!K10 -> 823 | K11: =H11*J11 -> 12345 | L11: =K11*L$5 -> 66412.397 | N11: =$N$4*I11 -> 0 | O11: ='Rateio Custos Fixos'!E16 -> 1923.068 | P11: =SUM(L11,O11) -> 68335.465 | Q11: =SUM(P11+R11) -> 76945.733 | R11: =$P11*R$5 -> 8610.2685 | S11: =$Q11*S$5 -> 7502.209 | T11: =$P11*T$5 -> 1435.0448 | U11: =$P11*U$5 -> 6594.3723 | V11: =$P11*V$5 -> 2733.4186 | W11: =SUM(R11:V11) -> 26875.313 | Y11: ='Rateio Custos Fixos'!F16 -> 7.2727273 | Z11: ='Rateio Custos Fixos'!G16 -> 3.475974 | AA11: ='Rateio Custos Fixos'!H16 -> 378.50552 | AB11: ='Rateio Custos Fixos'!I16 -> 0 | AC11: ='Rateio Custos Fixos'!J16 -> 4.2207792 | AD11: ='Rateio Custos Fixos'!K16 -> 0 | AE11: ='Rateio Custos Fixos'!L16 -> 0 | AF11: ='Rateio Custos Fixos'!M16 -> 0 | ... AO11: ='Rateio Custos Fixos'!V16 -> 45.12987 | AP11: =SUM(Y11:AO11) -> 1783.4425 | AQ11: =AP11+W11+P11 -> 96994.22 | AV11: =(L11+(L11*AP$29))/H11 -> 6918.5504 | AX11: =(J11*9) -> 7407
B12: 6 | C12: ='LISTA DE COMPRAS'!C11 -> BAC 218BA (220V) | G12: ='LISTA DE COMPRAS'!D11 -> 84186999 | H12: ='LISTA DE COMPRAS'!J11 -> 12 | I12: ='LISTA DE COMPRAS'!Q11 -> 0.12460015 | J12: ='LISTA DE COMPRAS'!K11 -> 818 | K12: =H12*J12 -> 9816 | L12: =K12*L$5 -> 52807.135 | N12: =$N$4*I12 -> 0 | O12: ='Rateio Custos Fixos'!E17 -> 1538.4544 | P12: =SUM(L12,O12) -> 54345.59 | Q12: =SUM(P12+R12) -> 61193.134 | R12: =$P12*R$5 -> 6847.5443 | S12: =$Q12*S$5 -> 5966.3306 | T12: =$P12*T$5 -> 1141.2574 | U12: =$P12*U$5 -> 5244.3494 | V12: =$P12*V$5 -> 2173.8236 | W12: =SUM(R12:V12) -> 21373.305 | Y12: ='Rateio Custos Fixos'!F17 -> 5.8181818 | Z12: ='Rateio Custos Fixos'!G17 -> 54.53 | AA12: ='Rateio Custos Fixos'!H17 -> 302.80442 | AB12: ='Rateio Custos Fixos'!I17 -> 0 | AC12: ='Rateio Custos Fixos'!J17 -> 3.3766234 | AD12: ='Rateio Custos Fixos'!K17 -> 0 | AE12: ='Rateio Custos Fixos'!L17 -> 0 | AF12: ='Rateio Custos Fixos'!M17 -> 0 | ... AO12: ='Rateio Custos Fixos'!V17 -> 36.103896 | AP12: =SUM(Y12:AO12) -> 1478.5032 | AQ12: =AP12+W12+P12 -> 77197.398 | AV12: =(L12+(L12*AP$29))/H12 -> 6876.5179 | AX12: =(J12*9) -> 7362
B13: 7 | C13: ='LISTA DE COMPRAS'!C12 -> BAC 28 (127V) | G13: ='LISTA DE COMPRAS'!D12 -> 84186999 | H13: ='LISTA DE COMPRAS'!J12 -> 40 | I13: ='LISTA DE COMPRAS'!Q12 -> 0.035643564 | J13: ='LISTA DE COMPRAS'!K12 -> 234 | K13: =H13*J13 -> 9360 | L13: =K13*L$5 -> 50353.992 | N13: =$N$4*I13 -> 0 | O13: ='Rateio Custos Fixos'!E18 -> 5128.1814 | P13: =SUM(L13,O13) -> 55482.173 | Q13: =SUM(P13+R13) -> 62472.927 | R13: =$P13*R$5 -> 6990.7538 | S13: =$Q13*S$5 -> 6091.1104 | T13: =$P13*T$5 -> 1165.1256 | U13: =$P13*U$5 -> 5354.0297 | V13: =$P13*V$5 -> 2219.2869 | W13: =SUM(R13:V13) -> 21820.307 | Y13: ='Rateio Custos Fixos'!F18 -> 19.393939 | Z13: ='Rateio Custos Fixos'!G18 -> 9.2692641 | AA13: ='Rateio Custos Fixos'!H18 -> 1009.3481 | AB13: ='Rateio Custos Fixos'!I18 -> 0 | AC13: ='Rateio Custos Fixos'!J18 -> 11.255411 | AD13: ='Rateio Custos Fixos'!K18 -> 0 | AE13: ='Rateio Custos Fixos'!L18 -> 0 | AF13: ='Rateio Custos Fixos'!M18 -> 0 | ... AO13: ='Rateio Custos Fixos'!V18 -> 120.34632 | AP13: =SUM(Y13:AO13) -> 4755.8468 | AQ13: =AP13+W13+P13 -> 82058.327 | AV13: =(L13+(L13*AP$29))/H13 -> 1967.1213 | AX13: =(J13*9) -> 2106
B14: 8 | C14: ='LISTA DE COMPRAS'!C13 -> BAC 28A (220V) | G14: ='LISTA DE COMPRAS'!D13 -> 84186999 | H14: ='LISTA DE COMPRAS'!J13 -> 20 | I14: ='LISTA DE COMPRAS'!Q13 -> 0.035643564 | J14: ='LISTA DE COMPRAS'!K13 -> 234 | K14: =H14*J14 -> 4680 | L14: =K14*L$5 -> 25176.996 | N14: =$N$4*I14 -> 0 | O14: ='Rateio Custos Fixos'!E19 -> 2564.0907 | P14: =SUM(L14,O14) -> 27741.087 | Q14: =SUM(P14+R14) -> 31236.464 | R14: =$P14*R$5 -> 3495.3769 | S14: =$Q14*S$5 -> 3045.5552 | T14: =$P14*T$5 -> 582.56282 | U14: =$P14*U$5 -> 2677.0149 | V14: =$P14*V$5 -> 1109.6435 | W14: =SUM(R14:V14) -> 10910.153 | Y14: ='Rateio Custos Fixos'!F19 -> 224 | Z14: ='Rateio Custos Fixos'!G19 -> 4.634632 | AA14: ='Rateio Custos Fixos'!H19 -> 504.67403 | AB14: ='Rateio Custos Fixos'!I19 -> 0 | AC14: ='Rateio Custos Fixos'!J19 -> 5.6277056 | AD14: ='Rateio Custos Fixos'!K19 -> 0 | AE14: ='Rateio Custos Fixos'!L19 -> 0 | AF14: ='Rateio Custos Fixos'!M19 -> 0 | ... AO14: ='Rateio Custos Fixos'!V19 -> 60.17316 | AP14: =SUM(Y14:AO14) -> 2592.2264 | AQ14: =AP14+W14+P14 -> 41243.466 | AV14: =(L14+(L14*AP$29))/H14 -> 1967.1213 | AX14: =(J14*9) -> 2106
B15: 9 | C15: ='LISTA DE COMPRAS'!C14 -> BAC 120A (220V) | G15: ='LISTA DE COMPRAS'!D14 -> 84186999 | H15: ='LISTA DE COMPRAS'!J14 -> 20 | I15: ='LISTA DE COMPRAS'!Q14 -> 0.050571211 | J15: ='LISTA DE COMPRAS'!K14 -> 332 | K15: =H15*J15 -> 6640 | L15: =K15*L$5 -> 35721.208 | N15: =$N$4*I15 -> 0 | O15: ='Rateio Custos Fixos'!E20 -> 2564.0907 | P15: =SUM(L15,O15) -> 38285.299 | Q15: =SUM(P15+R15) -> 43109.246 | R15: =$P15*R$5 -> 4823.9476 | S15: =$Q15*S$5 -> 4203.1515 | T15: =$P15*T$5 -> 803.99127 | U15: =$P15*U$5 -> 3694.5313 | V15: =$P15*V$5 -> 1531.4119 | W15: =SUM(R15:V15) -> 15057.034 | Y15: ='Rateio Custos Fixos'!F20 -> 9.6969697 | Z15: ='Rateio Custos Fixos'!G20 -> 4.634632 | AA15: ='Rateio Custos Fixos'!H20 -> 504.67403 | AB15: ='Rateio Custos Fixos'!I20 -> 0 | AC15: ='Rateio Custos Fixos'!J20 -> 5.6277056 | AD15: ='Rateio Custos Fixos'!K20 -> 0 | AE15: ='Rateio Custos Fixos'!L20 -> 0 | AF15: ='Rateio Custos Fixos'!M20 -> 0 | ... AO15: ='Rateio Custos Fixos'!V20 -> 60.17316 | AP15: =SUM(Y15:AO15) -> 2377.9234 | AQ15: =AP15+W15+P15 -> 55720.256 | AV15: =(L15+(L15*AP$29))/H15 -> 2790.9584 | AX15: =(J15*9) -> 2988
B16: 10 | C16: ='LISTA DE COMPRAS'!C15 -> BAC 120 (127V) | G16: ='LISTA DE COMPRAS'!D15 -> 84186999 | H16: ='LISTA DE COMPRAS'!J15 -> 34 | I16: ='LISTA DE COMPRAS'!Q15 -> 0.050571211 | J16: ='LISTA DE COMPRAS'!K15 -> 332 | K16: =H16*J16 -> 11288 | L16: =K16*L$5 -> 60726.054 | N16: =$N$4*I16 -> 0 | O16: ='Rateio Custos Fixos'!E21 -> 4358.9542 | P16: =SUM(L16,O16) -> 65085.008 | Q16: =SUM(P16+R16) -> 73285.719 | R16: =$P16*R$5 -> 8200.711 | S16: =$Q16*S$5 -> 7145.3576 | T16: =$P16*T$5 -> 1366.7852 | U16: =$P16*U$5 -> 6280.7033 | V16: =$P16*V$5 -> 2603.4003 | W16: =SUM(R16:V16) -> 25596.957 | Y16: ='Rateio Custos Fixos'!F21 -> 16.484848 | Z16: ='Rateio Custos Fixos'!G21 -> 1 | AA16: ='Rateio Custos Fixos'!H21 -> 857.94584 | AB16: ='Rateio Custos Fixos'!I21 -> 0 | AC16: ='Rateio Custos Fixos'!J21 -> 9.5670996 | AD16: ='Rateio Custos Fixos'!K21 -> 0 | AE16: ='Rateio Custos Fixos'!L21 -> 0 | AF16: ='Rateio Custos Fixos'!M21 -> 0 | ... AO16: ='Rateio Custos Fixos'!V21 -> 102.29437 | AP16: =SUM(Y16:AO16) -> 4035.5909 | AQ16: =AP16+W16+P16 -> 94717.556 | AV16: =(L16+(L16*AP$29))/H16 -> 2790.9584 | AX16: =(J16*9) -> 2988
B17: 11 | C17: ='LISTA DE COMPRAS'!C16 -> BAC111 (220V) | G17: ='LISTA DE COMPRAS'!D16 -> 84186999 | H17: ='LISTA DE COMPRAS'!J16 -> 14 | I17: ='LISTA DE COMPRAS'!Q16 -> 0.11119573 | J17: ='LISTA DE COMPRAS'!K16 -> 730 | K17: =H17*J17 -> 10220 | L17: =K17*L$5 -> 54980.534 | N17: =$N$4*I17 -> 0 | O17: ='Rateio Custos Fixos'!E22 -> 1794.8635 | P17: =SUM(L17,O17) -> 56775.397 | Q17: =SUM(P17+R17) -> 63929.098 | R17: =$P17*R$5 -> 7153.7001 | S17: =$Q17*S$5 -> 6233.087 | T17: =$P17*T$5 -> 1192.2833 | U17: =$P17*U$5 -> 5478.8259 | V17: =$P17*V$5 -> 2271.0159 | W17: =SUM(R17:V17) -> 22328.912 | Y17: ='Rateio Custos Fixos'!F22 -> 6.7878788 | Z17: ='Rateio Custos Fixos'!G22 -> 3.2442424 | AA17: ='Rateio Custos Fixos'!H22 -> 353.27182 | AB17: ='Rateio Custos Fixos'!I22 -> 0 | AC17: ='Rateio Custos Fixos'!J22 -> 3.9393939 | AD17: ='Rateio Custos Fixos'!K22 -> 0 | AE17: ='Rateio Custos Fixos'!L22 -> 0 | AF17: ='Rateio Custos Fixos'!M22 -> 0 | ... AO17: ='Rateio Custos Fixos'!V22 -> 42.121212 | AP17: =SUM(Y17:AO17) -> 1664.5464 | AQ17: =AP17+W17+P17 -> 80768.856 | AV17: =(L17+(L17*AP$29))/H17 -> 6136.7458 | AX17: =(J17*9) -> 6570
B18: 12 | C18: ='LISTA DE COMPRAS'!C17 -> BEC 100GD (127V) | G18: ='LISTA DE COMPRAS'!D17 -> 84186999 | H18: ='LISTA DE COMPRAS'!J17 -> 45 | I18: ='LISTA DE COMPRAS'!Q17 -> 0.036557502 | J18: ='LISTA DE COMPRAS'!K17 -> 240 | K18: =H18*J18 -> 10800 | L18: =K18*L$5 -> 58100.76 | N18: =$N$4*I18 -> 0 | O18: ='Rateio Custos Fixos'!E23 -> 5769.2041 | P18: =SUM(L18,O18) -> 63869.964 | Q18: =SUM(P18+R18) -> 71917.58 | R18: =$P18*R$5 -> 8047.6155 | S18: =$Q18*S$5 -> 7011.964 | T18: =$P18*T$5 -> 1341.2692 | U18: =$P18*U$5 -> 6163.4515 | V18: =$P18*V$5 -> 2554.7986 | W18: =SUM(R18:V18) -> 25119.099 | Y18: ='Rateio Custos Fixos'!F23 -> 224 | Z18: ='Rateio Custos Fixos'!G23 -> 55.53 | AA18: ='Rateio Custos Fixos'!H23 -> 1135.5166 | AB18: ='Rateio Custos Fixos'!I23 -> 0 | AC18: ='Rateio Custos Fixos'!J23 -> 12.662338 | AD18: ='Rateio Custos Fixos'!K23 -> 0 | AE18: ='Rateio Custos Fixos'!L23 -> 0 | AF18: ='Rateio Custos Fixos'!M23 -> 0 | ... AO18: ='Rateio Custos Fixos'!V23 -> 135.38961 | AP18: =SUM(Y18:AO18) -> 5597.6115 | AQ18: =AP18+W18+P18 -> 94586.674 | AV18: =(L18+(L18*AP$29))/H18 -> 2017.5603 | AX18: =(J18*9) -> 2160
C19: ='LISTA DE COMPRAS'!C18 -> BEC 100GDA (220V) | G19: ='LISTA DE COMPRAS'!D18 -> 84186999 | H19: ='LISTA DE COMPRAS'!J18 -> 20 | I19: ='LISTA DE COMPRAS'!Q18 -> 0.036557502 | J19: ='LISTA DE COMPRAS'!K18 -> 240 | K19: =H19*J19 -> 4800 | L19: =K19*L$5 -> 25822.56 | N19: =$N$4*I19 -> 0 | O19: ='Rateio Custos Fixos'!E24 -> 2564.0907 | P19: =SUM(L19,O19) -> 28386.651 | Q19: =SUM(P19+R19) -> 31963.369 | R19: =$P19*R$5 -> 3576.718 | S19: =$Q19*S$5 -> 3116.4284 | T19: =$P19*T$5 -> 596.11966 | U19: =$P19*U$5 -> 2739.3118 | V19: =$P19*V$5 -> 1135.466 | W19: =SUM(R19:V19) -> 11164.044 | Y19: ='Rateio Custos Fixos'!F24 -> 9.6969697 | Z19: ='Rateio Custos Fixos'!G24 -> 4.634632 | AA19: ='Rateio Custos Fixos'!H24 -> 504.67403 | AB19: ='Rateio Custos Fixos'!I24 -> 0 | AC19: ='Rateio Custos Fixos'!J24 -> 5.6277056 | AD19: ='Rateio Custos Fixos'!K24 -> 0 | AE19: ='Rateio Custos Fixos'!L24 -> 0 | AF19: ='Rateio Custos Fixos'!M24 -> 0 | ... AO19: ='Rateio Custos Fixos'!V24 -> 60.17316 | AP19: =SUM(Y19:AO19) -> 2377.9234 | AQ19: =AP19+W19+P19 -> 41928.618 | AV19: =(L19+(L19*AP$29))/H19 -> 2017.5603 | AX19: =(J19*9) -> 2160
C20: ='LISTA DE COMPRAS'!C19 -> BEC 100SD (127V) | G20: ='LISTA DE COMPRAS'!D19 -> 84186999 | H20: ='LISTA DE COMPRAS'!J19 -> 36 | I20: ='LISTA DE COMPRAS'!Q19 -> 0.037014471 | J20: ='LISTA DE COMPRAS'!K19 -> 243 | K20: =H20*J20 -> 8748 | L20: =K20*L$5 -> 47061.616 | N20: =$N$4*I20 -> 0 | O20: ='Rateio Custos Fixos'!E25 -> 4615.3632 | P20: =SUM(L20,O20) -> 51676.979 | Q20: =SUM(P20+R20) -> 58188.278 | R20: =$P20*R$5 -> 6511.2993 | S20: =$Q20*S$5 -> 5673.3571 | T20: =$P20*T$5 -> 1085.2166 | U20: =$P20*U$5 -> 4986.8285 | V20: =$P20*V$5 -> 2067.0792 | W20: =SUM(R20:V20) -> 20323.781 | Y20: ='Rateio Custos Fixos'!F25 -> 17.454545 | Z20: ='Rateio Custos Fixos'!G25 -> 8.3423377 | AA20: ='Rateio Custos Fixos'!H25 -> 908.41325 | AB20: ='Rateio Custos Fixos'!I25 -> 0 | AC20: ='Rateio Custos Fixos'!J25 -> 10.12987 | AD20: ='Rateio Custos Fixos'!K25 -> 0 | AE20: ='Rateio Custos Fixos'!L25 -> 0 | AF20: ='Rateio Custos Fixos'!M25 -> 0 | ... AO20: ='Rateio Custos Fixos'!V25 -> 108.31169 | AP20: =SUM(Y20:AO20) -> 4280.2621 | AQ20: =AP20+W20+P20 -> 76281.022 | AV20: =(L20+(L20*AP$29))/H20 -> 2042.7798 | AX20: =(J20*9) -> 2187
C21: ='LISTA DE COMPRAS'!C20 -> UCH50BA (220V) | G21: ='LISTA DE COMPRAS'!D20 -> 84186999 | H21: ='LISTA DE COMPRAS'!J20 -> 5 | I21: ='LISTA DE COMPRAS'!Q20 -> 0.01721249 | J21: ='LISTA DE COMPRAS'!K20 -> 113 | K21: =H21*J21 -> 565 | L21: =K21*L$5 -> 3039.5305 | N21: =$N$4*I21 -> 0 | O21: ='Rateio Custos Fixos'!E26 -> 641.02267 | P21: =SUM(L21,O21) -> 3680.5532 | Q21: =SUM(P21+R21) -> 4144.3029 | R21: =$P21*R$5 -> 463.7497 | S21: =$Q21*S$5 -> 404.06953 | T21: =$P21*T$5 -> 77.291617 | U21: =$P21*U$5 -> 355.17338 | V21: =$P21*V$5 -> 147.22213 | W21: =SUM(R21:V21) -> 1447.5064 | Y21: ='Rateio Custos Fixos'!F26 -> 2.4242424 | Z21: ='Rateio Custos Fixos'!G26 -> 1.158658 | AA21: ='Rateio Custos Fixos'!H26 -> 126.16851 | AB21: ='Rateio Custos Fixos'!I26 -> 0 | AC21: ='Rateio Custos Fixos'!J26 -> 1.4069264 | AD21: ='Rateio Custos Fixos'!K26 -> 0 | AE21: ='Rateio Custos Fixos'!L26 -> 0 | AF21: ='Rateio Custos Fixos'!M26 -> 0 | ... AO21: ='Rateio Custos Fixos'!V26 -> 15.04329 | AP21: =SUM(Y21:AO21) -> 594.48084 | AQ21: =AP21+W21+P21 -> 5722.5404 | AV21: =(L21+(L21*AP$29))/H21 -> 949.93462 | AX21: =(J21*9) -> 1017
C22: ='LISTA DE COMPRAS'!C21 -> UCH150SA (220V) | G22: ='LISTA DE COMPRAS'!D21 -> 84186999 | H22: ='LISTA DE COMPRAS'!J21 -> 2 | I22: ='LISTA DE COMPRAS'!Q21 -> 0.051637471 | J22: ='LISTA DE COMPRAS'!K21 -> 339 | K22: =H22*J22 -> 678 | L22: =K22*L$5 -> 3647.4366 | N22: =$N$4*I22 -> 0 | O22: ='Rateio Custos Fixos'!E27 -> 256.40907 | P22: =SUM(L22,O22) -> 3903.8457 | Q22: =SUM(P22+R22) -> 4395.7302 | R22: =$P22*R$5 -> 491.88455 | S22: =$Q22*S$5 -> 428.5837 | T22: =$P22*T$5 -> 81.980759 | U22: =$P22*U$5 -> 376.72111 | V22: =$P22*V$5 -> 156.15383 | W22: =SUM(R22:V22) -> 1535.3239 | Y22: ='Rateio Custos Fixos'!F27 -> 224 | Z22: ='Rateio Custos Fixos'!G27 -> 2 | AA22: ='Rateio Custos Fixos'!H27 -> 50.467403 | AB22: ='Rateio Custos Fixos'!I27 -> 0 | AC22: ='Rateio Custos Fixos'!J27 -> 0.56277056 | AD22: ='Rateio Custos Fixos'!K27 -> 0 | AE22: ='Rateio Custos Fixos'!L27 -> 0 | AF22: ='Rateio Custos Fixos'!M27 -> 0 | ... AO22: ='Rateio Custos Fixos'!V27 -> 6.017316 | AP22: =SUM(Y22:AO22) -> 462.35918 | AQ22: =AP22+W22+P22 -> 5901.5288 | AV22: =(L22+(L22*AP$29))/H22 -> 2849.8039 | AX22: =(J22*9) -> 3051
C23: ='LISTA DE COMPRAS'!C22 -> BEC 100SDA (220V) | G23: ='LISTA DE COMPRAS'!D22 -> 84186999 | H23: ='LISTA DE COMPRAS'!J22 -> 13 | I23: ='LISTA DE COMPRAS'!Q22 -> 0.037014471 | J23: ='LISTA DE COMPRAS'!K22 -> 243 | K23: =H23*J23 -> 3159 | L23: =K23*L$5 -> 16994.472 | N23: =$N$4*I23 -> 0 | O23: ='Rateio Custos Fixos'!E28 -> 1666.659 | P23: =SUM(L23,O23) -> 18661.131 | Q23: =SUM(P23+R23) -> 21012.434 | R23: =$P23*R$5 -> 2351.3025 | S23: =$Q23*S$5 -> 2048.7123 | T23: =$P23*T$5 -> 391.88376 | U23: =$P23*U$5 -> 1800.7992 | V23: =$P23*V$5 -> 746.44525 | W23: =SUM(R23:V23) -> 7339.143 | Y23: ='Rateio Custos Fixos'!F28 -> 6.3030303 | Z23: ='Rateio Custos Fixos'!G28 -> 3.0125108 | AA23: ='Rateio Custos Fixos'!H28 -> 328.03812 | AB23: ='Rateio Custos Fixos'!I28 -> 0 | AC23: ='Rateio Custos Fixos'!J28 -> 3.6580087 | AD23: ='Rateio Custos Fixos'!K28 -> 0 | AE23: ='Rateio Custos Fixos'!L28 -> 0 | AF23: ='Rateio Custos Fixos'!M28 -> 0 | ... AO23: ='Rateio Custos Fixos'!V28 -> 39.112554 | AP23: =SUM(Y23:AO23) -> 1545.6502 | AQ23: =AP23+W23+P23 -> 27545.924 | AV23: =(L23+(L23*AP$29))/H23 -> 2042.7798 | AX23: =(J23*9) -> 2187
C24: ='LISTA DE COMPRAS'!C23 -> SPARE PARTS | G24: ='LISTA DE COMPRAS'!D23 -> 84186999 | H24: ='LISTA DE COMPRAS'!J23 -> 5 | I24: ='LISTA DE COMPRAS'!Q23 -> 0.014470678 | J24: ='LISTA DE COMPRAS'!K23 -> 95 | K24: =H24*J24 -> 475 | L24: =K24*L$5 -> 2555.3575 | N24: =$N$4*I24 -> 0 | O24: ='Rateio Custos Fixos'!E29 -> 641.02267 | P24: =SUM(L24,O24) -> 3196.3802 | Q24: =SUM(P24+R24) -> 3599.1241 | R24: =$P24*R$5 -> 402.7439 | S24: =$Q24*S$5 -> 350.9146 | T24: =$P24*T$5 -> 67.123984 | U24: =$P24*U$5 -> 308.45069 | V24: =$P24*V$5 -> 127.85521 | W24: =SUM(R24:V24) -> 1257.0884 | Y24: ='Rateio Custos Fixos'!F29 -> 2.4242424 | Z24: ='Rateio Custos Fixos'!G29 -> 56.53 | AA24: ='Rateio Custos Fixos'!H29 -> 126.16851 | AB24: ='Rateio Custos Fixos'!I29 -> 0 | AC24: ='Rateio Custos Fixos'!J29 -> 1.4069264 | AD24: ='Rateio Custos Fixos'!K29 -> 0 | AE24: ='Rateio Custos Fixos'!L29 -> 0 | AF24: ='Rateio Custos Fixos'!M29 -> 0 | ... AO24: ='Rateio Custos Fixos'!V29 -> 15.04329 | AP24: =SUM(Y24:AO24) -> 649.85219 | AQ24: =AP24+W24+P24 -> 5103.3207 | AV24: =(L24+(L24*AP$29))/H24 -> 798.6176 | AX24: =(J24*9) -> 855
C25: ='LISTA DE COMPRAS'!C24 -> SPARE PARTS | G25: ='LISTA DE COMPRAS'!D24 -> 84186999 | H25: ='LISTA DE COMPRAS'!J24 -> 2 | I25: ='LISTA DE COMPRAS'!Q24 -> 0.01507997 | J25: ='LISTA DE COMPRAS'!K24 -> 99 | K25: =H25*J25 -> 198 | L25: =K25*L$5 -> 1065.1806 | N25: =$N$4*I25 -> 0 | O25: ='Rateio Custos Fixos'!E30 -> 256.40907 | P25: =SUM(L25,O25) -> 1321.5897 | Q25: =SUM(P25+R25) -> 1488.11 | R25: =$P25*R$5 -> 166.5203 | S25: =$Q25*S$5 -> 145.09072 | T25: =$P25*T$5 -> 27.753383 | U25: =$P25*U$5 -> 127.5334 | V25: =$P25*V$5 -> 52.863587 | W25: =SUM(R25:V25) -> 519.76139 | Y25: ='Rateio Custos Fixos'!F30 -> 0.96969697 | Z25: ='Rateio Custos Fixos'!G30 -> 57.53 | AA25: ='Rateio Custos Fixos'!H30 -> 50.467403 | AB25: ='Rateio Custos Fixos'!I30 -> 0 | AC25: ='Rateio Custos Fixos'!J30 -> 0.56277056 | AD25: ='Rateio Custos Fixos'!K30 -> 0 | AE25: ='Rateio Custos Fixos'!L30 -> 0 | AF25: ='Rateio Custos Fixos'!M30 -> 0 | ... AO25: ='Rateio Custos Fixos'!V30 -> 6.017316 | AP25: =SUM(Y25:AO25) -> 294.85887 | AQ25: =AP25+W25+P25 -> 2136.2099 | AV25: =(L25+(L25*AP$29))/H25 -> 832.24361
AO26: fob | AP26: =L4 -> 817827.37
AO27: despesas | AP27: =AP28-AP26 -> 460137.33
AO28: total | AP28: =AQ4 -> 1277964.7
AO29: despesas/fob | AP29: =AP27/AP26 -> 0.56263381

Sheet Rateio Custos Fixos
A1: CÂMBIO | F1: FRETE | G1: R$
F2: 3800 | G2: =F2*B3 -> 20442.86
A3: #VALUE! | B3: 5.3797 | F3: 2800 | G3: =F3 -> 2800
A4: #VALUE! | B4: {=_FV(A4,"Preço")} -> 6.2373 | F4: TOTAL | G4: 57347.6
G5: =G4/B3 -> 10660
F6: SEGURO
F7: 350 | G7: =F7*B3 -> 1882.895
A10: Produto | B10: Quantidade | C10: ='[2]Lista de Compra'!Q2 -> % Rateio Preço | E10: FRETE | F10: TAXA SISCOMEX | G10: ANUENCIA DE LI | H10: DIFERENÇA DO VALOR DO FRETE | I10: T.H.C| CAPATAZIA | J10: LICENÇA DE IMPORTAÇÃO | K10: ISPS | L10: DAMAGE PROTECTION | M10: DESCONSOLIDAÇÃO | N10: SERVIÇO DE ENTREGA DE CONTAINER | O10: Delivery order | P10: AFRMM | Q10: ARMAZENAGEM | R10: Import logistic fee | S10: Drop off | T10: TAXA | U10: FRETE RODOVIÁRIO | V10: DESEMBARAÇO ADUANEIRO
E11: =SUM(G4+G7) -> 59230.495 | F11: 224 | G11: 107.06 | H11: 11657.97 | I11: 0 | J11: 130 | K11: 0 | L11: 0 | M11: 0 | N11: 0 | O11: 0 | P11: 5221 | Q11: 24000 | R11: 0 | S11: 0 | T11: 0 | U11: 12200 | V11: 1390
A12: ='LISTA DE COMPRAS'!C6 -> BAC 51 LR (127V) | B12: ='LISTA DE COMPRAS'!J6 -> 75 | C12: ='LISTA DE COMPRAS'!P6 -> 0.16233766 | E12: =E$11*C12 -> 9615.3401 | F12: =F$11*C12 -> 36.363636 | G12: =G$11*C12 -> 17.37987 | H12: =H$11*C12 -> 1892.5276 | I12: =I$11*C12 -> 0 | J12: =J$11*C12 -> 21.103896 | K12: =K$11*C12 -> 0 | L12: =L$11*C12 -> 0 | M12: =M$11*C12 -> 0 | N12: =N$11*C12 -> 0 | O12: =O$11*C12 -> 0 | P12: =P$11*C12 -> 847.56494 | Q12: =Q$11*C12 -> 3896.1039 | R12: =R$11*C12 -> 0 | S12: =S$11*C12 -> 0 | T12: =T$11*C12 -> 0 | U12: =U$11*C12 -> 1980.5195 | V12: =V$11*C12 -> 225.64935 | W12: =SUM(F12:V12) -> 8917.2127
A13: ='LISTA DE COMPRAS'!C7 -> BAC 51 RL (127V) | B13: ='LISTA DE COMPRAS'!J7 -> 50 | C13: ='LISTA DE COMPRAS'!P7 -> 0.10822511 | E13: =E$11*C13 -> 6410.2267 | F13: =F$11*C13 -> 24.242424 | G13: =G$11*C13 -> 11.58658 | H13: =H$11*C13 -> 1261.6851 | I13: =I$11*C13 -> 0 | J13: =J$11*C13 -> 14.069264 | K13: =K$11*C13 -> 0 | L13: =L$11*C13 -> 0 | M13: =M$11*C13 -> 0 | N13: =N$11*C13 -> 0 | O13: =O$11*C13 -> 0 | P13: =P$11*C13 -> 565.04329 | Q13: =Q$11*C13 -> 2597.4026 | R13: =R$11*C13 -> 0 | S13: =S$11*C13 -> 0 | T13: =T$11*C13 -> 0 | U13: =U$11*C13 -> 1320.3463 | V13: =V$11*C13 -> 150.4329 | W13: =SUM(F13:V13) -> 5944.8084
A14: ='LISTA DE COMPRAS'!C8 -> BAC 209A (220V) | B14: ='LISTA DE COMPRAS'!J8 -> 20 | C14: ='LISTA DE COMPRAS'!P8 -> 0.043290043 | E14: =E$11*C14 -> 2564.0907 | F14: =F$11*C14 -> 9.6969697 | G14: =G$11*C14 -> 4.634632 | H14: =H$11*C14 -> 504.67403 | I14: =I$11*C14 -> 0 | J14: =J$11*C14 -> 5.6277056 | K14: =K$11*C14 -> 0 | L14: =L$11*C14 -> 0 | M14: =M$11*C14 -> 0 | N14: =N$11*C14 -> 0 | O14: =O$11*C14 -> 0 | P14: =P$11*C14 -> 226.01732 | Q14: =Q$11*C14 -> 1038.961 | R14: =R$11*C14 -> 0 | S14: =S$11*C14 -> 0 | T14: =T$11*C14 -> 0 | U14: =U$11*C14 -> 528.13853 | V14: =V$11*C14 -> 60.17316 | W14: =SUM(F14:V14) -> 2377.9234
A15: ='LISTA DE COMPRAS'!C9 -> BAC 209 (127V) | B15: ='LISTA DE COMPRAS'!J9 -> 34 | C15: ='LISTA DE COMPRAS'!P9 -> 0.073593074 | E15: =E$11*C15 -> 4358.9542 | F15: 224 | G15: 0 | H15: =H$11*C15 -> 857.94584 | I15: 0 | J15: =J$11*C15 -> 9.5670996 | K15: 0 | L15: 0 | M15: 0 | N15: 0 | O15: 0 | P15: =P$11*C15 -> 384.22944 | Q15: =Q$11*C15 -> 1766.2338 | R15: 0 | S15: 0 | T15: 0 | U15: =U$11*C15 -> 897.8355 | V15: =V$11*C15 -> 102.29437 | W15: =SUM(F15:V15) -> 4242.106
A16: ='LISTA DE COMPRAS'!C10 -> BAC 218SA (220V) | B16: ='LISTA DE COMPRAS'!J10 -> 15 | C16: ='LISTA DE COMPRAS'!P10 -> 0.032467532 | E16: =E$11*C16 -> 1923.068 | F16: =F$11*C16 -> 7.2727273 | G16: =G$11*C16 -> 3.475974 | H16: =H$11*C16 -> 378.50552 | I16: =I$11*C16 -> 0 | J16: =J$11*C16 -> 4.2207792 | K16: =K$11*C16 -> 0 | L16: =L$11*C16 -> 0 | M16: =M$11*C16 -> 0 | N16: =N$11*C16 -> 0 | O16: =O$11*C16 -> 0 | P16: =P$11*C16 -> 169.51299 | Q16: =Q$11*C16 -> 779.22078 | R16: =R$11*C16 -> 0 | S16: =S$11*C16 -> 0 | T16: =T$11*C16 -> 0 | U16: =U$11*C16 -> 396.1039 | V16: =V$11*C16 -> 45.12987 | W16: =SUM(F16:V16) -> 1783.4425
A17: ='LISTA DE COMPRAS'!C11 -> BAC 218BA (220V) | B17: ='LISTA DE COMPRAS'!J11 -> 12 | C17: ='LISTA DE COMPRAS'!P11 -> 0.025974026 | E17: =E$11*C17 -> 1538.4544 | F17: =F$11*C17 -> 5.8181818 | G17: 54.53 | H17: =H$11*C17 -> 302.80442 | I17: =I$11*C17 -> 0 | J17: =J$11*C17 -> 3.3766234 | K17: =K$11*C17 -> 0 | L17: =L$11*C17 -> 0 | M17: =M$11*C17 -> 0 | N17: =N$11*C17 -> 0 | O17: =O$11*C17 -> 0 | P17: =P$11*C17 -> 135.61039 | Q17: =Q$11*C17 -> 623.37662 | R17: =R$11*C17 -> 0 | S17: =S$11*C17 -> 0 | T17: =T$11*C17 -> 0 | U17: =U$11*C17 -> 316.88312 | V17: =V$11*C17 -> 36.103896 | W17: =SUM(F17:V17) -> 1478.5032
A18: ='LISTA DE COMPRAS'!C12 -> BAC 28 (127V) | B18: ='LISTA DE COMPRAS'!J12 -> 40 | C18: ='LISTA DE COMPRAS'!P12 -> 0.086580087 | E18: =E$11*C18 -> 5128.1814 | F18: =F$11*C18 -> 19.393939 | G18: =G$11*C18 -> 9.2692641 | H18: =H$11*C18 -> 1009.3481 | I18: =I$11*C18 -> 0 | J18: =J$11*C18 -> 11.255411 | K18: =K$11*C18 -> 0 | L18: =L$11*C18 -> 0 | M18: =M$11*C18 -> 0 | N18: =N$11*C18 -> 0 | O18: =O$11*C18 -> 0 | P18: =P$11*C18 -> 452.03463 | Q18: =Q$11*C18 -> 2077.9221 | R18: =R$11*C18 -> 0 | S18: =S$11*C18 -> 0 | T18: =T$11*C18 -> 0 | U18: =U$11*C18 -> 1056.2771 | V18: =V$11*C18 -> 120.34632 | W18: =SUM(F18:V18) -> 4755.8468
A19: ='LISTA DE COMPRAS'!C13 -> BAC 28A (220V) | B19: ='LISTA DE COMPRAS'!J13 -> 20 | C19: ='LISTA DE COMPRAS'!P13 -> 0.043290043 | E19: =E$11*C19 -> 2564.0907 | F19: 224 | G19: =G$11*C19 -> 4.634632 | H19: =H$11*C19 -> 504.67403 | I19: 0 | J19: =J$11*C19 -> 5.6277056 | K19: 0 | L19: 0 | M19: 0 | N19: 0 | O19: 0 | P19: =P$11*C19 -> 226.01732 | Q19: =Q$11*C19 -> 1038.961 | R19: 0 | S19: 0 | T19: 0 | U19: =U$11*C19 -> 528.13853 | V19: =V$11*C19 -> 60.17316 | W19: =SUM(F19:V19) -> 2592.2264
A20: ='LISTA DE COMPRAS'!C14 -> BAC 120A (220V) | B20: ='LISTA DE COMPRAS'!J14 -> 20 | C20: ='LISTA DE COMPRAS'!P14 -> 0.043290043 | E20: =E$11*C20 -> 2564.0907 | F20: =F$11*C20 -> 9.6969697 | G20: =G$11*C20 -> 4.634632 | H20: =H$11*C20 -> 504.67403 | I20: =I$11*C20 -> 0 | J20: =J$11*C20 -> 5.6277056 | K20: =K$11*C20 -> 0 | L20: =L$11*C20 -> 0 | M20: =M$11*C20 -> 0 | N20: =N$11*C20 -> 0 | O20: =O$11*C20 -> 0 | P20: =P$11*C20 -> 226.01732 | Q20: =Q$11*C20 -> 1038.961 | R20: =R$11*C20 -> 0 | S20: =S$11*C20 -> 0 | T20: =T$11*C20 -> 0 | U20: =U$11*C20 -> 528.13853 | V20: =V$11*C20 -> 60.17316 | W20: =SUM(F20:V20) -> 2377.9234
A21: ='LISTA DE COMPRAS'!C15 -> BAC 120 (127V) | B21: ='LISTA DE COMPRAS'!J15 -> 34 | C21: ='LISTA DE COMPRAS'!P15 -> 0.073593074 | E21: =E$11*C21 -> 4358.9542 | F21: =F$11*C21 -> 16.484848 | G21: 1 | H21: =H$11*C21 -> 857.94584 | I21: =I$11*C21 -> 0 | J21: =J$11*C21 -> 9.5670996 | K21: =K$11*C21 -> 0 | L21: =L$11*C21 -> 0 | M21: =M$11*C21 -> 0 | N21: =N$11*C21 -> 0 | O21: =O$11*C21 -> 0 | P21: =P$11*C21 -> 384.22944 | Q21: =Q$11*C21 -> 1766.2338 | R21: =R$11*C21 -> 0 | S21: =S$11*C21 -> 0 | T21: =T$11*C21 -> 0 | U21: =U$11*C21 -> 897.8355 | V21: =V$11*C21 -> 102.29437 | W21: =SUM(F21:V21) -> 4035.5909
A22: ='LISTA DE COMPRAS'!C16 -> BAC111 (220V) | B22: ='LISTA DE COMPRAS'!J16 -> 14 | C22: ='LISTA DE COMPRAS'!P16 -> 0.03030303 | E22: =E$11*C22 -> 1794.8635 | F22: =F$11*C22 -> 6.7878788 | G22: =G$11*C22 -> 3.2442424 | H22: =H$11*C22 -> 353.27182 | I22: =I$11*C22 -> 0 | J22: =J$11*C22 -> 3.9393939 | K22: =K$11*C22 -> 0 | L22: =L$11*C22 -> 0 | M22: =M$11*C22 -> 0 | N22: =N$11*C22 -> 0 | O22: =O$11*C22 -> 0 | P22: =P$11*C22 -> 158.21212 | Q22: =Q$11*C22 -> 727.27273 | R22: =R$11*C22 -> 0 | S22: =S$11*C22 -> 0 | T22: =T$11*C22 -> 0 | U22: =U$11*C22 -> 369.69697 | V22: =V$11*C22 -> 42.121212 | W22: =SUM(F22:V22) -> 1664.5464
A23: ='LISTA DE COMPRAS'!C17 -> BEC 100GD (127V) | B23: ='LISTA DE COMPRAS'!J17 -> 45 | C23: ='LISTA DE COMPRAS'!P17 -> 0.097402597 | E23: =E$11*C23 -> 5769.2041 | F23: 224 | G23: 55.53 | H23: =H$11*C23 -> 1135.5166 | I23: 0 | J23: =J$11*C23 -> 12.662338 | K23: 0 | L23: 0 | M23: 0 | N23: 0 | O23: 0 | P23: =P$11*C23 -> 508.53896 | Q23: =Q$11*C23 -> 2337.6623 | R23: 0 | S23: 0 | T23: 0 | U23: =U$11*C23 -> 1188.3117 | V23: =V$11*C23 -> 135.38961 | W23: =SUM(F23:V23) -> 5597.6115
A24: ='LISTA DE COMPRAS'!C18 -> BEC 100GDA (220V) | B24: ='LISTA DE COMPRAS'!J18 -> 20 | C24: ='LISTA DE COMPRAS'!P18 -> 0.043290043 | E24: =E$11*C24 -> 2564.0907 | F24: =F$11*C24 -> 9.6969697 | G24: =G$11*C24 -> 4.634632 | H24: =H$11*C24 -> 504.67403 | I24: =I$11*C24 -> 0 | J24: =J$11*C24 -> 5.6277056 | K24: =K$11*C24 -> 0 | L24: =L$11*C24 -> 0 | M24: =M$11*C24 -> 0 | N24: =N$11*C24 -> 0 | O24: =O$11*C24 -> 0 | P24: =P$11*C24 -> 226.01732 | Q24: =Q$11*C24 -> 1038.961 | R24: =R$11*C24 -> 0 | S24: =S$11*C24 -> 0 | T24: =T$11*C24 -> 0 | U24: =U$11*C24 -> 528.13853 | V24: =V$11*C24 -> 60.17316
A25: ='LISTA DE COMPRAS'!C19 -> BEC 100SD (127V) | B25: ='LISTA DE COMPRAS'!J19 -> 36 | C25: ='LISTA DE COMPRAS'!P19 -> 0.077922078 | E25: =E$11*C25 -> 4615.3632 | F25: =F$11*C25 -> 17.454545 | G25: =G$11*C25 -> 8.3423377 | H25: =H$11*C25 -> 908.41325 | I25: =I$11*C25 -> 0 | J25: =J$11*C25 -> 10.12987 | K25: =K$11*C25 -> 0 | L25: =L$11*C25 -> 0 | M25: =M$11*C25 -> 0 | N25: =N$11*C25 -> 0 | O25: =O$11*C25 -> 0 | P25: =P$11*C25 -> 406.83117 | Q25: =Q$11*C25 -> 1870.1299 | R25: =R$11*C25 -> 0 | S25: =S$11*C25 -> 0 | T25: =T$11*C25 -> 0 | U25: =U$11*C25 -> 950.64935 | V25: =V$11*C25 -> 108.31169
A26: ='LISTA DE COMPRAS'!C20 -> UCH50BA (220V) | B26: ='LISTA DE COMPRAS'!J20 -> 5 | C26: ='LISTA DE COMPRAS'!P20 -> 0.010822511 | E26: =E$11*C26 -> 641.02267 | F26: =F$11*C26 -> 2.4242424 | G26: =G$11*C26 -> 1.158658 | H26: =H$11*C26 -> 126.16851 | I26: =I$11*C26 -> 0 | J26: =J$11*C26 -> 1.4069264 | K26: =K$11*C26 -> 0 | L26: =L$11*C26 -> 0 | M26: =M$11*C26 -> 0 | N26: =N$11*C26 -> 0 | O26: =O$11*C26 -> 0 | P26: =P$11*C26 -> 56.504329 | Q26: =Q$11*C26 -> 259.74026 | R26: =R$11*C26 -> 0 | S26: =S$11*C26 -> 0 | T26: =T$11*C26 -> 0 | U26: =U$11*C26 -> 132.03463 | V26: =V$11*C26 -> 15.04329
A27: ='LISTA DE COMPRAS'!C21 -> UCH150SA (220V) | B27: ='LISTA DE COMPRAS'!J21 -> 2 | C27: ='LISTA DE COMPRAS'!P21 -> 0.0043290043 | E27: =E$11*C27 -> 256.40907 | F27: 224 | G27: 2 | H27: =H$11*C27 -> 50.467403 | I27: 0 | J27: =J$11*C27 -> 0.56277056 | K27: 0 | L27: 0 | M27: 0 | N27: 0 | O27: 0 | P27: =P$11*C27 -> 22.601732 | Q27: =Q$11*C27 -> 103.8961 | R27: 0 | S27: 0 | T27: 0 | U27: =U$11*C27 -> 52.813853 | V27: =V$11*C27 -> 6.017316
A28: ='LISTA DE COMPRAS'!C22 -> BEC 100SDA (220V) | B28: ='LISTA DE COMPRAS'!J22 -> 13 | C28: ='LISTA DE COMPRAS'!P22 -> 0.028138528 | E28: =E$11*C28 -> 1666.659 | F28: =F$11*C28 -> 6.3030303 | G28: =G$11*C28 -> 3.0125108 | H28: =H$11*C28 -> 328.03812 | I28: =I$11*C28 -> 0 | J28: =J$11*C28 -> 3.6580087 | K28: =K$11*C28 -> 0 | L28: =L$11*C28 -> 0 | M28: =M$11*C28 -> 0 | N28: =N$11*C28 -> 0 | O28: =O$11*C28 -> 0 | P28: =P$11*C28 -> 146.91126 | Q28: =Q$11*C28 -> 675.32468 | R28: =R$11*C28 -> 0 | S28: =S$11*C28 -> 0 | T28: =T$11*C28 -> 0 | U28: =U$11*C28 -> 343.29004 | V28: =V$11*C28 -> 39.112554
A29: ='LISTA DE COMPRAS'!C23 -> SPARE PARTS | B29: ='LISTA DE COMPRAS'!J23 -> 5 | C29: ='LISTA DE COMPRAS'!P23 -> 0.010822511 | E29: =E$11*C29 -> 641.02267 | F29: =F$11*C29 -> 2.4242424 | G29: 56.53 | H29: =H$11*C29 -> 126.16851 | I29: =I$11*C29 -> 0 | J29: =J$11*C29 -> 1.4069264 | K29: =K$11*C29 -> 0 | L29: =L$11*C29 -> 0 | M29: =M$11*C29 -> 0 | N29: =N$11*C29 -> 0 | O29: =O$11*C29 -> 0 | P29: =P$11*C29 -> 56.504329 | Q29: =Q$11*C29 -> 259.74026 | R29: =R$11*C29 -> 0 | S29: =S$11*C29 -> 0 | T29: =T$11*C29 -> 0 | U29: =U$11*C29 -> 132.03463 | V29: =V$11*C29 -> 15.04329
A30: ='LISTA DE COMPRAS'!C24 -> SPARE PARTS | B30: ='LISTA DE COMPRAS'!J24 -> 2 | C30: ='LISTA DE COMPRAS'!P24 -> 0.0043290043 | E30: =E$11*C30 -> 256.40907 | F30: =F$11*C30 -> 0.96969697 | G30: 57.53 | H30: =H$11*C30 -> 50.467403 | I30: =I$11*C30 -> 0 | J30: =J$11*C30 -> 0.56277056 | K30: =K$11*C30 -> 0 | L30: =L$11*C30 -> 0 | M30: =M$11*C30 -> 0 | N30: =N$11*C30 -> 0 | O30: =O$11*C30 -> 0 | P30: =P$11*C30 -> 22.601732 | Q30: =Q$11*C30 -> 103.8961 | R30: =R$11*C30 -> 0 | S30: =S$11*C30 -> 0 | T30: =T$11*C30 -> 0 | U30: =U$11*C30 -> 52.813853 | V30: =V$11*C30 -> 6.017316
