Workbook

Sheet EXW
A1: TABELA EXPORTAÇÃO - MOVELSUL 2026
A2: MODELO | C2: COMP. MONTADO | D2: PROF. MONTADO | E2: ALTURA MONTADO | F2: COMP (m) EMABALADO | G2: PROF (m) EMBALADO | H2: ALTURA (m) EMBALADO | I2: VOL (m³) | J2: QTD NO CAMINHÃO | K2: QTD NO CONTAINER | L2: COMPOSIÇÃO | M2: LINHA | N2: VALOR EM REAIS (UND) | O2: VALOR EM EXW (DÓLAR) (UND)
B3: BALDUZZI | C3: 1 LUGAR COM BRAÇO 1,08m | D3: 1.14 | E3: 0.9 | F3: 1.1 | G3: 1.16 | H3: 0.8 | I3: =F3*G3*H3 -> 1.0208 | J3: ='BASE DE CÁLCULO'!$B$3/EXW!$I3 -> 107.75862 | K3: ='BASE DE CÁLCULO'!$B$2/EXW!$I3 -> 70.532915 | L3: MÓDULO - 1 LUGAR COMBRAÇO - Assento s/bç: 0,75m | M3: TC-10 | N3: 1395 | O3: =SUM(N3/'BASE DE CÁLCULO'!$B$13) -> 288.81988
F4: 1.1 | G4: 1.16 | H4: 0.8 | I4: =F4*G4*H4 -> 1.0208 | J4: ='BASE DE CÁLCULO'!$B$3/EXW!$I4 -> 107.75862 | K4: ='BASE DE CÁLCULO'!$B$2/EXW!$I4 -> 70.532915 | M4: TC-12 | N4: 1361 | O4: =SUM(N4/'BASE DE CÁLCULO'!$B$13) -> 281.78054
F5: 1.1 | G5: 1.16 | H5: 0.8 | I5: =F5*G5*H5 -> 1.0208 | J5: ='BASE DE CÁLCULO'!$B$3/EXW!$I5 -> 107.75862 | K5: ='BASE DE CÁLCULO'!$B$2/EXW!$I5 -> 70.532915 | M5: TC-13 | N5: 1415 | O5: =SUM(N5/'BASE DE CÁLCULO'!$B$13) -> 292.96066
F6: 1.1 | G6: 1.16 | H6: 0.8 | I6: =F6*G6*H6 -> 1.0208 | J6: ='BASE DE CÁLCULO'!$B$3/EXW!$I6 -> 107.75862 | K6: ='BASE DE CÁLCULO'!$B$2/EXW!$I6 -> 70.532915 | M6: TC-14 | N6: 1440 | O6: =SUM(N6/'BASE DE CÁLCULO'!$B$13) -> 298.13665
F7: 1.1 | G7: 1.16 | H7: 0.8 | I7: =F7*G7*H7 -> 1.0208 | J7: ='BASE DE CÁLCULO'!$B$3/EXW!$I7 -> 107.75862 | K7: ='BASE DE CÁLCULO'!$B$2/EXW!$I7 -> 70.532915 | M7: TC-16 | N7: 1495 | O7: =SUM(N7/'BASE DE CÁLCULO'!$B$13) -> 309.52381
C8: 1 LUGAR COM BRAÇO 1,18m | D8: 1.14 | E8: 0.9 | F8: 1.2 | G8: 1.16 | H8: 0.8 | I8: =F8*G8*H8 -> 1.1136 | J8: ='BASE DE CÁLCULO'!$B$3/EXW!$I8 -> 98.778736 | K8: ='BASE DE CÁLCULO'!$B$2/EXW!$I8 -> 64.655172 | L8: MÓDULO - 1 LUGAR COMBRAÇO - Assento s/bç: 0,85m | M8: TC-10 | N8: 1455 | O8: =SUM(N8/'BASE DE CÁLCULO'!$B$13) -> 301.24224
F9: 1.2 | G9: 1.16 | H9: 0.8 | I9: =F9*G9*H9 -> 1.1136 | J9: ='BASE DE CÁLCULO'!$B$3/EXW!$I9 -> 98.778736 | K9: ='BASE DE CÁLCULO'!$B$2/EXW!$I9 -> 64.655172 | M9: TC-12 | N9: 1415 | O9: =SUM(N9/'BASE DE CÁLCULO'!$B$13) -> 292.96066
F10: 1.2 | G10: 1.16 | H10: 0.8 | I10: =F10*G10*H10 -> 1.1136 | J10: ='BASE DE CÁLCULO'!$B$3/EXW!$I10 -> 98.778736 | K10: ='BASE DE CÁLCULO'!$B$2/EXW!$I10 -> 64.655172 | M10: TC-13 | N10: 1475 | O10: =SUM(N10/'BASE DE CÁLCULO'!$B$13) -> 305.38302
F11: 1.2 | G11: 1.16 | H11: 0.8 | I11: =F11*G11*H11 -> 1.1136 | J11: ='BASE DE CÁLCULO'!$B$3/EXW!$I11 -> 98.778736 | K11: ='BASE DE CÁLCULO'!$B$2/EXW!$I11 -> 64.655172 | M11: TC-14 | N11: 1505 | O11: =SUM(N11/'BASE DE CÁLCULO'!$B$13) -> 311.5942
F12: 1.2 | G12: 1.16 | H12: 0.8 | I12: =F12*G12*H12 -> 1.1136 | J12: ='BASE DE CÁLCULO'!$B$3/EXW!$I12 -> 98.778736 | K12: ='BASE DE CÁLCULO'!$B$2/EXW!$I12 -> 64.655172 | M12: TC-16 | N12: 1565 | O12: =SUM(N12/'BASE DE CÁLCULO'!$B$13) -> 324.01656
C13: 1 LUGAR COM BRAÇO 1,28m | D13: 1.14 | E13: 0.9 | F13: 1.3 | G13: 1.16 | H13: 0.8 | I13: =F13*G13*H13 -> 1.2064 | J13: ='BASE DE CÁLCULO'!$B$3/EXW!$I13 -> 91.180371 | K13: ='BASE DE CÁLCULO'!$B$2/EXW!$I13 -> 59.681698 | L13: MÓDULO - 1 LUGAR COMBRAÇO - Assento s/bç: 0,95m | M13: TC-10 | N13: 1505 | O13: =SUM(N13/'BASE DE CÁLCULO'!$B$13) -> 311.5942
F14: 1.3 | G14: 1.16 | H14: 0.8 | I14: =F14*G14*H14 -> 1.2064 | J14: ='BASE DE CÁLCULO'!$B$3/EXW!$I14 -> 91.180371 | K14: ='BASE DE CÁLCULO'!$B$2/EXW!$I14 -> 59.681698 | M14: TC-12 | N14: 1470 | O14: =SUM(N14/'BASE DE CÁLCULO'!$B$13) -> 304.34783
F15: 1.3 | G15: 1.16 | H15: 0.8 | I15: =F15*G15*H15 -> 1.2064 | J15: ='BASE DE CÁLCULO'!$B$3/EXW!$I15 -> 91.180371 | K15: ='BASE DE CÁLCULO'!$B$2/EXW!$I15 -> 59.681698 | M15: TC-13 | N15: 1530 | O15: =SUM(N15/'BASE DE CÁLCULO'!$B$13) -> 316.77019
F16: 1.3 | G16: 1.16 | H16: 0.8 | I16: =F16*G16*H16 -> 1.2064 | J16: ='BASE DE CÁLCULO'!$B$3/EXW!$I16 -> 91.180371 | K16: ='BASE DE CÁLCULO'!$B$2/EXW!$I16 -> 59.681698 | M16: TC-14 | N16: 1560 | O16: =SUM(N16/'BASE DE CÁLCULO'!$B$13) -> 322.98137
F17: 1.3 | G17: 1.16 | H17: 0.8 | I17: =F17*G17*H17 -> 1.2064 | J17: ='BASE DE CÁLCULO'!$B$3/EXW!$I17 -> 91.180371 | K17: ='BASE DE CÁLCULO'!$B$2/EXW!$I17 -> 59.681698 | M17: TC-16 | N17: 1620 | O17: =SUM(N17/'BASE DE CÁLCULO'!$B$13) -> 335.40373
C18: 1 LUGAR SEM BRAÇO 0,75m | D18: 1.14 | E18: 0.9 | F18: 0.77 | G18: 1.16 | H18: 0.8 | I18: =F18*G18*H18 -> 0.71456 | J18: ='BASE DE CÁLCULO'!$B$3/EXW!$I18 -> 153.94089 | K18: ='BASE DE CÁLCULO'!$B$2/EXW!$I18 -> 100.76131 | L18: MÓDULO - 1 LUGAR SEMBRAÇO - Assento s/bç: 0,75m | M18: TC-10 | N18: 1230 | O18: =SUM(N18/'BASE DE CÁLCULO'!$B$13) -> 254.65839
F19: 0.77 | G19: 1.16 | H19: 0.8 | I19: =F19*G19*H19 -> 0.71456 | J19: ='BASE DE CÁLCULO'!$B$3/EXW!$I19 -> 153.94089 | K19: ='BASE DE CÁLCULO'!$B$2/EXW!$I19 -> 100.76131 | M19: TC-12 | N19: 1205 | O19: =SUM(N19/'BASE DE CÁLCULO'!$B$13) -> 249.4824
F20: 0.77 | G20: 1.16 | H20: 0.8 | I20: =F20*G20*H20 -> 0.71456 | J20: ='BASE DE CÁLCULO'!$B$3/EXW!$I20 -> 153.94089 | K20: ='BASE DE CÁLCULO'!$B$2/EXW!$I20 -> 100.76131 | M20: TC-13 | N20: 1250 | O20: =SUM(N20/'BASE DE CÁLCULO'!$B$13) -> 258.79917
F21: 0.77 | G21: 1.16 | H21: 0.8 | I21: =F21*G21*H21 -> 0.71456 | J21: ='BASE DE CÁLCULO'!$B$3/EXW!$I21 -> 153.94089 | K21: ='BASE DE CÁLCULO'!$B$2/EXW!$I21 -> 100.76131 | M21: TC-14 | N21: 1265 | O21: =SUM(N21/'BASE DE CÁLCULO'!$B$13) -> 261.90476
F22: 0.77 | G22: 1.16 | H22: 0.8 | I22: =F22*G22*H22 -> 0.71456 | J22: ='BASE DE CÁLCULO'!$B$3/EXW!$I22 -> 153.94089 | K22: ='BASE DE CÁLCULO'!$B$2/EXW!$I22 -> 100.76131 | M22: TC-16 | N22: 1305 | O22: =SUM(N22/'BASE DE CÁLCULO'!$B$13) -> 270.18634
C23: 1 LUGAR SEM BRAÇO 0,85m | D23: 1.14 | E23: 0.9 | F23: 0.87 | G23: 1.16 | H23: 0.8 | I23: =F23*G23*H23 -> 0.80736 | J23: ='BASE DE CÁLCULO'!$B$3/EXW!$I23 -> 136.24653 | K23: ='BASE DE CÁLCULO'!$B$2/EXW!$I23 -> 89.179548 | L23: MÓDULO - 1 LUGAR SEMBRAÇO - Assento s/bç: 0,85m | M23: TC-10 | N23: 1285 | O23: =SUM(N23/'BASE DE CÁLCULO'!$B$13) -> 266.04555
F24: 0.87 | G24: 1.16 | H24: 0.8 | I24: =F24*G24*H24 -> 0.80736 | J24: ='BASE DE CÁLCULO'!$B$3/EXW!$I24 -> 136.24653 | K24: ='BASE DE CÁLCULO'!$B$2/EXW!$I24 -> 89.179548 | M24: TC-12 | N24: 1255 | O24: =SUM(N24/'BASE DE CÁLCULO'!$B$13) -> 259.83437
F25: 0.87 | G25: 1.16 | H25: 0.8 | I25: =F25*G25*H25 -> 0.80736 | J25: ='BASE DE CÁLCULO'!$B$3/EXW!$I25 -> 136.24653 | K25: ='BASE DE CÁLCULO'!$B$2/EXW!$I25 -> 89.179548 | M25: TC-13 | N25: 1299 | O25: =SUM(N25/'BASE DE CÁLCULO'!$B$13) -> 268.9441
F26: 0.87 | G26: 1.16 | H26: 0.8 | I26: =F26*G26*H26 -> 0.80736 | J26: ='BASE DE CÁLCULO'!$B$3/EXW!$I26 -> 136.24653 | K26: ='BASE DE CÁLCULO'!$B$2/EXW!$I26 -> 89.179548 | M26: TC-14 | N26: 1320 | O26: =SUM(N26/'BASE DE CÁLCULO'!$B$13) -> 273.29193
F27: 0.87 | G27: 1.16 | H27: 0.8 | I27: =F27*G27*H27 -> 0.80736 | J27: ='BASE DE CÁLCULO'!$B$3/EXW!$I27 -> 136.24653 | K27: ='BASE DE CÁLCULO'!$B$2/EXW!$I27 -> 89.179548 | M27: TC-16 | N27: 1365 | O27: =SUM(N27/'BASE DE CÁLCULO'!$B$13) -> 282.6087
C28: 1 LUGAR SEM BRAÇO 0,95m | D28: 1.14 | E28: 0.9 | F28: 0.97 | G28: 1.16 | H28: 0.8 | I28: =F28*G28*H28 -> 0.90016 | J28: ='BASE DE CÁLCULO'!$B$3/EXW!$I28 -> 122.2005 | K28: ='BASE DE CÁLCULO'!$B$2/EXW!$I28 -> 79.98578 | L28: MÓDULO - 1 LUGAR SEMBRAÇO - Assento s/bç: 0,95m | M28: TC-10 | N28: 1340 | O28: =SUM(N28/'BASE DE CÁLCULO'!$B$13) -> 277.43271
F29: 0.97 | G29: 1.16 | H29: 0.8 | I29: =F29*G29*H29 -> 0.90016 | J29: ='BASE DE CÁLCULO'!$B$3/EXW!$I29 -> 122.2005 | K29: ='BASE DE CÁLCULO'!$B$2/EXW!$I29 -> 79.98578 | M29: TC-12 | N29: 1310 | O29: =SUM(N29/'BASE DE CÁLCULO'!$B$13) -> 271.22153
F30: 0.97 | G30: 1.16 | H30: 0.8 | I30: =F30*G30*H30 -> 0.90016 | J30: ='BASE DE CÁLCULO'!$B$3/EXW!$I30 -> 122.2005 | K30: ='BASE DE CÁLCULO'!$B$2/EXW!$I30 -> 79.98578 | M30: TC-13 | N30: 1360 | O30: =SUM(N30/'BASE DE CÁLCULO'!$B$13) -> 281.5735
F31: 0.97 | G31: 1.16 | H31: 0.8 | I31: =F31*G31*H31 -> 0.90016 | J31: ='BASE DE CÁLCULO'!$B$3/EXW!$I31 -> 122.2005 | K31: ='BASE DE CÁLCULO'!$B$2/EXW!$I31 -> 79.98578 | M31: TC-14 | N31: 1380 | O31: =SUM(N31/'BASE DE CÁLCULO'!$B$13) -> 285.71429
F32: 0.97 | G32: 1.16 | H32: 0.8 | I32: =F32*G32*H32 -> 0.90016 | J32: ='BASE DE CÁLCULO'!$B$3/EXW!$I32 -> 122.2005 | K32: ='BASE DE CÁLCULO'!$B$2/EXW!$I32 -> 79.98578 | M32: TC-16 | N32: 1430 | O32: =SUM(N32/'BASE DE CÁLCULO'!$B$13) -> 296.06625
C33: CHAISE 1,08m | D33: 1.59 | E33: 0.9 | F33: 1.1 | G33: 1.61 | H33: 0.8 | I33: =F33*G33*H33 -> 1.4168 | J33: ='BASE DE CÁLCULO'!$B$3/EXW!$I33 -> 77.639752 | K33: ='BASE DE CÁLCULO'!$B$2/EXW!$I33 -> 50.818746 | L33: MÓDULO CHAISE - Assento s/bç: 0,75m | M33: TC-10 | N33: 1550 | O33: =SUM(N33/'BASE DE CÁLCULO'!$B$13) -> 320.91097
F34: 1.1 | G34: 1.61 | H34: 0.8 | I34: =F34*G34*H34 -> 1.4168 | J34: ='BASE DE CÁLCULO'!$B$3/EXW!$I34 -> 77.639752 | K34: ='BASE DE CÁLCULO'!$B$2/EXW!$I34 -> 50.818746 | M34: TC-12 | N34: 1510 | O34: =SUM(N34/'BASE DE CÁLCULO'!$B$13) -> 312.6294
F35: 1.1 | G35: 1.61 | H35: 0.8 | I35: =F35*G35*H35 -> 1.4168 | J35: ='BASE DE CÁLCULO'!$B$3/EXW!$I35 -> 77.639752 | K35: ='BASE DE CÁLCULO'!$B$2/EXW!$I35 -> 50.818746 | M35: TC-13 | N35: 1570 | O35: =SUM(N35/'BASE DE CÁLCULO'!$B$13) -> 325.05176
F36: 1.1 | G36: 1.61 | H36: 0.8 | I36: =F36*G36*H36 -> 1.4168 | J36: ='BASE DE CÁLCULO'!$B$3/EXW!$I36 -> 77.639752 | K36: ='BASE DE CÁLCULO'!$B$2/EXW!$I36 -> 50.818746 | M36: TC-14 | N36: 1599 | O36: =SUM(N36/'BASE DE CÁLCULO'!$B$13) -> 331.0559
F37: 1.1 | G37: 1.61 | H37: 0.8 | I37: =F37*G37*H37 -> 1.4168 | J37: ='BASE DE CÁLCULO'!$B$3/EXW!$I37 -> 77.639752 | K37: ='BASE DE CÁLCULO'!$B$2/EXW!$I37 -> 50.818746 | M37: TC-16 | N37: 1670 | O37: =SUM(N37/'BASE DE CÁLCULO'!$B$13) -> 345.75569
C38: CHAISE 1,18m | D38: 1.59 | E38: 0.9 | F38: 1.2 | G38: 1.61 | H38: 0.8 | I38: =F38*G38*H38 -> 1.5456 | J38: ='BASE DE CÁLCULO'!$B$3/EXW!$I38 -> 71.169772 | K38: ='BASE DE CÁLCULO'!$B$2/EXW!$I38 -> 46.583851 | L38: MÓDULO CHAISE - Assento s/bç: 0,85m | M38: TC-10 | N38: 1610 | O38: =SUM(N38/'BASE DE CÁLCULO'!$B$13) -> 333.33333
F39: 1.2 | G39: 1.61 | H39: 0.8 | I39: =F39*G39*H39 -> 1.5456 | J39: ='BASE DE CÁLCULO'!$B$3/EXW!$I39 -> 71.169772 | K39: ='BASE DE CÁLCULO'!$B$2/EXW!$I39 -> 46.583851 | M39: TC-12 | N39: 1570 | O39: =SUM(N39/'BASE DE CÁLCULO'!$B$13) -> 325.05176
F40: 1.2 | G40: 1.61 | H40: 0.8 | I40: =F40*G40*H40 -> 1.5456 | J40: ='BASE DE CÁLCULO'!$B$3/EXW!$I40 -> 71.169772 | K40: ='BASE DE CÁLCULO'!$B$2/EXW!$I40 -> 46.583851 | M40: TC-13 | N40: 1640 | O40: =SUM(N40/'BASE DE CÁLCULO'!$B$13) -> 339.54451
...

Sheet BASE DE CÁLCULO
A1: TRANSPORTE
A2: CONTEINER 40' HC - CBMS | B2: 72
A3: CAMINHÃO | B3: 110
A11: COTAÇÃO
A12: Dólar | B12: 5.18
A13: COTAÇÃO UTILIZADA CÁLCULO | B13: =SUM(B12-0.35) -> 4.83
A15: FOB PARANAGUÁ | B15: 14750
A16: FCA FÁBRICA | B16: 2000
A19: DESPESAS COM FRETE TERRESTE E DESPACHO ADUANEIRO|FOB Marítimo
A20: Frete até o Porto de Paranaguá | B20: 9500
A21: Despesas Portuárias de Registro e Documentos | B21: =3600 -> 3600
A22: Despesas c/ Despachante Aduaneiro | B22: 1650
A23: Despesas Courier | B23: 500
A24: TOTAL | B24: =SUM(B20:B23) -> 15250
