Workbook

Sheet LIVINTUS COURO
A1: TABELA EXPORTAÇÃO - MOVELSUL 2026
A2: MODELO | C2: COMP. | D2: ALTURA | E2: PROF. | F2: COMPOSIÇÃO | G2: LINHA | H2: VALOR EM REAIS (UNITÁRIO) | I2: VALOR EM EXW (UNITÁRIO)
B3: MILANO | C3: ASSENTO 1,00m | D3: 0,46m | E3: 1,00m | F3: MÓDULO ASSENTO | G3: CO-5 | H3: 1110 | I3: =SUM(H3/'BASE CÁLCULO'!$B$13) -> 229.81366
G4: CO-6 | H4: 1185 | I4: =SUM(H4/'BASE CÁLCULO'!$B$13) -> 245.34161
G5: CO-7 | H5: 1245 | I5: =SUM(H5/'BASE CÁLCULO'!$B$13) -> 257.76398
C6: ASSENTO 1,20m | D6: 0,46m | E6: 1,00m | F6: MÓDULO ASSENTO | G6: CO-5 | H6: 1265 | I6: =SUM(H6/'BASE CÁLCULO'!$B$13) -> 261.90476
G7: CO-6 | H7: 1350 | I7: =SUM(H7/'BASE CÁLCULO'!$B$13) -> 279.50311
G8: CO-7 | H8: 1420 | I8: =SUM(H8/'BASE CÁLCULO'!$B$13) -> 293.99586
C9: ASSENTO 1,40m | D9: 0,46m | E9: 1,00m | F9: MÓDULO ASSENTO | G9: CO-5 | H9: 1425 | I9: =SUM(H9/'BASE CÁLCULO'!$B$13) -> 295.03106
G10: CO-6 | H10: 1515 | I10: =SUM(H10/'BASE CÁLCULO'!$B$13) -> 313.6646
G11: CO-7 | H11: 1595 | I11: =SUM(H11/'BASE CÁLCULO'!$B$13) -> 330.22774
C12: ASSENTO 1,60m | D12: 0,46m | E12: 1,00m | F12: MÓDULO ASSENTO | G12: CO-5 | H12: 1635 | I12: =SUM(H12/'BASE CÁLCULO'!$B$13) -> 338.50932
G13: CO-6 | H13: 1740 | I13: =SUM(H13/'BASE CÁLCULO'!$B$13) -> 360.24845
G14: CO-7 | H14: 1825 | I14: =SUM(H14/'BASE CÁLCULO'!$B$13) -> 377.84679
C15: ASSENTO 1,80m | D15: 0,46m | E15: 1,00m | F15: MÓDULO ASSENTO | G15: CO-5 | H15: 1870 | I15: =SUM(H15/'BASE CÁLCULO'!$B$13) -> 387.16356
G16: CO-6 | H16: 1985 | I16: =SUM(H16/'BASE CÁLCULO'!$B$13) -> 410.97308
G17: CO-7 | H17: 2085 | I17: =SUM(H17/'BASE CÁLCULO'!$B$13) -> 431.67702
C18: ASSENTO 2,00m | D18: 0,46m | E18: 1,00m | F18: MÓDULO ASSENTO | G18: CO-5 | H18: 2160 | I18: =SUM(H18/'BASE CÁLCULO'!$B$13) -> 447.20497
G19: CO-6 | H19: 2295 | I19: =SUM(H19/'BASE CÁLCULO'!$B$13) -> 475.15528
G20: CO-7 | H20: 2405 | I20: =SUM(H20/'BASE CÁLCULO'!$B$13) -> 497.92961
C21: ALMOFADA ENCOSTO 0,60m | D21: 0,50m | E21: - | F21: ALMOFADA ENCOSTO | G21: CO-5 | H21: 160 | I21: =SUM(H21/'BASE CÁLCULO'!$B$13) -> 33.126294
G22: CO-6 | H22: 175 | I22: =SUM(H22/'BASE CÁLCULO'!$B$13) -> 36.231884
G23: CO-7 | H23: 190 | I23: =SUM(H23/'BASE CÁLCULO'!$B$13) -> 39.337474
C24: ALMOFADA ENCOSTO 0,90m | D24: 0,50m | E24: - | F24: ALMOFADA ENCOSTO | G24: CO-5 | H24: 205 | I24: =SUM(H24/'BASE CÁLCULO'!$B$13) -> 42.443064
G25: CO-6 | H25: 225 | I25: =SUM(H25/'BASE CÁLCULO'!$B$13) -> 46.583851
G26: CO-7 | H26: 240 | I26: =SUM(H26/'BASE CÁLCULO'!$B$13) -> 49.689441
C27: BASE DO ENCOSTO 0,60m | D27: 0.29 | E27: 0,624m | F27: BASE DO ENCOSTO | G27: CO-5 | H27: 285 | I27: =SUM(H27/'BASE CÁLCULO'!$B$13) -> 59.006211
G28: CO-6 | H28: 295 | I28: =SUM(H28/'BASE CÁLCULO'!$B$13) -> 61.076605
G29: CO-7 | H29: 305 | I29: =SUM(H29/'BASE CÁLCULO'!$B$13) -> 63.146998
C30: BASE DO ENCOSTO 0,90m | D30: 0.29 | E30: 0,624m | F30: BASE DO ENCOSTO | G30: CO-5 | H30: 325 | I30: =SUM(H30/'BASE CÁLCULO'!$B$13) -> 67.287785
G31: CO-6 | H31: 345 | I31: =SUM(H31/'BASE CÁLCULO'!$B$13) -> 71.428571
G32: CO-7 | H32: 360 | I32: =SUM(H32/'BASE CÁLCULO'!$B$13) -> 74.534161
C33: PUFF 0,32m | D33: 0,46m | E33: 1,00m | F33: PUFF | G33: CO-5 | H33: 620 | I33: =SUM(H33/'BASE CÁLCULO'!$B$13) -> 128.36439
G34: CO-6 | H34: 660 | I34: =SUM(H34/'BASE CÁLCULO'!$B$13) -> 136.64596
G35: CO-7 | H35: 695 | I35: =SUM(H35/'BASE CÁLCULO'!$B$13) -> 143.89234
C36: BRAÇO 0,24m | D36: 0,14m | E36: 0,76m | F36: BRAÇO | G36: CO-5 | H36: 255 | I36: =SUM(H36/'BASE CÁLCULO'!$B$13) -> 52.795031
G37: CO-6 | H37: 265 | I37: =SUM(H37/'BASE CÁLCULO'!$B$13) -> 54.865424
G38: CO-7 | H38: 280 | I38: =SUM(H38/'BASE CÁLCULO'!$B$13) -> 57.971014
B39: BALDUZZI | C39: 1 LUGAR COM BRAÇO 1,08m | D39: 0,90m | E39: 1,14m | F39: MÓDULO - 1 LUGAR COM BRAÇO - Assento s/bç: 0,75m | G39: CO-5 | H39: 2445 | I39: =SUM(H39/'BASE CÁLCULO'!$B$13) -> 506.21118
G40: CO-6 | H40: 2559 | I40: =SUM(H40/'BASE CÁLCULO'!$B$13) -> 529.81366
...

Sheet BASE CÁLCULO
A1: TRANSPORTE
A2: CONTEINER 40' HC - CBMS | B2: 72
A3: CAMINHÃO | B3: 110
A11: COTAÇÃO
A12: Cotação Dólar | B12: 5.18 | D12: 5,77 Foi o dola ussado para os primeiros clientes
A13: COTAÇÃO UTILIZADA CÁCULO | B13: =SUM(B12-0.35) -> 4.83
A15: FOB PARANAGUÁ | B15: 14750
A16: FCA FÁBRICA | B16: 2000
A19: DESPESAS COM FRETE TERRESTE E DESPACHO ADUANEIRO|FOB Marítimo
A20: Frete até o Porto de Paranaguá | B20: 9500
A21: Despesas Portuárias de Registro e Documentos | B21: 3600
A22: Despesas c/ Despachante Aduaneiro | B22: 1650
A23: Despesas Courier | B23: 500
A24: TOTAL | B24: =SUM(B20:B23) -> 15250
